Workbook

Sheet Table B1
A1: Table B1: Policy Benchmark Returns of Conflicted and Unconflicted CIOs
A2: This table reports results of tests that regress the return of a plan's total-fund policy benchmark on Conflicted CIO, which is equal to 1 for all years prior to the plan's investment officer's departure for a position with a pension plan vendor and 0 otherwise. The dependent variable is the fiscal-year return of the plan's policy benchmark, in percent, as reported in the plan's financial statements. All columns include fiscal-year-end date fixed effects, so plans are compared only with plans whose fiscal year covers the same twelve months. Columns 2 to 4 add the plan's target allocation to each asset class (cash omitted), and Columns 3 and 4 add the control variables of Table III. Column 4 adds plan fixed effects. The standard errors are double clustered by plan and year. Coefficients marked with ***, **, and * are significant at the 1%, 5%, and 10% level, respectively.
B4: (1) | C4: (2) | D4: (3) | E4: (4)
B5: Benchmark Ret. (t) | C5: Benchmark Ret. (t) | D5: Benchmark Ret. (t) | E5: Benchmark Ret. (t)
A6: Conflicted CIO (0/1) | B6: =IF(Estimates!H4="","n/a",TEXT(Estimates!D4,"0.000")&IF(Estimates!H4<0.01,"***",IF(Estimates!H4<0.05,"**",IF(Estimates!H4<0.1,"*","")))) -> -0.153 | C6: =IF(Estimates!H5="","n/a",TEXT(Estimates!D5,"0.000")&IF(Estimates!H5<0.01,"***",IF(Estimates!H5<0.05,"**",IF(Estimates!H5<0.1,"*","")))) -> 0.002 | D6: =IF(Estimates!H6="","n/a",TEXT(Estimates!D6,"0.000")&IF(Estimates!H6<0.01,"***",IF(Estimates!H6<0.05,"**",IF(Estimates!H6<0.1,"*","")))) -> 0.000 | E6: =IF(Estimates!H7="","n/a",TEXT(Estimates!D7,"0.000")&IF(Estimates!H7<0.01,"***",IF(Estimates!H7<0.05,"**",IF(Estimates!H7<0.1,"*","")))) -> -0.096
B7: =IF(Estimates!G4="","","("&TEXT(Estimates!G4,"0.00")&")") -> (-0.56) | C7: =IF(Estimates!G5="","","("&TEXT(Estimates!G5,"0.00")&")") -> (0.01) | D7: =IF(Estimates!G6="","","("&TEXT(Estimates!G6,"0.00")&")") -> (0.00) | E7: =IF(Estimates!G7="","","("&TEXT(Estimates!G7,"0.00")&")") -> (-0.15)
A8: Equity Target Allocation (%) | C8: =IF(Estimates!H8="","n/a",TEXT(Estimates!D8,"0.000")&IF(Estimates!H8<0.01,"***",IF(Estimates!H8<0.05,"**",IF(Estimates!H8<0.1,"*","")))) -> 0.141* | D8: =IF(Estimates!H9="","n/a",TEXT(Estimates!D9,"0.000")&IF(Estimates!H9<0.01,"***",IF(Estimates!H9<0.05,"**",IF(Estimates!H9<0.1,"*","")))) -> 0.167** | E8: =IF(Estimates!H10="","n/a",TEXT(Estimates!D10,"0.000")&IF(Estimates!H10<0.01,"***",IF(Estimates!H10<0.05,"**",IF(Estimates!H10<0.1,"*","")))) -> 0.181*
C9: =IF(Estimates!G8="","","("&TEXT(Estimates!G8,"0.00")&")") -> (1.88) | D9: =IF(Estimates!G9="","","("&TEXT(Estimates!G9,"0.00")&")") -> (2.21) | E9: =IF(Estimates!G10="","","("&TEXT(Estimates!G10,"0.00")&")") -> (1.76)
A10: Fixed Income Target Allocation (%) | C10: =IF(Estimates!H11="","n/a",TEXT(Estimates!D11,"0.000")&IF(Estimates!H11<0.01,"***",IF(Estimates!H11<0.05,"**",IF(Estimates!H11<0.1,"*","")))) -> 0.148* | D10: =IF(Estimates!H12="","n/a",TEXT(Estimates!D12,"0.000")&IF(Estimates!H12<0.01,"***",IF(Estimates!H12<0.05,"**",IF(Estimates!H12<0.1,"*","")))) -> 0.171** | E10: =IF(Estimates!H13="","n/a",TEXT(Estimates!D13,"0.000")&IF(Estimates!H13<0.01,"***",IF(Estimates!H13<0.05,"**",IF(Estimates!H13<0.1,"*","")))) -> 0.219
C11: =IF(Estimates!G11="","","("&TEXT(Estimates!G11,"0.00")&")") -> (1.97) | D11: =IF(Estimates!G12="","","("&TEXT(Estimates!G12,"0.00")&")") -> (2.14) | E11: =IF(Estimates!G13="","","("&TEXT(Estimates!G13,"0.00")&")") -> (1.67)
A12: Real Estate Target Allocation (%) | C12: =IF(Estimates!H14="","n/a",TEXT(Estimates!D14,"0.000")&IF(Estimates!H14<0.01,"***",IF(Estimates!H14<0.05,"**",IF(Estimates!H14<0.1,"*","")))) -> 0.169** | D12: =IF(Estimates!H15="","n/a",TEXT(Estimates!D15,"0.000")&IF(Estimates!H15<0.01,"***",IF(Estimates!H15<0.05,"**",IF(Estimates!H15<0.1,"*","")))) -> 0.172** | E12: =IF(Estimates!H16="","n/a",TEXT(Estimates!D16,"0.000")&IF(Estimates!H16<0.01,"***",IF(Estimates!H16<0.05,"**",IF(Estimates!H16<0.1,"*","")))) -> 0.103
C13: =IF(Estimates!G14="","","("&TEXT(Estimates!G14,"0.00")&")") -> (2.28) | D13: =IF(Estimates!G15="","","("&TEXT(Estimates!G15,"0.00")&")") -> (2.42) | E13: =IF(Estimates!G16="","","("&TEXT(Estimates!G16,"0.00")&")") -> (0.93)
A14: Private Equity Target Allocation (%) | C14: =IF(Estimates!H17="","n/a",TEXT(Estimates!D17,"0.000")&IF(Estimates!H17<0.01,"***",IF(Estimates!H17<0.05,"**",IF(Estimates!H17<0.1,"*","")))) -> 0.137* | D14: =IF(Estimates!H18="","n/a",TEXT(Estimates!D18,"0.000")&IF(Estimates!H18<0.01,"***",IF(Estimates!H18<0.05,"**",IF(Estimates!H18<0.1,"*","")))) -> 0.191** | E14: =IF(Estimates!H19="","n/a",TEXT(Estimates!D19,"0.000")&IF(Estimates!H19<0.01,"***",IF(Estimates!H19<0.05,"**",IF(Estimates!H19<0.1,"*","")))) -> 0.252**
C15: =IF(Estimates!G17="","","("&TEXT(Estimates!G17,"0.00")&")") -> (1.90) | D15: =IF(Estimates!G18="","","("&TEXT(Estimates!G18,"0.00")&")") -> (2.64) | E15: =IF(Estimates!G19="","","("&TEXT(Estimates!G19,"0.00")&")") -> (2.23)
A16: Hedge Fund Target Allocation (%) | C16: =IF(Estimates!H20="","n/a",TEXT(Estimates!D20,"0.000")&IF(Estimates!H20<0.01,"***",IF(Estimates!H20<0.05,"**",IF(Estimates!H20<0.1,"*","")))) -> 0.084 | D16: =IF(Estimates!H21="","n/a",TEXT(Estimates!D21,"0.000")&IF(Estimates!H21<0.01,"***",IF(Estimates!H21<0.05,"**",IF(Estimates!H21<0.1,"*","")))) -> 0.108 | E16: =IF(Estimates!H22="","n/a",TEXT(Estimates!D22,"0.000")&IF(Estimates!H22<0.01,"***",IF(Estimates!H22<0.05,"**",IF(Estimates!H22<0.1,"*","")))) -> 0.092
C17: =IF(Estimates!G20="","","("&TEXT(Estimates!G20,"0.00")&")") -> (1.09) | D17: =IF(Estimates!G21="","","("&TEXT(Estimates!G21,"0.00")&")") -> (1.32) | E17: =IF(Estimates!G22="","","("&TEXT(Estimates!G22,"0.00")&")") -> (0.74)
A18: Misc. Alternatives Target Allocation (%) | C18: =IF(Estimates!H23="","n/a",TEXT(Estimates!D23,"0.000")&IF(Estimates!H23<0.01,"***",IF(Estimates!H23<0.05,"**",IF(Estimates!H23<0.1,"*","")))) -> 0.189** | D18: =IF(Estimates!H24="","n/a",TEXT(Estimates!D24,"0.000")&IF(Estimates!H24<0.01,"***",IF(Estimates!H24<0.05,"**",IF(Estimates!H24<0.1,"*","")))) -> 0.198** | E18: =IF(Estimates!H25="","n/a",TEXT(Estimates!D25,"0.000")&IF(Estimates!H25<0.01,"***",IF(Estimates!H25<0.05,"**",IF(Estimates!H25<0.1,"*","")))) -> 0.255**
C19: =IF(Estimates!G23="","","("&TEXT(Estimates!G23,"0.00")&")") -> (2.40) | D19: =IF(Estimates!G24="","","("&TEXT(Estimates!G24,"0.00")&")") -> (2.35) | E19: =IF(Estimates!G25="","","("&TEXT(Estimates!G25,"0.00")&")") -> (2.43)
A20: Commodities Target Allocation (%) | C20: =IF(Estimates!H26="","n/a",TEXT(Estimates!D26,"0.000")&IF(Estimates!H26<0.01,"***",IF(Estimates!H26<0.05,"**",IF(Estimates!H26<0.1,"*","")))) -> 0.124 | D20: =IF(Estimates!H27="","n/a",TEXT(Estimates!D27,"0.000")&IF(Estimates!H27<0.01,"***",IF(Estimates!H27<0.05,"**",IF(Estimates!H27<0.1,"*","")))) -> 0.141* | E20: =IF(Estimates!H28="","n/a",TEXT(Estimates!D28,"0.000")&IF(Estimates!H28<0.01,"***",IF(Estimates!H28<0.05,"**",IF(Estimates!H28<0.1,"*","")))) -> 0.129
C21: =IF(Estimates!G26="","","("&TEXT(Estimates!G26,"0.00")&")") -> (1.57) | D21: =IF(Estimates!G27="","","("&TEXT(Estimates!G27,"0.00")&")") -> (1.87) | E21: =IF(Estimates!G28="","","("&TEXT(Estimates!G28,"0.00")&")") -> (1.18)
A22: Investment Return (t - 1) | D22: =IF(Estimates!H29="","n/a",TEXT(Estimates!D29,"0.000")&IF(Estimates!H29<0.01,"***",IF(Estimates!H29<0.05,"**",IF(Estimates!H29<0.1,"*","")))) -> -0.065 | E22: =IF(Estimates!H30="","n/a",TEXT(Estimates!D30,"0.000")&IF(Estimates!H30<0.01,"***",IF(Estimates!H30<0.05,"**",IF(Estimates!H30<0.1,"*","")))) -> -0.088
D23: =IF(Estimates!G29="","","("&TEXT(Estimates!G29,"0.00")&")") -> (-0.97) | E23: =IF(Estimates!G30="","","("&TEXT(Estimates!G30,"0.00")&")") -> (-1.09)
A24: Log (Plan Size) (t-1) | D24: =IF(Estimates!H31="","n/a",TEXT(Estimates!D31,"0.000")&IF(Estimates!H31<0.01,"***",IF(Estimates!H31<0.05,"**",IF(Estimates!H31<0.1,"*","")))) -> 0.126 | E24: =IF(Estimates!H32="","n/a",TEXT(Estimates!D32,"0.000")&IF(Estimates!H32<0.01,"***",IF(Estimates!H32<0.05,"**",IF(Estimates!H32<0.1,"*","")))) -> -0.956
D25: =IF(Estimates!G31="","","("&TEXT(Estimates!G31,"0.00")&")") -> (1.68) | E25: =IF(Estimates!G32="","","("&TEXT(Estimates!G32,"0.00")&")") -> (-0.98)
A26: Funding Ratio (t-1) | D26: =IF(Estimates!H33="","n/a",TEXT(Estimates!D33,"0.000")&IF(Estimates!H33<0.01,"***",IF(Estimates!H33<0.05,"**",IF(Estimates!H33<0.1,"*","")))) -> -0.008 | E26: =IF(Estimates!H34="","n/a",TEXT(Estimates!D34,"0.000")&IF(Estimates!H34<0.01,"***",IF(Estimates!H34<0.05,"**",IF(Estimates!H34<0.1,"*","")))) -> -0.015
D27: =IF(Estimates!G33="","","("&TEXT(Estimates!G33,"0.00")&")") -> (-1.15) | E27: =IF(Estimates!G34="","","("&TEXT(Estimates!G34,"0.00")&")") -> (-0.91)
A28: Financial Center (0/1) | D28: =IF(Estimates!H35="","n/a",TEXT(Estimates!D35,"0.000")&IF(Estimates!H35<0.01,"***",IF(Estimates!H35<0.05,"**",IF(Estimates!H35<0.1,"*","")))) -> 0.358
D29: =IF(Estimates!G35="","","("&TEXT(Estimates!G35,"0.00")&")") -> (1.17)
A30: Log (CIO Age) (t-1) | D30: =IF(Estimates!H36="","n/a",TEXT(Estimates!D36,"0.000")&IF(Estimates!H36<0.01,"***",IF(Estimates!H36<0.05,"**",IF(Estimates!H36<0.1,"*","")))) -> 0.306 | E30: =IF(Estimates!H37="","n/a",TEXT(Estimates!D37,"0.000")&IF(Estimates!H37<0.01,"***",IF(Estimates!H37<0.05,"**",IF(Estimates!H37<0.1,"*","")))) -> 2.588**
D31: =IF(Estimates!G36="","","("&TEXT(Estimates!G36,"0.00")&")") -> (0.75) | E31: =IF(Estimates!G37="","","("&TEXT(Estimates!G37,"0.00")&")") -> (2.36)
A32: Log (CIO Tenure) (t-1) | D32: =IF(Estimates!H38="","n/a",TEXT(Estimates!D38,"0.000")&IF(Estimates!H38<0.01,"***",IF(Estimates!H38<0.05,"**",IF(Estimates!H38<0.1,"*","")))) -> 0.038 | E32: =IF(Estimates!H39="","n/a",TEXT(Estimates!D39,"0.000")&IF(Estimates!H39<0.01,"***",IF(Estimates!H39<0.05,"**",IF(Estimates!H39<0.1,"*","")))) -> -0.113
D33: =IF(Estimates!G38="","","("&TEXT(Estimates!G38,"0.00")&")") -> (0.27) | E33: =IF(Estimates!G39="","","("&TEXT(Estimates!G39,"0.00")&")") -> (-0.50)
A34: CIO Prior Private Experience (0/1) | D34: =IF(Estimates!H40="","n/a",TEXT(Estimates!D40,"0.000")&IF(Estimates!H40<0.01,"***",IF(Estimates!H40<0.05,"**",IF(Estimates!H40<0.1,"*","")))) -> 0.131 | E34: =IF(Estimates!H41="","n/a",TEXT(Estimates!D41,"0.000")&IF(Estimates!H41<0.01,"***",IF(Estimates!H41<0.05,"**",IF(Estimates!H41<0.1,"*","")))) -> 0.258
D35: =IF(Estimates!G40="","","("&TEXT(Estimates!G40,"0.00")&")") -> (0.57) | E35: =IF(Estimates!G41="","","("&TEXT(Estimates!G41,"0.00")&")") -> (0.87)
A36: CIO Attended Elite College (0/1) | D36: =IF(Estimates!H42="","n/a",TEXT(Estimates!D42,"0.000")&IF(Estimates!H42<0.01,"***",IF(Estimates!H42<0.05,"**",IF(Estimates!H42<0.1,"*","")))) -> -0.355 | E36: =IF(Estimates!H43="","n/a",TEXT(Estimates!D43,"0.000")&IF(Estimates!H43<0.01,"***",IF(Estimates!H43<0.05,"**",IF(Estimates!H43<0.1,"*","")))) -> 0.069
D37: =IF(Estimates!G42="","","("&TEXT(Estimates!G42,"0.00")&")") -> (-1.58) | E37: =IF(Estimates!G43="","","("&TEXT(Estimates!G43,"0.00")&")") -> (0.24)
A38: Separate Investment Board (0/1) | D38: =IF(Estimates!H44="","n/a",TEXT(Estimates!D44,"0.000")&IF(Estimates!H44<0.01,"***",IF(Estimates!H44<0.05,"**",IF(Estimates!H44<0.1,"*","")))) -> -0.074 | E38: =IF(Estimates!H45="","n/a",TEXT(Estimates!D45,"0.000")&IF(Estimates!H45<0.01,"***",IF(Estimates!H45<0.05,"**",IF(Estimates!H45<0.1,"*","")))) -> -0.401
D39: =IF(Estimates!G44="","","("&TEXT(Estimates!G44,"0.00")&")") -> (-0.37) | E39: =IF(Estimates!G45="","","("&TEXT(Estimates!G45,"0.00")&")") -> (-0.24)
A40: % Political Appointees on Board | D40: =IF(Estimates!H46="","n/a",TEXT(Estimates!D46,"0.000")&IF(Estimates!H46<0.01,"***",IF(Estimates!H46<0.05,"**",IF(Estimates!H46<0.1,"*","")))) -> -0.423 | E40: =IF(Estimates!H47="","n/a",TEXT(Estimates!D47,"0.000")&IF(Estimates!H47<0.01,"***",IF(Estimates!H47<0.05,"**",IF(Estimates!H47<0.1,"*","")))) -> 1.288
D41: =IF(Estimates!G46="","","("&TEXT(Estimates!G46,"0.00")&")") -> (-0.80) | E41: =IF(Estimates!G47="","","("&TEXT(Estimates!G47,"0.00")&")") -> (0.61)
...

Sheet Table B2
A1: Table B2: Policy Benchmark Returns of Conflicted CIOs by Cross-Sectional Group
A2: This table reports results of tests that divide the sample into the cross-sectional groups of Tables V to VII and regress the return of a plan's total-fund policy benchmark, in percent, on Conflicted CIO interacted with the group indicator. Each row is a separate regression in which all control variables are also interacted with the group indicator, as in Tables V to VII. Panel A uses the control variables of the corresponding table in the paper. Panel B adds the plan's target allocation to each asset class, interacted with the group indicator. All regressions include fiscal-year-end date fixed effects. The last column reports the p-value of a test that the two coefficients are equal. The standard errors are double clustered by plan and year. Coefficients marked with ***, **, and * are significant at the 1%, 5%, and 10% level, respectively.
A4: Panel A. Without target allocation controls
B5: Group x Conflicted | C5: Other Group x Conflicted | D5: p-value: equal | E5: Observations | F5: Adj. R-squared
A6: Underpaid: Underpaid vs. Not Underpaid | B6: =IF(Estimates!H48="","n/a",TEXT(Estimates!D48,"0.000")&IF(Estimates!H48<0.01,"***",IF(Estimates!H48<0.05,"**",IF(Estimates!H48<0.1,"*","")))) -> -0.411 | C6: =IF(Estimates!H49="","n/a",TEXT(Estimates!D49,"0.000")&IF(Estimates!H49<0.01,"***",IF(Estimates!H49<0.05,"**",IF(Estimates!H49<0.1,"*","")))) -> 0.251 | D6: =IF(Estimates!H50="","",Estimates!H50) -> 0.25146173 | E6: 1054 | F6: 0.93426258
B7: =IF(Estimates!G48="","","("&TEXT(Estimates!G48,"0.00")&")") -> (-1.00) | C7: =IF(Estimates!G49="","","("&TEXT(Estimates!G49,"0.00")&")") -> (0.71)
A8: Young: Young vs. Not Young | B8: =IF(Estimates!H51="","n/a",TEXT(Estimates!D51,"0.000")&IF(Estimates!H51<0.01,"***",IF(Estimates!H51<0.05,"**",IF(Estimates!H51<0.1,"*","")))) -> -0.855* | C8: =IF(Estimates!H52="","n/a",TEXT(Estimates!D52,"0.000")&IF(Estimates!H52<0.01,"***",IF(Estimates!H52<0.05,"**",IF(Estimates!H52<0.1,"*","")))) -> 0.352 | D8: =IF(Estimates!H53="","",Estimates!H53) -> 0.012448854 | E8: 1150 | F8: 0.93660328
B9: =IF(Estimates!G51="","","("&TEXT(Estimates!G51,"0.00")&")") -> (-1.82) | C9: =IF(Estimates!G52="","","("&TEXT(Estimates!G52,"0.00")&")") -> (1.54)
A10: High funding: High Funding vs. Lower Funding | B10: =IF(Estimates!H54="","n/a",TEXT(Estimates!D54,"0.000")&IF(Estimates!H54<0.01,"***",IF(Estimates!H54<0.05,"**",IF(Estimates!H54<0.1,"*","")))) -> -0.285 | C10: =IF(Estimates!H55="","n/a",TEXT(Estimates!D55,"0.000")&IF(Estimates!H55<0.01,"***",IF(Estimates!H55<0.05,"**",IF(Estimates!H55<0.1,"*","")))) -> 0.223 | D10: =IF(Estimates!H56="","",Estimates!H56) -> 0.40772146 | E10: 1196 | F10: 0.93099718
B11: =IF(Estimates!G54="","","("&TEXT(Estimates!G54,"0.00")&")") -> (-0.56) | C11: =IF(Estimates!G55="","","("&TEXT(Estimates!G55,"0.00")&")") -> (0.65)
A12: Financial center: Financial Center vs. Non-Financial Center | B12: =IF(Estimates!H57="","n/a",TEXT(Estimates!D57,"0.000")&IF(Estimates!H57<0.01,"***",IF(Estimates!H57<0.05,"**",IF(Estimates!H57<0.1,"*","")))) -> 0.730*** | C12: =IF(Estimates!H58="","n/a",TEXT(Estimates!D58,"0.000")&IF(Estimates!H58<0.01,"***",IF(Estimates!H58<0.05,"**",IF(Estimates!H58<0.1,"*","")))) -> -0.124 | D12: =IF(Estimates!H59="","",Estimates!H59) -> 0.035596346 | E12: 1120 | F12: 0.93530901
B13: =IF(Estimates!G57="","","("&TEXT(Estimates!G57,"0.00")&")") -> (3.06) | C13: =IF(Estimates!G58="","","("&TEXT(Estimates!G58,"0.00")&")") -> (-0.40)
A14: Prior private experience: Prior Private Exp. vs. No Prior Private Exp. | B14: =IF(Estimates!H60="","n/a",TEXT(Estimates!D60,"0.000")&IF(Estimates!H60<0.01,"***",IF(Estimates!H60<0.05,"**",IF(Estimates!H60<0.1,"*","")))) -> 0.694** | C14: =IF(Estimates!H61="","n/a",TEXT(Estimates!D61,"0.000")&IF(Estimates!H61<0.01,"***",IF(Estimates!H61<0.05,"**",IF(Estimates!H61<0.1,"*","")))) -> -0.517 | D14: =IF(Estimates!H62="","",Estimates!H62) -> 0.0077791241 | E14: 1066 | F14: 0.93233462
B15: =IF(Estimates!G60="","","("&TEXT(Estimates!G60,"0.00")&")") -> (2.43) | C15: =IF(Estimates!G61="","","("&TEXT(Estimates!G61,"0.00")&")") -> (-1.15)
A16: High discount rate: High Discount Rate vs. Not High Discount Rate | B16: =IF(Estimates!H63="","n/a",TEXT(Estimates!D63,"0.000")&IF(Estimates!H63<0.01,"***",IF(Estimates!H63<0.05,"**",IF(Estimates!H63<0.1,"*","")))) -> -0.435 | C16: =IF(Estimates!H64="","n/a",TEXT(Estimates!D64,"0.000")&IF(Estimates!H64<0.01,"***",IF(Estimates!H64<0.05,"**",IF(Estimates!H64<0.1,"*","")))) -> 0.059 | D16: =IF(Estimates!H65="","",Estimates!H65) -> 0.63933009 | E16: 1109 | F16: 0.93760794
B17: =IF(Estimates!G63="","","("&TEXT(Estimates!G63,"0.00")&")") -> (-0.43) | C17: =IF(Estimates!G64="","","("&TEXT(Estimates!G64,"0.00")&")") -> (0.19)
A19: Panel B. With target allocation controls
B20: Group x Conflicted | C20: Other Group x Conflicted | D20: p-value: equal | E20: Observations | F20: Adj. R-squared
A21: Underpaid: Underpaid vs. Not Underpaid | B21: =IF(Estimates!H66="","n/a",TEXT(Estimates!D66,"0.000")&IF(Estimates!H66<0.01,"***",IF(Estimates!H66<0.05,"**",IF(Estimates!H66<0.1,"*","")))) -> -0.660 | C21: =IF(Estimates!H67="","n/a",TEXT(Estimates!D67,"0.000")&IF(Estimates!H67<0.01,"***",IF(Estimates!H67<0.05,"**",IF(Estimates!H67<0.1,"*","")))) -> 0.111 | D21: =IF(Estimates!H68="","",Estimates!H68) -> 0.15974871 | E21: 1052 | F21: 0.93481296
B22: =IF(Estimates!G66="","","("&TEXT(Estimates!G66,"0.00")&")") -> (-1.48) | C22: =IF(Estimates!G67="","","("&TEXT(Estimates!G67,"0.00")&")") -> (0.41)
A23: Young: Young vs. Not Young | B23: =IF(Estimates!H69="","n/a",TEXT(Estimates!D69,"0.000")&IF(Estimates!H69<0.01,"***",IF(Estimates!H69<0.05,"**",IF(Estimates!H69<0.1,"*","")))) -> -0.393 | C23: =IF(Estimates!H70="","n/a",TEXT(Estimates!D70,"0.000")&IF(Estimates!H70<0.01,"***",IF(Estimates!H70<0.05,"**",IF(Estimates!H70<0.1,"*","")))) -> 0.236 | D23: =IF(Estimates!H71="","",Estimates!H71) -> 0.21278348 | E23: 1149 | F23: 0.938823
B24: =IF(Estimates!G69="","","("&TEXT(Estimates!G69,"0.00")&")") -> (-1.20) | C24: =IF(Estimates!G70="","","("&TEXT(Estimates!G70,"0.00")&")") -> (1.00)
A25: High funding: High Funding vs. Lower Funding | B25: =IF(Estimates!H72="","n/a",TEXT(Estimates!D72,"0.000")&IF(Estimates!H72<0.01,"***",IF(Estimates!H72<0.05,"**",IF(Estimates!H72<0.1,"*","")))) -> -0.756 | C25: =IF(Estimates!H73="","n/a",TEXT(Estimates!D73,"0.000")&IF(Estimates!H73<0.01,"***",IF(Estimates!H73<0.05,"**",IF(Estimates!H73<0.1,"*","")))) -> 0.162 | D25: =IF(Estimates!H74="","",Estimates!H74) -> 0.18910425 | E25: 1192 | F25: 0.9317105
B26: =IF(Estimates!G72="","","("&TEXT(Estimates!G72,"0.00")&")") -> (-1.48) | C26: =IF(Estimates!G73="","","("&TEXT(Estimates!G73,"0.00")&")") -> (0.50)
A27: Financial center: Financial Center vs. Non-Financial Center | B27: =IF(Estimates!H75="","n/a",TEXT(Estimates!D75,"0.000")&IF(Estimates!H75<0.01,"***",IF(Estimates!H75<0.05,"**",IF(Estimates!H75<0.1,"*","")))) -> 0.417 | C27: =IF(Estimates!H76="","n/a",TEXT(Estimates!D76,"0.000")&IF(Estimates!H76<0.01,"***",IF(Estimates!H76<0.05,"**",IF(Estimates!H76<0.1,"*","")))) -> -0.185 | D27: =IF(Estimates!H77="","",Estimates!H77) -> 0.18751863 | E27: 1119 | F27: 0.93575922
B28: =IF(Estimates!G75="","","("&TEXT(Estimates!G75,"0.00")&")") -> (1.32) | C28: =IF(Estimates!G76="","","("&TEXT(Estimates!G76,"0.00")&")") -> (-0.66)
A29: Prior private experience: Prior Private Exp. vs. No Prior Private Exp. | B29: =IF(Estimates!H78="","n/a",TEXT(Estimates!D78,"0.000")&IF(Estimates!H78<0.01,"***",IF(Estimates!H78<0.05,"**",IF(Estimates!H78<0.1,"*","")))) -> 0.439* | C29: =IF(Estimates!H79="","n/a",TEXT(Estimates!D79,"0.000")&IF(Estimates!H79<0.01,"***",IF(Estimates!H79<0.05,"**",IF(Estimates!H79<0.1,"*","")))) -> -0.556 | D29: =IF(Estimates!H80="","",Estimates!H80) -> 0.0084661138 | E29: 1065 | F29: 0.93342102
B30: =IF(Estimates!G78="","","("&TEXT(Estimates!G78,"0.00")&")") -> (1.95) | C30: =IF(Estimates!G79="","","("&TEXT(Estimates!G79,"0.00")&")") -> (-1.28)
A31: High discount rate: High Discount Rate vs. Not High Discount Rate | B31: =IF(Estimates!H81="","n/a",TEXT(Estimates!D81,"0.000")&IF(Estimates!H81<0.01,"***",IF(Estimates!H81<0.05,"**",IF(Estimates!H81<0.1,"*","")))) -> -0.243 | C31: =IF(Estimates!H82="","n/a",TEXT(Estimates!D82,"0.000")&IF(Estimates!H82<0.01,"***",IF(Estimates!H82<0.05,"**",IF(Estimates!H82<0.1,"*","")))) -> -0.091 | D31: =IF(Estimates!H83="","",Estimates!H83) -> 0.78765884 | E31: 1108 | F31: 0.93861503
B32: =IF(Estimates!G81="","","("&TEXT(Estimates!G81,"0.00")&")") -> (-0.49) | C32: =IF(Estimates!G82="","","("&TEXT(Estimates!G82,"0.00")&")") -> (-0.32)

Sheet Table B3
A1: Table B3: Policy Benchmark Returns among Conflicted CIOs, by Cross-Sectional Group
A2: This table restricts the sample to plan-years run by conflicted CIOs and regresses the return of the plan's total-fund policy benchmark, in percent, on the cross-sectional group indicator. Column 1 includes only fiscal-year-end date fixed effects; Column 2 adds the plan's target allocation to each asset class; Column 3 adds the control variables of Table III. A negative coefficient means that conflicted CIOs in the group run plans whose policy benchmarks returned less than those of other conflicted CIOs with the same fiscal-year end. The standard errors are double clustered by plan and year. Coefficients marked with ***, **, and * are significant at the 1%, 5%, and 10% level, respectively.
B4: (1) | C4: (2) | D4: (3)
B5: Benchmark Ret. (t) | C5: Benchmark Ret. (t) | D5: Benchmark Ret. (t)
A6: Underpaid (0/1) | B6: =IF(Estimates!H84="","n/a",TEXT(Estimates!D84,"0.000")&IF(Estimates!H84<0.01,"***",IF(Estimates!H84<0.05,"**",IF(Estimates!H84<0.1,"*","")))) -> -0.602 | C6: =IF(Estimates!H85="","n/a",TEXT(Estimates!D85,"0.000")&IF(Estimates!H85<0.01,"***",IF(Estimates!H85<0.05,"**",IF(Estimates!H85<0.1,"*","")))) -> -0.539 | D6: =IF(Estimates!H86="","n/a",TEXT(Estimates!D86,"0.000")&IF(Estimates!H86<0.01,"***",IF(Estimates!H86<0.05,"**",IF(Estimates!H86<0.1,"*","")))) -> 0.707
B7: =IF(Estimates!G84="","","("&TEXT(Estimates!G84,"0.00")&")") -> (-0.86) | C7: =IF(Estimates!G85="","","("&TEXT(Estimates!G85,"0.00")&")") -> (-0.65) | D7: =IF(Estimates!G86="","","("&TEXT(Estimates!G86,"0.00")&")") -> (1.19)
A8: Observations | B8: 224 | C8: 212 | D8: 177
A9: Young (0/1) | B9: =IF(Estimates!H87="","n/a",TEXT(Estimates!D87,"0.000")&IF(Estimates!H87<0.01,"***",IF(Estimates!H87<0.05,"**",IF(Estimates!H87<0.1,"*","")))) -> -0.601 | C9: =IF(Estimates!H88="","n/a",TEXT(Estimates!D88,"0.000")&IF(Estimates!H88<0.01,"***",IF(Estimates!H88<0.05,"**",IF(Estimates!H88<0.1,"*","")))) -> -0.464 | D9: =IF(Estimates!H89="","n/a",TEXT(Estimates!D89,"0.000")&IF(Estimates!H89<0.01,"***",IF(Estimates!H89<0.05,"**",IF(Estimates!H89<0.1,"*","")))) -> -0.371
B10: =IF(Estimates!G87="","","("&TEXT(Estimates!G87,"0.00")&")") -> (-1.21) | C10: =IF(Estimates!G88="","","("&TEXT(Estimates!G88,"0.00")&")") -> (-0.73) | D10: =IF(Estimates!G89="","","("&TEXT(Estimates!G89,"0.00")&")") -> (-0.50)
A11: Observations | B11: 226 | C11: 214 | D11: 179
A12: High Funding (0/1) | B12: =IF(Estimates!H90="","n/a",TEXT(Estimates!D90,"0.000")&IF(Estimates!H90<0.01,"***",IF(Estimates!H90<0.05,"**",IF(Estimates!H90<0.1,"*","")))) -> -0.647 | C12: =IF(Estimates!H91="","n/a",TEXT(Estimates!D91,"0.000")&IF(Estimates!H91<0.01,"***",IF(Estimates!H91<0.05,"**",IF(Estimates!H91<0.1,"*","")))) -> -0.235*** | D12: =IF(Estimates!H92="","n/a",TEXT(Estimates!D92,"0.000")&IF(Estimates!H92<0.01,"***",IF(Estimates!H92<0.05,"**",IF(Estimates!H92<0.1,"*","")))) -> -0.628
B13: =IF(Estimates!G90="","","("&TEXT(Estimates!G90,"0.00")&")") -> (-1.39) | C13: =IF(Estimates!G91="","","("&TEXT(Estimates!G91,"0.00")&")") -> (-24.94) | D13: =IF(Estimates!G92="","","("&TEXT(Estimates!G92,"0.00")&")") -> (-1.59)
A14: Observations | B14: 225 | C14: 213 | D14: 179
A15: Financial Center (0/1) | B15: =IF(Estimates!H93="","n/a",TEXT(Estimates!D93,"0.000")&IF(Estimates!H93<0.01,"***",IF(Estimates!H93<0.05,"**",IF(Estimates!H93<0.1,"*","")))) -> 1.527* | C15: =IF(Estimates!H94="","n/a",TEXT(Estimates!D94,"0.000")&IF(Estimates!H94<0.01,"***",IF(Estimates!H94<0.05,"**",IF(Estimates!H94<0.1,"*","")))) -> 1.857 | D15: =IF(Estimates!H95="","n/a",TEXT(Estimates!D95,"0.000")&IF(Estimates!H95<0.01,"***",IF(Estimates!H95<0.05,"**",IF(Estimates!H95<0.1,"*","")))) -> 1.173
B16: =IF(Estimates!G93="","","("&TEXT(Estimates!G93,"0.00")&")") -> (1.77) | C16: =IF(Estimates!G94="","","("&TEXT(Estimates!G94,"0.00")&")") -> (1.26) | D16: =IF(Estimates!G95="","","("&TEXT(Estimates!G95,"0.00")&")") -> (1.17)
A17: Observations | B17: 226 | C17: 214 | D17: 179
A18: Prior Private Exp. (0/1) | B18: =IF(Estimates!H96="","n/a",TEXT(Estimates!D96,"0.000")&IF(Estimates!H96<0.01,"***",IF(Estimates!H96<0.05,"**",IF(Estimates!H96<0.1,"*","")))) -> 1.078* | C18: =IF(Estimates!H97="","n/a",TEXT(Estimates!D97,"0.000")&IF(Estimates!H97<0.01,"***",IF(Estimates!H97<0.05,"**",IF(Estimates!H97<0.1,"*","")))) -> 0.927* | D18: =IF(Estimates!H98="","n/a",TEXT(Estimates!D98,"0.000")&IF(Estimates!H98<0.01,"***",IF(Estimates!H98<0.05,"**",IF(Estimates!H98<0.1,"*","")))) -> 0.927
B19: =IF(Estimates!G96="","","("&TEXT(Estimates!G96,"0.00")&")") -> (1.97) | C19: =IF(Estimates!G97="","","("&TEXT(Estimates!G97,"0.00")&")") -> (1.92) | D19: =IF(Estimates!G98="","","("&TEXT(Estimates!G98,"0.00")&")") -> (1.37)
A20: Observations | B20: 220 | C20: 208 | D20: 179
A21: High Discount Rate (0/1) | B21: =IF(Estimates!H99="","n/a",TEXT(Estimates!D99,"0.000")&IF(Estimates!H99<0.01,"***",IF(Estimates!H99<0.05,"**",IF(Estimates!H99<0.1,"*","")))) -> 0.172 | C21: =IF(Estimates!H100="","n/a",TEXT(Estimates!D100,"0.000")&IF(Estimates!H100<0.01,"***",IF(Estimates!H100<0.05,"**",IF(Estimates!H100<0.1,"*","")))) -> 0.006 | D21: =IF(Estimates!H101="","n/a",TEXT(Estimates!D101,"0.000")&IF(Estimates!H101<0.01,"***",IF(Estimates!H101<0.05,"**",IF(Estimates!H101<0.1,"*","")))) -> 0.009
B22: =IF(Estimates!G99="","","("&TEXT(Estimates!G99,"0.00")&")") -> (0.24) | C22: =IF(Estimates!G100="","","("&TEXT(Estimates!G100,"0.00")&")") -> (0.01) | D22: =IF(Estimates!G101="","","("&TEXT(Estimates!G101,"0.00")&")") -> (0.02)
A23: Observations | B23: 215 | C23: 203 | D23: 172
A24: Target Allocation Controls | B24: No | C24: Yes | D24: Yes
A25: Table III Controls | B25: No | C25: No | D25: Yes
A26: Fiscal-Year-End FE | B26: Yes | C26: Yes | D26: Yes

Sheet Table B4
A1: Table B4: Asset-Class Benchmark Returns of Conflicted and Unconflicted CIOs
A2: This table regresses the fiscal-year return of the benchmark index each plan designates for an asset class, in percent, on Conflicted CIO. Asset-class benchmark returns are collected from plans' financial reports. Column 1 includes only fiscal-year-end date fixed effects; Column 2 adds the plan's target allocation to each asset class and the control variables of Table III. A negative coefficient means that conflicted CIOs' plans designate indexes for that asset class that returned less than the indexes designated by other plans with the same fiscal-year end. The standard errors are double clustered by plan and year. Coefficients marked with ***, **, and * are significant at the 1%, 5%, and 10% level, respectively.
B4: (1) No controls | C4: Observations | D4: (2) With controls | E4: Observations
A5: U.S. equity | B5: =IF(Estimates!H102="","n/a",TEXT(Estimates!D102,"0.000")&IF(Estimates!H102<0.01,"***",IF(Estimates!H102<0.05,"**",IF(Estimates!H102<0.1,"*","")))) -> -0.076 | C5: 1378 | D5: =IF(Estimates!H103="","n/a",TEXT(Estimates!D103,"0.000")&IF(Estimates!H103<0.01,"***",IF(Estimates!H103<0.05,"**",IF(Estimates!H103<0.1,"*","")))) -> -0.109 | E5: 1046
B6: =IF(Estimates!G102="","","("&TEXT(Estimates!G102,"0.00")&")") -> (-0.76) | D6: =IF(Estimates!G103="","","("&TEXT(Estimates!G103,"0.00")&")") -> (-1.41)
A7: Intl equity | B7: =IF(Estimates!H104="","n/a",TEXT(Estimates!D104,"0.000")&IF(Estimates!H104<0.01,"***",IF(Estimates!H104<0.05,"**",IF(Estimates!H104<0.1,"*","")))) -> -0.246 | C7: 1343 | D7: =IF(Estimates!H105="","n/a",TEXT(Estimates!D105,"0.000")&IF(Estimates!H105<0.01,"***",IF(Estimates!H105<0.05,"**",IF(Estimates!H105<0.1,"*","")))) -> -0.597** | E7: 1029
B8: =IF(Estimates!G104="","","("&TEXT(Estimates!G104,"0.00")&")") -> (-1.36) | D8: =IF(Estimates!G105="","","("&TEXT(Estimates!G105,"0.00")&")") -> (-2.33)
A9: Fixed income | B9: =IF(Estimates!H106="","n/a",TEXT(Estimates!D106,"0.000")&IF(Estimates!H106<0.01,"***",IF(Estimates!H106<0.05,"**",IF(Estimates!H106<0.1,"*","")))) -> 0.140 | C9: 1635 | D9: =IF(Estimates!H107="","n/a",TEXT(Estimates!D107,"0.000")&IF(Estimates!H107<0.01,"***",IF(Estimates!H107<0.05,"**",IF(Estimates!H107<0.1,"*","")))) -> 0.307 | E9: 1282
B10: =IF(Estimates!G106="","","("&TEXT(Estimates!G106,"0.00")&")") -> (0.66) | D10: =IF(Estimates!G107="","","("&TEXT(Estimates!G107,"0.00")&")") -> (1.46)
A11: Real estate | B11: =IF(Estimates!H108="","n/a",TEXT(Estimates!D108,"0.000")&IF(Estimates!H108<0.01,"***",IF(Estimates!H108<0.05,"**",IF(Estimates!H108<0.1,"*","")))) -> 0.025 | C11: 1088 | D11: =IF(Estimates!H109="","n/a",TEXT(Estimates!D109,"0.000")&IF(Estimates!H109<0.01,"***",IF(Estimates!H109<0.05,"**",IF(Estimates!H109<0.1,"*","")))) -> 0.290 | E11: 894
B12: =IF(Estimates!G108="","","("&TEXT(Estimates!G108,"0.00")&")") -> (0.11) | D12: =IF(Estimates!G109="","","("&TEXT(Estimates!G109,"0.00")&")") -> (0.79)
A13: Private equity | B13: =IF(Estimates!H110="","n/a",TEXT(Estimates!D110,"0.000")&IF(Estimates!H110<0.01,"***",IF(Estimates!H110<0.05,"**",IF(Estimates!H110<0.1,"*","")))) -> -2.868** | C13: 878 | D13: =IF(Estimates!H111="","n/a",TEXT(Estimates!D111,"0.000")&IF(Estimates!H111<0.01,"***",IF(Estimates!H111<0.05,"**",IF(Estimates!H111<0.1,"*","")))) -> -1.686 | E13: 782
B14: =IF(Estimates!G110="","","("&TEXT(Estimates!G110,"0.00")&")") -> (-2.12) | D14: =IF(Estimates!G111="","","("&TEXT(Estimates!G111,"0.00")&")") -> (-1.57)
A15: Hedge funds | B15: =IF(Estimates!H112="","n/a",TEXT(Estimates!D112,"0.000")&IF(Estimates!H112<0.01,"***",IF(Estimates!H112<0.05,"**",IF(Estimates!H112<0.1,"*","")))) -> -0.531 | C15: 470 | D15: =IF(Estimates!H113="","n/a",TEXT(Estimates!D113,"0.000")&IF(Estimates!H113<0.01,"***",IF(Estimates!H113<0.05,"**",IF(Estimates!H113<0.1,"*","")))) -> -1.314*** | E15: 413
B16: =IF(Estimates!G112="","","("&TEXT(Estimates!G112,"0.00")&")") -> (-1.54) | D16: =IF(Estimates!G113="","","("&TEXT(Estimates!G113,"0.00")&")") -> (-2.90)
A17: Total fund (collected file) | B17: =IF(Estimates!H114="","n/a",TEXT(Estimates!D114,"0.000")&IF(Estimates!H114<0.01,"***",IF(Estimates!H114<0.05,"**",IF(Estimates!H114<0.1,"*","")))) -> -0.192 | C17: 1410 | D17: =IF(Estimates!H115="","n/a",TEXT(Estimates!D115,"0.000")&IF(Estimates!H115<0.01,"***",IF(Estimates!H115<0.05,"**",IF(Estimates!H115<0.1,"*","")))) -> 0.015 | E17: 1115
B18: =IF(Estimates!G114="","","("&TEXT(Estimates!G114,"0.00")&")") -> (-1.19) | D18: =IF(Estimates!G115="","","("&TEXT(Estimates!G115,"0.00")&")") -> (0.10)
A19: Fiscal-Year-End FE | B19: Yes | D19: Yes

Sheet Table B5
A1: Table B5: Asset-Class Benchmark Returns of Conflicted CIOs by Cross-Sectional Group
A2: This table repeats the tests of Table B4 within the cross-sectional groups of Tables V to VII. Each row is a separate regression of the asset-class benchmark return, in percent, on Conflicted CIO interacted with the group indicator, with the plan's target allocations and the corresponding table's control variables also interacted with the group indicator, and fiscal-year-end date fixed effects. The last column reports the p-value of a test that the two coefficients are equal. The standard errors are double clustered by plan and year. Coefficients marked with ***, **, and * are significant at the 1%, 5%, and 10% level, respectively.
A4: Panel: Underpaid
B5: Underpaid x Conflicted | C5: Not Underpaid x Conflicted | D5: p-value: equal | E5: Observations
A6: U.S. equity | B6: =IF(Estimates!H116="","n/a",TEXT(Estimates!D116,"0.000")&IF(Estimates!H116<0.01,"***",IF(Estimates!H116<0.05,"**",IF(Estimates!H116<0.1,"*","")))) -> -0.066 | C6: =IF(Estimates!H117="","n/a",TEXT(Estimates!D117,"0.000")&IF(Estimates!H117<0.01,"***",IF(Estimates!H117<0.05,"**",IF(Estimates!H117<0.1,"*","")))) -> -0.098 | D6: =IF(Estimates!H118="","",Estimates!H118) -> 0.82296492 | E6: 1051
B7: =IF(Estimates!G116="","","("&TEXT(Estimates!G116,"0.00")&")") -> (-0.47) | C7: =IF(Estimates!G117="","","("&TEXT(Estimates!G117,"0.00")&")") -> (-1.34)
A8: Intl equity | B8: =IF(Estimates!H119="","n/a",TEXT(Estimates!D119,"0.000")&IF(Estimates!H119<0.01,"***",IF(Estimates!H119<0.05,"**",IF(Estimates!H119<0.1,"*","")))) -> -0.582** | C8: =IF(Estimates!H120="","n/a",TEXT(Estimates!D120,"0.000")&IF(Estimates!H120<0.01,"***",IF(Estimates!H120<0.05,"**",IF(Estimates!H120<0.1,"*","")))) -> 0.428 | D8: =IF(Estimates!H121="","",Estimates!H121) -> 0.083530348 | E8: 1034
B9: =IF(Estimates!G119="","","("&TEXT(Estimates!G119,"0.00")&")") -> (-2.15) | C9: =IF(Estimates!G120="","","("&TEXT(Estimates!G120,"0.00")&")") -> (0.87)
A10: Fixed income | B10: =IF(Estimates!H122="","n/a",TEXT(Estimates!D122,"0.000")&IF(Estimates!H122<0.01,"***",IF(Estimates!H122<0.05,"**",IF(Estimates!H122<0.1,"*","")))) -> 0.453 | C10: =IF(Estimates!H123="","n/a",TEXT(Estimates!D123,"0.000")&IF(Estimates!H123<0.01,"***",IF(Estimates!H123<0.05,"**",IF(Estimates!H123<0.1,"*","")))) -> -0.101 | D10: =IF(Estimates!H124="","",Estimates!H124) -> 0.16929282 | E10: 1280
B11: =IF(Estimates!G122="","","("&TEXT(Estimates!G122,"0.00")&")") -> (1.47) | C11: =IF(Estimates!G123="","","("&TEXT(Estimates!G123,"0.00")&")") -> (-0.36)
A12: Real estate | B12: =IF(Estimates!H125="","n/a",TEXT(Estimates!D125,"0.000")&IF(Estimates!H125<0.01,"***",IF(Estimates!H125<0.05,"**",IF(Estimates!H125<0.1,"*","")))) -> 0.077 | C12: =IF(Estimates!H126="","n/a",TEXT(Estimates!D126,"0.000")&IF(Estimates!H126<0.01,"***",IF(Estimates!H126<0.05,"**",IF(Estimates!H126<0.1,"*","")))) -> 0.122 | D12: =IF(Estimates!H127="","",Estimates!H127) -> 0.9516808 | E12: 890
B13: =IF(Estimates!G125="","","("&TEXT(Estimates!G125,"0.00")&")") -> (0.15) | C13: =IF(Estimates!G126="","","("&TEXT(Estimates!G126,"0.00")&")") -> (0.23)
A14: Private equity | B14: =IF(Estimates!H128="","n/a",TEXT(Estimates!D128,"0.000")&IF(Estimates!H128<0.01,"***",IF(Estimates!H128<0.05,"**",IF(Estimates!H128<0.1,"*","")))) -> -1.260 | C14: =IF(Estimates!H129="","n/a",TEXT(Estimates!D129,"0.000")&IF(Estimates!H129<0.01,"***",IF(Estimates!H129<0.05,"**",IF(Estimates!H129<0.1,"*","")))) -> -1.785 | D14: =IF(Estimates!H130="","",Estimates!H130) -> 0.8203308 | E14: 754
B15: =IF(Estimates!G128="","","("&TEXT(Estimates!G128,"0.00")&")") -> (-0.66) | C15: =IF(Estimates!G129="","","("&TEXT(Estimates!G129,"0.00")&")") -> (-0.86)
A16: Hedge funds | B16: =IF(Estimates!H131="","n/a",TEXT(Estimates!D131,"0.000")&IF(Estimates!H131<0.01,"***",IF(Estimates!H131<0.05,"**",IF(Estimates!H131<0.1,"*","")))) -> 0.062 | C16: =IF(Estimates!H132="","n/a",TEXT(Estimates!D132,"0.000")&IF(Estimates!H132<0.01,"***",IF(Estimates!H132<0.05,"**",IF(Estimates!H132<0.1,"*","")))) -> -1.394 | D16: =IF(Estimates!H133="","",Estimates!H133) -> 0.3928209 | E16: 376
B17: =IF(Estimates!G131="","","("&TEXT(Estimates!G131,"0.00")&")") -> (0.07) | C17: =IF(Estimates!G132="","","("&TEXT(Estimates!G132,"0.00")&")") -> (-0.94)
A19: Panel: Young
B20: Young x Conflicted | C20: Not Young x Conflicted | D20: p-value: equal | E20: Observations
A21: U.S. equity | B21: =IF(Estimates!H134="","n/a",TEXT(Estimates!D134,"0.000")&IF(Estimates!H134<0.01,"***",IF(Estimates!H134<0.05,"**",IF(Estimates!H134<0.1,"*","")))) -> -0.243 | C21: =IF(Estimates!H135="","n/a",TEXT(Estimates!D135,"0.000")&IF(Estimates!H135<0.01,"***",IF(Estimates!H135<0.05,"**",IF(Estimates!H135<0.1,"*","")))) -> -0.051 | D21: =IF(Estimates!H136="","",Estimates!H136) -> 0.35215045 | E21: 1127
B22: =IF(Estimates!G134="","","("&TEXT(Estimates!G134,"0.00")&")") -> (-1.28) | C22: =IF(Estimates!G135="","","("&TEXT(Estimates!G135,"0.00")&")") -> (-0.72)
A23: Intl equity | B23: =IF(Estimates!H137="","n/a",TEXT(Estimates!D137,"0.000")&IF(Estimates!H137<0.01,"***",IF(Estimates!H137<0.05,"**",IF(Estimates!H137<0.1,"*","")))) -> -0.994*** | C23: =IF(Estimates!H138="","n/a",TEXT(Estimates!D138,"0.000")&IF(Estimates!H138<0.01,"***",IF(Estimates!H138<0.05,"**",IF(Estimates!H138<0.1,"*","")))) -> -0.078 | D23: =IF(Estimates!H139="","",Estimates!H139) -> 0.0063784059 | E23: 1110
B24: =IF(Estimates!G137="","","("&TEXT(Estimates!G137,"0.00")&")") -> (-4.13) | C24: =IF(Estimates!G138="","","("&TEXT(Estimates!G138,"0.00")&")") -> (-0.24)
A25: Fixed income | B25: =IF(Estimates!H140="","n/a",TEXT(Estimates!D140,"0.000")&IF(Estimates!H140<0.01,"***",IF(Estimates!H140<0.05,"**",IF(Estimates!H140<0.1,"*","")))) -> 0.194 | C25: =IF(Estimates!H141="","n/a",TEXT(Estimates!D141,"0.000")&IF(Estimates!H141<0.01,"***",IF(Estimates!H141<0.05,"**",IF(Estimates!H141<0.1,"*","")))) -> 0.099 | D25: =IF(Estimates!H142="","",Estimates!H142) -> 0.77997759 | E25: 1384
B26: =IF(Estimates!G140="","","("&TEXT(Estimates!G140,"0.00")&")") -> (0.71) | C26: =IF(Estimates!G141="","","("&TEXT(Estimates!G141,"0.00")&")") -> (0.30)
A27: Real estate | B27: =IF(Estimates!H143="","n/a",TEXT(Estimates!D143,"0.000")&IF(Estimates!H143<0.01,"***",IF(Estimates!H143<0.05,"**",IF(Estimates!H143<0.1,"*","")))) -> 1.151* | C27: =IF(Estimates!H144="","n/a",TEXT(Estimates!D144,"0.000")&IF(Estimates!H144<0.01,"***",IF(Estimates!H144<0.05,"**",IF(Estimates!H144<0.1,"*","")))) -> -0.698*** | D27: =IF(Estimates!H145="","",Estimates!H145) -> 0.011373723 | E27: 972
B28: =IF(Estimates!G143="","","("&TEXT(Estimates!G143,"0.00")&")") -> (1.97) | C28: =IF(Estimates!G144="","","("&TEXT(Estimates!G144,"0.00")&")") -> (-4.84)
A29: Private equity | B29: =IF(Estimates!H146="","n/a",TEXT(Estimates!D146,"0.000")&IF(Estimates!H146<0.01,"***",IF(Estimates!H146<0.05,"**",IF(Estimates!H146<0.1,"*","")))) -> -0.120 | C29: =IF(Estimates!H147="","n/a",TEXT(Estimates!D147,"0.000")&IF(Estimates!H147<0.01,"***",IF(Estimates!H147<0.05,"**",IF(Estimates!H147<0.1,"*","")))) -> -2.584 | D29: =IF(Estimates!H148="","",Estimates!H148) -> 0.31049999 | E29: 806
B30: =IF(Estimates!G146="","","("&TEXT(Estimates!G146,"0.00")&")") -> (-0.06) | C30: =IF(Estimates!G147="","","("&TEXT(Estimates!G147,"0.00")&")") -> (-1.58)
A31: Hedge funds | B31: =IF(Estimates!H149="","n/a",TEXT(Estimates!D149,"0.000")&IF(Estimates!H149<0.01,"***",IF(Estimates!H149<0.05,"**",IF(Estimates!H149<0.1,"*","")))) -> -0.921 | C31: =IF(Estimates!H150="","n/a",TEXT(Estimates!D150,"0.000")&IF(Estimates!H150<0.01,"***",IF(Estimates!H150<0.05,"**",IF(Estimates!H150<0.1,"*","")))) -> 0.827 | D31: =IF(Estimates!H151="","",Estimates!H151) -> 0.48986292 | E31: 427
B32: =IF(Estimates!G149="","","("&TEXT(Estimates!G149,"0.00")&")") -> (-0.45) | C32: =IF(Estimates!G150="","","("&TEXT(Estimates!G150,"0.00")&")") -> (1.35)
A34: Panel: High funding
B35: High Funding x Conflicted | C35: Lower Funding x Conflicted | D35: p-value: equal | E35: Observations
A36: U.S. equity | B36: =IF(Estimates!H152="","n/a",TEXT(Estimates!D152,"0.000")&IF(Estimates!H152<0.01,"***",IF(Estimates!H152<0.05,"**",IF(Estimates!H152<0.1,"*","")))) -> 0.194 | C36: =IF(Estimates!H153="","n/a",TEXT(Estimates!D153,"0.000")&IF(Estimates!H153<0.01,"***",IF(Estimates!H153<0.05,"**",IF(Estimates!H153<0.1,"*","")))) -> -0.153 | D36: =IF(Estimates!H154="","",Estimates!H154) -> 0.38080564 | E36: 1186
B37: =IF(Estimates!G152="","","("&TEXT(Estimates!G152,"0.00")&")") -> (0.63) | C37: =IF(Estimates!G153="","","("&TEXT(Estimates!G153,"0.00")&")") -> (-1.18)
A38: Intl equity | B38: =IF(Estimates!H155="","n/a",TEXT(Estimates!D155,"0.000")&IF(Estimates!H155<0.01,"***",IF(Estimates!H155<0.05,"**",IF(Estimates!H155<0.1,"*","")))) -> 1.037* | C38: =IF(Estimates!H156="","n/a",TEXT(Estimates!D156,"0.000")&IF(Estimates!H156<0.01,"***",IF(Estimates!H156<0.05,"**",IF(Estimates!H156<0.1,"*","")))) -> -0.504** | D38: =IF(Estimates!H157="","",Estimates!H157) -> 0.025526091 | E38: 1161
B39: =IF(Estimates!G155="","","("&TEXT(Estimates!G155,"0.00")&")") -> (1.92) | C39: =IF(Estimates!G156="","","("&TEXT(Estimates!G156,"0.00")&")") -> (-2.14)
A40: Fixed income | B40: =IF(Estimates!H158="","n/a",TEXT(Estimates!D158,"0.000")&IF(Estimates!H158<0.01,"***",IF(Estimates!H158<0.05,"**",IF(Estimates!H158<0.1,"*","")))) -> -0.118 | C40: =IF(Estimates!H159="","n/a",TEXT(Estimates!D159,"0.000")&IF(Estimates!H159<0.01,"***",IF(Estimates!H159<0.05,"**",IF(Estimates!H159<0.1,"*","")))) -> 0.308 | D40: =IF(Estimates!H160="","",Estimates!H160) -> 0.28497567 | E40: 1431
B41: =IF(Estimates!G158="","","("&TEXT(Estimates!G158,"0.00")&")") -> (-0.26) | C41: =IF(Estimates!G159="","","("&TEXT(Estimates!G159,"0.00")&")") -> (1.10)
A42: Real estate | B42: =IF(Estimates!H161="","n/a",TEXT(Estimates!D161,"0.000")&IF(Estimates!H161<0.01,"***",IF(Estimates!H161<0.05,"**",IF(Estimates!H161<0.1,"*","")))) -> 0.216 | C42: =IF(Estimates!H162="","n/a",TEXT(Estimates!D162,"0.000")&IF(Estimates!H162<0.01,"***",IF(Estimates!H162<0.05,"**",IF(Estimates!H162<0.1,"*","")))) -> -0.590 | D42: =IF(Estimates!H163="","",Estimates!H163) -> 0.57058364 | E42: 975
B43: =IF(Estimates!G161="","","("&TEXT(Estimates!G161,"0.00")&")") -> (0.22) | C43: =IF(Estimates!G162="","","("&TEXT(Estimates!G162,"0.00")&")") -> (-0.85)
...

Sheet Estimates
A1: Estimates behind the tables: blue = regression output (coefficient, SE, min cluster count); t, p and stars in the tables are formulas. SE double clustered by plan and fiscal year, PSD-corrected; p from t distribution with (min clusters - 1) df.
A3: Table | B3: Row | C3: Column | D3: Coefficient | E3: SE | F3: Clusters (min) | G3: t | H3: p
A4: B1 | B4: Conflicted CIO (0/1) | C4: (1) | D4: -0.15274846 | E4: 0.27394509 | F4: 20 | G4: =IF(AND(ISNUMBER(D4),E4>0),D4/E4,"") -> -0.55758787 | H4: =IF(G4="","",TDIST(ABS(G4),F4-1,2)) -> 0.58363621
A5: B1 | B5: Conflicted CIO (0/1) | C5: (2) | D5: 0.0021034237 | E5: 0.26259824 | F5: 20 | G5: =IF(AND(ISNUMBER(D5),E5>0),D5/E5,"") -> 0.0080100451 | H5: =IF(G5="","",TDIST(ABS(G5),F5-1,2)) -> 0.99369248
A6: B1 | B6: Conflicted CIO (0/1) | C6: (3) | D6: -0.00041125636 | E6: 0.30053463 | F6: 20 | G6: =IF(AND(ISNUMBER(D6),E6>0),D6/E6,"") -> -0.0013684159 | H6: =IF(G6="","",TDIST(ABS(G6),F6-1,2)) -> 0.99892243
A7: B1 | B7: Conflicted CIO (0/1) | C7: (4) | D7: -0.095956076 | E7: 0.63469109 | F7: 20 | G7: =IF(AND(ISNUMBER(D7),E7>0),D7/E7,"") -> -0.15118548 | H7: =IF(G7="","",TDIST(ABS(G7),F7-1,2)) -> 0.88142305
A8: B1 | B8: Equity Target Allocation (%) | C8: (2) | D8: 0.14072452 | E8: 0.074745645 | F8: 20 | G8: =IF(AND(ISNUMBER(D8),E8>0),D8/E8,"") -> 1.882712 | H8: =IF(G8="","",TDIST(ABS(G8),F8-1,2)) -> 0.075143976
A9: B1 | B9: Equity Target Allocation (%) | C9: (3) | D9: 0.16655618 | E9: 0.075455762 | F9: 20 | G9: =IF(AND(ISNUMBER(D9),E9>0),D9/E9,"") -> 2.2073355 | H9: =IF(G9="","",TDIST(ABS(G9),F9-1,2)) -> 0.039787915
A10: B1 | B10: Equity Target Allocation (%) | C10: (4) | D10: 0.18146673 | E10: 0.10283747 | F10: 20 | G10: =IF(AND(ISNUMBER(D10),E10>0),D10/E10,"") -> 1.7645974 | H10: =IF(G10="","",TDIST(ABS(G10),F10-1,2)) -> 0.093701853
A11: B1 | B11: Fixed Income Target Allocation (%) | C11: (2) | D11: 0.14797135 | E11: 0.075098842 | F11: 20 | G11: =IF(AND(ISNUMBER(D11),E11>0),D11/E11,"") -> 1.9703547 | H11: =IF(G11="","",TDIST(ABS(G11),F11-1,2)) -> 0.063547304
A12: B1 | B12: Fixed Income Target Allocation (%) | C12: (3) | D12: 0.17119634 | E12: 0.079951485 | F12: 20 | G12: =IF(AND(ISNUMBER(D12),E12>0),D12/E12,"") -> 2.1412528 | H12: =IF(G12="","",TDIST(ABS(G12),F12-1,2)) -> 0.045431396
A13: B1 | B13: Fixed Income Target Allocation (%) | C13: (4) | D13: 0.21858462 | E13: 0.13118847 | F13: 20 | G13: =IF(AND(ISNUMBER(D13),E13>0),D13/E13,"") -> 1.6661877 | H13: =IF(G13="","",TDIST(ABS(G13),F13-1,2)) -> 0.11207732
A14: B1 | B14: Real Estate Target Allocation (%) | C14: (2) | D14: 0.16942905 | E14: 0.074253208 | F14: 20 | G14: =IF(AND(ISNUMBER(D14),E14>0),D14/E14,"") -> 2.2817741 | H14: =IF(G14="","",TDIST(ABS(G14),F14-1,2)) -> 0.034204809
A15: B1 | B15: Real Estate Target Allocation (%) | C15: (3) | D15: 0.17221993 | E15: 0.071217894 | F15: 20 | G15: =IF(AND(ISNUMBER(D15),E15>0),D15/E15,"") -> 2.4182115 | H15: =IF(G15="","",TDIST(ABS(G15),F15-1,2)) -> 0.025807474
... A166: B5 | B166: High funding: Private equity | C166: difference | D166: -4.7536551 | E166: 4.3943378 | F166: 20 | G166: =IF(AND(ISNUMBER(D166),E166>0),D166/E166,"") -> -1.0817682 | H166: =IF(G166="","",TDIST(ABS(G166),F166-1,2)) -> 0.2928948
A167: B5 | B167: High funding: Hedge funds | C167: group x conf | F167: 20 | G167: =IF(AND(ISNUMBER(D167),E167>0),D167/E167,"") | H167: =IF(G167="","",TDIST(ABS(G167),F167-1,2))
A168: B5 | B168: High funding: Hedge funds | C168: other x conf | D168: -0.057983889 | E168: 0.46751854 | F168: 20 | G168: =IF(AND(ISNUMBER(D168),E168>0),D168/E168,"") -> -0.12402479 | H168: =IF(G168="","",TDIST(ABS(G168),F168-1,2)) -> 0.90259834
A169: B5 | B169: High funding: Hedge funds | C169: difference | F169: 20 | G169: =IF(AND(ISNUMBER(D169),E169>0),D169/E169,"") | H169: =IF(G169="","",TDIST(ABS(G169),F169-1,2))
A170: B5 | B170: Financial center: U.S. equity | C170: group x conf | D170: -0.0043300293 | E170: 0.11273593 | F170: 20 | G170: =IF(AND(ISNUMBER(D170),E170>0),D170/E170,"") -> -0.0384086 | H170: =IF(G170="","",TDIST(ABS(G170),F170-1,2)) -> 0.9697626
A171: B5 | B171: Financial center: U.S. equity | C171: other x conf | D171: -0.10442185 | E171: 0.092568083 | F171: 20 | G171: =IF(AND(ISNUMBER(D171),E171>0),D171/E171,"") -> -1.1280546 | H171: =IF(G171="","",TDIST(ABS(G171),F171-1,2)) -> 0.2733406
A172: B5 | B172: Financial center: U.S. equity | C172: difference | D172: 0.10009182 | E172: 0.16696933 | F172: 20 | G172: =IF(AND(ISNUMBER(D172),E172>0),D172/E172,"") -> 0.59946231 | H172: =IF(G172="","",TDIST(ABS(G172),F172-1,2)) -> 0.55594636
A173: B5 | B173: Financial center: Intl equity | C173: group x conf | D173: -0.64650964 | E173: 0.7462326 | F173: 20 | G173: =IF(AND(ISNUMBER(D173),E173>0),D173/E173,"") -> -0.86636477 | H173: =IF(G173="","",TDIST(ABS(G173),F173-1,2)) -> 0.39709912
A174: B5 | B174: Financial center: Intl equity | C174: other x conf | D174: -0.29635892 | E174: 0.26868943 | F174: 20 | G174: =IF(AND(ISNUMBER(D174),E174>0),D174/E174,"") -> -1.1029795 | H174: =IF(G174="","",TDIST(ABS(G174),F174-1,2)) -> 0.28381108
A175: B5 | B175: Financial center: Intl equity | C175: difference | D175: -0.35015071 | E175: 0.86219686 | F175: 20 | G175: =IF(AND(ISNUMBER(D175),E175>0),D175/E175,"") -> -0.40611458 | H175: =IF(G175="","",TDIST(ABS(G175),F175-1,2)) -> 0.68919589
A176: B5 | B176: Financial center: Fixed income | C176: group x conf | D176: 0.00091434284 | E176: 0.092905979 | F176: 20 | G176: =IF(AND(ISNUMBER(D176),E176>0),D176/E176,"") -> 0.0098415931 | H176: =IF(G176="","",TDIST(ABS(G176),F176-1,2)) -> 0.99225027
A177: B5 | B177: Financial center: Fixed income | C177: other x conf | D177: 0.30693299 | E177: 0.35817204 | F177: 20 | G177: =IF(AND(ISNUMBER(D177),E177>0),D177/E177,"") -> 0.85694289 | H177: =IF(G177="","",TDIST(ABS(G177),F177-1,2)) -> 0.40215611
A178: B5 | B178: Financial center: Fixed income | C178: difference | D178: -0.30601864 | E178: 0.38898835 | F178: 20 | G178: =IF(AND(ISNUMBER(D178),E178>0),D178/E178,"") -> -0.78670388 | H178: =IF(G178="","",TDIST(ABS(G178),F178-1,2)) -> 0.44115804
A179: B5 | B179: Financial center: Real estate | C179: group x conf | D179: 3.1765718 | E179: 0.7978948 | F179: 20 | G179: =IF(AND(ISNUMBER(D179),E179>0),D179/E179,"") -> 3.9811913 | H179: =IF(G179="","",TDIST(ABS(G179),F179-1,2)) -> 0.00079982874
A180: B5 | B180: Financial center: Real estate | C180: other x conf | D180: 0.20353063 | E180: 0.44821633 | F180: 20 | G180: =IF(AND(ISNUMBER(D180),E180>0),D180/E180,"") -> 0.45409018 | H180: =IF(G180="","",TDIST(ABS(G180),F180-1,2)) -> 0.65490844
A181: B5 | B181: Financial center: Real estate | C181: difference | D181: 2.9730412 | E181: 0.62072732 | F181: 20 | G181: =IF(AND(ISNUMBER(D181),E181>0),D181/E181,"") -> 4.7896091 | H181: =IF(G181="","",TDIST(ABS(G181),F181-1,2)) -> 0.00012741051
... A205: B5 | B205: Prior private experience: Hedge funds | C205: difference | D205: 1.1317062 | E205: 2.4181022 | F205: 20 | G205: =IF(AND(ISNUMBER(D205),E205>0),D205/E205,"") -> 0.46801421 | H205: =IF(G205="","",TDIST(ABS(G205),F205-1,2)) -> 0.64509837
