Workbook

Sheet Table III Panel B
A1: Table III: Peer- and Benchmark-Adjusted Returns by Benchmark Confidence
A2: This table re-estimates Table III. Panel A uses Peer-Adjusted Return, for all plan-years (as in the paper) and for the plan-years that also have the grade-A benchmark-adjusted return. Panel B uses Benchmark-Adjusted Return for three versions of the policy benchmark. Benchmark-Adjusted Return is the plan's return minus its policy benchmark return. 'Reported + inferred grade A/B' uses the benchmark return reported in the plan's financial report or, where none is stated, an inferred value graded A or B (the version in the earlier tables). 'Reported + inferred grade A only' drops the inferred values graded B (28 plan-years, 10 of them conflicted). 'Reported benchmarks only' drops all inferred values. Columns follow Table III: (1) base controls with year fixed effects; (2) all controls with year fixed effects; (3) plan fixed effects; (4) plan and year fixed effects; (5) and (6) code Conflicted CIO as 1 only in the last 5 or 10 years before the CIO departs. The standard errors are double clustered by plan and year. Coefficients marked with ***, **, and * are significant at the 1%, 5%, and 10% level, respectively.
B4: (1) | C4: (2) | D4: (3) | E4: (4) | F4: (5) | G4: (6)
A5: Panel A. Peer-Adjusted Returns
A6: All plan-years
A7: Conflicted CIO (0/1) | B7: =IF(Estimates!I4="","",TEXT(Estimates!E4,"0.000")&IF(Estimates!I4<0.01,"***",IF(Estimates!I4<0.05,"**",IF(Estimates!I4<0.1,"*","")))) -> -0.557*** | C7: =IF(Estimates!I5="","",TEXT(Estimates!E5,"0.000")&IF(Estimates!I5<0.01,"***",IF(Estimates!I5<0.05,"**",IF(Estimates!I5<0.1,"*","")))) -> -0.582*** | D7: =IF(Estimates!I6="","",TEXT(Estimates!E6,"0.000")&IF(Estimates!I6<0.01,"***",IF(Estimates!I6<0.05,"**",IF(Estimates!I6<0.1,"*","")))) -> -0.641** | E7: =IF(Estimates!I7="","",TEXT(Estimates!E7,"0.000")&IF(Estimates!I7<0.01,"***",IF(Estimates!I7<0.05,"**",IF(Estimates!I7<0.1,"*","")))) -> -0.698** | F7: =IF(Estimates!I8="","",TEXT(Estimates!E8,"0.000")&IF(Estimates!I8<0.01,"***",IF(Estimates!I8<0.05,"**",IF(Estimates!I8<0.1,"*","")))) -> -0.475* | G7: =IF(Estimates!I9="","",TEXT(Estimates!E9,"0.000")&IF(Estimates!I9<0.01,"***",IF(Estimates!I9<0.05,"**",IF(Estimates!I9<0.1,"*","")))) -> -0.508**
B8: =IF(Estimates!H4="","","("&TEXT(Estimates!H4,"0.00")&")") -> (-3.68) | C8: =IF(Estimates!H5="","","("&TEXT(Estimates!H5,"0.00")&")") -> (-3.13) | D8: =IF(Estimates!H6="","","("&TEXT(Estimates!H6,"0.00")&")") -> (-2.21) | E8: =IF(Estimates!H7="","","("&TEXT(Estimates!H7,"0.00")&")") -> (-2.38) | F8: =IF(Estimates!H8="","","("&TEXT(Estimates!H8,"0.00")&")") -> (-2.10) | G8: =IF(Estimates!H9="","","("&TEXT(Estimates!H9,"0.00")&")") -> (-2.78)
A9: Observations | B9: 1727 | C9: 1483 | D9: 1482 | E9: 1482 | F9: 1483 | G9: 1483
A10: Conflicted plan-years | B10: 309 | C10: 283 | D10: 282 | E10: 282 | F10: 194 | G10: 220
A11: Adjusted R-squared | B11: 0.049684036 | C11: 0.059398101 | D11: 0.081182181 | E11: 0.095642068 | F11: 0.055524906 | G11: 0.056709498
A13: Plan-years with the grade-A benchmark-adjusted return
A14: Conflicted CIO (0/1) | B14: =IF(Estimates!I10="","",TEXT(Estimates!E10,"0.000")&IF(Estimates!I10<0.01,"***",IF(Estimates!I10<0.05,"**",IF(Estimates!I10<0.1,"*","")))) -> -0.566*** | C14: =IF(Estimates!I11="","",TEXT(Estimates!E11,"0.000")&IF(Estimates!I11<0.01,"***",IF(Estimates!I11<0.05,"**",IF(Estimates!I11<0.1,"*","")))) -> -0.584** | D14: =IF(Estimates!I12="","",TEXT(Estimates!E12,"0.000")&IF(Estimates!I12<0.01,"***",IF(Estimates!I12<0.05,"**",IF(Estimates!I12<0.1,"*","")))) -> -0.604* | E14: =IF(Estimates!I13="","",TEXT(Estimates!E13,"0.000")&IF(Estimates!I13<0.01,"***",IF(Estimates!I13<0.05,"**",IF(Estimates!I13<0.1,"*","")))) -> -0.642** | F14: =IF(Estimates!I14="","",TEXT(Estimates!E14,"0.000")&IF(Estimates!I14<0.01,"***",IF(Estimates!I14<0.05,"**",IF(Estimates!I14<0.1,"*","")))) -> -0.399* | G14: =IF(Estimates!I15="","",TEXT(Estimates!E15,"0.000")&IF(Estimates!I15<0.01,"***",IF(Estimates!I15<0.05,"**",IF(Estimates!I15<0.1,"*","")))) -> -0.506**
B15: =IF(Estimates!H10="","","("&TEXT(Estimates!H10,"0.00")&")") -> (-3.26) | C15: =IF(Estimates!H11="","","("&TEXT(Estimates!H11,"0.00")&")") -> (-2.74) | D15: =IF(Estimates!H12="","","("&TEXT(Estimates!H12,"0.00")&")") -> (-2.06) | E15: =IF(Estimates!H13="","","("&TEXT(Estimates!H13,"0.00")&")") -> (-2.26) | F15: =IF(Estimates!H14="","","("&TEXT(Estimates!H14,"0.00")&")") -> (-1.97) | G15: =IF(Estimates!H15="","","("&TEXT(Estimates!H15,"0.00")&")") -> (-2.35)
A16: Observations | B16: 1516 | C16: 1306 | D16: 1305 | E16: 1305 | F16: 1306 | G16: 1306
A17: Conflicted plan-years | B17: 272 | C17: 250 | D17: 249 | E17: 249 | F17: 174 | G17: 197
A18: Adjusted R-squared | B18: 0.055382183 | C18: 0.072459984 | D18: 0.082552373 | E18: 0.10418587 | F18: 0.067438815 | G18: 0.07000859
A20: Panel B. Benchmark-Adjusted Returns
A21: Reported + inferred grade A/B (as before)
A22: Conflicted CIO (0/1) | B22: =IF(Estimates!I16="","",TEXT(Estimates!E16,"0.000")&IF(Estimates!I16<0.01,"***",IF(Estimates!I16<0.05,"**",IF(Estimates!I16<0.1,"*","")))) -> -0.385** | C22: =IF(Estimates!I17="","",TEXT(Estimates!E17,"0.000")&IF(Estimates!I17<0.01,"***",IF(Estimates!I17<0.05,"**",IF(Estimates!I17<0.1,"*","")))) -> -0.491*** | D22: =IF(Estimates!I18="","",TEXT(Estimates!E18,"0.000")&IF(Estimates!I18<0.01,"***",IF(Estimates!I18<0.05,"**",IF(Estimates!I18<0.1,"*","")))) -> -0.373** | E22: =IF(Estimates!I19="","",TEXT(Estimates!E19,"0.000")&IF(Estimates!I19<0.01,"***",IF(Estimates!I19<0.05,"**",IF(Estimates!I19<0.1,"*","")))) -> -0.411** | F22: =IF(Estimates!I20="","",TEXT(Estimates!E20,"0.000")&IF(Estimates!I20<0.01,"***",IF(Estimates!I20<0.05,"**",IF(Estimates!I20<0.1,"*","")))) -> -0.384* | G22: =IF(Estimates!I21="","",TEXT(Estimates!E21,"0.000")&IF(Estimates!I21<0.01,"***",IF(Estimates!I21<0.05,"**",IF(Estimates!I21<0.1,"*","")))) -> -0.441**
B23: =IF(Estimates!H16="","","("&TEXT(Estimates!H16,"0.00")&")") -> (-2.46) | C23: =IF(Estimates!H17="","","("&TEXT(Estimates!H17,"0.00")&")") -> (-4.15) | D23: =IF(Estimates!H18="","","("&TEXT(Estimates!H18,"0.00")&")") -> (-2.23) | E23: =IF(Estimates!H19="","","("&TEXT(Estimates!H19,"0.00")&")") -> (-2.15) | F23: =IF(Estimates!H20="","","("&TEXT(Estimates!H20,"0.00")&")") -> (-1.84) | G23: =IF(Estimates!H21="","","("&TEXT(Estimates!H21,"0.00")&")") -> (-2.36)
A24: Observations | B24: 1538 | C24: 1320 | D24: 1319 | E24: 1319 | F24: 1320 | G24: 1320
A25: Conflicted plan-years | B25: 280 | C25: 258 | D25: 257 | E25: 257 | F25: 180 | G25: 203
A26: Adjusted R-squared | B26: 0.11853027 | C26: 0.12765408 | D26: 0.020739289 | E26: 0.12215393 | F26: 0.12484178 | G26: 0.12619652
A28: Reported + inferred grade A only
A29: Conflicted CIO (0/1) | B29: =IF(Estimates!I22="","",TEXT(Estimates!E22,"0.000")&IF(Estimates!I22<0.01,"***",IF(Estimates!I22<0.05,"**",IF(Estimates!I22<0.1,"*","")))) -> -0.366** | C29: =IF(Estimates!I23="","",TEXT(Estimates!E23,"0.000")&IF(Estimates!I23<0.01,"***",IF(Estimates!I23<0.05,"**",IF(Estimates!I23<0.1,"*","")))) -> -0.462*** | D29: =IF(Estimates!I24="","",TEXT(Estimates!E24,"0.000")&IF(Estimates!I24<0.01,"***",IF(Estimates!I24<0.05,"**",IF(Estimates!I24<0.1,"*","")))) -> -0.364** | E29: =IF(Estimates!I25="","",TEXT(Estimates!E25,"0.000")&IF(Estimates!I25<0.01,"***",IF(Estimates!I25<0.05,"**",IF(Estimates!I25<0.1,"*","")))) -> -0.388* | F29: =IF(Estimates!I26="","",TEXT(Estimates!E26,"0.000")&IF(Estimates!I26<0.01,"***",IF(Estimates!I26<0.05,"**",IF(Estimates!I26<0.1,"*","")))) -> -0.355 | G29: =IF(Estimates!I27="","",TEXT(Estimates!E27,"0.000")&IF(Estimates!I27<0.01,"***",IF(Estimates!I27<0.05,"**",IF(Estimates!I27<0.1,"*","")))) -> -0.414**
B30: =IF(Estimates!H22="","","("&TEXT(Estimates!H22,"0.00")&")") -> (-2.27) | C30: =IF(Estimates!H23="","","("&TEXT(Estimates!H23,"0.00")&")") -> (-3.91) | D30: =IF(Estimates!H24="","","("&TEXT(Estimates!H24,"0.00")&")") -> (-2.25) | E30: =IF(Estimates!H25="","","("&TEXT(Estimates!H25,"0.00")&")") -> (-2.09) | F30: =IF(Estimates!H26="","","("&TEXT(Estimates!H26,"0.00")&")") -> (-1.72) | G30: =IF(Estimates!H27="","","("&TEXT(Estimates!H27,"0.00")&")") -> (-2.22)
A31: Observations | B31: 1516 | C31: 1306 | D31: 1305 | E31: 1305 | F31: 1306 | G31: 1306
A32: Conflicted plan-years | B32: 272 | C32: 250 | D32: 249 | E32: 249 | F32: 174 | G32: 197
A33: Adjusted R-squared | B33: 0.11897314 | C33: 0.12861101 | D33: 0.021627095 | E33: 0.12174018 | F33: 0.12607913 | G33: 0.12736711
A35: Reported benchmarks only
A36: Conflicted CIO (0/1) | B36: =IF(Estimates!I28="","",TEXT(Estimates!E28,"0.000")&IF(Estimates!I28<0.01,"***",IF(Estimates!I28<0.05,"**",IF(Estimates!I28<0.1,"*","")))) -> -0.393** | C36: =IF(Estimates!I29="","",TEXT(Estimates!E29,"0.000")&IF(Estimates!I29<0.01,"***",IF(Estimates!I29<0.05,"**",IF(Estimates!I29<0.1,"*","")))) -> -0.434*** | D36: =IF(Estimates!I30="","",TEXT(Estimates!E30,"0.000")&IF(Estimates!I30<0.01,"***",IF(Estimates!I30<0.05,"**",IF(Estimates!I30<0.1,"*","")))) -> -0.319* | E36: =IF(Estimates!I31="","",TEXT(Estimates!E31,"0.000")&IF(Estimates!I31<0.01,"***",IF(Estimates!I31<0.05,"**",IF(Estimates!I31<0.1,"*","")))) -> -0.333** | F36: =IF(Estimates!I32="","",TEXT(Estimates!E32,"0.000")&IF(Estimates!I32<0.01,"***",IF(Estimates!I32<0.05,"**",IF(Estimates!I32<0.1,"*","")))) -> -0.380* | G36: =IF(Estimates!I33="","",TEXT(Estimates!E33,"0.000")&IF(Estimates!I33<0.01,"***",IF(Estimates!I33<0.05,"**",IF(Estimates!I33<0.1,"*","")))) -> -0.424**
B37: =IF(Estimates!H28="","","("&TEXT(Estimates!H28,"0.00")&")") -> (-2.49) | C37: =IF(Estimates!H29="","","("&TEXT(Estimates!H29,"0.00")&")") -> (-4.12) | D37: =IF(Estimates!H30="","","("&TEXT(Estimates!H30,"0.00")&")") -> (-1.92) | E37: =IF(Estimates!H31="","","("&TEXT(Estimates!H31,"0.00")&")") -> (-2.12) | F37: =IF(Estimates!H32="","","("&TEXT(Estimates!H32,"0.00")&")") -> (-1.92) | G37: =IF(Estimates!H33="","","("&TEXT(Estimates!H33,"0.00")&")") -> (-2.42)
A38: Observations | B38: 1453 | C38: 1249 | D38: 1248 | E38: 1248 | F38: 1249 | G38: 1249
A39: Conflicted plan-years | B39: 256 | C39: 234 | D39: 233 | E39: 233 | F39: 158 | G39: 180
A40: Adjusted R-squared | B40: 0.11805122 | C40: 0.11880225 | D40: 0.016051344 | E40: 0.10838134 | F40: 0.11717637 | G40: 0.11826853
A42: Controls | B42: Base | C42: All | D42: All | E42: All | F42: All | G42: All
A43: Plan FE | B43: No | C43: No | D43: Yes | E43: Yes | F43: No | G43: No
A44: Year FE | B44: Yes | C44: Yes | D44: No | E44: Yes | F44: Yes | G44: Yes
A45: Last n years | F45: 5 | G45: 10

Sheet Interactions Panel B
A1: Interaction Specification: Peer- and Benchmark-Adjusted Returns by Benchmark Confidence
A2: This table repeats the interaction specification of xsec_interactions_fye1.xlsx (all Table III controls, fiscal-year fixed effects instead of fiscal-year-end date fixed effects, Conflicted CIO interacted with X). Panel A uses Peer-Adjusted Return, for all plan-years and for the plan-years that also have the grade-A benchmark-adjusted return; Panel B uses Benchmark-Adjusted Return for three versions of the policy benchmark. Benchmark-Adjusted Return is the plan's return minus its policy benchmark return. 'Reported + inferred grade A/B' uses the benchmark return reported in the plan's financial report or, where none is stated, an inferred value graded A or B (the version in the earlier tables). 'Reported + inferred grade A only' drops the inferred values graded B (28 plan-years, 10 of them conflicted). 'Reported benchmarks only' drops all inferred values. For binary X, Conflicted CIO is the effect when X = 0 and the italic row gives the effect when X = 1. Continuous X (log pay, relative pay filled within spell, log CIO age) is centered at its regression-sample mean, so Conflicted CIO is the effect at average X, and the italic rows give the effect at the 25th and 75th percentiles. Log CIO Age is the paper's log_cio_age, ln(1 + age); that column drops the lagged log CIO age control. The standard errors are double clustered by plan and year. Coefficients marked with ***, **, and * are significant at the 1%, 5%, and 10% level, respectively.
A4: Panel A. Peer-Adjusted Returns
A5: All plan-years
B6: X = Underpaid | C6: X = Young CIO | D6: X = Prior Private Exp. | E6: X = Financial Center | F6: X = High Discount Rate | G6: X = High Funding | H6: X = Log CIO Total Comp. | I6: X = Relative CIO Pay (filled) | J6: X = Log CIO Age
A7: Conflicted CIO (0/1) | B7: =IF(Estimates!I34="","",TEXT(Estimates!E34,"0.000")&IF(Estimates!I34<0.01,"***",IF(Estimates!I34<0.05,"**",IF(Estimates!I34<0.1,"*","")))) -> -0.455 | C7: =IF(Estimates!I35="","",TEXT(Estimates!E35,"0.000")&IF(Estimates!I35<0.01,"***",IF(Estimates!I35<0.05,"**",IF(Estimates!I35<0.1,"*","")))) -> -0.223 | D7: =IF(Estimates!I36="","",TEXT(Estimates!E36,"0.000")&IF(Estimates!I36<0.01,"***",IF(Estimates!I36<0.05,"**",IF(Estimates!I36<0.1,"*","")))) -> -0.792*** | E7: =IF(Estimates!I37="","",TEXT(Estimates!E37,"0.000")&IF(Estimates!I37<0.01,"***",IF(Estimates!I37<0.05,"**",IF(Estimates!I37<0.1,"*","")))) -> -0.712*** | F7: =IF(Estimates!I38="","",TEXT(Estimates!E38,"0.000")&IF(Estimates!I38<0.01,"***",IF(Estimates!I38<0.05,"**",IF(Estimates!I38<0.1,"*","")))) -> -0.424** | G7: =IF(Estimates!I39="","",TEXT(Estimates!E39,"0.000")&IF(Estimates!I39<0.01,"***",IF(Estimates!I39<0.05,"**",IF(Estimates!I39<0.1,"*","")))) -> -0.433** | H7: =IF(Estimates!I40="","",TEXT(Estimates!E40,"0.000")&IF(Estimates!I40<0.01,"***",IF(Estimates!I40<0.05,"**",IF(Estimates!I40<0.1,"*","")))) -> -0.355** | I7: =IF(Estimates!I41="","",TEXT(Estimates!E41,"0.000")&IF(Estimates!I41<0.01,"***",IF(Estimates!I41<0.05,"**",IF(Estimates!I41<0.1,"*","")))) -> -0.456*** | J7: =IF(Estimates!I42="","",TEXT(Estimates!E42,"0.000")&IF(Estimates!I42<0.01,"***",IF(Estimates!I42<0.05,"**",IF(Estimates!I42<0.1,"*","")))) -> -0.329**
B8: =IF(Estimates!H34="","","("&TEXT(Estimates!H34,"0.00")&")") -> (-1.72) | C8: =IF(Estimates!H35="","","("&TEXT(Estimates!H35,"0.00")&")") -> (-1.17) | D8: =IF(Estimates!H36="","","("&TEXT(Estimates!H36,"0.00")&")") -> (-3.20) | E8: =IF(Estimates!H37="","","("&TEXT(Estimates!H37,"0.00")&")") -> (-3.34) | F8: =IF(Estimates!H38="","","("&TEXT(Estimates!H38,"0.00")&")") -> (-2.12) | G8: =IF(Estimates!H39="","","("&TEXT(Estimates!H39,"0.00")&")") -> (-2.56) | H8: =IF(Estimates!H40="","","("&TEXT(Estimates!H40,"0.00")&")") -> (-2.50) | I8: =IF(Estimates!H41="","","("&TEXT(Estimates!H41,"0.00")&")") -> (-3.63) | J8: =IF(Estimates!H42="","","("&TEXT(Estimates!H42,"0.00")&")") -> (-2.24)
A9: Conflicted CIO x X | B9: =IF(Estimates!I43="","",TEXT(Estimates!E43,"0.000")&IF(Estimates!I43<0.01,"***",IF(Estimates!I43<0.05,"**",IF(Estimates!I43<0.1,"*","")))) -> -0.219 | C9: =IF(Estimates!I44="","",TEXT(Estimates!E44,"0.000")&IF(Estimates!I44<0.01,"***",IF(Estimates!I44<0.05,"**",IF(Estimates!I44<0.1,"*","")))) -> -0.763 | D9: =IF(Estimates!I45="","",TEXT(Estimates!E45,"0.000")&IF(Estimates!I45<0.01,"***",IF(Estimates!I45<0.05,"**",IF(Estimates!I45<0.1,"*","")))) -> 0.438 | E9: =IF(Estimates!I46="","",TEXT(Estimates!E46,"0.000")&IF(Estimates!I46<0.01,"***",IF(Estimates!I46<0.05,"**",IF(Estimates!I46<0.1,"*","")))) -> 0.750** | F9: =IF(Estimates!I47="","",TEXT(Estimates!E47,"0.000")&IF(Estimates!I47<0.01,"***",IF(Estimates!I47<0.05,"**",IF(Estimates!I47<0.1,"*","")))) -> -0.895** | G9: =IF(Estimates!I48="","",TEXT(Estimates!E48,"0.000")&IF(Estimates!I48<0.01,"***",IF(Estimates!I48<0.05,"**",IF(Estimates!I48<0.1,"*","")))) -> -0.954*** | H9: =IF(Estimates!I49="","",TEXT(Estimates!E49,"0.000")&IF(Estimates!I49<0.01,"***",IF(Estimates!I49<0.05,"**",IF(Estimates!I49<0.1,"*","")))) -> 0.523 | I9: =IF(Estimates!I50="","",TEXT(Estimates!E50,"0.000")&IF(Estimates!I50<0.01,"***",IF(Estimates!I50<0.05,"**",IF(Estimates!I50<0.1,"*","")))) -> -0.068 | J9: =IF(Estimates!I51="","",TEXT(Estimates!E51,"0.000")&IF(Estimates!I51<0.01,"***",IF(Estimates!I51<0.05,"**",IF(Estimates!I51<0.1,"*","")))) -> 2.620**
B10: =IF(Estimates!H43="","","("&TEXT(Estimates!H43,"0.00")&")") -> (-0.74) | C10: =IF(Estimates!H44="","","("&TEXT(Estimates!H44,"0.00")&")") -> (-1.72) | D10: =IF(Estimates!H45="","","("&TEXT(Estimates!H45,"0.00")&")") -> (1.37) | E10: =IF(Estimates!H46="","","("&TEXT(Estimates!H46,"0.00")&")") -> (2.58) | F10: =IF(Estimates!H47="","","("&TEXT(Estimates!H47,"0.00")&")") -> (-2.19) | G10: =IF(Estimates!H48="","","("&TEXT(Estimates!H48,"0.00")&")") -> (-6.34) | H10: =IF(Estimates!H49="","","("&TEXT(Estimates!H49,"0.00")&")") -> (1.25) | I10: =IF(Estimates!H50="","","("&TEXT(Estimates!H50,"0.00")&")") -> (-0.25) | J10: =IF(Estimates!H51="","","("&TEXT(Estimates!H51,"0.00")&")") -> (2.57)
A11: X | B11: =IF(Estimates!I52="","",TEXT(Estimates!E52,"0.000")&IF(Estimates!I52<0.01,"***",IF(Estimates!I52<0.05,"**",IF(Estimates!I52<0.1,"*","")))) -> 0.012 | C11: =IF(Estimates!I53="","",TEXT(Estimates!E53,"0.000")&IF(Estimates!I53<0.01,"***",IF(Estimates!I53<0.05,"**",IF(Estimates!I53<0.1,"*","")))) -> 0.301 | D11: =IF(Estimates!I54="","",TEXT(Estimates!E54,"0.000")&IF(Estimates!I54<0.01,"***",IF(Estimates!I54<0.05,"**",IF(Estimates!I54<0.1,"*","")))) -> -0.103 | E11: =IF(Estimates!I55="","",TEXT(Estimates!E55,"0.000")&IF(Estimates!I55<0.01,"***",IF(Estimates!I55<0.05,"**",IF(Estimates!I55<0.1,"*","")))) -> -0.037 | F11: =IF(Estimates!I56="","",TEXT(Estimates!E56,"0.000")&IF(Estimates!I56<0.01,"***",IF(Estimates!I56<0.05,"**",IF(Estimates!I56<0.1,"*","")))) -> 0.626** | G11: =IF(Estimates!I57="","",TEXT(Estimates!E57,"0.000")&IF(Estimates!I57<0.01,"***",IF(Estimates!I57<0.05,"**",IF(Estimates!I57<0.1,"*","")))) -> 0.148 | H11: =IF(Estimates!I58="","",TEXT(Estimates!E58,"0.000")&IF(Estimates!I58<0.01,"***",IF(Estimates!I58<0.05,"**",IF(Estimates!I58<0.1,"*","")))) -> 0.299** | I11: =IF(Estimates!I59="","",TEXT(Estimates!E59,"0.000")&IF(Estimates!I59<0.01,"***",IF(Estimates!I59<0.05,"**",IF(Estimates!I59<0.1,"*","")))) -> 0.265* | J11: =IF(Estimates!I60="","",TEXT(Estimates!E60,"0.000")&IF(Estimates!I60<0.01,"***",IF(Estimates!I60<0.05,"**",IF(Estimates!I60<0.1,"*","")))) -> -1.096
B12: =IF(Estimates!H52="","","("&TEXT(Estimates!H52,"0.00")&")") -> (0.06) | C12: =IF(Estimates!H53="","","("&TEXT(Estimates!H53,"0.00")&")") -> (1.08) | D12: =IF(Estimates!H54="","","("&TEXT(Estimates!H54,"0.00")&")") -> (-0.60) | E12: =IF(Estimates!H55="","","("&TEXT(Estimates!H55,"0.00")&")") -> (-0.25) | F12: =IF(Estimates!H56="","","("&TEXT(Estimates!H56,"0.00")&")") -> (2.20) | G12: =IF(Estimates!H57="","","("&TEXT(Estimates!H57,"0.00")&")") -> (0.73) | H12: =IF(Estimates!H58="","","("&TEXT(Estimates!H58,"0.00")&")") -> (2.86) | I12: =IF(Estimates!H59="","","("&TEXT(Estimates!H59,"0.00")&")") -> (1.96) | J12: =IF(Estimates!H60="","","("&TEXT(Estimates!H60,"0.00")&")") -> (-1.70)
A14: Conflicted CIO effect when X = 1 | B14: =IF(Estimates!I61="","",TEXT(Estimates!E61,"0.000")&IF(Estimates!I61<0.01,"***",IF(Estimates!I61<0.05,"**",IF(Estimates!I61<0.1,"*","")))) -> -0.673*** | C14: =IF(Estimates!I62="","",TEXT(Estimates!E62,"0.000")&IF(Estimates!I62<0.01,"***",IF(Estimates!I62<0.05,"**",IF(Estimates!I62<0.1,"*","")))) -> -0.986** | D14: =IF(Estimates!I63="","",TEXT(Estimates!E63,"0.000")&IF(Estimates!I63<0.01,"***",IF(Estimates!I63<0.05,"**",IF(Estimates!I63<0.1,"*","")))) -> -0.354 | E14: =IF(Estimates!I64="","",TEXT(Estimates!E64,"0.000")&IF(Estimates!I64<0.01,"***",IF(Estimates!I64<0.05,"**",IF(Estimates!I64<0.1,"*","")))) -> 0.038 | F14: =IF(Estimates!I65="","",TEXT(Estimates!E65,"0.000")&IF(Estimates!I65<0.01,"***",IF(Estimates!I65<0.05,"**",IF(Estimates!I65<0.1,"*","")))) -> -1.319*** | G14: =IF(Estimates!I66="","",TEXT(Estimates!E66,"0.000")&IF(Estimates!I66<0.01,"***",IF(Estimates!I66<0.05,"**",IF(Estimates!I66<0.1,"*","")))) -> -1.387***
B15: =IF(Estimates!H61="","","("&TEXT(Estimates!H61,"0.00")&")") -> (-3.29) | C15: =IF(Estimates!H62="","","("&TEXT(Estimates!H62,"0.00")&")") -> (-2.74) | D15: =IF(Estimates!H63="","","("&TEXT(Estimates!H63,"0.00")&")") -> (-1.69) | E15: =IF(Estimates!H64="","","("&TEXT(Estimates!H64,"0.00")&")") -> (0.16) | F15: =IF(Estimates!H65="","","("&TEXT(Estimates!H65,"0.00")&")") -> (-3.98) | G15: =IF(Estimates!H66="","","("&TEXT(Estimates!H66,"0.00")&")") -> (-6.42)
A16: Conflicted CIO effect, 25th pct. of X | H16: =IF(Estimates!I67="","",TEXT(Estimates!E67,"0.000")&IF(Estimates!I67<0.01,"***",IF(Estimates!I67<0.05,"**",IF(Estimates!I67<0.1,"*","")))) -> -0.590** | I16: =IF(Estimates!I68="","",TEXT(Estimates!E68,"0.000")&IF(Estimates!I68<0.01,"***",IF(Estimates!I68<0.05,"**",IF(Estimates!I68<0.1,"*","")))) -> -0.433** | J16: =IF(Estimates!I69="","",TEXT(Estimates!E69,"0.000")&IF(Estimates!I69<0.01,"***",IF(Estimates!I69<0.05,"**",IF(Estimates!I69<0.1,"*","")))) -> -0.623***
H17: =IF(Estimates!H67="","","("&TEXT(Estimates!H67,"0.00")&")") -> (-2.80) | I17: =IF(Estimates!H68="","","("&TEXT(Estimates!H68,"0.00")&")") -> (-2.52) | J17: =IF(Estimates!H69="","","("&TEXT(Estimates!H69,"0.00")&")") -> (-3.48)
A18: Conflicted CIO effect, 75th pct. of X | H18: =IF(Estimates!I70="","",TEXT(Estimates!E70,"0.000")&IF(Estimates!I70<0.01,"***",IF(Estimates!I70<0.05,"**",IF(Estimates!I70<0.1,"*","")))) -> -0.159 | I18: =IF(Estimates!I71="","",TEXT(Estimates!E71,"0.000")&IF(Estimates!I71<0.01,"***",IF(Estimates!I71<0.05,"**",IF(Estimates!I71<0.1,"*","")))) -> -0.480*** | J18: =IF(Estimates!I72="","",TEXT(Estimates!E72,"0.000")&IF(Estimates!I72<0.01,"***",IF(Estimates!I72<0.05,"**",IF(Estimates!I72<0.1,"*","")))) -> -0.027
H19: =IF(Estimates!H70="","","("&TEXT(Estimates!H70,"0.00")&")") -> (-0.69) | I19: =IF(Estimates!H71="","","("&TEXT(Estimates!H71,"0.00")&")") -> (-3.51) | J19: =IF(Estimates!H72="","","("&TEXT(Estimates!H72,"0.00")&")") -> (-0.14)
A20: Observations | B20: 1412 | C20: 1480 | D20: 1483 | E20: 1483 | F20: 1468 | G20: 1483 | H20: 1040 | I20: 1266 | J20: 1480
A21: Adjusted R-squared | B21: 0.061586371 | C21: 0.063100996 | D21: 0.060165293 | E21: 0.061302625 | F21: 0.066169994 | G21: 0.061972541 | H21: 0.061678599 | I21: 0.070554706 | J21: 0.065384966
A24: Plan-years with the grade-A benchmark-adjusted return
B25: X = Underpaid | C25: X = Young CIO | D25: X = Prior Private Exp. | E25: X = Financial Center | F25: X = High Discount Rate | G25: X = High Funding | H25: X = Log CIO Total Comp. | I25: X = Relative CIO Pay (filled) | J25: X = Log CIO Age
A26: Conflicted CIO (0/1) | B26: =IF(Estimates!I73="","",TEXT(Estimates!E73,"0.000")&IF(Estimates!I73<0.01,"***",IF(Estimates!I73<0.05,"**",IF(Estimates!I73<0.1,"*","")))) -> -0.459 | C26: =IF(Estimates!I74="","",TEXT(Estimates!E74,"0.000")&IF(Estimates!I74<0.01,"***",IF(Estimates!I74<0.05,"**",IF(Estimates!I74<0.1,"*","")))) -> -0.195 | D26: =IF(Estimates!I75="","",TEXT(Estimates!E75,"0.000")&IF(Estimates!I75<0.01,"***",IF(Estimates!I75<0.05,"**",IF(Estimates!I75<0.1,"*","")))) -> -0.868*** | E26: =IF(Estimates!I76="","",TEXT(Estimates!E76,"0.000")&IF(Estimates!I76<0.01,"***",IF(Estimates!I76<0.05,"**",IF(Estimates!I76<0.1,"*","")))) -> -0.746*** | F26: =IF(Estimates!I77="","",TEXT(Estimates!E77,"0.000")&IF(Estimates!I77<0.01,"***",IF(Estimates!I77<0.05,"**",IF(Estimates!I77<0.1,"*","")))) -> -0.400 | G26: =IF(Estimates!I78="","",TEXT(Estimates!E78,"0.000")&IF(Estimates!I78<0.01,"***",IF(Estimates!I78<0.05,"**",IF(Estimates!I78<0.1,"*","")))) -> -0.452** | H26: =IF(Estimates!I79="","",TEXT(Estimates!E79,"0.000")&IF(Estimates!I79<0.01,"***",IF(Estimates!I79<0.05,"**",IF(Estimates!I79<0.1,"*","")))) -> -0.337** | I26: =IF(Estimates!I80="","",TEXT(Estimates!E80,"0.000")&IF(Estimates!I80<0.01,"***",IF(Estimates!I80<0.05,"**",IF(Estimates!I80<0.1,"*","")))) -> -0.460*** | J26: =IF(Estimates!I81="","",TEXT(Estimates!E81,"0.000")&IF(Estimates!I81<0.01,"***",IF(Estimates!I81<0.05,"**",IF(Estimates!I81<0.1,"*","")))) -> -0.298*
B27: =IF(Estimates!H73="","","("&TEXT(Estimates!H73,"0.00")&")") -> (-1.44) | C27: =IF(Estimates!H74="","","("&TEXT(Estimates!H74,"0.00")&")") -> (-0.98) | D27: =IF(Estimates!H75="","","("&TEXT(Estimates!H75,"0.00")&")") -> (-3.13) | E27: =IF(Estimates!H76="","","("&TEXT(Estimates!H76,"0.00")&")") -> (-2.98) | F27: =IF(Estimates!H77="","","("&TEXT(Estimates!H77,"0.00")&")") -> (-1.73) | G27: =IF(Estimates!H78="","","("&TEXT(Estimates!H78,"0.00")&")") -> (-2.52) | H27: =IF(Estimates!H79="","","("&TEXT(Estimates!H79,"0.00")&")") -> (-2.54) | I27: =IF(Estimates!H80="","","("&TEXT(Estimates!H80,"0.00")&")") -> (-3.49) | J27: =IF(Estimates!H81="","","("&TEXT(Estimates!H81,"0.00")&")") -> (-1.93)
A28: Conflicted CIO x X | B28: =IF(Estimates!I82="","",TEXT(Estimates!E82,"0.000")&IF(Estimates!I82<0.01,"***",IF(Estimates!I82<0.05,"**",IF(Estimates!I82<0.1,"*","")))) -> -0.269 | C28: =IF(Estimates!I83="","",TEXT(Estimates!E83,"0.000")&IF(Estimates!I83<0.01,"***",IF(Estimates!I83<0.05,"**",IF(Estimates!I83<0.1,"*","")))) -> -0.842* | D28: =IF(Estimates!I84="","",TEXT(Estimates!E84,"0.000")&IF(Estimates!I84<0.01,"***",IF(Estimates!I84<0.05,"**",IF(Estimates!I84<0.1,"*","")))) -> 0.564 | E28: =IF(Estimates!I85="","",TEXT(Estimates!E85,"0.000")&IF(Estimates!I85<0.01,"***",IF(Estimates!I85<0.05,"**",IF(Estimates!I85<0.1,"*","")))) -> 0.995*** | F28: =IF(Estimates!I86="","",TEXT(Estimates!E86,"0.000")&IF(Estimates!I86<0.01,"***",IF(Estimates!I86<0.05,"**",IF(Estimates!I86<0.1,"*","")))) -> -0.998** | G28: =IF(Estimates!I87="","",TEXT(Estimates!E87,"0.000")&IF(Estimates!I87<0.01,"***",IF(Estimates!I87<0.05,"**",IF(Estimates!I87<0.1,"*","")))) -> -1.097** | H28: =IF(Estimates!I88="","",TEXT(Estimates!E88,"0.000")&IF(Estimates!I88<0.01,"***",IF(Estimates!I88<0.05,"**",IF(Estimates!I88<0.1,"*","")))) -> 0.587 | I28: =IF(Estimates!I89="","",TEXT(Estimates!E89,"0.000")&IF(Estimates!I89<0.01,"***",IF(Estimates!I89<0.05,"**",IF(Estimates!I89<0.1,"*","")))) -> -0.149 | J28: =IF(Estimates!I90="","",TEXT(Estimates!E90,"0.000")&IF(Estimates!I90<0.01,"***",IF(Estimates!I90<0.05,"**",IF(Estimates!I90<0.1,"*","")))) -> 3.081**
B29: =IF(Estimates!H82="","","("&TEXT(Estimates!H82,"0.00")&")") -> (-0.79) | C29: =IF(Estimates!H83="","","("&TEXT(Estimates!H83,"0.00")&")") -> (-1.83) | D29: =IF(Estimates!H84="","","("&TEXT(Estimates!H84,"0.00")&")") -> (1.60) | E29: =IF(Estimates!H85="","","("&TEXT(Estimates!H85,"0.00")&")") -> (3.01) | F29: =IF(Estimates!H86="","","("&TEXT(Estimates!H86,"0.00")&")") -> (-2.25) | G29: =IF(Estimates!H87="","","("&TEXT(Estimates!H87,"0.00")&")") -> (-2.35) | H29: =IF(Estimates!H88="","","("&TEXT(Estimates!H88,"0.00")&")") -> (1.42) | I29: =IF(Estimates!H89="","","("&TEXT(Estimates!H89,"0.00")&")") -> (-0.51) | J29: =IF(Estimates!H90="","","("&TEXT(Estimates!H90,"0.00")&")") -> (2.60)
A30: X | B30: =IF(Estimates!I91="","",TEXT(Estimates!E91,"0.000")&IF(Estimates!I91<0.01,"***",IF(Estimates!I91<0.05,"**",IF(Estimates!I91<0.1,"*","")))) -> 0.009 | C30: =IF(Estimates!I92="","",TEXT(Estimates!E92,"0.000")&IF(Estimates!I92<0.01,"***",IF(Estimates!I92<0.05,"**",IF(Estimates!I92<0.1,"*","")))) -> 0.247 | D30: =IF(Estimates!I93="","",TEXT(Estimates!E93,"0.000")&IF(Estimates!I93<0.01,"***",IF(Estimates!I93<0.05,"**",IF(Estimates!I93<0.1,"*","")))) -> -0.057 | E30: =IF(Estimates!I94="","",TEXT(Estimates!E94,"0.000")&IF(Estimates!I94<0.01,"***",IF(Estimates!I94<0.05,"**",IF(Estimates!I94<0.1,"*","")))) -> -0.104 | F30: =IF(Estimates!I95="","",TEXT(Estimates!E95,"0.000")&IF(Estimates!I95<0.01,"***",IF(Estimates!I95<0.05,"**",IF(Estimates!I95<0.1,"*","")))) -> 0.577** | G30: =IF(Estimates!I96="","",TEXT(Estimates!E96,"0.000")&IF(Estimates!I96<0.01,"***",IF(Estimates!I96<0.05,"**",IF(Estimates!I96<0.1,"*","")))) -> 0.095 | H30: =IF(Estimates!I97="","",TEXT(Estimates!E97,"0.000")&IF(Estimates!I97<0.01,"***",IF(Estimates!I97<0.05,"**",IF(Estimates!I97<0.1,"*","")))) -> 0.200* | I30: =IF(Estimates!I98="","",TEXT(Estimates!E98,"0.000")&IF(Estimates!I98<0.01,"***",IF(Estimates!I98<0.05,"**",IF(Estimates!I98<0.1,"*","")))) -> 0.240* | J30: =IF(Estimates!I99="","",TEXT(Estimates!E99,"0.000")&IF(Estimates!I99<0.01,"***",IF(Estimates!I99<0.05,"**",IF(Estimates!I99<0.1,"*","")))) -> -1.250
B31: =IF(Estimates!H91="","","("&TEXT(Estimates!H91,"0.00")&")") -> (0.04) | C31: =IF(Estimates!H92="","","("&TEXT(Estimates!H92,"0.00")&")") -> (0.87) | D31: =IF(Estimates!H93="","","("&TEXT(Estimates!H93,"0.00")&")") -> (-0.32) | E31: =IF(Estimates!H94="","","("&TEXT(Estimates!H94,"0.00")&")") -> (-0.54) | F31: =IF(Estimates!H95="","","("&TEXT(Estimates!H95,"0.00")&")") -> (2.37) | G31: =IF(Estimates!H96="","","("&TEXT(Estimates!H96,"0.00")&")") -> (0.45) | H31: =IF(Estimates!H97="","","("&TEXT(Estimates!H97,"0.00")&")") -> (1.79) | I31: =IF(Estimates!H98="","","("&TEXT(Estimates!H98,"0.00")&")") -> (2.00) | J31: =IF(Estimates!H99="","","("&TEXT(Estimates!H99,"0.00")&")") -> (-1.68)
A33: Conflicted CIO effect when X = 1 | B33: =IF(Estimates!I100="","",TEXT(Estimates!E100,"0.000")&IF(Estimates!I100<0.01,"***",IF(Estimates!I100<0.05,"**",IF(Estimates!I100<0.1,"*","")))) -> -0.728*** | C33: =IF(Estimates!I101="","",TEXT(Estimates!E101,"0.000")&IF(Estimates!I101<0.01,"***",IF(Estimates!I101<0.05,"**",IF(Estimates!I101<0.1,"*","")))) -> -1.037** | D33: =IF(Estimates!I102="","",TEXT(Estimates!E102,"0.000")&IF(Estimates!I102<0.01,"***",IF(Estimates!I102<0.05,"**",IF(Estimates!I102<0.1,"*","")))) -> -0.305 | E33: =IF(Estimates!I103="","",TEXT(Estimates!E103,"0.000")&IF(Estimates!I103<0.01,"***",IF(Estimates!I103<0.05,"**",IF(Estimates!I103<0.1,"*","")))) -> 0.249 | F33: =IF(Estimates!I104="","",TEXT(Estimates!E104,"0.000")&IF(Estimates!I104<0.01,"***",IF(Estimates!I104<0.05,"**",IF(Estimates!I104<0.1,"*","")))) -> -1.398*** | G33: =IF(Estimates!I105="","",TEXT(Estimates!E105,"0.000")&IF(Estimates!I105<0.01,"***",IF(Estimates!I105<0.05,"**",IF(Estimates!I105<0.1,"*","")))) -> -1.550***
B34: =IF(Estimates!H100="","","("&TEXT(Estimates!H100,"0.00")&")") -> (-3.30) | C34: =IF(Estimates!H101="","","("&TEXT(Estimates!H101,"0.00")&")") -> (-2.64) | D34: =IF(Estimates!H102="","","("&TEXT(Estimates!H102,"0.00")&")") -> (-1.32) | E34: =IF(Estimates!H103="","","("&TEXT(Estimates!H103,"0.00")&")") -> (1.24) | F34: =IF(Estimates!H104="","","("&TEXT(Estimates!H104,"0.00")&")") -> (-4.21) | G34: =IF(Estimates!H105="","","("&TEXT(Estimates!H105,"0.00")&")") -> (-3.00)
A35: Conflicted CIO effect, 25th pct. of X | H35: =IF(Estimates!I106="","",TEXT(Estimates!E106,"0.000")&IF(Estimates!I106<0.01,"***",IF(Estimates!I106<0.05,"**",IF(Estimates!I106<0.1,"*","")))) -> -0.586*** | I35: =IF(Estimates!I107="","",TEXT(Estimates!E107,"0.000")&IF(Estimates!I107<0.01,"***",IF(Estimates!I107<0.05,"**",IF(Estimates!I107<0.1,"*","")))) -> -0.414** | J35: =IF(Estimates!I108="","",TEXT(Estimates!E108,"0.000")&IF(Estimates!I108<0.01,"***",IF(Estimates!I108<0.05,"**",IF(Estimates!I108<0.1,"*","")))) -> -0.636***
H36: =IF(Estimates!H106="","","("&TEXT(Estimates!H106,"0.00")&")") -> (-3.09) | I36: =IF(Estimates!H107="","","("&TEXT(Estimates!H107,"0.00")&")") -> (-2.32) | J36: =IF(Estimates!H108="","","("&TEXT(Estimates!H108,"0.00")&")") -> (-3.02)
A37: Conflicted CIO effect, 75th pct. of X | H37: =IF(Estimates!I109="","",TEXT(Estimates!E109,"0.000")&IF(Estimates!I109<0.01,"***",IF(Estimates!I109<0.05,"**",IF(Estimates!I109<0.1,"*","")))) -> -0.144 | I37: =IF(Estimates!I110="","",TEXT(Estimates!E110,"0.000")&IF(Estimates!I110<0.01,"***",IF(Estimates!I110<0.05,"**",IF(Estimates!I110<0.1,"*","")))) -> -0.509*** | J37: =IF(Estimates!I111="","",TEXT(Estimates!E111,"0.000")&IF(Estimates!I111<0.01,"***",IF(Estimates!I111<0.05,"**",IF(Estimates!I111<0.1,"*","")))) -> 0.065
H38: =IF(Estimates!H109="","","("&TEXT(Estimates!H109,"0.00")&")") -> (-0.68) | I38: =IF(Estimates!H110="","","("&TEXT(Estimates!H110,"0.00")&")") -> (-3.61) | J38: =IF(Estimates!H111="","","("&TEXT(Estimates!H111,"0.00")&")") -> (0.33)
A39: Observations | B39: 1239 | C39: 1303 | D39: 1306 | E39: 1306 | F39: 1293 | G39: 1306 | H39: 930 | I39: 1124 | J39: 1303
A40: Adjusted R-squared | B40: 0.074250756 | C40: 0.076778348 | D40: 0.07400676 | E40: 0.075986083 | F40: 0.079321742 | G40: 0.075181097 | H40: 0.067480099 | I40: 0.083009229 | J40: 0.080229626
A43: Panel B. Benchmark-Adjusted Returns
A44: Reported + inferred grade A/B (as before)
B45: X = Underpaid | C45: X = Young CIO | D45: X = Prior Private Exp. | E45: X = Financial Center | F45: X = High Discount Rate | G45: X = High Funding | H45: X = Log CIO Total Comp. | I45: X = Relative CIO Pay (filled) | J45: X = Log CIO Age
A46: Conflicted CIO (0/1) | B46: =IF(Estimates!I112="","",TEXT(Estimates!E112,"0.000")&IF(Estimates!I112<0.01,"***",IF(Estimates!I112<0.05,"**",IF(Estimates!I112<0.1,"*","")))) -> -0.344* | C46: =IF(Estimates!I113="","",TEXT(Estimates!E113,"0.000")&IF(Estimates!I113<0.01,"***",IF(Estimates!I113<0.05,"**",IF(Estimates!I113<0.1,"*","")))) -> -0.315** | D46: =IF(Estimates!I114="","",TEXT(Estimates!E114,"0.000")&IF(Estimates!I114<0.01,"***",IF(Estimates!I114<0.05,"**",IF(Estimates!I114<0.1,"*","")))) -> -0.527** | E46: =IF(Estimates!I115="","",TEXT(Estimates!E115,"0.000")&IF(Estimates!I115<0.01,"***",IF(Estimates!I115<0.05,"**",IF(Estimates!I115<0.1,"*","")))) -> -0.512*** | F46: =IF(Estimates!I116="","",TEXT(Estimates!E116,"0.000")&IF(Estimates!I116<0.01,"***",IF(Estimates!I116<0.05,"**",IF(Estimates!I116<0.1,"*","")))) -> -0.316** | G46: =IF(Estimates!I117="","",TEXT(Estimates!E117,"0.000")&IF(Estimates!I117<0.01,"***",IF(Estimates!I117<0.05,"**",IF(Estimates!I117<0.1,"*","")))) -> -0.402*** | H46: =IF(Estimates!I118="","",TEXT(Estimates!E118,"0.000")&IF(Estimates!I118<0.01,"***",IF(Estimates!I118<0.05,"**",IF(Estimates!I118<0.1,"*","")))) -> -0.492*** | I46: =IF(Estimates!I119="","",TEXT(Estimates!E119,"0.000")&IF(Estimates!I119<0.01,"***",IF(Estimates!I119<0.05,"**",IF(Estimates!I119<0.1,"*","")))) -> -0.489*** | J46: =IF(Estimates!I120="","",TEXT(Estimates!E120,"0.000")&IF(Estimates!I120<0.01,"***",IF(Estimates!I120<0.05,"**",IF(Estimates!I120<0.1,"*","")))) -> -0.371**
B47: =IF(Estimates!H112="","","("&TEXT(Estimates!H112,"0.00")&")") -> (-2.06) | C47: =IF(Estimates!H113="","","("&TEXT(Estimates!H113,"0.00")&")") -> (-2.70) | D47: =IF(Estimates!H114="","","("&TEXT(Estimates!H114,"0.00")&")") -> (-2.71) | E47: =IF(Estimates!H115="","","("&TEXT(Estimates!H115,"0.00")&")") -> (-3.63) | F47: =IF(Estimates!H116="","","("&TEXT(Estimates!H116,"0.00")&")") -> (-2.40) | G47: =IF(Estimates!H117="","","("&TEXT(Estimates!H117,"0.00")&")") -> (-3.83) | H47: =IF(Estimates!H118="","","("&TEXT(Estimates!H118,"0.00")&")") -> (-4.23) | I47: =IF(Estimates!H119="","","("&TEXT(Estimates!H119,"0.00")&")") -> (-3.69) | J47: =IF(Estimates!H120="","","("&TEXT(Estimates!H120,"0.00")&")") -> (-2.72)
...

Sheet Correlations
A1: Correlation of Benchmark-Adjusted and Peer-Adjusted Returns
A2: Correlations are computed over Table III sample plan-years (cio_dum = 1, fy <= 2020, curr1 = 0) where both returns are available. 'Within fiscal year' demeans both returns by fiscal year (fy) before correlating. Benchmark-Adjusted Return is the plan's return minus its policy benchmark return. 'Reported + inferred grade A/B' uses the benchmark return reported in the plan's financial report or, where none is stated, an inferred value graded A or B (the version in the earlier tables). 'Reported + inferred grade A only' drops the inferred values graded B (28 plan-years, 10 of them conflicted). 'Reported benchmarks only' drops all inferred values.
A4: Benchmark version | B4: Plan-years | C4: Pearson | D4: Spearman | E4: Pearson, within fiscal year | F4: Pearson, conflicted plan-years | G4: Pearson, other plan-years
A5: Reported + inferred grade A/B (as before) | B5: 1649 | C5: 0.44465216 | D5: 0.41606045 | E5: 0.44347178 | F5: 0.62290393 | G5: 0.40249726
A6: Reported + inferred grade A only | B6: 1621 | C6: 0.44631084 | D6: 0.41822288 | E6: 0.44330465 | F6: 0.62401249 | G6: 0.4044764
A7: Reported benchmarks only | B7: 1543 | C7: 0.47361757 | D7: 0.41716771 | E7: 0.47062867 | F7: 0.62980804 | G7: 0.43238715

Sheet Estimates
A1: Estimates behind the tables. Blue = regression output (coefficient, SE, minimum cluster count). t and p are formulas; p uses the t distribution with (min clusters - 1) df. SE double clustered by plan and year, with the eigenvalue fix.
A3: Table | B3: Benchmark | C3: Column / X | D3: Term | E3: Coefficient | F3: SE | G3: Clusters (min) | H3: t | I3: p
A4: Table III B | B4: Peer-adjusted: All plan-years | C4: (1) | D4: Conflicted CIO | E4: -0.55697013 | F4: 0.15141822 | G4: 19 | H4: =IF(F4>0,E4/F4,"") -> -3.678356 | I4: =IF(H4="","",TDIST(ABS(H4),G4-1,2)) -> 0.0017195765
A5: Table III B | B5: Peer-adjusted: All plan-years | C5: (2) | D5: Conflicted CIO | E5: -0.58232518 | F5: 0.1862998 | G5: 19 | H5: =IF(F5>0,E5/F5,"") -> -3.1257424 | I5: =IF(H5="","",TDIST(ABS(H5),G5-1,2)) -> 0.0058407567
A6: Table III B | B6: Peer-adjusted: All plan-years | C6: (3) | D6: Conflicted CIO | E6: -0.64076312 | F6: 0.29037999 | G6: 19 | H6: =IF(F6>0,E6/F6,"") -> -2.2066366 | I6: =IF(H6="","",TDIST(ABS(H6),G6-1,2)) -> 0.04056821
A7: Table III B | B7: Peer-adjusted: All plan-years | C7: (4) | D7: Conflicted CIO | E7: -0.69792191 | F7: 0.29373844 | G7: 19 | H7: =IF(F7>0,E7/F7,"") -> -2.3759979 | I7: =IF(H7="","",TDIST(ABS(H7),G7-1,2)) -> 0.028809582
A8: Table III B | B8: Peer-adjusted: All plan-years | C8: (5) | D8: Conflicted CIO | E8: -0.47452374 | F8: 0.22639981 | G8: 19 | H8: =IF(F8>0,E8/F8,"") -> -2.0959547 | I8: =IF(H8="","",TDIST(ABS(H8),G8-1,2)) -> 0.050488803
A9: Table III B | B9: Peer-adjusted: All plan-years | C9: (6) | D9: Conflicted CIO | E9: -0.50834616 | F9: 0.1826916 | G9: 19 | H9: =IF(F9>0,E9/F9,"") -> -2.7825371 | I9: =IF(H9="","",TDIST(ABS(H9),G9-1,2)) -> 0.012287709
A10: Table III B | B10: Peer-adjusted: Plan-years with the grade-A benchmark-adjusted return | C10: (1) | D10: Conflicted CIO | E10: -0.56584929 | F10: 0.17331657 | G10: 19 | H10: =IF(F10>0,E10/F10,"") -> -3.2648309 | I10: =IF(H10="","",TDIST(ABS(H10),G10-1,2)) -> 0.0043024694
A11: Table III B | B11: Peer-adjusted: Plan-years with the grade-A benchmark-adjusted return | C11: (2) | D11: Conflicted CIO | E11: -0.583696 | F11: 0.21332484 | G11: 19 | H11: =IF(F11>0,E11/F11,"") -> -2.736184 | I11: =IF(H11="","",TDIST(ABS(H11),G11-1,2)) -> 0.013566157
A12: Table III B | B12: Peer-adjusted: Plan-years with the grade-A benchmark-adjusted return | C12: (3) | D12: Conflicted CIO | E12: -0.60361757 | F12: 0.29273578 | G12: 19 | H12: =IF(F12>0,E12/F12,"") -> -2.0619876 | I12: =IF(H12="","",TDIST(ABS(H12),G12-1,2)) -> 0.053949199
A13: Table III B | B13: Peer-adjusted: Plan-years with the grade-A benchmark-adjusted return | C13: (4) | D13: Conflicted CIO | E13: -0.64219301 | F13: 0.28426977 | G13: 19 | H13: =IF(F13>0,E13/F13,"") -> -2.2590971 | I13: =IF(H13="","",TDIST(ABS(H13),G13-1,2)) -> 0.036521229
A14: Table III B | B14: Peer-adjusted: Plan-years with the grade-A benchmark-adjusted return | C14: (5) | D14: Conflicted CIO | E14: -0.39857056 | F14: 0.20237481 | G14: 19 | H14: =IF(F14>0,E14/F14,"") -> -1.9694672 | I14: =IF(H14="","",TDIST(ABS(H14),G14-1,2)) -> 0.06448766
A15: Table III B | B15: Peer-adjusted: Plan-years with the grade-A benchmark-adjusted return | C15: (6) | D15: Conflicted CIO | E15: -0.50587251 | F15: 0.21523059 | G15: 19 | H15: =IF(F15>0,E15/F15,"") -> -2.3503746 | I15: =IF(H15="","",TDIST(ABS(H15),G15-1,2)) -> 0.030357303
... A228: Interactions B | B228: Benchmark-adjusted: Reported benchmarks only | C228: Log CIO Age | D228: Conflicted CIO effect, 75th pct. of X | E228: -0.24054975 | F228: 0.18503189 | G228: 19 | H228: =IF(F228>0,E228/F228,"") -> -1.3000448 | I228: =IF(H228="","",TDIST(ABS(H228),G228-1,2)) -> 0.20998738
