Workbook

Sheet Event study
A1: Table 5b: Event Study of Conflicted CIO Performance Around the Loglisci Shock (FY2017 Base Year)
A2: This table re-estimates the Table 5b event study for Peer-Adjusted Return and for Benchmark-Adjusted Return (the plan's return minus the updated policy benchmark: the benchmark return reported in the plan's financial report or, where none is stated, an inferred value graded A or B). Each regression includes Conflicted CIO interacted with indicators for fiscal years 2005-2016 (FY2017 is the omitted base year), and endpoint bins for Conflicted CIO in years before 2005 and after 2017; there is no standalone Conflicted CIO term, so each coefficient is the effect of conflict in that year relative to FY2017. The control variables are those in effect at Table 5b in the paper's code: the lagged return, Size, the lagged funding ratio, lagged allocations, Financial Center, lagged log CIO age and tenure, lagged sibling plans and the political-state indicator. The tests group the coefficients by the timing of the shock: pre-shock (the pre-2005 bin and FY2005-2008), shock period (FY2009-2013, when shock2 = 1) and late period (FY2014-2016 and the post-2017 bin). 'Pre-shock equal' tests that the pre-shock coefficients are equal to each other. 'Pre-shock minus shock period' is the mean of the FY2005-2008 coefficients minus the mean of the FY2009-2013 coefficients, which does not depend on the choice of base year. The standard errors are double clustered by plan and year. Coefficients marked with ***, **, and * are significant at the 1%, 5%, and 10% level, respectively.
B4: Peer-adjusted return | F4: Benchmark-adjusted return (updated benchmark)
B5: Year FE | C5: Plan FE | D5: Plan and year FE | F5: Year FE | G5: Plan FE | H5: Plan and year FE
A6: Conflicted CIO x FY<2005 | B6: =IF(Estimates!H4="","",TEXT(Estimates!D4,"0.000")&IF(Estimates!H4<0.01,"***",IF(Estimates!H4<0.05,"**",IF(Estimates!H4<0.1,"*","")))) -> -0.845*** | C6: =IF(Estimates!H5="","",TEXT(Estimates!D5,"0.000")&IF(Estimates!H5<0.01,"***",IF(Estimates!H5<0.05,"**",IF(Estimates!H5<0.1,"*","")))) -> -0.504 | D6: =IF(Estimates!H6="","",TEXT(Estimates!D6,"0.000")&IF(Estimates!H6<0.01,"***",IF(Estimates!H6<0.05,"**",IF(Estimates!H6<0.1,"*","")))) -> -0.678** | F6: =IF(Estimates!H7="","",TEXT(Estimates!D7,"0.000")&IF(Estimates!H7<0.01,"***",IF(Estimates!H7<0.05,"**",IF(Estimates!H7<0.1,"*","")))) -> -0.805*** | G6: =IF(Estimates!H8="","",TEXT(Estimates!D8,"0.000")&IF(Estimates!H8<0.01,"***",IF(Estimates!H8<0.05,"**",IF(Estimates!H8<0.1,"*","")))) -> -0.591** | H6: =IF(Estimates!H9="","",TEXT(Estimates!D9,"0.000")&IF(Estimates!H9<0.01,"***",IF(Estimates!H9<0.05,"**",IF(Estimates!H9<0.1,"*","")))) -> -0.692***
B7: =IF(Estimates!G4="","","("&TEXT(Estimates!G4,"0.00")&")") -> (-4.89) | C7: =IF(Estimates!G5="","","("&TEXT(Estimates!G5,"0.00")&")") -> (-1.62) | D7: =IF(Estimates!G6="","","("&TEXT(Estimates!G6,"0.00")&")") -> (-2.18) | F7: =IF(Estimates!G7="","","("&TEXT(Estimates!G7,"0.00")&")") -> (-8.48) | G7: =IF(Estimates!G8="","","("&TEXT(Estimates!G8,"0.00")&")") -> (-2.11) | H7: =IF(Estimates!G9="","","("&TEXT(Estimates!G9,"0.00")&")") -> (-4.91)
A8: Conflicted CIO x FY2005 | B8: =IF(Estimates!H10="","",TEXT(Estimates!D10,"0.000")&IF(Estimates!H10<0.01,"***",IF(Estimates!H10<0.05,"**",IF(Estimates!H10<0.1,"*","")))) -> -0.710** | C8: =IF(Estimates!H11="","",TEXT(Estimates!D11,"0.000")&IF(Estimates!H11<0.01,"***",IF(Estimates!H11<0.05,"**",IF(Estimates!H11<0.1,"*","")))) -> -0.669* | D8: =IF(Estimates!H12="","",TEXT(Estimates!D12,"0.000")&IF(Estimates!H12<0.01,"***",IF(Estimates!H12<0.05,"**",IF(Estimates!H12<0.1,"*","")))) -> -0.796** | F8: =IF(Estimates!H13="","",TEXT(Estimates!D13,"0.000")&IF(Estimates!H13<0.01,"***",IF(Estimates!H13<0.05,"**",IF(Estimates!H13<0.1,"*","")))) -> -0.597** | G8: =IF(Estimates!H14="","",TEXT(Estimates!D14,"0.000")&IF(Estimates!H14<0.01,"***",IF(Estimates!H14<0.05,"**",IF(Estimates!H14<0.1,"*","")))) -> -0.090 | H8: =IF(Estimates!H15="","",TEXT(Estimates!D15,"0.000")&IF(Estimates!H15<0.01,"***",IF(Estimates!H15<0.05,"**",IF(Estimates!H15<0.1,"*","")))) -> -0.512
B9: =IF(Estimates!G10="","","("&TEXT(Estimates!G10,"0.00")&")") -> (-2.70) | C9: =IF(Estimates!G11="","","("&TEXT(Estimates!G11,"0.00")&")") -> (-1.77) | D9: =IF(Estimates!G12="","","("&TEXT(Estimates!G12,"0.00")&")") -> (-2.11) | F9: =IF(Estimates!G13="","","("&TEXT(Estimates!G13,"0.00")&")") -> (-2.74) | G9: =IF(Estimates!G14="","","("&TEXT(Estimates!G14,"0.00")&")") -> (-0.23) | H9: =IF(Estimates!G15="","","("&TEXT(Estimates!G15,"0.00")&")") -> (-1.69)
A10: Conflicted CIO x FY2006 | B10: =IF(Estimates!H16="","",TEXT(Estimates!D16,"0.000")&IF(Estimates!H16<0.01,"***",IF(Estimates!H16<0.05,"**",IF(Estimates!H16<0.1,"*","")))) -> -1.846*** | C10: =IF(Estimates!H17="","",TEXT(Estimates!D17,"0.000")&IF(Estimates!H17<0.01,"***",IF(Estimates!H17<0.05,"**",IF(Estimates!H17<0.1,"*","")))) -> -1.401*** | D10: =IF(Estimates!H18="","",TEXT(Estimates!D18,"0.000")&IF(Estimates!H18<0.01,"***",IF(Estimates!H18<0.05,"**",IF(Estimates!H18<0.1,"*","")))) -> -1.987*** | F10: =IF(Estimates!H19="","",TEXT(Estimates!D19,"0.000")&IF(Estimates!H19<0.01,"***",IF(Estimates!H19<0.05,"**",IF(Estimates!H19<0.1,"*","")))) -> -0.719*** | G10: =IF(Estimates!H20="","",TEXT(Estimates!D20,"0.000")&IF(Estimates!H20<0.01,"***",IF(Estimates!H20<0.05,"**",IF(Estimates!H20<0.1,"*","")))) -> 0.224 | H10: =IF(Estimates!H21="","",TEXT(Estimates!D21,"0.000")&IF(Estimates!H21<0.01,"***",IF(Estimates!H21<0.05,"**",IF(Estimates!H21<0.1,"*","")))) -> -0.514
B11: =IF(Estimates!G16="","","("&TEXT(Estimates!G16,"0.00")&")") -> (-5.27) | C11: =IF(Estimates!G17="","","("&TEXT(Estimates!G17,"0.00")&")") -> (-3.42) | D11: =IF(Estimates!G18="","","("&TEXT(Estimates!G18,"0.00")&")") -> (-4.35) | F11: =IF(Estimates!G19="","","("&TEXT(Estimates!G19,"0.00")&")") -> (-3.18) | G11: =IF(Estimates!G20="","","("&TEXT(Estimates!G20,"0.00")&")") -> (0.69) | H11: =IF(Estimates!G21="","","("&TEXT(Estimates!G21,"0.00")&")") -> (-1.67)
A12: Conflicted CIO x FY2007 | B12: =IF(Estimates!H22="","",TEXT(Estimates!D22,"0.000")&IF(Estimates!H22<0.01,"***",IF(Estimates!H22<0.05,"**",IF(Estimates!H22<0.1,"*","")))) -> -2.066*** | C12: =IF(Estimates!H23="","",TEXT(Estimates!D23,"0.000")&IF(Estimates!H23<0.01,"***",IF(Estimates!H23<0.05,"**",IF(Estimates!H23<0.1,"*","")))) -> -1.905*** | D12: =IF(Estimates!H24="","",TEXT(Estimates!D24,"0.000")&IF(Estimates!H24<0.01,"***",IF(Estimates!H24<0.05,"**",IF(Estimates!H24<0.1,"*","")))) -> -2.402*** | F12: =IF(Estimates!H25="","",TEXT(Estimates!D25,"0.000")&IF(Estimates!H25<0.01,"***",IF(Estimates!H25<0.05,"**",IF(Estimates!H25<0.1,"*","")))) -> -1.338*** | G12: =IF(Estimates!H26="","",TEXT(Estimates!D26,"0.000")&IF(Estimates!H26<0.01,"***",IF(Estimates!H26<0.05,"**",IF(Estimates!H26<0.1,"*","")))) -> -0.722** | H12: =IF(Estimates!H27="","",TEXT(Estimates!D27,"0.000")&IF(Estimates!H27<0.01,"***",IF(Estimates!H27<0.05,"**",IF(Estimates!H27<0.1,"*","")))) -> -1.225***
B13: =IF(Estimates!G22="","","("&TEXT(Estimates!G22,"0.00")&")") -> (-5.86) | C13: =IF(Estimates!G23="","","("&TEXT(Estimates!G23,"0.00")&")") -> (-4.62) | D13: =IF(Estimates!G24="","","("&TEXT(Estimates!G24,"0.00")&")") -> (-5.14) | F13: =IF(Estimates!G25="","","("&TEXT(Estimates!G25,"0.00")&")") -> (-6.00) | G13: =IF(Estimates!G26="","","("&TEXT(Estimates!G26,"0.00")&")") -> (-2.36) | H13: =IF(Estimates!G27="","","("&TEXT(Estimates!G27,"0.00")&")") -> (-4.45)
A14: Conflicted CIO x FY2008 | B14: =IF(Estimates!H28="","",TEXT(Estimates!D28,"0.000")&IF(Estimates!H28<0.01,"***",IF(Estimates!H28<0.05,"**",IF(Estimates!H28<0.1,"*","")))) -> -0.526 | C14: =IF(Estimates!H29="","",TEXT(Estimates!D29,"0.000")&IF(Estimates!H29<0.01,"***",IF(Estimates!H29<0.05,"**",IF(Estimates!H29<0.1,"*","")))) -> -1.038** | D14: =IF(Estimates!H30="","",TEXT(Estimates!D30,"0.000")&IF(Estimates!H30<0.01,"***",IF(Estimates!H30<0.05,"**",IF(Estimates!H30<0.1,"*","")))) -> -0.930* | F14: =IF(Estimates!H31="","",TEXT(Estimates!D31,"0.000")&IF(Estimates!H31<0.01,"***",IF(Estimates!H31<0.05,"**",IF(Estimates!H31<0.1,"*","")))) -> -0.189 | G14: =IF(Estimates!H32="","",TEXT(Estimates!D32,"0.000")&IF(Estimates!H32<0.01,"***",IF(Estimates!H32<0.05,"**",IF(Estimates!H32<0.1,"*","")))) -> -0.710* | H14: =IF(Estimates!H33="","",TEXT(Estimates!D33,"0.000")&IF(Estimates!H33<0.01,"***",IF(Estimates!H33<0.05,"**",IF(Estimates!H33<0.1,"*","")))) -> -0.075
B15: =IF(Estimates!G28="","","("&TEXT(Estimates!G28,"0.00")&")") -> (-1.62) | C15: =IF(Estimates!G29="","","("&TEXT(Estimates!G29,"0.00")&")") -> (-2.55) | D15: =IF(Estimates!G30="","","("&TEXT(Estimates!G30,"0.00")&")") -> (-1.96) | F15: =IF(Estimates!G31="","","("&TEXT(Estimates!G31,"0.00")&")") -> (-0.86) | G15: =IF(Estimates!G32="","","("&TEXT(Estimates!G32,"0.00")&")") -> (-2.02) | H15: =IF(Estimates!G33="","","("&TEXT(Estimates!G33,"0.00")&")") -> (-0.22)
A16: Conflicted CIO x FY2009 | B16: =IF(Estimates!H34="","",TEXT(Estimates!D34,"0.000")&IF(Estimates!H34<0.01,"***",IF(Estimates!H34<0.05,"**",IF(Estimates!H34<0.1,"*","")))) -> 1.160*** | C16: =IF(Estimates!H35="","",TEXT(Estimates!D35,"0.000")&IF(Estimates!H35<0.01,"***",IF(Estimates!H35<0.05,"**",IF(Estimates!H35<0.1,"*","")))) -> -0.148 | D16: =IF(Estimates!H36="","",TEXT(Estimates!D36,"0.000")&IF(Estimates!H36<0.01,"***",IF(Estimates!H36<0.05,"**",IF(Estimates!H36<0.1,"*","")))) -> 0.853* | F16: =IF(Estimates!H37="","",TEXT(Estimates!D37,"0.000")&IF(Estimates!H37<0.01,"***",IF(Estimates!H37<0.05,"**",IF(Estimates!H37<0.1,"*","")))) -> 0.342 | G16: =IF(Estimates!H38="","",TEXT(Estimates!D38,"0.000")&IF(Estimates!H38<0.01,"***",IF(Estimates!H38<0.05,"**",IF(Estimates!H38<0.1,"*","")))) -> -1.413*** | H16: =IF(Estimates!H39="","",TEXT(Estimates!D39,"0.000")&IF(Estimates!H39<0.01,"***",IF(Estimates!H39<0.05,"**",IF(Estimates!H39<0.1,"*","")))) -> 0.476
B17: =IF(Estimates!G34="","","("&TEXT(Estimates!G34,"0.00")&")") -> (3.99) | C17: =IF(Estimates!G35="","","("&TEXT(Estimates!G35,"0.00")&")") -> (-0.32) | D17: =IF(Estimates!G36="","","("&TEXT(Estimates!G36,"0.00")&")") -> (1.74) | F17: =IF(Estimates!G37="","","("&TEXT(Estimates!G37,"0.00")&")") -> (1.36) | G17: =IF(Estimates!G38="","","("&TEXT(Estimates!G38,"0.00")&")") -> (-3.29) | H17: =IF(Estimates!G39="","","("&TEXT(Estimates!G39,"0.00")&")") -> (1.22)
A18: Conflicted CIO x FY2010 | B18: =IF(Estimates!H40="","",TEXT(Estimates!D40,"0.000")&IF(Estimates!H40<0.01,"***",IF(Estimates!H40<0.05,"**",IF(Estimates!H40<0.1,"*","")))) -> -0.327 | C18: =IF(Estimates!H41="","",TEXT(Estimates!D41,"0.000")&IF(Estimates!H41<0.01,"***",IF(Estimates!H41<0.05,"**",IF(Estimates!H41<0.1,"*","")))) -> -0.624* | D18: =IF(Estimates!H42="","",TEXT(Estimates!D42,"0.000")&IF(Estimates!H42<0.01,"***",IF(Estimates!H42<0.05,"**",IF(Estimates!H42<0.1,"*","")))) -> -0.610* | F18: =IF(Estimates!H43="","",TEXT(Estimates!D43,"0.000")&IF(Estimates!H43<0.01,"***",IF(Estimates!H43<0.05,"**",IF(Estimates!H43<0.1,"*","")))) -> -0.081 | G18: =IF(Estimates!H44="","",TEXT(Estimates!D44,"0.000")&IF(Estimates!H44<0.01,"***",IF(Estimates!H44<0.05,"**",IF(Estimates!H44<0.1,"*","")))) -> 0.701 | H18: =IF(Estimates!H45="","",TEXT(Estimates!D45,"0.000")&IF(Estimates!H45<0.01,"***",IF(Estimates!H45<0.05,"**",IF(Estimates!H45<0.1,"*","")))) -> -0.067
B19: =IF(Estimates!G40="","","("&TEXT(Estimates!G40,"0.00")&")") -> (-1.26) | C19: =IF(Estimates!G41="","","("&TEXT(Estimates!G41,"0.00")&")") -> (-1.76) | D19: =IF(Estimates!G42="","","("&TEXT(Estimates!G42,"0.00")&")") -> (-1.87) | F19: =IF(Estimates!G43="","","("&TEXT(Estimates!G43,"0.00")&")") -> (-0.34) | G19: =IF(Estimates!G44="","","("&TEXT(Estimates!G44,"0.00")&")") -> (1.59) | H19: =IF(Estimates!G45="","","("&TEXT(Estimates!G45,"0.00")&")") -> (-0.25)
A20: Conflicted CIO x FY2011 | B20: =IF(Estimates!H46="","",TEXT(Estimates!D46,"0.000")&IF(Estimates!H46<0.01,"***",IF(Estimates!H46<0.05,"**",IF(Estimates!H46<0.1,"*","")))) -> -0.276 | C20: =IF(Estimates!H47="","",TEXT(Estimates!D47,"0.000")&IF(Estimates!H47<0.01,"***",IF(Estimates!H47<0.05,"**",IF(Estimates!H47<0.1,"*","")))) -> -1.142** | D20: =IF(Estimates!H48="","",TEXT(Estimates!D48,"0.000")&IF(Estimates!H48<0.01,"***",IF(Estimates!H48<0.05,"**",IF(Estimates!H48<0.1,"*","")))) -> -0.686* | F20: =IF(Estimates!H49="","",TEXT(Estimates!D49,"0.000")&IF(Estimates!H49<0.01,"***",IF(Estimates!H49<0.05,"**",IF(Estimates!H49<0.1,"*","")))) -> -0.196 | G20: =IF(Estimates!H50="","",TEXT(Estimates!D50,"0.000")&IF(Estimates!H50<0.01,"***",IF(Estimates!H50<0.05,"**",IF(Estimates!H50<0.1,"*","")))) -> -0.602*** | H20: =IF(Estimates!H51="","",TEXT(Estimates!D51,"0.000")&IF(Estimates!H51<0.01,"***",IF(Estimates!H51<0.05,"**",IF(Estimates!H51<0.1,"*","")))) -> -0.170
B21: =IF(Estimates!G46="","","("&TEXT(Estimates!G46,"0.00")&")") -> (-1.02) | C21: =IF(Estimates!G47="","","("&TEXT(Estimates!G47,"0.00")&")") -> (-2.71) | D21: =IF(Estimates!G48="","","("&TEXT(Estimates!G48,"0.00")&")") -> (-1.76) | F21: =IF(Estimates!G49="","","("&TEXT(Estimates!G49,"0.00")&")") -> (-0.86) | G21: =IF(Estimates!G50="","","("&TEXT(Estimates!G50,"0.00")&")") -> (-3.16) | H21: =IF(Estimates!G51="","","("&TEXT(Estimates!G51,"0.00")&")") -> (-0.71)
A22: Conflicted CIO x FY2012 | B22: =IF(Estimates!H52="","",TEXT(Estimates!D52,"0.000")&IF(Estimates!H52<0.01,"***",IF(Estimates!H52<0.05,"**",IF(Estimates!H52<0.1,"*","")))) -> -0.252 | C22: =IF(Estimates!H53="","",TEXT(Estimates!D53,"0.000")&IF(Estimates!H53<0.01,"***",IF(Estimates!H53<0.05,"**",IF(Estimates!H53<0.1,"*","")))) -> -0.983** | D22: =IF(Estimates!H54="","",TEXT(Estimates!D54,"0.000")&IF(Estimates!H54<0.01,"***",IF(Estimates!H54<0.05,"**",IF(Estimates!H54<0.1,"*","")))) -> -0.358 | F22: =IF(Estimates!H55="","",TEXT(Estimates!D55,"0.000")&IF(Estimates!H55<0.01,"***",IF(Estimates!H55<0.05,"**",IF(Estimates!H55<0.1,"*","")))) -> -0.380* | G22: =IF(Estimates!H56="","",TEXT(Estimates!D56,"0.000")&IF(Estimates!H56<0.01,"***",IF(Estimates!H56<0.05,"**",IF(Estimates!H56<0.1,"*","")))) -> -0.931*** | H22: =IF(Estimates!H57="","",TEXT(Estimates!D57,"0.000")&IF(Estimates!H57<0.01,"***",IF(Estimates!H57<0.05,"**",IF(Estimates!H57<0.1,"*","")))) -> -0.201
B23: =IF(Estimates!G52="","","("&TEXT(Estimates!G52,"0.00")&")") -> (-1.28) | C23: =IF(Estimates!G53="","","("&TEXT(Estimates!G53,"0.00")&")") -> (-2.73) | D23: =IF(Estimates!G54="","","("&TEXT(Estimates!G54,"0.00")&")") -> (-1.28) | F23: =IF(Estimates!G55="","","("&TEXT(Estimates!G55,"0.00")&")") -> (-1.76) | G23: =IF(Estimates!G56="","","("&TEXT(Estimates!G56,"0.00")&")") -> (-2.96) | H23: =IF(Estimates!G57="","","("&TEXT(Estimates!G57,"0.00")&")") -> (-0.68)
A24: Conflicted CIO x FY2013 | B24: =IF(Estimates!H58="","",TEXT(Estimates!D58,"0.000")&IF(Estimates!H58<0.01,"***",IF(Estimates!H58<0.05,"**",IF(Estimates!H58<0.1,"*","")))) -> 0.274 | C24: =IF(Estimates!H59="","",TEXT(Estimates!D59,"0.000")&IF(Estimates!H59<0.01,"***",IF(Estimates!H59<0.05,"**",IF(Estimates!H59<0.1,"*","")))) -> -0.515* | D24: =IF(Estimates!H60="","",TEXT(Estimates!D60,"0.000")&IF(Estimates!H60<0.01,"***",IF(Estimates!H60<0.05,"**",IF(Estimates!H60<0.1,"*","")))) -> -0.007 | F24: =IF(Estimates!H61="","",TEXT(Estimates!D61,"0.000")&IF(Estimates!H61<0.01,"***",IF(Estimates!H61<0.05,"**",IF(Estimates!H61<0.1,"*","")))) -> -0.372** | G24: =IF(Estimates!H62="","",TEXT(Estimates!D62,"0.000")&IF(Estimates!H62<0.01,"***",IF(Estimates!H62<0.05,"**",IF(Estimates!H62<0.1,"*","")))) -> 0.208 | H24: =IF(Estimates!H63="","",TEXT(Estimates!D63,"0.000")&IF(Estimates!H63<0.01,"***",IF(Estimates!H63<0.05,"**",IF(Estimates!H63<0.1,"*","")))) -> -0.354
B25: =IF(Estimates!G58="","","("&TEXT(Estimates!G58,"0.00")&")") -> (1.51) | C25: =IF(Estimates!G59="","","("&TEXT(Estimates!G59,"0.00")&")") -> (-1.92) | D25: =IF(Estimates!G60="","","("&TEXT(Estimates!G60,"0.00")&")") -> (-0.03) | F25: =IF(Estimates!G61="","","("&TEXT(Estimates!G61,"0.00")&")") -> (-2.54) | G25: =IF(Estimates!G62="","","("&TEXT(Estimates!G62,"0.00")&")") -> (0.77) | H25: =IF(Estimates!G63="","","("&TEXT(Estimates!G63,"0.00")&")") -> (-1.41)
A26: Conflicted CIO x FY2014 | B26: =IF(Estimates!H64="","",TEXT(Estimates!D64,"0.000")&IF(Estimates!H64<0.01,"***",IF(Estimates!H64<0.05,"**",IF(Estimates!H64<0.1,"*","")))) -> -0.471** | C26: =IF(Estimates!H65="","",TEXT(Estimates!D65,"0.000")&IF(Estimates!H65<0.01,"***",IF(Estimates!H65<0.05,"**",IF(Estimates!H65<0.1,"*","")))) -> -0.570* | D26: =IF(Estimates!H66="","",TEXT(Estimates!D66,"0.000")&IF(Estimates!H66<0.01,"***",IF(Estimates!H66<0.05,"**",IF(Estimates!H66<0.1,"*","")))) -> -0.652* | F26: =IF(Estimates!H67="","",TEXT(Estimates!D67,"0.000")&IF(Estimates!H67<0.01,"***",IF(Estimates!H67<0.05,"**",IF(Estimates!H67<0.1,"*","")))) -> 0.226 | G26: =IF(Estimates!H68="","",TEXT(Estimates!D68,"0.000")&IF(Estimates!H68<0.01,"***",IF(Estimates!H68<0.05,"**",IF(Estimates!H68<0.1,"*","")))) -> 0.391 | H26: =IF(Estimates!H69="","",TEXT(Estimates!D69,"0.000")&IF(Estimates!H69<0.01,"***",IF(Estimates!H69<0.05,"**",IF(Estimates!H69<0.1,"*","")))) -> 0.451*
B27: =IF(Estimates!G64="","","("&TEXT(Estimates!G64,"0.00")&")") -> (-2.61) | C27: =IF(Estimates!G65="","","("&TEXT(Estimates!G65,"0.00")&")") -> (-1.79) | D27: =IF(Estimates!G66="","","("&TEXT(Estimates!G66,"0.00")&")") -> (-2.02) | F27: =IF(Estimates!G67="","","("&TEXT(Estimates!G67,"0.00")&")") -> (0.98) | G27: =IF(Estimates!G68="","","("&TEXT(Estimates!G68,"0.00")&")") -> (1.63) | H27: =IF(Estimates!G69="","","("&TEXT(Estimates!G69,"0.00")&")") -> (1.74)
A28: Conflicted CIO x FY2015 | B28: =IF(Estimates!H70="","",TEXT(Estimates!D70,"0.000")&IF(Estimates!H70<0.01,"***",IF(Estimates!H70<0.05,"**",IF(Estimates!H70<0.1,"*","")))) -> -0.502** | C28: =IF(Estimates!H71="","",TEXT(Estimates!D71,"0.000")&IF(Estimates!H71<0.01,"***",IF(Estimates!H71<0.05,"**",IF(Estimates!H71<0.1,"*","")))) -> -0.485 | D28: =IF(Estimates!H72="","",TEXT(Estimates!D72,"0.000")&IF(Estimates!H72<0.01,"***",IF(Estimates!H72<0.05,"**",IF(Estimates!H72<0.1,"*","")))) -> -0.562 | F28: =IF(Estimates!H73="","",TEXT(Estimates!D73,"0.000")&IF(Estimates!H73<0.01,"***",IF(Estimates!H73<0.05,"**",IF(Estimates!H73<0.1,"*","")))) -> -0.680*** | G28: =IF(Estimates!H74="","",TEXT(Estimates!D74,"0.000")&IF(Estimates!H74<0.01,"***",IF(Estimates!H74<0.05,"**",IF(Estimates!H74<0.1,"*","")))) -> -0.236 | H28: =IF(Estimates!H75="","",TEXT(Estimates!D75,"0.000")&IF(Estimates!H75<0.01,"***",IF(Estimates!H75<0.05,"**",IF(Estimates!H75<0.1,"*","")))) -> -0.315
B29: =IF(Estimates!G70="","","("&TEXT(Estimates!G70,"0.00")&")") -> (-2.57) | C29: =IF(Estimates!G71="","","("&TEXT(Estimates!G71,"0.00")&")") -> (-1.37) | D29: =IF(Estimates!G72="","","("&TEXT(Estimates!G72,"0.00")&")") -> (-1.52) | F29: =IF(Estimates!G73="","","("&TEXT(Estimates!G73,"0.00")&")") -> (-4.11) | G29: =IF(Estimates!G74="","","("&TEXT(Estimates!G74,"0.00")&")") -> (-0.87) | H29: =IF(Estimates!G75="","","("&TEXT(Estimates!G75,"0.00")&")") -> (-1.44)
A30: Conflicted CIO x FY2016 | B30: =IF(Estimates!H76="","",TEXT(Estimates!D76,"0.000")&IF(Estimates!H76<0.01,"***",IF(Estimates!H76<0.05,"**",IF(Estimates!H76<0.1,"*","")))) -> -1.208*** | C30: =IF(Estimates!H77="","",TEXT(Estimates!D77,"0.000")&IF(Estimates!H77<0.01,"***",IF(Estimates!H77<0.05,"**",IF(Estimates!H77<0.1,"*","")))) -> -0.536 | D30: =IF(Estimates!H78="","",TEXT(Estimates!D78,"0.000")&IF(Estimates!H78<0.01,"***",IF(Estimates!H78<0.05,"**",IF(Estimates!H78<0.1,"*","")))) -> -1.047** | F30: =IF(Estimates!H79="","",TEXT(Estimates!D79,"0.000")&IF(Estimates!H79<0.01,"***",IF(Estimates!H79<0.05,"**",IF(Estimates!H79<0.1,"*","")))) -> -0.549** | G30: =IF(Estimates!H80="","",TEXT(Estimates!D80,"0.000")&IF(Estimates!H80<0.01,"***",IF(Estimates!H80<0.05,"**",IF(Estimates!H80<0.1,"*","")))) -> -0.517 | H30: =IF(Estimates!H81="","",TEXT(Estimates!D81,"0.000")&IF(Estimates!H81<0.01,"***",IF(Estimates!H81<0.05,"**",IF(Estimates!H81<0.1,"*","")))) -> 0.138
B31: =IF(Estimates!G76="","","("&TEXT(Estimates!G76,"0.00")&")") -> (-5.25) | C31: =IF(Estimates!G77="","","("&TEXT(Estimates!G77,"0.00")&")") -> (-1.36) | D31: =IF(Estimates!G78="","","("&TEXT(Estimates!G78,"0.00")&")") -> (-2.29) | F31: =IF(Estimates!G79="","","("&TEXT(Estimates!G79,"0.00")&")") -> (-2.80) | G31: =IF(Estimates!G80="","","("&TEXT(Estimates!G80,"0.00")&")") -> (-1.52) | H31: =IF(Estimates!G81="","","("&TEXT(Estimates!G81,"0.00")&")") -> (0.43)
A32: Conflicted CIO x FY>2017 | B32: =IF(Estimates!H82="","",TEXT(Estimates!D82,"0.000")&IF(Estimates!H82<0.01,"***",IF(Estimates!H82<0.05,"**",IF(Estimates!H82<0.1,"*","")))) -> 0.533 | C32: =IF(Estimates!H83="","",TEXT(Estimates!D83,"0.000")&IF(Estimates!H83<0.01,"***",IF(Estimates!H83<0.05,"**",IF(Estimates!H83<0.1,"*","")))) -> 0.717 | D32: =IF(Estimates!H84="","",TEXT(Estimates!D84,"0.000")&IF(Estimates!H84<0.01,"***",IF(Estimates!H84<0.05,"**",IF(Estimates!H84<0.1,"*","")))) -> 0.235 | F32: =IF(Estimates!H85="","",TEXT(Estimates!D85,"0.000")&IF(Estimates!H85<0.01,"***",IF(Estimates!H85<0.05,"**",IF(Estimates!H85<0.1,"*","")))) -> 0.462 | G32: =IF(Estimates!H86="","",TEXT(Estimates!D86,"0.000")&IF(Estimates!H86<0.01,"***",IF(Estimates!H86<0.05,"**",IF(Estimates!H86<0.1,"*","")))) -> 0.518 | H32: =IF(Estimates!H87="","",TEXT(Estimates!D87,"0.000")&IF(Estimates!H87<0.01,"***",IF(Estimates!H87<0.05,"**",IF(Estimates!H87<0.1,"*","")))) -> 0.497
B33: =IF(Estimates!G82="","","("&TEXT(Estimates!G82,"0.00")&")") -> (1.45) | C33: =IF(Estimates!G83="","","("&TEXT(Estimates!G83,"0.00")&")") -> (1.08) | D33: =IF(Estimates!G84="","","("&TEXT(Estimates!G84,"0.00")&")") -> (0.35) | F33: =IF(Estimates!G85="","","("&TEXT(Estimates!G85,"0.00")&")") -> (1.04) | G33: =IF(Estimates!G86="","","("&TEXT(Estimates!G86,"0.00")&")") -> (1.41) | H33: =IF(Estimates!G87="","","("&TEXT(Estimates!G87,"0.00")&")") -> (0.96)
A35: Pre-shock minus shock period | B35: =IF(Estimates!H88="","",TEXT(Estimates!D88,"0.000")&IF(Estimates!H88<0.01,"***",IF(Estimates!H88<0.05,"**",IF(Estimates!H88<0.1,"*","")))) -> -1.403*** | C35: =IF(Estimates!H89="","",TEXT(Estimates!D89,"0.000")&IF(Estimates!H89<0.01,"***",IF(Estimates!H89<0.05,"**",IF(Estimates!H89<0.1,"*","")))) -> -0.571* | D35: =IF(Estimates!H90="","",TEXT(Estimates!D90,"0.000")&IF(Estimates!H90<0.01,"***",IF(Estimates!H90<0.05,"**",IF(Estimates!H90<0.1,"*","")))) -> -1.367*** | F35: =IF(Estimates!H91="","",TEXT(Estimates!D91,"0.000")&IF(Estimates!H91<0.01,"***",IF(Estimates!H91<0.05,"**",IF(Estimates!H91<0.1,"*","")))) -> -0.573*** | G35: =IF(Estimates!H92="","",TEXT(Estimates!D92,"0.000")&IF(Estimates!H92<0.01,"***",IF(Estimates!H92<0.05,"**",IF(Estimates!H92<0.1,"*","")))) -> 0.083 | H35: =IF(Estimates!H93="","",TEXT(Estimates!D93,"0.000")&IF(Estimates!H93<0.01,"***",IF(Estimates!H93<0.05,"**",IF(Estimates!H93<0.1,"*","")))) -> -0.518*
B36: =IF(Estimates!G88="","","("&TEXT(Estimates!G88,"0.00")&")") -> (-4.59) | C36: =IF(Estimates!G89="","","("&TEXT(Estimates!G89,"0.00")&")") -> (-1.96) | D36: =IF(Estimates!G90="","","("&TEXT(Estimates!G90,"0.00")&")") -> (-3.92) | F36: =IF(Estimates!G91="","","("&TEXT(Estimates!G91,"0.00")&")") -> (-3.09) | G36: =IF(Estimates!G92="","","("&TEXT(Estimates!G92,"0.00")&")") -> (0.25) | H36: =IF(Estimates!G93="","","("&TEXT(Estimates!G93,"0.00")&")") -> (-1.79)
A38: p-value: pre-shock jointly zero | B38: 1.6909564e-05 | C38: 8.9381232e-05 | D38: 0.00012863434 | F38: 3.8601137e-07 | G38: 0.0053508312 | H38: 8.382982e-08
A39: p-value: pre-shock equal | B39: 2.4214406e-05 | C39: 5.4222074e-05 | D39: 0.0010919591 | F39: 0.00032906099 | G39: 0.0048794889 | H39: 0.0022773673
A40: p-value: shock period jointly zero | B40: 0.00058966844 | C40: 0.00032079931 | D40: 3.2924778e-05 | F40: 0.047613172 | G40: 0.00010499233 | H40: 0.60588825
A41: p-value: late period jointly zero | B41: 1.9006718e-05 | C41: 1.6105074e-05 | D41: 0.001745973 | F41: 0.00091189529 | G41: 0.0027711467 | H41: 0.021515528
A42: Observations | B42: 1566 | C42: 1565 | D42: 1565 | F42: 1395 | G42: 1394 | H42: 1394
A43: Adjusted R-squared | B43: 0.072688457 | C43: 0.078029218 | D43: 0.098563334 | F43: 0.13489278 | G43: 0.03070548 | H43: 0.13168022
...

Sheet Estimates
A1: Estimates behind the table. Blue = regression output (coefficient, SE, minimum cluster count). t and p are formulas; p uses the t distribution with (min clusters - 1) df. SE double clustered by plan and year, with the eigenvalue fix.
A3: Dependent variable | B3: Specification | C3: Term | D3: Coefficient | E3: SE | F3: Clusters (min) | G3: t | H3: p
A4: Peer-adjusted return | B4: Year FE | C4: pre_bin | D4: -0.84496985 | E4: 0.17268978 | F4: 19 | G4: =IF(E4>0,D4/E4,"") -> -4.8929927 | H4: =IF(G4="","",TDIST(ABS(G4),F4-1,2)) -> 0.00011710036
A5: Peer-adjusted return | B5: Plan FE | C5: pre_bin | D5: -0.50429919 | E5: 0.31038543 | F5: 19 | G5: =IF(E5>0,D5/E5,"") -> -1.6247515 | H5: =IF(G5="","",TDIST(ABS(G5),F5-1,2)) -> 0.12159654
A6: Peer-adjusted return | B6: Plan and year FE | C6: pre_bin | D6: -0.67806926 | E6: 0.31042857 | F6: 19 | G6: =IF(E6>0,D6/E6,"") -> -2.1843004 | H6: =IF(G6="","",TDIST(ABS(G6),F6-1,2)) -> 0.042413319
A7: Benchmark-adjusted return (updated benchmark) | B7: Year FE | C7: pre_bin | D7: -0.80533373 | E7: 0.095012711 | F7: 19 | G7: =IF(E7>0,D7/E7,"") -> -8.4760631 | H7: =IF(G7="","",TDIST(ABS(G7),F7-1,2)) -> 1.0656017e-07
A8: Benchmark-adjusted return (updated benchmark) | B8: Plan FE | C8: pre_bin | D8: -0.5912622 | E8: 0.2797206 | F8: 19 | G8: =IF(E8>0,D8/E8,"") -> -2.1137599 | H8: =IF(G8="","",TDIST(ABS(G8),F8-1,2)) -> 0.048756568
A9: Benchmark-adjusted return (updated benchmark) | B9: Plan and year FE | C9: pre_bin | D9: -0.69203436 | E9: 0.14108006 | F9: 19 | G9: =IF(E9>0,D9/E9,"") -> -4.90526 | H9: =IF(G9="","",TDIST(ABS(G9),F9-1,2)) -> 0.00011401891
A10: Peer-adjusted return | B10: Year FE | C10: conf_yr_2005 | D10: -0.7098586 | E10: 0.26309945 | F10: 19 | G10: =IF(E10>0,D10/E10,"") -> -2.6980619 | H10: =IF(G10="","",TDIST(ABS(G10),F10-1,2)) -> 0.014712089
A11: Peer-adjusted return | B11: Plan FE | C11: conf_yr_2005 | D11: -0.66938892 | E11: 0.37887219 | F11: 19 | G11: =IF(E11>0,D11/E11,"") -> -1.7667935 | H11: =IF(G11="","",TDIST(ABS(G11),F11-1,2)) -> 0.09421448
A12: Peer-adjusted return | B12: Plan and year FE | C12: conf_yr_2005 | D12: -0.79615333 | E12: 0.37806395 | F12: 19 | G12: =IF(E12>0,D12/E12,"") -> -2.1058695 | H12: =IF(G12="","",TDIST(ABS(G12),F12-1,2)) -> 0.049517435
A13: Benchmark-adjusted return (updated benchmark) | B13: Year FE | C13: conf_yr_2005 | D13: -0.59722457 | E13: 0.21768019 | F13: 19 | G13: =IF(E13>0,D13/E13,"") -> -2.7435872 | H13: =IF(G13="","",TDIST(ABS(G13),F13-1,2)) -> 0.013353752
A14: Benchmark-adjusted return (updated benchmark) | B14: Plan FE | C14: conf_yr_2005 | D14: -0.089608424 | E14: 0.39339372 | F14: 19 | G14: =IF(E14>0,D14/E14,"") -> -0.22778305 | H14: =IF(G14="","",TDIST(ABS(G14),F14-1,2)) -> 0.82238227
A15: Benchmark-adjusted return (updated benchmark) | B15: Plan and year FE | C15: conf_yr_2005 | D15: -0.51153756 | E15: 0.30357291 | F15: 19 | G15: =IF(E15>0,D15/E15,"") -> -1.6850567 | H15: =IF(G15="","",TDIST(ABS(G15),F15-1,2)) -> 0.10923604
... A93: Benchmark-adjusted return (updated benchmark) | B93: Plan and year FE | C93: pre-shock minus shock period | D93: -0.51799572 | E93: 0.28916287 | F93: 19 | G93: =IF(E93>0,D93/E93,"") -> -1.7913632 | H93: =IF(G93="","",TDIST(ABS(G93),F93-1,2)) -> 0.090064712
