Workbook

Sheet Table XI-split
A1: Table XI: Conflicted CIOs: Plan Performance in the First versus Second Half of Tenure (updated benchmark, fiscal-year-end fixed effects)
A2: This table repeats the regressions of Table III, splitting the Conflicted CIO indicator into two indicators: Conflicted CIO x First Half of Tenure, equal to 1 in the fiscal years in which a conflicted CIO's tenure is at most one half of the CIO's tenure at departure, and Conflicted CIO x Second Half of Tenure, equal to 1 in the remaining fiscal years of a conflicted CIO's tenure. The omitted category is all plan-years run by non-conflicted CIOs, so each coefficient is the performance differential of conflicted CIOs in that part of their tenure relative to non-conflicted CIOs. Tenure at departure is the CIO's tenure in the last fiscal year observed in the plan plus any gap to the departure year. 11 conflicted plan-years for which tenure at departure cannot be determined are absorbed by a separate indicator that is not reported. The performance measure in Panel A is Peer-Adjusted Return, which is the difference of a plan's return and the average pension plan return each year. The performance measure in Panel B is Benchmark-Adjusted Return, which is calculated as the plan's return minus the return of its updated policy benchmark (the benchmark return reported in the plan's financial report or, where none is stated, an inferred value graded A or B). The other independent variables are as defined in Table I. All columns include fiscal-year-end date fixed effects, so plans are compared only with plans whose fiscal year covers the same twelve months. Column 3 adds plan fixed effects. The last row reports the p-value of a test that the first-half and second-half coefficients are equal. The standard errors are double clustered by plan and year. Coefficients marked with ***, **, and * are significant at the 1%, 5%, and 10% level, respectively.
A4: Panel A. Peer-Adjusted Returns
B5: (1) | C5: (2) | D5: (3)
B6: Peer-adj. Ret. (t) | C6: Peer-adj. Ret. (t) | D6: Peer-adj. Ret. (t)
A7: Conflicted CIO x First Half of Tenure (0/1) | B7: =TEXT('Estimates-split'!B4,"0.000")&IF('Estimates-split'!E4="","",IF('Estimates-split'!E4<0.01,"***",IF('Estimates-split'!E4<0.05,"**",IF('Estimates-split'!E4<0.1,"*","")))) -> -0.474** | C7: =TEXT('Estimates-split'!F4,"0.000")&IF('Estimates-split'!I4="","",IF('Estimates-split'!I4<0.01,"***",IF('Estimates-split'!I4<0.05,"**",IF('Estimates-split'!I4<0.1,"*","")))) -> -0.497* | D7: =TEXT('Estimates-split'!J4,"0.000")&IF('Estimates-split'!M4="","",IF('Estimates-split'!M4<0.01,"***",IF('Estimates-split'!M4<0.05,"**",IF('Estimates-split'!M4<0.1,"*","")))) -> -0.845**
B8: =IF('Estimates-split'!D4="","(n/a)","("&TEXT('Estimates-split'!D4,"0.00")&")") -> (-2.51) | C8: =IF('Estimates-split'!H4="","(n/a)","("&TEXT('Estimates-split'!H4,"0.00")&")") -> (-2.10) | D8: =IF('Estimates-split'!L4="","(n/a)","("&TEXT('Estimates-split'!L4,"0.00")&")") -> (-2.29)
A9: Conflicted CIO x Second Half of Tenure (0/1) | B9: =TEXT('Estimates-split'!B5,"0.000")&IF('Estimates-split'!E5="","",IF('Estimates-split'!E5<0.01,"***",IF('Estimates-split'!E5<0.05,"**",IF('Estimates-split'!E5<0.1,"*","")))) -> -0.596*** | C9: =TEXT('Estimates-split'!F5,"0.000")&IF('Estimates-split'!I5="","",IF('Estimates-split'!I5<0.01,"***",IF('Estimates-split'!I5<0.05,"**",IF('Estimates-split'!I5<0.1,"*","")))) -> -0.536** | D9: =TEXT('Estimates-split'!J5,"0.000")&IF('Estimates-split'!M5="","",IF('Estimates-split'!M5<0.01,"***",IF('Estimates-split'!M5<0.05,"**",IF('Estimates-split'!M5<0.1,"*","")))) -> -0.644*
B10: =IF('Estimates-split'!D5="","(n/a)","("&TEXT('Estimates-split'!D5,"0.00")&")") -> (-3.32) | C10: =IF('Estimates-split'!H5="","(n/a)","("&TEXT('Estimates-split'!H5,"0.00")&")") -> (-2.56) | D10: =IF('Estimates-split'!L5="","(n/a)","("&TEXT('Estimates-split'!L5,"0.00")&")") -> (-2.02)
A11: Investment Return (t - 1) | B11: =TEXT('Estimates-split'!B6,"0.000")&IF('Estimates-split'!E6="","",IF('Estimates-split'!E6<0.01,"***",IF('Estimates-split'!E6<0.05,"**",IF('Estimates-split'!E6<0.1,"*","")))) -> 0.119 | C11: =TEXT('Estimates-split'!F6,"0.000")&IF('Estimates-split'!I6="","",IF('Estimates-split'!I6<0.01,"***",IF('Estimates-split'!I6<0.05,"**",IF('Estimates-split'!I6<0.1,"*","")))) -> 0.091 | D11: =TEXT('Estimates-split'!J6,"0.000")&IF('Estimates-split'!M6="","",IF('Estimates-split'!M6<0.01,"***",IF('Estimates-split'!M6<0.05,"**",IF('Estimates-split'!M6<0.1,"*","")))) -> 0.030
B12: =IF('Estimates-split'!D6="","(n/a)","("&TEXT('Estimates-split'!D6,"0.00")&")") -> (1.55) | C12: =IF('Estimates-split'!H6="","(n/a)","("&TEXT('Estimates-split'!H6,"0.00")&")") -> (1.16) | D12: =IF('Estimates-split'!L6="","(n/a)","("&TEXT('Estimates-split'!L6,"0.00")&")") -> (0.40)
A13: Log (Plan Size) (t-1) | B13: =TEXT('Estimates-split'!B7,"0.000")&IF('Estimates-split'!E7="","",IF('Estimates-split'!E7<0.01,"***",IF('Estimates-split'!E7<0.05,"**",IF('Estimates-split'!E7<0.1,"*","")))) -> 0.013 | C13: =TEXT('Estimates-split'!F7,"0.000")&IF('Estimates-split'!I7="","",IF('Estimates-split'!I7<0.01,"***",IF('Estimates-split'!I7<0.05,"**",IF('Estimates-split'!I7<0.1,"*","")))) -> 0.072 | D13: =TEXT('Estimates-split'!J7,"0.000")&IF('Estimates-split'!M7="","",IF('Estimates-split'!M7<0.01,"***",IF('Estimates-split'!M7<0.05,"**",IF('Estimates-split'!M7<0.1,"*","")))) -> -1.428*
B14: =IF('Estimates-split'!D7="","(n/a)","("&TEXT('Estimates-split'!D7,"0.00")&")") -> (0.26) | C14: =IF('Estimates-split'!H7="","(n/a)","("&TEXT('Estimates-split'!H7,"0.00")&")") -> (1.27) | D14: =IF('Estimates-split'!L7="","(n/a)","("&TEXT('Estimates-split'!L7,"0.00")&")") -> (-1.77)
A15: Funding Ratio (t-1) | B15: =TEXT('Estimates-split'!B8,"0.000")&IF('Estimates-split'!E8="","",IF('Estimates-split'!E8<0.01,"***",IF('Estimates-split'!E8<0.05,"**",IF('Estimates-split'!E8<0.1,"*","")))) -> -0.004 | C15: =TEXT('Estimates-split'!F8,"0.000")&IF('Estimates-split'!I8="","",IF('Estimates-split'!I8<0.01,"***",IF('Estimates-split'!I8<0.05,"**",IF('Estimates-split'!I8<0.1,"*","")))) -> -0.006 | D15: =TEXT('Estimates-split'!J8,"0.000")&IF('Estimates-split'!M8="","",IF('Estimates-split'!M8<0.01,"***",IF('Estimates-split'!M8<0.05,"**",IF('Estimates-split'!M8<0.1,"*","")))) -> -0.030**
B16: =IF('Estimates-split'!D8="","(n/a)","("&TEXT('Estimates-split'!D8,"0.00")&")") -> (-0.94) | C16: =IF('Estimates-split'!H8="","(n/a)","("&TEXT('Estimates-split'!H8,"0.00")&")") -> (-1.00) | D16: =IF('Estimates-split'!L8="","(n/a)","("&TEXT('Estimates-split'!L8,"0.00")&")") -> (-2.68)
A17: Equity Allocation (%) | B17: =TEXT('Estimates-split'!B9,"0.000")&IF('Estimates-split'!E9="","",IF('Estimates-split'!E9<0.01,"***",IF('Estimates-split'!E9<0.05,"**",IF('Estimates-split'!E9<0.1,"*","")))) -> -0.073 | C17: =TEXT('Estimates-split'!F9,"0.000")&IF('Estimates-split'!I9="","",IF('Estimates-split'!I9<0.01,"***",IF('Estimates-split'!I9<0.05,"**",IF('Estimates-split'!I9<0.1,"*","")))) -> -0.012 | D17: =TEXT('Estimates-split'!J9,"0.000")&IF('Estimates-split'!M9="","",IF('Estimates-split'!M9<0.01,"***",IF('Estimates-split'!M9<0.05,"**",IF('Estimates-split'!M9<0.1,"*","")))) -> -0.035
B18: =IF('Estimates-split'!D9="","(n/a)","("&TEXT('Estimates-split'!D9,"0.00")&")") -> (-0.58) | C18: =IF('Estimates-split'!H9="","(n/a)","("&TEXT('Estimates-split'!H9,"0.00")&")") -> (-0.21) | D18: =IF('Estimates-split'!L9="","(n/a)","("&TEXT('Estimates-split'!L9,"0.00")&")") -> (-0.40)
A19: Fixed Income Allocation (%) | B19: =TEXT('Estimates-split'!B10,"0.000")&IF('Estimates-split'!E10="","",IF('Estimates-split'!E10<0.01,"***",IF('Estimates-split'!E10<0.05,"**",IF('Estimates-split'!E10<0.1,"*","")))) -> -0.086 | C19: =TEXT('Estimates-split'!F10,"0.000")&IF('Estimates-split'!I10="","",IF('Estimates-split'!I10<0.01,"***",IF('Estimates-split'!I10<0.05,"**",IF('Estimates-split'!I10<0.1,"*","")))) -> -0.020 | D19: =TEXT('Estimates-split'!J10,"0.000")&IF('Estimates-split'!M10="","",IF('Estimates-split'!M10<0.01,"***",IF('Estimates-split'!M10<0.05,"**",IF('Estimates-split'!M10<0.1,"*","")))) -> -0.041
B20: =IF('Estimates-split'!D10="","(n/a)","("&TEXT('Estimates-split'!D10,"0.00")&")") -> (-0.64) | C20: =IF('Estimates-split'!H10="","(n/a)","("&TEXT('Estimates-split'!H10,"0.00")&")") -> (-0.26) | D20: =IF('Estimates-split'!L10="","(n/a)","("&TEXT('Estimates-split'!L10,"0.00")&")") -> (-0.42)
A21: Real Estate Allocation (%) | B21: =TEXT('Estimates-split'!B11,"0.000")&IF('Estimates-split'!E11="","",IF('Estimates-split'!E11<0.01,"***",IF('Estimates-split'!E11<0.05,"**",IF('Estimates-split'!E11<0.1,"*","")))) -> -0.067 | C21: =TEXT('Estimates-split'!F11,"0.000")&IF('Estimates-split'!I11="","",IF('Estimates-split'!I11<0.01,"***",IF('Estimates-split'!I11<0.05,"**",IF('Estimates-split'!I11<0.1,"*","")))) -> -0.005 | D21: =TEXT('Estimates-split'!J11,"0.000")&IF('Estimates-split'!M11="","",IF('Estimates-split'!M11<0.01,"***",IF('Estimates-split'!M11<0.05,"**",IF('Estimates-split'!M11<0.1,"*","")))) -> -0.082
B22: =IF('Estimates-split'!D11="","(n/a)","("&TEXT('Estimates-split'!D11,"0.00")&")") -> (-0.53) | C22: =IF('Estimates-split'!H11="","(n/a)","("&TEXT('Estimates-split'!H11,"0.00")&")") -> (-0.09) | D22: =IF('Estimates-split'!L11="","(n/a)","("&TEXT('Estimates-split'!L11,"0.00")&")") -> (-0.87)
A23: Private Equity Allocation (%) | B23: =TEXT('Estimates-split'!B12,"0.000")&IF('Estimates-split'!E12="","",IF('Estimates-split'!E12<0.01,"***",IF('Estimates-split'!E12<0.05,"**",IF('Estimates-split'!E12<0.1,"*","")))) -> -0.061 | C23: =TEXT('Estimates-split'!F12,"0.000")&IF('Estimates-split'!I12="","",IF('Estimates-split'!I12<0.01,"***",IF('Estimates-split'!I12<0.05,"**",IF('Estimates-split'!I12<0.1,"*","")))) -> 0.011 | D23: =TEXT('Estimates-split'!J12,"0.000")&IF('Estimates-split'!M12="","",IF('Estimates-split'!M12<0.01,"***",IF('Estimates-split'!M12<0.05,"**",IF('Estimates-split'!M12<0.1,"*","")))) -> 0.013
B24: =IF('Estimates-split'!D12="","(n/a)","("&TEXT('Estimates-split'!D12,"0.00")&")") -> (-0.45) | C24: =IF('Estimates-split'!H12="","(n/a)","("&TEXT('Estimates-split'!H12,"0.00")&")") -> (0.17) | D24: =IF('Estimates-split'!L12="","(n/a)","("&TEXT('Estimates-split'!L12,"0.00")&")") -> (0.14)
A25: Hedge Fund Allocation (%) | B25: =TEXT('Estimates-split'!B13,"0.000")&IF('Estimates-split'!E13="","",IF('Estimates-split'!E13<0.01,"***",IF('Estimates-split'!E13<0.05,"**",IF('Estimates-split'!E13<0.1,"*","")))) -> -0.117 | C25: =TEXT('Estimates-split'!F13,"0.000")&IF('Estimates-split'!I13="","",IF('Estimates-split'!I13<0.01,"***",IF('Estimates-split'!I13<0.05,"**",IF('Estimates-split'!I13<0.1,"*","")))) -> -0.053 | D25: =TEXT('Estimates-split'!J13,"0.000")&IF('Estimates-split'!M13="","",IF('Estimates-split'!M13<0.01,"***",IF('Estimates-split'!M13<0.05,"**",IF('Estimates-split'!M13<0.1,"*","")))) -> -0.087
B26: =IF('Estimates-split'!D13="","(n/a)","("&TEXT('Estimates-split'!D13,"0.00")&")") -> (-0.93) | C26: =IF('Estimates-split'!H13="","(n/a)","("&TEXT('Estimates-split'!H13,"0.00")&")") -> (-0.87) | D26: =IF('Estimates-split'!L13="","(n/a)","("&TEXT('Estimates-split'!L13,"0.00")&")") -> (-1.17)
A27: Misc. Alternatives Allocation (%) | B27: =TEXT('Estimates-split'!B14,"0.000")&IF('Estimates-split'!E14="","",IF('Estimates-split'!E14<0.01,"***",IF('Estimates-split'!E14<0.05,"**",IF('Estimates-split'!E14<0.1,"*","")))) -> -0.094 | C27: =TEXT('Estimates-split'!F14,"0.000")&IF('Estimates-split'!I14="","",IF('Estimates-split'!I14<0.01,"***",IF('Estimates-split'!I14<0.05,"**",IF('Estimates-split'!I14<0.1,"*","")))) -> -0.032 | D27: =TEXT('Estimates-split'!J14,"0.000")&IF('Estimates-split'!M14="","",IF('Estimates-split'!M14<0.01,"***",IF('Estimates-split'!M14<0.05,"**",IF('Estimates-split'!M14<0.1,"*","")))) -> -0.081
B28: =IF('Estimates-split'!D14="","(n/a)","("&TEXT('Estimates-split'!D14,"0.00")&")") -> (-0.72) | C28: =IF('Estimates-split'!H14="","(n/a)","("&TEXT('Estimates-split'!H14,"0.00")&")") -> (-0.55) | D28: =IF('Estimates-split'!L14="","(n/a)","("&TEXT('Estimates-split'!L14,"0.00")&")") -> (-0.90)
A29: Commodities Allocation (%) | B29: =TEXT('Estimates-split'!B15,"0.000")&IF('Estimates-split'!E15="","",IF('Estimates-split'!E15<0.01,"***",IF('Estimates-split'!E15<0.05,"**",IF('Estimates-split'!E15<0.1,"*","")))) -> -0.134 | C29: =TEXT('Estimates-split'!F15,"0.000")&IF('Estimates-split'!I15="","",IF('Estimates-split'!I15<0.01,"***",IF('Estimates-split'!I15<0.05,"**",IF('Estimates-split'!I15<0.1,"*","")))) -> -0.065 | D29: =TEXT('Estimates-split'!J15,"0.000")&IF('Estimates-split'!M15="","",IF('Estimates-split'!M15<0.01,"***",IF('Estimates-split'!M15<0.05,"**",IF('Estimates-split'!M15<0.1,"*","")))) -> -0.135
B30: =IF('Estimates-split'!D15="","(n/a)","("&TEXT('Estimates-split'!D15,"0.00")&")") -> (-1.02) | C30: =IF('Estimates-split'!H15="","(n/a)","("&TEXT('Estimates-split'!H15,"0.00")&")") -> (-1.14) | D30: =IF('Estimates-split'!L15="","(n/a)","("&TEXT('Estimates-split'!L15,"0.00")&")") -> (-1.34)
A31: Cash Allocation (%) | B31: =TEXT('Estimates-split'!B16,"0.000")&IF('Estimates-split'!E16="","",IF('Estimates-split'!E16<0.01,"***",IF('Estimates-split'!E16<0.05,"**",IF('Estimates-split'!E16<0.1,"*","")))) -> -0.094 | C31: =TEXT('Estimates-split'!F16,"0.000")&IF('Estimates-split'!I16="","",IF('Estimates-split'!I16<0.01,"***",IF('Estimates-split'!I16<0.05,"**",IF('Estimates-split'!I16<0.1,"*","")))) -> -0.039 | D31: =TEXT('Estimates-split'!J16,"0.000")&IF('Estimates-split'!M16="","",IF('Estimates-split'!M16<0.01,"***",IF('Estimates-split'!M16<0.05,"**",IF('Estimates-split'!M16<0.1,"*","")))) -> -0.056
B32: =IF('Estimates-split'!D16="","(n/a)","("&TEXT('Estimates-split'!D16,"0.00")&")") -> (-0.67) | C32: =IF('Estimates-split'!H16="","(n/a)","("&TEXT('Estimates-split'!H16,"0.00")&")") -> (-0.52) | D32: =IF('Estimates-split'!L16="","(n/a)","("&TEXT('Estimates-split'!L16,"0.00")&")") -> (-0.47)
A33: Financial Center (0/1) | B33: =TEXT('Estimates-split'!B17,"0.000")&IF('Estimates-split'!E17="","",IF('Estimates-split'!E17<0.01,"***",IF('Estimates-split'!E17<0.05,"**",IF('Estimates-split'!E17<0.1,"*","")))) -> 0.065 | C33: =TEXT('Estimates-split'!F17,"0.000")&IF('Estimates-split'!I17="","",IF('Estimates-split'!I17<0.01,"***",IF('Estimates-split'!I17<0.05,"**",IF('Estimates-split'!I17<0.1,"*","")))) -> 0.089
B34: =IF('Estimates-split'!D17="","(n/a)","("&TEXT('Estimates-split'!D17,"0.00")&")") -> (0.46) | C34: =IF('Estimates-split'!H17="","(n/a)","("&TEXT('Estimates-split'!H17,"0.00")&")") -> (0.58)
A35: Log (CIO Age) (t-1) | C35: =TEXT('Estimates-split'!F18,"0.000")&IF('Estimates-split'!I18="","",IF('Estimates-split'!I18<0.01,"***",IF('Estimates-split'!I18<0.05,"**",IF('Estimates-split'!I18<0.1,"*","")))) -> -0.270 | D35: =TEXT('Estimates-split'!J18,"0.000")&IF('Estimates-split'!M18="","",IF('Estimates-split'!M18<0.01,"***",IF('Estimates-split'!M18<0.05,"**",IF('Estimates-split'!M18<0.1,"*","")))) -> 0.793
C36: =IF('Estimates-split'!H18="","(n/a)","("&TEXT('Estimates-split'!H18,"0.00")&")") -> (-0.50) | D36: =IF('Estimates-split'!L18="","(n/a)","("&TEXT('Estimates-split'!L18,"0.00")&")") -> (0.96)
A37: Log (CIO Tenure) (t-1) | C37: =TEXT('Estimates-split'!F19,"0.000")&IF('Estimates-split'!I19="","",IF('Estimates-split'!I19<0.01,"***",IF('Estimates-split'!I19<0.05,"**",IF('Estimates-split'!I19<0.1,"*","")))) -> 0.066 | D37: =TEXT('Estimates-split'!J19,"0.000")&IF('Estimates-split'!M19="","",IF('Estimates-split'!M19<0.01,"***",IF('Estimates-split'!M19<0.05,"**",IF('Estimates-split'!M19<0.1,"*","")))) -> 0.008
C38: =IF('Estimates-split'!H19="","(n/a)","("&TEXT('Estimates-split'!H19,"0.00")&")") -> (0.79) | D38: =IF('Estimates-split'!L19="","(n/a)","("&TEXT('Estimates-split'!L19,"0.00")&")") -> (0.06)
A39: CIO Prior Private Experience (0/1) | C39: =TEXT('Estimates-split'!F20,"0.000")&IF('Estimates-split'!I20="","",IF('Estimates-split'!I20<0.01,"***",IF('Estimates-split'!I20<0.05,"**",IF('Estimates-split'!I20<0.1,"*","")))) -> 0.062 | D39: =TEXT('Estimates-split'!J20,"0.000")&IF('Estimates-split'!M20="","",IF('Estimates-split'!M20<0.01,"***",IF('Estimates-split'!M20<0.05,"**",IF('Estimates-split'!M20<0.1,"*","")))) -> 0.009
C40: =IF('Estimates-split'!H20="","(n/a)","("&TEXT('Estimates-split'!H20,"0.00")&")") -> (0.56) | D40: =IF('Estimates-split'!L20="","(n/a)","("&TEXT('Estimates-split'!L20,"0.00")&")") -> (0.04)
A41: CIO Attended Elite College (0/1) | C41: =TEXT('Estimates-split'!F21,"0.000")&IF('Estimates-split'!I21="","",IF('Estimates-split'!I21<0.01,"***",IF('Estimates-split'!I21<0.05,"**",IF('Estimates-split'!I21<0.1,"*","")))) -> -0.183 | D41: =TEXT('Estimates-split'!J21,"0.000")&IF('Estimates-split'!M21="","",IF('Estimates-split'!M21<0.01,"***",IF('Estimates-split'!M21<0.05,"**",IF('Estimates-split'!M21<0.1,"*","")))) -> 0.287
...

Sheet Table XII-split
A1: Table XII: Conflicted CIOs: Fee Ratio in the First versus Second Half of Tenure (fiscal-year-end fixed effects)
A2: This table repeats the regressions of Table XI with Fee Ratio as the dependent variable. Fee Ratio is the plan's total investment fees as a percentage of plan assets. Conflicted CIO x First Half of Tenure and Conflicted CIO x Second Half of Tenure are defined as in Table XI, and the omitted category is all plan-years run by non-conflicted CIOs. The other independent variables are as defined in Table I. All columns include fiscal-year-end date fixed effects, so plans are compared only with plans whose fiscal year covers the same twelve months. Column 3 adds plan fixed effects. The last row reports the p-value of a test that the first-half and second-half coefficients are equal. The standard errors are double clustered by plan and year. Coefficients marked with ***, **, and * are significant at the 1%, 5%, and 10% level, respectively.
B4: (1) | C4: (2) | D4: (3)
B5: Fee Ratio (t) | C5: Fee Ratio (t) | D5: Fee Ratio (t)
A6: Conflicted CIO x First Half of Tenure (0/1) | B6: =TEXT('Estimates-split'!Z4,"0.000")&IF('Estimates-split'!AC4="","",IF('Estimates-split'!AC4<0.01,"***",IF('Estimates-split'!AC4<0.05,"**",IF('Estimates-split'!AC4<0.1,"*","")))) -> -0.065 | C6: =TEXT('Estimates-split'!AD4,"0.000")&IF('Estimates-split'!AG4="","",IF('Estimates-split'!AG4<0.01,"***",IF('Estimates-split'!AG4<0.05,"**",IF('Estimates-split'!AG4<0.1,"*","")))) -> -0.027 | D6: =TEXT('Estimates-split'!AH4,"0.000")&IF('Estimates-split'!AK4="","",IF('Estimates-split'!AK4<0.01,"***",IF('Estimates-split'!AK4<0.05,"**",IF('Estimates-split'!AK4<0.1,"*","")))) -> 0.041
B7: =IF('Estimates-split'!AB4="","(n/a)","("&TEXT('Estimates-split'!AB4,"0.00")&")") -> (-1.68) | C7: =IF('Estimates-split'!AF4="","(n/a)","("&TEXT('Estimates-split'!AF4,"0.00")&")") -> (-0.52) | D7: =IF('Estimates-split'!AJ4="","(n/a)","("&TEXT('Estimates-split'!AJ4,"0.00")&")") -> (0.69)
A8: Conflicted CIO x Second Half of Tenure (0/1) | B8: =TEXT('Estimates-split'!Z5,"0.000")&IF('Estimates-split'!AC5="","",IF('Estimates-split'!AC5<0.01,"***",IF('Estimates-split'!AC5<0.05,"**",IF('Estimates-split'!AC5<0.1,"*","")))) -> -0.069 | C8: =TEXT('Estimates-split'!AD5,"0.000")&IF('Estimates-split'!AG5="","",IF('Estimates-split'!AG5<0.01,"***",IF('Estimates-split'!AG5<0.05,"**",IF('Estimates-split'!AG5<0.1,"*","")))) -> -0.042 | D8: =TEXT('Estimates-split'!AH5,"0.000")&IF('Estimates-split'!AK5="","",IF('Estimates-split'!AK5<0.01,"***",IF('Estimates-split'!AK5<0.05,"**",IF('Estimates-split'!AK5<0.1,"*","")))) -> 0.031
B9: =IF('Estimates-split'!AB5="","(n/a)","("&TEXT('Estimates-split'!AB5,"0.00")&")") -> (-1.61) | C9: =IF('Estimates-split'!AF5="","(n/a)","("&TEXT('Estimates-split'!AF5,"0.00")&")") -> (-0.91) | D9: =IF('Estimates-split'!AJ5="","(n/a)","("&TEXT('Estimates-split'!AJ5,"0.00")&")") -> (0.51)
A10: Investment Return (t - 1) | B10: =TEXT('Estimates-split'!Z6,"0.000")&IF('Estimates-split'!AC6="","",IF('Estimates-split'!AC6<0.01,"***",IF('Estimates-split'!AC6<0.05,"**",IF('Estimates-split'!AC6<0.1,"*","")))) -> 0.002 | C10: =TEXT('Estimates-split'!AD6,"0.000")&IF('Estimates-split'!AG6="","",IF('Estimates-split'!AG6<0.01,"***",IF('Estimates-split'!AG6<0.05,"**",IF('Estimates-split'!AG6<0.1,"*","")))) -> 0.001 | D10: =TEXT('Estimates-split'!AH6,"0.000")&IF('Estimates-split'!AK6="","",IF('Estimates-split'!AK6<0.01,"***",IF('Estimates-split'!AK6<0.05,"**",IF('Estimates-split'!AK6<0.1,"*","")))) -> -0.003
B11: =IF('Estimates-split'!AB6="","(n/a)","("&TEXT('Estimates-split'!AB6,"0.00")&")") -> (0.46) | C11: =IF('Estimates-split'!AF6="","(n/a)","("&TEXT('Estimates-split'!AF6,"0.00")&")") -> (0.22) | D11: =IF('Estimates-split'!AJ6="","(n/a)","("&TEXT('Estimates-split'!AJ6,"0.00")&")") -> (-0.82)
A12: Log (Plan Size) (t-1) | B12: =TEXT('Estimates-split'!Z7,"0.000")&IF('Estimates-split'!AC7="","",IF('Estimates-split'!AC7<0.01,"***",IF('Estimates-split'!AC7<0.05,"**",IF('Estimates-split'!AC7<0.1,"*","")))) -> -0.026* | C12: =TEXT('Estimates-split'!AD7,"0.000")&IF('Estimates-split'!AG7="","",IF('Estimates-split'!AG7<0.01,"***",IF('Estimates-split'!AG7<0.05,"**",IF('Estimates-split'!AG7<0.1,"*","")))) -> -0.030* | D12: =TEXT('Estimates-split'!AH7,"0.000")&IF('Estimates-split'!AK7="","",IF('Estimates-split'!AK7<0.01,"***",IF('Estimates-split'!AK7<0.05,"**",IF('Estimates-split'!AK7<0.1,"*","")))) -> 0.025
B13: =IF('Estimates-split'!AB7="","(n/a)","("&TEXT('Estimates-split'!AB7,"0.00")&")") -> (-1.78) | C13: =IF('Estimates-split'!AF7="","(n/a)","("&TEXT('Estimates-split'!AF7,"0.00")&")") -> (-2.01) | D13: =IF('Estimates-split'!AJ7="","(n/a)","("&TEXT('Estimates-split'!AJ7,"0.00")&")") -> (0.20)
A14: Funding Ratio (t-1) | B14: =TEXT('Estimates-split'!Z8,"0.000")&IF('Estimates-split'!AC8="","",IF('Estimates-split'!AC8<0.01,"***",IF('Estimates-split'!AC8<0.05,"**",IF('Estimates-split'!AC8<0.1,"*","")))) -> -0.001 | C14: =TEXT('Estimates-split'!AD8,"0.000")&IF('Estimates-split'!AG8="","",IF('Estimates-split'!AG8<0.01,"***",IF('Estimates-split'!AG8<0.05,"**",IF('Estimates-split'!AG8<0.1,"*","")))) -> -0.001 | D14: =TEXT('Estimates-split'!AH8,"0.000")&IF('Estimates-split'!AK8="","",IF('Estimates-split'!AK8<0.01,"***",IF('Estimates-split'!AK8<0.05,"**",IF('Estimates-split'!AK8<0.1,"*","")))) -> -0.002**
B15: =IF('Estimates-split'!AB8="","(n/a)","("&TEXT('Estimates-split'!AB8,"0.00")&")") -> (-0.69) | C15: =IF('Estimates-split'!AF8="","(n/a)","("&TEXT('Estimates-split'!AF8,"0.00")&")") -> (-1.36) | D15: =IF('Estimates-split'!AJ8="","(n/a)","("&TEXT('Estimates-split'!AJ8,"0.00")&")") -> (-2.71)
A16: Equity Allocation (%) | B16: =TEXT('Estimates-split'!Z9,"0.000")&IF('Estimates-split'!AC9="","",IF('Estimates-split'!AC9<0.01,"***",IF('Estimates-split'!AC9<0.05,"**",IF('Estimates-split'!AC9<0.1,"*","")))) -> -0.036 | C16: =TEXT('Estimates-split'!AD9,"0.000")&IF('Estimates-split'!AG9="","",IF('Estimates-split'!AG9<0.01,"***",IF('Estimates-split'!AG9<0.05,"**",IF('Estimates-split'!AG9<0.1,"*","")))) -> -0.084 | D16: =TEXT('Estimates-split'!AH9,"0.000")&IF('Estimates-split'!AK9="","",IF('Estimates-split'!AK9<0.01,"***",IF('Estimates-split'!AK9<0.05,"**",IF('Estimates-split'!AK9<0.1,"*","")))) -> -0.080
B17: =IF('Estimates-split'!AB9="","(n/a)","("&TEXT('Estimates-split'!AB9,"0.00")&")") -> (-1.06) | C17: =IF('Estimates-split'!AF9="","(n/a)","("&TEXT('Estimates-split'!AF9,"0.00")&")") -> (-1.25) | D17: =IF('Estimates-split'!AJ9="","(n/a)","("&TEXT('Estimates-split'!AJ9,"0.00")&")") -> (-1.55)
A18: Fixed Income Allocation (%) | B18: =TEXT('Estimates-split'!Z10,"0.000")&IF('Estimates-split'!AC10="","",IF('Estimates-split'!AC10<0.01,"***",IF('Estimates-split'!AC10<0.05,"**",IF('Estimates-split'!AC10<0.1,"*","")))) -> -0.040 | C18: =TEXT('Estimates-split'!AD10,"0.000")&IF('Estimates-split'!AG10="","",IF('Estimates-split'!AG10<0.01,"***",IF('Estimates-split'!AG10<0.05,"**",IF('Estimates-split'!AG10<0.1,"*","")))) -> -0.088 | D18: =TEXT('Estimates-split'!AH10,"0.000")&IF('Estimates-split'!AK10="","",IF('Estimates-split'!AK10<0.01,"***",IF('Estimates-split'!AK10<0.05,"**",IF('Estimates-split'!AK10<0.1,"*","")))) -> -0.086
B19: =IF('Estimates-split'!AB10="","(n/a)","("&TEXT('Estimates-split'!AB10,"0.00")&")") -> (-1.19) | C19: =IF('Estimates-split'!AF10="","(n/a)","("&TEXT('Estimates-split'!AF10,"0.00")&")") -> (-1.31) | D19: =IF('Estimates-split'!AJ10="","(n/a)","("&TEXT('Estimates-split'!AJ10,"0.00")&")") -> (-1.65)
A20: Real Estate Allocation (%) | B20: =TEXT('Estimates-split'!Z11,"0.000")&IF('Estimates-split'!AC11="","",IF('Estimates-split'!AC11<0.01,"***",IF('Estimates-split'!AC11<0.05,"**",IF('Estimates-split'!AC11<0.1,"*","")))) -> -0.034 | C20: =TEXT('Estimates-split'!AD11,"0.000")&IF('Estimates-split'!AG11="","",IF('Estimates-split'!AG11<0.01,"***",IF('Estimates-split'!AG11<0.05,"**",IF('Estimates-split'!AG11<0.1,"*","")))) -> -0.080 | D20: =TEXT('Estimates-split'!AH11,"0.000")&IF('Estimates-split'!AK11="","",IF('Estimates-split'!AK11<0.01,"***",IF('Estimates-split'!AK11<0.05,"**",IF('Estimates-split'!AK11<0.1,"*","")))) -> -0.084
B21: =IF('Estimates-split'!AB11="","(n/a)","("&TEXT('Estimates-split'!AB11,"0.00")&")") -> (-0.96) | C21: =IF('Estimates-split'!AF11="","(n/a)","("&TEXT('Estimates-split'!AF11,"0.00")&")") -> (-1.19) | D21: =IF('Estimates-split'!AJ11="","(n/a)","("&TEXT('Estimates-split'!AJ11,"0.00")&")") -> (-1.63)
A22: Private Equity Allocation (%) | B22: =TEXT('Estimates-split'!Z12,"0.000")&IF('Estimates-split'!AC12="","",IF('Estimates-split'!AC12<0.01,"***",IF('Estimates-split'!AC12<0.05,"**",IF('Estimates-split'!AC12<0.1,"*","")))) -> -0.030 | C22: =TEXT('Estimates-split'!AD12,"0.000")&IF('Estimates-split'!AG12="","",IF('Estimates-split'!AG12<0.01,"***",IF('Estimates-split'!AG12<0.05,"**",IF('Estimates-split'!AG12<0.1,"*","")))) -> -0.077 | D22: =TEXT('Estimates-split'!AH12,"0.000")&IF('Estimates-split'!AK12="","",IF('Estimates-split'!AK12<0.01,"***",IF('Estimates-split'!AK12<0.05,"**",IF('Estimates-split'!AK12<0.1,"*","")))) -> -0.059
B23: =IF('Estimates-split'!AB12="","(n/a)","("&TEXT('Estimates-split'!AB12,"0.00")&")") -> (-0.91) | C23: =IF('Estimates-split'!AF12="","(n/a)","("&TEXT('Estimates-split'!AF12,"0.00")&")") -> (-1.15) | D23: =IF('Estimates-split'!AJ12="","(n/a)","("&TEXT('Estimates-split'!AJ12,"0.00")&")") -> (-1.13)
A24: Hedge Fund Allocation (%) | B24: =TEXT('Estimates-split'!Z13,"0.000")&IF('Estimates-split'!AC13="","",IF('Estimates-split'!AC13<0.01,"***",IF('Estimates-split'!AC13<0.05,"**",IF('Estimates-split'!AC13<0.1,"*","")))) -> -0.019 | C24: =TEXT('Estimates-split'!AD13,"0.000")&IF('Estimates-split'!AG13="","",IF('Estimates-split'!AG13<0.01,"***",IF('Estimates-split'!AG13<0.05,"**",IF('Estimates-split'!AG13<0.1,"*","")))) -> -0.066 | D24: =TEXT('Estimates-split'!AH13,"0.000")&IF('Estimates-split'!AK13="","",IF('Estimates-split'!AK13<0.01,"***",IF('Estimates-split'!AK13<0.05,"**",IF('Estimates-split'!AK13<0.1,"*","")))) -> -0.063
B25: =IF('Estimates-split'!AB13="","(n/a)","("&TEXT('Estimates-split'!AB13,"0.00")&")") -> (-0.55) | C25: =IF('Estimates-split'!AF13="","(n/a)","("&TEXT('Estimates-split'!AF13,"0.00")&")") -> (-0.97) | D25: =IF('Estimates-split'!AJ13="","(n/a)","("&TEXT('Estimates-split'!AJ13,"0.00")&")") -> (-1.23)
A26: Misc. Alternatives Allocation (%) | B26: =TEXT('Estimates-split'!Z14,"0.000")&IF('Estimates-split'!AC14="","",IF('Estimates-split'!AC14<0.01,"***",IF('Estimates-split'!AC14<0.05,"**",IF('Estimates-split'!AC14<0.1,"*","")))) -> -0.033 | C26: =TEXT('Estimates-split'!AD14,"0.000")&IF('Estimates-split'!AG14="","",IF('Estimates-split'!AG14<0.01,"***",IF('Estimates-split'!AG14<0.05,"**",IF('Estimates-split'!AG14<0.1,"*","")))) -> -0.079 | D26: =TEXT('Estimates-split'!AH14,"0.000")&IF('Estimates-split'!AK14="","",IF('Estimates-split'!AK14<0.01,"***",IF('Estimates-split'!AK14<0.05,"**",IF('Estimates-split'!AK14<0.1,"*","")))) -> -0.068
B27: =IF('Estimates-split'!AB14="","(n/a)","("&TEXT('Estimates-split'!AB14,"0.00")&")") -> (-1.01) | C27: =IF('Estimates-split'!AF14="","(n/a)","("&TEXT('Estimates-split'!AF14,"0.00")&")") -> (-1.19) | D27: =IF('Estimates-split'!AJ14="","(n/a)","("&TEXT('Estimates-split'!AJ14,"0.00")&")") -> (-1.32)
A28: Commodities Allocation (%) | B28: =TEXT('Estimates-split'!Z15,"0.000")&IF('Estimates-split'!AC15="","",IF('Estimates-split'!AC15<0.01,"***",IF('Estimates-split'!AC15<0.05,"**",IF('Estimates-split'!AC15<0.1,"*","")))) -> -0.031 | C28: =TEXT('Estimates-split'!AD15,"0.000")&IF('Estimates-split'!AG15="","",IF('Estimates-split'!AG15<0.01,"***",IF('Estimates-split'!AG15<0.05,"**",IF('Estimates-split'!AG15<0.1,"*","")))) -> -0.076 | D28: =TEXT('Estimates-split'!AH15,"0.000")&IF('Estimates-split'!AK15="","",IF('Estimates-split'!AK15<0.01,"***",IF('Estimates-split'!AK15<0.05,"**",IF('Estimates-split'!AK15<0.1,"*","")))) -> -0.078
B29: =IF('Estimates-split'!AB15="","(n/a)","("&TEXT('Estimates-split'!AB15,"0.00")&")") -> (-0.89) | C29: =IF('Estimates-split'!AF15="","(n/a)","("&TEXT('Estimates-split'!AF15,"0.00")&")") -> (-1.16) | D29: =IF('Estimates-split'!AJ15="","(n/a)","("&TEXT('Estimates-split'!AJ15,"0.00")&")") -> (-1.54)
A30: Cash Allocation (%) | B30: =TEXT('Estimates-split'!Z16,"0.000")&IF('Estimates-split'!AC16="","",IF('Estimates-split'!AC16<0.01,"***",IF('Estimates-split'!AC16<0.05,"**",IF('Estimates-split'!AC16<0.1,"*","")))) -> -0.034 | C30: =TEXT('Estimates-split'!AD16,"0.000")&IF('Estimates-split'!AG16="","",IF('Estimates-split'!AG16<0.01,"***",IF('Estimates-split'!AG16<0.05,"**",IF('Estimates-split'!AG16<0.1,"*","")))) -> -0.082 | D30: =TEXT('Estimates-split'!AH16,"0.000")&IF('Estimates-split'!AK16="","",IF('Estimates-split'!AK16<0.01,"***",IF('Estimates-split'!AK16<0.05,"**",IF('Estimates-split'!AK16<0.1,"*","")))) -> -0.074
B31: =IF('Estimates-split'!AB16="","(n/a)","("&TEXT('Estimates-split'!AB16,"0.00")&")") -> (-1.01) | C31: =IF('Estimates-split'!AF16="","(n/a)","("&TEXT('Estimates-split'!AF16,"0.00")&")") -> (-1.22) | D31: =IF('Estimates-split'!AJ16="","(n/a)","("&TEXT('Estimates-split'!AJ16,"0.00")&")") -> (-1.43)
A32: Financial Center (0/1) | B32: =TEXT('Estimates-split'!Z17,"0.000")&IF('Estimates-split'!AC17="","",IF('Estimates-split'!AC17<0.01,"***",IF('Estimates-split'!AC17<0.05,"**",IF('Estimates-split'!AC17<0.1,"*","")))) -> -0.027 | C32: =TEXT('Estimates-split'!AD17,"0.000")&IF('Estimates-split'!AG17="","",IF('Estimates-split'!AG17<0.01,"***",IF('Estimates-split'!AG17<0.05,"**",IF('Estimates-split'!AG17<0.1,"*","")))) -> 0.027
B33: =IF('Estimates-split'!AB17="","(n/a)","("&TEXT('Estimates-split'!AB17,"0.00")&")") -> (-0.66) | C33: =IF('Estimates-split'!AF17="","(n/a)","("&TEXT('Estimates-split'!AF17,"0.00")&")") -> (0.74)
A34: Log (CIO Age) (t-1) | C34: =TEXT('Estimates-split'!AD18,"0.000")&IF('Estimates-split'!AG18="","",IF('Estimates-split'!AG18<0.01,"***",IF('Estimates-split'!AG18<0.05,"**",IF('Estimates-split'!AG18<0.1,"*","")))) -> 0.064 | D34: =TEXT('Estimates-split'!AH18,"0.000")&IF('Estimates-split'!AK18="","",IF('Estimates-split'!AK18<0.01,"***",IF('Estimates-split'!AK18<0.05,"**",IF('Estimates-split'!AK18<0.1,"*","")))) -> -0.188*
C35: =IF('Estimates-split'!AF18="","(n/a)","("&TEXT('Estimates-split'!AF18,"0.00")&")") -> (0.64) | D35: =IF('Estimates-split'!AJ18="","(n/a)","("&TEXT('Estimates-split'!AJ18,"0.00")&")") -> (-1.78)
A36: Log (CIO Tenure) (t-1) | C36: =TEXT('Estimates-split'!AD19,"0.000")&IF('Estimates-split'!AG19="","",IF('Estimates-split'!AG19<0.01,"***",IF('Estimates-split'!AG19<0.05,"**",IF('Estimates-split'!AG19<0.1,"*","")))) -> -0.004 | D36: =TEXT('Estimates-split'!AH19,"0.000")&IF('Estimates-split'!AK19="","",IF('Estimates-split'!AK19<0.01,"***",IF('Estimates-split'!AK19<0.05,"**",IF('Estimates-split'!AK19<0.1,"*","")))) -> 0.019
C37: =IF('Estimates-split'!AF19="","(n/a)","("&TEXT('Estimates-split'!AF19,"0.00")&")") -> (-0.32) | D37: =IF('Estimates-split'!AJ19="","(n/a)","("&TEXT('Estimates-split'!AJ19,"0.00")&")") -> (1.66)
A38: CIO Prior Private Experience (0/1) | C38: =TEXT('Estimates-split'!AD20,"0.000")&IF('Estimates-split'!AG20="","",IF('Estimates-split'!AG20<0.01,"***",IF('Estimates-split'!AG20<0.05,"**",IF('Estimates-split'!AG20<0.1,"*","")))) -> -0.070 | D38: =TEXT('Estimates-split'!AH20,"0.000")&IF('Estimates-split'!AK20="","",IF('Estimates-split'!AK20<0.01,"***",IF('Estimates-split'!AK20<0.05,"**",IF('Estimates-split'!AK20<0.1,"*","")))) -> -0.069
C39: =IF('Estimates-split'!AF20="","(n/a)","("&TEXT('Estimates-split'!AF20,"0.00")&")") -> (-1.63) | D39: =IF('Estimates-split'!AJ20="","(n/a)","("&TEXT('Estimates-split'!AJ20,"0.00")&")") -> (-1.22)
A40: CIO Attended Elite College (0/1) | C40: =TEXT('Estimates-split'!AD21,"0.000")&IF('Estimates-split'!AG21="","",IF('Estimates-split'!AG21<0.01,"***",IF('Estimates-split'!AG21<0.05,"**",IF('Estimates-split'!AG21<0.1,"*","")))) -> 0.026 | D40: =TEXT('Estimates-split'!AH21,"0.000")&IF('Estimates-split'!AK21="","",IF('Estimates-split'!AK21<0.01,"***",IF('Estimates-split'!AK21<0.05,"**",IF('Estimates-split'!AK21<0.1,"*","")))) -> -0.068*
C41: =IF('Estimates-split'!AF21="","(n/a)","("&TEXT('Estimates-split'!AF21,"0.00")&")") -> (0.66) | D41: =IF('Estimates-split'!AJ21="","(n/a)","("&TEXT('Estimates-split'!AJ21,"0.00")&")") -> (-1.90)
...

Sheet Table XI
A1: Table XI: Conflicted CIOs: Plan Performance in the First versus Second Half of Tenure, Conflicted CIOs Only (updated benchmark, fiscal-year-end fixed effects)
A2: This table reports results of tests that regress the returns of public pension plans run by conflicted CIOs on an indicator variable, Second Half of Tenure, which is equal to 1 in the fiscal years in which the CIO's tenure exceeds one half of the CIO's tenure at departure and 0 otherwise. Conflicted CIOs are defined as in Table III, and the sample is restricted to their plan-years, so the coefficient compares the second half of a conflicted CIO's tenure with the first half. Tenure at departure is the CIO's tenure in the last fiscal year observed in the plan plus any gap to the departure year. The performance measure in Panel A is Peer-Adjusted Return, which is the difference of a plan's return and the average pension plan return each year. The performance measure in Panel B is Benchmark-Adjusted Return, which is calculated as the plan's return minus the return of its updated policy benchmark (the benchmark return reported in the plan's financial report or, where none is stated, an inferred value graded A or B). The other independent variables are as defined in Table I. All columns include fiscal-year-end date fixed effects, so plans are compared only with plans whose fiscal year covers the same twelve months. Column 3 adds plan fixed effects. Columns 4 and 5 include CIO fixed effects and omit the CIO-level controls; Column 5 restricts the sample to CIOs whose tenure at departure is at least four years, so that each half of tenure contains at least two fiscal years. The standard errors are double clustered by plan and year. Coefficients marked with ***, **, and * are significant at the 1%, 5%, and 10% level, respectively.
A4: Panel A. Peer-Adjusted Returns
B5: (1) | C5: (2) | D5: (3) | E5: (4) | F5: (5)
B6: Peer-adj. Ret. (t) | C6: Peer-adj. Ret. (t) | D6: Peer-adj. Ret. (t) | E6: Peer-adj. Ret. (t) | F6: Peer-adj. Ret. (t)
A7: Second Half of Tenure (0/1) | B7: =TEXT(Estimates!B4,"0.000")&IF(Estimates!E4="","",IF(Estimates!E4<0.01,"***",IF(Estimates!E4<0.05,"**",IF(Estimates!E4<0.1,"*","")))) -> -0.214 | C7: =TEXT(Estimates!F4,"0.000")&IF(Estimates!I4="","",IF(Estimates!I4<0.01,"***",IF(Estimates!I4<0.05,"**",IF(Estimates!I4<0.1,"*","")))) -> -0.081 | D7: =TEXT(Estimates!J4,"0.000")&IF(Estimates!M4="","",IF(Estimates!M4<0.01,"***",IF(Estimates!M4<0.05,"**",IF(Estimates!M4<0.1,"*","")))) -> -0.088 | E7: =TEXT(Estimates!N4,"0.000")&IF(Estimates!Q4="","",IF(Estimates!Q4<0.01,"***",IF(Estimates!Q4<0.05,"**",IF(Estimates!Q4<0.1,"*","")))) -> -0.965* | F7: =TEXT(Estimates!R4,"0.000")&IF(Estimates!U4="","",IF(Estimates!U4<0.01,"***",IF(Estimates!U4<0.05,"**",IF(Estimates!U4<0.1,"*","")))) -> -0.267
B8: =IF(Estimates!D4="","(n/a)","("&TEXT(Estimates!D4,"0.00")&")") -> (-1.15) | C8: =IF(Estimates!H4="","(n/a)","("&TEXT(Estimates!H4,"0.00")&")") -> (-0.34) | D8: =IF(Estimates!L4="","(n/a)","("&TEXT(Estimates!L4,"0.00")&")") -> (-0.30) | E8: =IF(Estimates!P4="","(n/a)","("&TEXT(Estimates!P4,"0.00")&")") -> (-1.88) | F8: =IF(Estimates!T4="","(n/a)","("&TEXT(Estimates!T4,"0.00")&")") -> (-0.27)
A9: Investment Return (t - 1) | B9: =TEXT(Estimates!B5,"0.000")&IF(Estimates!E5="","",IF(Estimates!E5<0.01,"***",IF(Estimates!E5<0.05,"**",IF(Estimates!E5<0.1,"*","")))) -> 0.168 | C9: =TEXT(Estimates!F5,"0.000")&IF(Estimates!I5="","",IF(Estimates!I5<0.01,"***",IF(Estimates!I5<0.05,"**",IF(Estimates!I5<0.1,"*","")))) -> 0.118 | D9: =TEXT(Estimates!J5,"0.000")&IF(Estimates!M5="","",IF(Estimates!M5<0.01,"***",IF(Estimates!M5<0.05,"**",IF(Estimates!M5<0.1,"*","")))) -> 0.084 | E9: =TEXT(Estimates!N5,"0.000")&IF(Estimates!Q5="","",IF(Estimates!Q5<0.01,"***",IF(Estimates!Q5<0.05,"**",IF(Estimates!Q5<0.1,"*","")))) -> 0.099 | F9: =TEXT(Estimates!R5,"0.000")&IF(Estimates!U5="","",IF(Estimates!U5<0.01,"***",IF(Estimates!U5<0.05,"**",IF(Estimates!U5<0.1,"*","")))) -> 0.223
B10: =IF(Estimates!D5="","(n/a)","("&TEXT(Estimates!D5,"0.00")&")") -> (1.10) | C10: =IF(Estimates!H5="","(n/a)","("&TEXT(Estimates!H5,"0.00")&")") -> (0.72) | D10: =IF(Estimates!L5="","(n/a)","("&TEXT(Estimates!L5,"0.00")&")") -> (0.56) | E10: =IF(Estimates!P5="","(n/a)","("&TEXT(Estimates!P5,"0.00")&")") -> (0.75) | F10: =IF(Estimates!T5="","(n/a)","("&TEXT(Estimates!T5,"0.00")&")") -> (1.66)
A11: Log (Plan Size) (t-1) | B11: =TEXT(Estimates!B6,"0.000")&IF(Estimates!E6="","",IF(Estimates!E6<0.01,"***",IF(Estimates!E6<0.05,"**",IF(Estimates!E6<0.1,"*","")))) -> -0.075 | C11: =TEXT(Estimates!F6,"0.000")&IF(Estimates!I6="","",IF(Estimates!I6<0.01,"***",IF(Estimates!I6<0.05,"**",IF(Estimates!I6<0.1,"*","")))) -> -0.082 | D11: =TEXT(Estimates!J6,"0.000")&IF(Estimates!M6="","",IF(Estimates!M6<0.01,"***",IF(Estimates!M6<0.05,"**",IF(Estimates!M6<0.1,"*","")))) -> -0.080 | E11: =TEXT(Estimates!N6,"0.000")&IF(Estimates!Q6="","",IF(Estimates!Q6<0.01,"***",IF(Estimates!Q6<0.05,"**",IF(Estimates!Q6<0.1,"*","")))) -> 1.085 | F11: =TEXT(Estimates!R6,"0.000")&IF(Estimates!U6="","",IF(Estimates!U6<0.01,"***",IF(Estimates!U6<0.05,"**",IF(Estimates!U6<0.1,"*","")))) -> 0.656
B12: =IF(Estimates!D6="","(n/a)","("&TEXT(Estimates!D6,"0.00")&")") -> (-0.69) | C12: =IF(Estimates!H6="","(n/a)","("&TEXT(Estimates!H6,"0.00")&")") -> (-0.70) | D12: =IF(Estimates!L6="","(n/a)","("&TEXT(Estimates!L6,"0.00")&")") -> (-0.09) | E12: =IF(Estimates!P6="","(n/a)","("&TEXT(Estimates!P6,"0.00")&")") -> (0.59) | F12: =IF(Estimates!T6="","(n/a)","("&TEXT(Estimates!T6,"0.00")&")") -> (0.32)
A13: Funding Ratio (t-1) | B13: =TEXT(Estimates!B7,"0.000")&IF(Estimates!E7="","",IF(Estimates!E7<0.01,"***",IF(Estimates!E7<0.05,"**",IF(Estimates!E7<0.1,"*","")))) -> -0.016 | C13: =TEXT(Estimates!F7,"0.000")&IF(Estimates!I7="","",IF(Estimates!I7<0.01,"***",IF(Estimates!I7<0.05,"**",IF(Estimates!I7<0.1,"*","")))) -> -0.014* | D13: =TEXT(Estimates!J7,"0.000")&IF(Estimates!M7="","",IF(Estimates!M7<0.01,"***",IF(Estimates!M7<0.05,"**",IF(Estimates!M7<0.1,"*","")))) -> -0.027 | E13: =TEXT(Estimates!N7,"0.000")&IF(Estimates!Q7="","",IF(Estimates!Q7<0.01,"***",IF(Estimates!Q7<0.05,"**",IF(Estimates!Q7<0.1,"*","")))) -> -0.071** | F13: =TEXT(Estimates!R7,"0.000")&IF(Estimates!U7="","",IF(Estimates!U7<0.01,"***",IF(Estimates!U7<0.05,"**",IF(Estimates!U7<0.1,"*","")))) -> -0.077**
B14: =IF(Estimates!D7="","(n/a)","("&TEXT(Estimates!D7,"0.00")&")") -> (-1.63) | C14: =IF(Estimates!H7="","(n/a)","("&TEXT(Estimates!H7,"0.00")&")") -> (-2.06) | D14: =IF(Estimates!L7="","(n/a)","("&TEXT(Estimates!L7,"0.00")&")") -> (-0.97) | E14: =IF(Estimates!P7="","(n/a)","("&TEXT(Estimates!P7,"0.00")&")") -> (-2.61) | F14: =IF(Estimates!T7="","(n/a)","("&TEXT(Estimates!T7,"0.00")&")") -> (-2.25)
A15: Equity Allocation (%) | B15: =TEXT(Estimates!B8,"0.000")&IF(Estimates!E8="","",IF(Estimates!E8<0.01,"***",IF(Estimates!E8<0.05,"**",IF(Estimates!E8<0.1,"*","")))) -> 0.024 | C15: =TEXT(Estimates!F8,"0.000")&IF(Estimates!I8="","",IF(Estimates!I8<0.01,"***",IF(Estimates!I8<0.05,"**",IF(Estimates!I8<0.1,"*","")))) -> 0.051 | D15: =TEXT(Estimates!J8,"0.000")&IF(Estimates!M8="","",IF(Estimates!M8<0.01,"***",IF(Estimates!M8<0.05,"**",IF(Estimates!M8<0.1,"*","")))) -> -0.605 | E15: =TEXT(Estimates!N8,"0.000")&IF(Estimates!Q8="","",IF(Estimates!Q8<0.01,"***",IF(Estimates!Q8<0.05,"**",IF(Estimates!Q8<0.1,"*","")))) -> -1.644*** | F15: =TEXT(Estimates!R8,"0.000")&IF(Estimates!U8="","",IF(Estimates!U8<0.01,"***",IF(Estimates!U8<0.05,"**",IF(Estimates!U8<0.1,"*","")))) -> -2.006***
B16: =IF(Estimates!D8="","(n/a)","("&TEXT(Estimates!D8,"0.00")&")") -> (0.21) | C16: =IF(Estimates!H8="","(n/a)","("&TEXT(Estimates!H8,"0.00")&")") -> (0.43) | D16: =IF(Estimates!L8="","(n/a)","("&TEXT(Estimates!L8,"0.00")&")") -> (-1.59) | E16: =IF(Estimates!P8="","(n/a)","("&TEXT(Estimates!P8,"0.00")&")") -> (-3.94) | F16: =IF(Estimates!T8="","(n/a)","("&TEXT(Estimates!T8,"0.00")&")") -> (-4.22)
A17: Fixed Income Allocation (%) | B17: =TEXT(Estimates!B9,"0.000")&IF(Estimates!E9="","",IF(Estimates!E9<0.01,"***",IF(Estimates!E9<0.05,"**",IF(Estimates!E9<0.1,"*","")))) -> -0.006 | C17: =TEXT(Estimates!F9,"0.000")&IF(Estimates!I9="","",IF(Estimates!I9<0.01,"***",IF(Estimates!I9<0.05,"**",IF(Estimates!I9<0.1,"*","")))) -> 0.007 | D17: =TEXT(Estimates!J9,"0.000")&IF(Estimates!M9="","",IF(Estimates!M9<0.01,"***",IF(Estimates!M9<0.05,"**",IF(Estimates!M9<0.1,"*","")))) -> -0.640 | E17: =TEXT(Estimates!N9,"0.000")&IF(Estimates!Q9="","",IF(Estimates!Q9<0.01,"***",IF(Estimates!Q9<0.05,"**",IF(Estimates!Q9<0.1,"*","")))) -> -1.709*** | F17: =TEXT(Estimates!R9,"0.000")&IF(Estimates!U9="","",IF(Estimates!U9<0.01,"***",IF(Estimates!U9<0.05,"**",IF(Estimates!U9<0.1,"*","")))) -> -2.090***
B18: =IF(Estimates!D9="","(n/a)","("&TEXT(Estimates!D9,"0.00")&")") -> (-0.05) | C18: =IF(Estimates!H9="","(n/a)","("&TEXT(Estimates!H9,"0.00")&")") -> (0.07) | D18: =IF(Estimates!L9="","(n/a)","("&TEXT(Estimates!L9,"0.00")&")") -> (-1.70) | E18: =IF(Estimates!P9="","(n/a)","("&TEXT(Estimates!P9,"0.00")&")") -> (-3.94) | F18: =IF(Estimates!T9="","(n/a)","("&TEXT(Estimates!T9,"0.00")&")") -> (-4.33)
A19: Real Estate Allocation (%) | B19: =TEXT(Estimates!B10,"0.000")&IF(Estimates!E10="","",IF(Estimates!E10<0.01,"***",IF(Estimates!E10<0.05,"**",IF(Estimates!E10<0.1,"*","")))) -> 0.074 | C19: =TEXT(Estimates!F10,"0.000")&IF(Estimates!I10="","",IF(Estimates!I10<0.01,"***",IF(Estimates!I10<0.05,"**",IF(Estimates!I10<0.1,"*","")))) -> 0.100 | D19: =TEXT(Estimates!J10,"0.000")&IF(Estimates!M10="","",IF(Estimates!M10<0.01,"***",IF(Estimates!M10<0.05,"**",IF(Estimates!M10<0.1,"*","")))) -> -0.660 | E19: =TEXT(Estimates!N10,"0.000")&IF(Estimates!Q10="","",IF(Estimates!Q10<0.01,"***",IF(Estimates!Q10<0.05,"**",IF(Estimates!Q10<0.1,"*","")))) -> -2.007*** | F19: =TEXT(Estimates!R10,"0.000")&IF(Estimates!U10="","",IF(Estimates!U10<0.01,"***",IF(Estimates!U10<0.05,"**",IF(Estimates!U10<0.1,"*","")))) -> -2.539***
B20: =IF(Estimates!D10="","(n/a)","("&TEXT(Estimates!D10,"0.00")&")") -> (0.56) | C20: =IF(Estimates!H10="","(n/a)","("&TEXT(Estimates!H10,"0.00")&")") -> (0.89) | D20: =IF(Estimates!L10="","(n/a)","("&TEXT(Estimates!L10,"0.00")&")") -> (-1.66) | E20: =IF(Estimates!P10="","(n/a)","("&TEXT(Estimates!P10,"0.00")&")") -> (-3.21) | F20: =IF(Estimates!T10="","(n/a)","("&TEXT(Estimates!T10,"0.00")&")") -> (-3.81)
A21: Private Equity Allocation (%) | B21: =TEXT(Estimates!B11,"0.000")&IF(Estimates!E11="","",IF(Estimates!E11<0.01,"***",IF(Estimates!E11<0.05,"**",IF(Estimates!E11<0.1,"*","")))) -> 0.019 | C21: =TEXT(Estimates!F11,"0.000")&IF(Estimates!I11="","",IF(Estimates!I11<0.01,"***",IF(Estimates!I11<0.05,"**",IF(Estimates!I11<0.1,"*","")))) -> 0.043 | D21: =TEXT(Estimates!J11,"0.000")&IF(Estimates!M11="","",IF(Estimates!M11<0.01,"***",IF(Estimates!M11<0.05,"**",IF(Estimates!M11<0.1,"*","")))) -> -0.545 | E21: =TEXT(Estimates!N11,"0.000")&IF(Estimates!Q11="","",IF(Estimates!Q11<0.01,"***",IF(Estimates!Q11<0.05,"**",IF(Estimates!Q11<0.1,"*","")))) -> -1.504*** | F21: =TEXT(Estimates!R11,"0.000")&IF(Estimates!U11="","",IF(Estimates!U11<0.01,"***",IF(Estimates!U11<0.05,"**",IF(Estimates!U11<0.1,"*","")))) -> -1.739***
B22: =IF(Estimates!D11="","(n/a)","("&TEXT(Estimates!D11,"0.00")&")") -> (0.14) | C22: =IF(Estimates!H11="","(n/a)","("&TEXT(Estimates!H11,"0.00")&")") -> (0.36) | D22: =IF(Estimates!L11="","(n/a)","("&TEXT(Estimates!L11,"0.00")&")") -> (-1.33) | E22: =IF(Estimates!P11="","(n/a)","("&TEXT(Estimates!P11,"0.00")&")") -> (-3.80) | F22: =IF(Estimates!T11="","(n/a)","("&TEXT(Estimates!T11,"0.00")&")") -> (-3.83)
A23: Hedge Fund Allocation (%) | B23: =TEXT(Estimates!B12,"0.000")&IF(Estimates!E12="","",IF(Estimates!E12<0.01,"***",IF(Estimates!E12<0.05,"**",IF(Estimates!E12<0.1,"*","")))) -> -0.010 | C23: =TEXT(Estimates!F12,"0.000")&IF(Estimates!I12="","",IF(Estimates!I12<0.01,"***",IF(Estimates!I12<0.05,"**",IF(Estimates!I12<0.1,"*","")))) -> 0.003 | D23: =TEXT(Estimates!J12,"0.000")&IF(Estimates!M12="","",IF(Estimates!M12<0.01,"***",IF(Estimates!M12<0.05,"**",IF(Estimates!M12<0.1,"*","")))) -> -0.647* | E23: =TEXT(Estimates!N12,"0.000")&IF(Estimates!Q12="","",IF(Estimates!Q12<0.01,"***",IF(Estimates!Q12<0.05,"**",IF(Estimates!Q12<0.1,"*","")))) -> -1.699*** | F23: =TEXT(Estimates!R12,"0.000")&IF(Estimates!U12="","",IF(Estimates!U12<0.01,"***",IF(Estimates!U12<0.05,"**",IF(Estimates!U12<0.1,"*","")))) -> -2.055***
B24: =IF(Estimates!D12="","(n/a)","("&TEXT(Estimates!D12,"0.00")&")") -> (-0.09) | C24: =IF(Estimates!H12="","(n/a)","("&TEXT(Estimates!H12,"0.00")&")") -> (0.03) | D24: =IF(Estimates!L12="","(n/a)","("&TEXT(Estimates!L12,"0.00")&")") -> (-2.02) | E24: =IF(Estimates!P12="","(n/a)","("&TEXT(Estimates!P12,"0.00")&")") -> (-3.74) | F24: =IF(Estimates!T12="","(n/a)","("&TEXT(Estimates!T12,"0.00")&")") -> (-4.04)
A25: Misc. Alternatives Allocation (%) | B25: =TEXT(Estimates!B13,"0.000")&IF(Estimates!E13="","",IF(Estimates!E13<0.01,"***",IF(Estimates!E13<0.05,"**",IF(Estimates!E13<0.1,"*","")))) -> 0.077 | C25: =TEXT(Estimates!F13,"0.000")&IF(Estimates!I13="","",IF(Estimates!I13<0.01,"***",IF(Estimates!I13<0.05,"**",IF(Estimates!I13<0.1,"*","")))) -> 0.105 | D25: =TEXT(Estimates!J13,"0.000")&IF(Estimates!M13="","",IF(Estimates!M13<0.01,"***",IF(Estimates!M13<0.05,"**",IF(Estimates!M13<0.1,"*","")))) -> -0.253 | E25: =TEXT(Estimates!N13,"0.000")&IF(Estimates!Q13="","",IF(Estimates!Q13<0.01,"***",IF(Estimates!Q13<0.05,"**",IF(Estimates!Q13<0.1,"*","")))) -> -1.527 | F25: =TEXT(Estimates!R13,"0.000")&IF(Estimates!U13="","",IF(Estimates!U13<0.01,"***",IF(Estimates!U13<0.05,"**",IF(Estimates!U13<0.1,"*","")))) -> -2.017*
B26: =IF(Estimates!D13="","(n/a)","("&TEXT(Estimates!D13,"0.00")&")") -> (0.59) | C26: =IF(Estimates!H13="","(n/a)","("&TEXT(Estimates!H13,"0.00")&")") -> (1.14) | D26: =IF(Estimates!L13="","(n/a)","("&TEXT(Estimates!L13,"0.00")&")") -> (-0.22) | E26: =IF(Estimates!P13="","(n/a)","("&TEXT(Estimates!P13,"0.00")&")") -> (-1.39) | F26: =IF(Estimates!T13="","(n/a)","("&TEXT(Estimates!T13,"0.00")&")") -> (-1.86)
A27: Commodities Allocation (%) | B27: =TEXT(Estimates!B14,"0.000")&IF(Estimates!E14="","",IF(Estimates!E14<0.01,"***",IF(Estimates!E14<0.05,"**",IF(Estimates!E14<0.1,"*","")))) -> -0.027 | C27: =TEXT(Estimates!F14,"0.000")&IF(Estimates!I14="","",IF(Estimates!I14<0.01,"***",IF(Estimates!I14<0.05,"**",IF(Estimates!I14<0.1,"*","")))) -> -0.015 | D27: =TEXT(Estimates!J14,"0.000")&IF(Estimates!M14="","",IF(Estimates!M14<0.01,"***",IF(Estimates!M14<0.05,"**",IF(Estimates!M14<0.1,"*","")))) -> -0.702* | E27: =TEXT(Estimates!N14,"0.000")&IF(Estimates!Q14="","",IF(Estimates!Q14<0.01,"***",IF(Estimates!Q14<0.05,"**",IF(Estimates!Q14<0.1,"*","")))) -> -1.535*** | F27: =TEXT(Estimates!R14,"0.000")&IF(Estimates!U14="","",IF(Estimates!U14<0.01,"***",IF(Estimates!U14<0.05,"**",IF(Estimates!U14<0.1,"*","")))) -> -1.670***
B28: =IF(Estimates!D14="","(n/a)","("&TEXT(Estimates!D14,"0.00")&")") -> (-0.26) | C28: =IF(Estimates!H14="","(n/a)","("&TEXT(Estimates!H14,"0.00")&")") -> (-0.14) | D28: =IF(Estimates!L14="","(n/a)","("&TEXT(Estimates!L14,"0.00")&")") -> (-1.81) | E28: =IF(Estimates!P14="","(n/a)","("&TEXT(Estimates!P14,"0.00")&")") -> (-3.88) | F28: =IF(Estimates!T14="","(n/a)","("&TEXT(Estimates!T14,"0.00")&")") -> (-4.61)
A29: Cash Allocation (%) | B29: =TEXT(Estimates!B15,"0.000")&IF(Estimates!E15="","",IF(Estimates!E15<0.01,"***",IF(Estimates!E15<0.05,"**",IF(Estimates!E15<0.1,"*","")))) -> 0.033 | C29: =TEXT(Estimates!F15,"0.000")&IF(Estimates!I15="","",IF(Estimates!I15<0.01,"***",IF(Estimates!I15<0.05,"**",IF(Estimates!I15<0.1,"*","")))) -> 0.076 | D29: =TEXT(Estimates!J15,"0.000")&IF(Estimates!M15="","",IF(Estimates!M15<0.01,"***",IF(Estimates!M15<0.05,"**",IF(Estimates!M15<0.1,"*","")))) -> -0.499 | E29: =TEXT(Estimates!N15,"0.000")&IF(Estimates!Q15="","",IF(Estimates!Q15<0.01,"***",IF(Estimates!Q15<0.05,"**",IF(Estimates!Q15<0.1,"*","")))) -> -1.514*** | F29: =TEXT(Estimates!R15,"0.000")&IF(Estimates!U15="","",IF(Estimates!U15<0.01,"***",IF(Estimates!U15<0.05,"**",IF(Estimates!U15<0.1,"*","")))) -> -2.031***
B30: =IF(Estimates!D15="","(n/a)","("&TEXT(Estimates!D15,"0.00")&")") -> (0.28) | C30: =IF(Estimates!H15="","(n/a)","("&TEXT(Estimates!H15,"0.00")&")") -> (0.52) | D30: =IF(Estimates!L15="","(n/a)","("&TEXT(Estimates!L15,"0.00")&")") -> (-1.25) | E30: =IF(Estimates!P15="","(n/a)","("&TEXT(Estimates!P15,"0.00")&")") -> (-3.46) | F30: =IF(Estimates!T15="","(n/a)","("&TEXT(Estimates!T15,"0.00")&")") -> (-3.87)
A31: Financial Center (0/1) | B31: =TEXT(Estimates!B16,"0.000")&IF(Estimates!E16="","",IF(Estimates!E16<0.01,"***",IF(Estimates!E16<0.05,"**",IF(Estimates!E16<0.1,"*","")))) -> 0.435 | C31: =TEXT(Estimates!F16,"0.000")&IF(Estimates!I16="","",IF(Estimates!I16<0.01,"***",IF(Estimates!I16<0.05,"**",IF(Estimates!I16<0.1,"*","")))) -> 0.412 | E31: =TEXT(Estimates!N16,"0.000")&IF(Estimates!Q16="","",IF(Estimates!Q16<0.01,"***",IF(Estimates!Q16<0.05,"**",IF(Estimates!Q16<0.1,"*","")))) -> 0.550
B32: =IF(Estimates!D16="","(n/a)","("&TEXT(Estimates!D16,"0.00")&")") -> (1.06) | C32: =IF(Estimates!H16="","(n/a)","("&TEXT(Estimates!H16,"0.00")&")") -> (1.28) | E32: =IF(Estimates!P16="","(n/a)","("&TEXT(Estimates!P16,"0.00")&")") -> (0.00)
A33: Log (CIO Age) (t-1) | C33: =TEXT(Estimates!F17,"0.000")&IF(Estimates!I17="","",IF(Estimates!I17<0.01,"***",IF(Estimates!I17<0.05,"**",IF(Estimates!I17<0.1,"*","")))) -> -0.122 | D33: =TEXT(Estimates!J17,"0.000")&IF(Estimates!M17="","",IF(Estimates!M17<0.01,"***",IF(Estimates!M17<0.05,"**",IF(Estimates!M17<0.1,"*","")))) -> 0.733
C34: =IF(Estimates!H17="","(n/a)","("&TEXT(Estimates!H17,"0.00")&")") -> (-0.12) | D34: =IF(Estimates!L17="","(n/a)","("&TEXT(Estimates!L17,"0.00")&")") -> (0.40)
A35: Log (CIO Tenure) (t-1) | C35: =TEXT(Estimates!F18,"0.000")&IF(Estimates!I18="","",IF(Estimates!I18<0.01,"***",IF(Estimates!I18<0.05,"**",IF(Estimates!I18<0.1,"*","")))) -> 0.031 | D35: =TEXT(Estimates!J18,"0.000")&IF(Estimates!M18="","",IF(Estimates!M18<0.01,"***",IF(Estimates!M18<0.05,"**",IF(Estimates!M18<0.1,"*","")))) -> 0.025
C36: =IF(Estimates!H18="","(n/a)","("&TEXT(Estimates!H18,"0.00")&")") -> (0.17) | D36: =IF(Estimates!L18="","(n/a)","("&TEXT(Estimates!L18,"0.00")&")") -> (0.07)
A37: CIO Prior Private Experience (0/1) | C37: =TEXT(Estimates!F19,"0.000")&IF(Estimates!I19="","",IF(Estimates!I19<0.01,"***",IF(Estimates!I19<0.05,"**",IF(Estimates!I19<0.1,"*","")))) -> -0.034 | D37: =TEXT(Estimates!J19,"0.000")&IF(Estimates!M19="","",IF(Estimates!M19<0.01,"***",IF(Estimates!M19<0.05,"**",IF(Estimates!M19<0.1,"*","")))) -> -0.136
C38: =IF(Estimates!H19="","(n/a)","("&TEXT(Estimates!H19,"0.00")&")") -> (-0.18) | D38: =IF(Estimates!L19="","(n/a)","("&TEXT(Estimates!L19,"0.00")&")") -> (-0.16)
A39: CIO Attended Elite College (0/1) | C39: =TEXT(Estimates!F20,"0.000")&IF(Estimates!I20="","",IF(Estimates!I20<0.01,"***",IF(Estimates!I20<0.05,"**",IF(Estimates!I20<0.1,"*","")))) -> -0.134 | D39: =TEXT(Estimates!J20,"0.000")&IF(Estimates!M20="","",IF(Estimates!M20<0.01,"***",IF(Estimates!M20<0.05,"**",IF(Estimates!M20<0.1,"*","")))) -> 0.158
C40: =IF(Estimates!H20="","(n/a)","("&TEXT(Estimates!H20,"0.00")&")") -> (-0.71) | D40: =IF(Estimates!L20="","(n/a)","("&TEXT(Estimates!L20,"0.00")&")") -> (0.31)
A41: Separate Investment Board (0/1) | C41: =TEXT(Estimates!F21,"0.000")&IF(Estimates!I21="","",IF(Estimates!I21<0.01,"***",IF(Estimates!I21<0.05,"**",IF(Estimates!I21<0.1,"*","")))) -> 0.240
...

Sheet Table XII
A1: Table XII: Conflicted CIOs: Fee Ratio in the First versus Second Half of Tenure, Conflicted CIOs Only (fiscal-year-end fixed effects)
A2: This table repeats the tests of Table XI with Fee Ratio as the dependent variable. Fee Ratio is the plan's total investment fees as a percentage of plan assets. The sample is restricted to plan-years of conflicted CIOs, and Second Half of Tenure is equal to 1 in the fiscal years in which the CIO's tenure exceeds one half of the CIO's tenure at departure and 0 otherwise. The other independent variables are as defined in Table I. All columns include fiscal-year-end date fixed effects, so plans are compared only with plans whose fiscal year covers the same twelve months. Column 3 adds plan fixed effects. Columns 4 and 5 include CIO fixed effects and omit the CIO-level controls; Column 5 restricts the sample to CIOs whose tenure at departure is at least four years. The standard errors are double clustered by plan and year. Coefficients marked with ***, **, and * are significant at the 1%, 5%, and 10% level, respectively.
B4: (1) | C4: (2) | D4: (3) | E4: (4) | F4: (5)
B5: Fee Ratio (t) | C5: Fee Ratio (t) | D5: Fee Ratio (t) | E5: Fee Ratio (t) | F5: Fee Ratio (t)
A6: Second Half of Tenure (0/1) | B6: =TEXT(Estimates!AP4,"0.000")&IF(Estimates!AS4="","",IF(Estimates!AS4<0.01,"***",IF(Estimates!AS4<0.05,"**",IF(Estimates!AS4<0.1,"*","")))) -> -0.065 | C6: =TEXT(Estimates!AT4,"0.000")&IF(Estimates!AW4="","",IF(Estimates!AW4<0.01,"***",IF(Estimates!AW4<0.05,"**",IF(Estimates!AW4<0.1,"*","")))) -> -0.082 | D6: =TEXT(Estimates!AX4,"0.000")&IF(Estimates!BA4="","",IF(Estimates!BA4<0.01,"***",IF(Estimates!BA4<0.05,"**",IF(Estimates!BA4<0.1,"*","")))) -> -0.059 | E6: =TEXT(Estimates!BB4,"0.000")&IF(Estimates!BE4="","",IF(Estimates!BE4<0.01,"***",IF(Estimates!BE4<0.05,"**",IF(Estimates!BE4<0.1,"*","")))) -> -0.066 | F6: =TEXT(Estimates!BF4,"0.000")&IF(Estimates!BI4="","",IF(Estimates!BI4<0.01,"***",IF(Estimates!BI4<0.05,"**",IF(Estimates!BI4<0.1,"*","")))) -> -0.038
B7: =IF(Estimates!AR4="","(n/a)","("&TEXT(Estimates!AR4,"0.00")&")") -> (-1.62) | C7: =IF(Estimates!AV4="","(n/a)","("&TEXT(Estimates!AV4,"0.00")&")") -> (-1.41) | D7: =IF(Estimates!AZ4="","(n/a)","("&TEXT(Estimates!AZ4,"0.00")&")") -> (-1.38) | E7: =IF(Estimates!BD4="","(n/a)","("&TEXT(Estimates!BD4,"0.00")&")") -> (-1.21) | F7: =IF(Estimates!BH4="","(n/a)","("&TEXT(Estimates!BH4,"0.00")&")") -> (-0.54)
A8: Investment Return (t - 1) | B8: =TEXT(Estimates!AP5,"0.000")&IF(Estimates!AS5="","",IF(Estimates!AS5<0.01,"***",IF(Estimates!AS5<0.05,"**",IF(Estimates!AS5<0.1,"*","")))) -> 0.000 | C8: =TEXT(Estimates!AT5,"0.000")&IF(Estimates!AW5="","",IF(Estimates!AW5<0.01,"***",IF(Estimates!AW5<0.05,"**",IF(Estimates!AW5<0.1,"*","")))) -> 0.004 | D8: =TEXT(Estimates!AX5,"0.000")&IF(Estimates!BA5="","",IF(Estimates!BA5<0.01,"***",IF(Estimates!BA5<0.05,"**",IF(Estimates!BA5<0.1,"*","")))) -> 0.007 | E8: =TEXT(Estimates!BB5,"0.000")&IF(Estimates!BE5="","",IF(Estimates!BE5<0.01,"***",IF(Estimates!BE5<0.05,"**",IF(Estimates!BE5<0.1,"*","")))) -> 0.005 | F8: =TEXT(Estimates!BF5,"0.000")&IF(Estimates!BI5="","",IF(Estimates!BI5<0.01,"***",IF(Estimates!BI5<0.05,"**",IF(Estimates!BI5<0.1,"*","")))) -> 0.007*
B9: =IF(Estimates!AR5="","(n/a)","("&TEXT(Estimates!AR5,"0.00")&")") -> (0.03) | C9: =IF(Estimates!AV5="","(n/a)","("&TEXT(Estimates!AV5,"0.00")&")") -> (0.58) | D9: =IF(Estimates!AZ5="","(n/a)","("&TEXT(Estimates!AZ5,"0.00")&")") -> (1.28) | E9: =IF(Estimates!BD5="","(n/a)","("&TEXT(Estimates!BD5,"0.00")&")") -> (1.19) | F9: =IF(Estimates!BH5="","(n/a)","("&TEXT(Estimates!BH5,"0.00")&")") -> (2.00)
A10: Log (Plan Size) (t-1) | B10: =TEXT(Estimates!AP6,"0.000")&IF(Estimates!AS6="","",IF(Estimates!AS6<0.01,"***",IF(Estimates!AS6<0.05,"**",IF(Estimates!AS6<0.1,"*","")))) -> -0.034* | C10: =TEXT(Estimates!AT6,"0.000")&IF(Estimates!AW6="","",IF(Estimates!AW6<0.01,"***",IF(Estimates!AW6<0.05,"**",IF(Estimates!AW6<0.1,"*","")))) -> -0.044* | D10: =TEXT(Estimates!AX6,"0.000")&IF(Estimates!BA6="","",IF(Estimates!BA6<0.01,"***",IF(Estimates!BA6<0.05,"**",IF(Estimates!BA6<0.1,"*","")))) -> -0.348** | E10: =TEXT(Estimates!BB6,"0.000")&IF(Estimates!BE6="","",IF(Estimates!BE6<0.01,"***",IF(Estimates!BE6<0.05,"**",IF(Estimates!BE6<0.1,"*","")))) -> -0.243 | F10: =TEXT(Estimates!BF6,"0.000")&IF(Estimates!BI6="","",IF(Estimates!BI6<0.01,"***",IF(Estimates!BI6<0.05,"**",IF(Estimates!BI6<0.1,"*","")))) -> -0.090
B11: =IF(Estimates!AR6="","(n/a)","("&TEXT(Estimates!AR6,"0.00")&")") -> (-1.75) | C11: =IF(Estimates!AV6="","(n/a)","("&TEXT(Estimates!AV6,"0.00")&")") -> (-2.02) | D11: =IF(Estimates!AZ6="","(n/a)","("&TEXT(Estimates!AZ6,"0.00")&")") -> (-2.35) | E11: =IF(Estimates!BD6="","(n/a)","("&TEXT(Estimates!BD6,"0.00")&")") -> (-1.02) | F11: =IF(Estimates!BH6="","(n/a)","("&TEXT(Estimates!BH6,"0.00")&")") -> (-0.41)
A12: Funding Ratio (t-1) | B12: =TEXT(Estimates!AP7,"0.000")&IF(Estimates!AS7="","",IF(Estimates!AS7<0.01,"***",IF(Estimates!AS7<0.05,"**",IF(Estimates!AS7<0.1,"*","")))) -> -0.003*** | C12: =TEXT(Estimates!AT7,"0.000")&IF(Estimates!AW7="","",IF(Estimates!AW7<0.01,"***",IF(Estimates!AW7<0.05,"**",IF(Estimates!AW7<0.1,"*","")))) -> -0.002*** | D12: =TEXT(Estimates!AX7,"0.000")&IF(Estimates!BA7="","",IF(Estimates!BA7<0.01,"***",IF(Estimates!BA7<0.05,"**",IF(Estimates!BA7<0.1,"*","")))) -> 0.000 | E12: =TEXT(Estimates!BB7,"0.000")&IF(Estimates!BE7="","",IF(Estimates!BE7<0.01,"***",IF(Estimates!BE7<0.05,"**",IF(Estimates!BE7<0.1,"*","")))) -> 0.000 | F12: =TEXT(Estimates!BF7,"0.000")&IF(Estimates!BI7="","",IF(Estimates!BI7<0.01,"***",IF(Estimates!BI7<0.05,"**",IF(Estimates!BI7<0.1,"*","")))) -> -0.001
B13: =IF(Estimates!AR7="","(n/a)","("&TEXT(Estimates!AR7,"0.00")&")") -> (-3.03) | C13: =IF(Estimates!AV7="","(n/a)","("&TEXT(Estimates!AV7,"0.00")&")") -> (-3.17) | D13: =IF(Estimates!AZ7="","(n/a)","("&TEXT(Estimates!AZ7,"0.00")&")") -> (-0.07) | E13: =IF(Estimates!BD7="","(n/a)","("&TEXT(Estimates!BD7,"0.00")&")") -> (0.05) | F13: =IF(Estimates!BH7="","(n/a)","("&TEXT(Estimates!BH7,"0.00")&")") -> (-0.37)
A14: Equity Allocation (%) | B14: =TEXT(Estimates!AP8,"0.000")&IF(Estimates!AS8="","",IF(Estimates!AS8<0.01,"***",IF(Estimates!AS8<0.05,"**",IF(Estimates!AS8<0.1,"*","")))) -> -0.090 | C14: =TEXT(Estimates!AT8,"0.000")&IF(Estimates!AW8="","",IF(Estimates!AW8<0.01,"***",IF(Estimates!AW8<0.05,"**",IF(Estimates!AW8<0.1,"*","")))) -> -0.042 | D14: =TEXT(Estimates!AX8,"0.000")&IF(Estimates!BA8="","",IF(Estimates!BA8<0.01,"***",IF(Estimates!BA8<0.05,"**",IF(Estimates!BA8<0.1,"*","")))) -> -0.058* | E14: =TEXT(Estimates!BB8,"0.000")&IF(Estimates!BE8="","",IF(Estimates!BE8<0.01,"***",IF(Estimates!BE8<0.05,"**",IF(Estimates!BE8<0.1,"*","")))) -> -0.058 | F14: =TEXT(Estimates!BF8,"0.000")&IF(Estimates!BI8="","",IF(Estimates!BI8<0.01,"***",IF(Estimates!BI8<0.05,"**",IF(Estimates!BI8<0.1,"*","")))) -> 0.011
B15: =IF(Estimates!AR8="","(n/a)","("&TEXT(Estimates!AR8,"0.00")&")") -> (-1.30) | C15: =IF(Estimates!AV8="","(n/a)","("&TEXT(Estimates!AV8,"0.00")&")") -> (-0.70) | D15: =IF(Estimates!AZ8="","(n/a)","("&TEXT(Estimates!AZ8,"0.00")&")") -> (-2.03) | E15: =IF(Estimates!BD8="","(n/a)","("&TEXT(Estimates!BD8,"0.00")&")") -> (-1.23) | F15: =IF(Estimates!BH8="","(n/a)","("&TEXT(Estimates!BH8,"0.00")&")") -> (0.17)
