Workbook

Sheet Table XI-split
A1: Table XI: Conflicted CIOs: Plan Performance in the First versus Second Half of Tenure (updated benchmark)
A2: This table repeats the regressions of Table III, splitting the Conflicted CIO indicator into two indicators: Conflicted CIO x First Half of Tenure, equal to 1 in the fiscal years in which a conflicted CIO's tenure is at most one half of the CIO's tenure at departure, and Conflicted CIO x Second Half of Tenure, equal to 1 in the remaining fiscal years of a conflicted CIO's tenure. The omitted category is all plan-years run by non-conflicted CIOs, so each coefficient is the performance differential of conflicted CIOs in that part of their tenure relative to non-conflicted CIOs. Tenure at departure is the CIO's tenure in the last fiscal year observed in the plan plus any gap to the departure year. 11 conflicted plan-years for which tenure at departure cannot be determined are absorbed by a separate indicator that is not reported. The performance measure in Panel A is Peer-Adjusted Return, which is the difference of a plan's return and the average pension plan return each year. The performance measure in Panel B is Benchmark-Adjusted Return, which is calculated as the plan's return minus the return of its updated policy benchmark (the benchmark return reported in the plan's financial report or, where none is stated, an inferred value graded A or B). The other independent variables are as defined in Table I. The last row reports the p-value of a test that the first-half and second-half coefficients are equal. The standard errors are double clustered by plan and year. Coefficients marked with ***, **, and * are significant at the 1%, 5%, and 10% level, respectively.
A4: Panel A. Peer-Adjusted Returns
B5: (1) | C5: (2) | D5: (3) | E5: (4)
B6: Peer-adj. Ret. (t) | C6: Peer-adj. Ret. (t) | D6: Peer-adj. Ret. (t) | E6: Peer-adj. Ret. (t)
A7: Conflicted CIO x First Half of Tenure (0/1) | B7: =TEXT('Estimates-split'!B4,"0.000")&IF('Estimates-split'!E4="","",IF('Estimates-split'!E4<0.01,"***",IF('Estimates-split'!E4<0.05,"**",IF('Estimates-split'!E4<0.1,"*","")))) -> -0.510*** | C7: =TEXT('Estimates-split'!F4,"0.000")&IF('Estimates-split'!I4="","",IF('Estimates-split'!I4<0.01,"***",IF('Estimates-split'!I4<0.05,"**",IF('Estimates-split'!I4<0.1,"*","")))) -> -0.605** | D7: =TEXT('Estimates-split'!J4,"0.000")&IF('Estimates-split'!M4="","",IF('Estimates-split'!M4<0.01,"***",IF('Estimates-split'!M4<0.05,"**",IF('Estimates-split'!M4<0.1,"*","")))) -> -0.773** | E7: =TEXT('Estimates-split'!N4,"0.000")&IF('Estimates-split'!Q4="","",IF('Estimates-split'!Q4<0.01,"***",IF('Estimates-split'!Q4<0.05,"**",IF('Estimates-split'!Q4<0.1,"*","")))) -> -0.861**
B8: =IF('Estimates-split'!D4="","(n/a)","("&TEXT('Estimates-split'!D4,"0.00")&")") -> (-2.89) | C8: =IF('Estimates-split'!H4="","(n/a)","("&TEXT('Estimates-split'!H4,"0.00")&")") -> (-2.83) | D8: =IF('Estimates-split'!L4="","(n/a)","("&TEXT('Estimates-split'!L4,"0.00")&")") -> (-2.29) | E8: =IF('Estimates-split'!P4="","(n/a)","("&TEXT('Estimates-split'!P4,"0.00")&")") -> (-2.45)
A9: Conflicted CIO x Second Half of Tenure (0/1) | B9: =TEXT('Estimates-split'!B5,"0.000")&IF('Estimates-split'!E5="","",IF('Estimates-split'!E5<0.01,"***",IF('Estimates-split'!E5<0.05,"**",IF('Estimates-split'!E5<0.1,"*","")))) -> -0.615*** | C9: =TEXT('Estimates-split'!F5,"0.000")&IF('Estimates-split'!I5="","",IF('Estimates-split'!I5<0.01,"***",IF('Estimates-split'!I5<0.05,"**",IF('Estimates-split'!I5<0.1,"*","")))) -> -0.581** | D9: =TEXT('Estimates-split'!J5,"0.000")&IF('Estimates-split'!M5="","",IF('Estimates-split'!M5<0.01,"***",IF('Estimates-split'!M5<0.05,"**",IF('Estimates-split'!M5<0.1,"*","")))) -> -0.553* | E9: =TEXT('Estimates-split'!N5,"0.000")&IF('Estimates-split'!Q5="","",IF('Estimates-split'!Q5<0.01,"***",IF('Estimates-split'!Q5<0.05,"**",IF('Estimates-split'!Q5<0.1,"*","")))) -> -0.579*
B10: =IF('Estimates-split'!D5="","(n/a)","("&TEXT('Estimates-split'!D5,"0.00")&")") -> (-2.99) | C10: =IF('Estimates-split'!H5="","(n/a)","("&TEXT('Estimates-split'!H5,"0.00")&")") -> (-2.68) | D10: =IF('Estimates-split'!L5="","(n/a)","("&TEXT('Estimates-split'!L5,"0.00")&")") -> (-1.84) | E10: =IF('Estimates-split'!P5="","(n/a)","("&TEXT('Estimates-split'!P5,"0.00")&")") -> (-1.97)
A11: Investment Return (t - 1) | B11: =TEXT('Estimates-split'!B6,"0.000")&IF('Estimates-split'!E6="","",IF('Estimates-split'!E6<0.01,"***",IF('Estimates-split'!E6<0.05,"**",IF('Estimates-split'!E6<0.1,"*","")))) -> 0.014 | C11: =TEXT('Estimates-split'!F6,"0.000")&IF('Estimates-split'!I6="","",IF('Estimates-split'!I6<0.01,"***",IF('Estimates-split'!I6<0.05,"**",IF('Estimates-split'!I6<0.1,"*","")))) -> 0.004 | D11: =TEXT('Estimates-split'!J6,"0.000")&IF('Estimates-split'!M6="","",IF('Estimates-split'!M6<0.01,"***",IF('Estimates-split'!M6<0.05,"**",IF('Estimates-split'!M6<0.1,"*","")))) -> 0.011 | E11: =TEXT('Estimates-split'!N6,"0.000")&IF('Estimates-split'!Q6="","",IF('Estimates-split'!Q6<0.01,"***",IF('Estimates-split'!Q6<0.05,"**",IF('Estimates-split'!Q6<0.1,"*","")))) -> 0.000
B12: =IF('Estimates-split'!D6="","(n/a)","("&TEXT('Estimates-split'!D6,"0.00")&")") -> (0.65) | C12: =IF('Estimates-split'!H6="","(n/a)","("&TEXT('Estimates-split'!H6,"0.00")&")") -> (0.20) | D12: =IF('Estimates-split'!L6="","(n/a)","("&TEXT('Estimates-split'!L6,"0.00")&")") -> (1.19) | E12: =IF('Estimates-split'!P6="","(n/a)","("&TEXT('Estimates-split'!P6,"0.00")&")") -> (0.01)
A13: Log (Plan Size) (t-1) | B13: =TEXT('Estimates-split'!B7,"0.000")&IF('Estimates-split'!E7="","",IF('Estimates-split'!E7<0.01,"***",IF('Estimates-split'!E7<0.05,"**",IF('Estimates-split'!E7<0.1,"*","")))) -> 0.007 | C13: =TEXT('Estimates-split'!F7,"0.000")&IF('Estimates-split'!I7="","",IF('Estimates-split'!I7<0.01,"***",IF('Estimates-split'!I7<0.05,"**",IF('Estimates-split'!I7<0.1,"*","")))) -> 0.068 | D13: =TEXT('Estimates-split'!J7,"0.000")&IF('Estimates-split'!M7="","",IF('Estimates-split'!M7<0.01,"***",IF('Estimates-split'!M7<0.05,"**",IF('Estimates-split'!M7<0.1,"*","")))) -> -0.945** | E13: =TEXT('Estimates-split'!N7,"0.000")&IF('Estimates-split'!Q7="","",IF('Estimates-split'!Q7<0.01,"***",IF('Estimates-split'!Q7<0.05,"**",IF('Estimates-split'!Q7<0.1,"*","")))) -> -1.418*
B14: =IF('Estimates-split'!D7="","(n/a)","("&TEXT('Estimates-split'!D7,"0.00")&")") -> (0.13) | C14: =IF('Estimates-split'!H7="","(n/a)","("&TEXT('Estimates-split'!H7,"0.00")&")") -> (1.04) | D14: =IF('Estimates-split'!L7="","(n/a)","("&TEXT('Estimates-split'!L7,"0.00")&")") -> (-2.48) | E14: =IF('Estimates-split'!P7="","(n/a)","("&TEXT('Estimates-split'!P7,"0.00")&")") -> (-1.95)
A15: Funding Ratio (t-1) | B15: =TEXT('Estimates-split'!B8,"0.000")&IF('Estimates-split'!E8="","",IF('Estimates-split'!E8<0.01,"***",IF('Estimates-split'!E8<0.05,"**",IF('Estimates-split'!E8<0.1,"*","")))) -> -0.005 | C15: =TEXT('Estimates-split'!F8,"0.000")&IF('Estimates-split'!I8="","",IF('Estimates-split'!I8<0.01,"***",IF('Estimates-split'!I8<0.05,"**",IF('Estimates-split'!I8<0.1,"*","")))) -> -0.006 | D15: =TEXT('Estimates-split'!J8,"0.000")&IF('Estimates-split'!M8="","",IF('Estimates-split'!M8<0.01,"***",IF('Estimates-split'!M8<0.05,"**",IF('Estimates-split'!M8<0.1,"*","")))) -> -0.027*** | E15: =TEXT('Estimates-split'!N8,"0.000")&IF('Estimates-split'!Q8="","",IF('Estimates-split'!Q8<0.01,"***",IF('Estimates-split'!Q8<0.05,"**",IF('Estimates-split'!Q8<0.1,"*","")))) -> -0.030***
B16: =IF('Estimates-split'!D8="","(n/a)","("&TEXT('Estimates-split'!D8,"0.00")&")") -> (-1.17) | C16: =IF('Estimates-split'!H8="","(n/a)","("&TEXT('Estimates-split'!H8,"0.00")&")") -> (-1.20) | D16: =IF('Estimates-split'!L8="","(n/a)","("&TEXT('Estimates-split'!L8,"0.00")&")") -> (-3.18) | E16: =IF('Estimates-split'!P8="","(n/a)","("&TEXT('Estimates-split'!P8,"0.00")&")") -> (-2.95)
A17: Equity Allocation (%) | B17: =TEXT('Estimates-split'!B9,"0.000")&IF('Estimates-split'!E9="","",IF('Estimates-split'!E9<0.01,"***",IF('Estimates-split'!E9<0.05,"**",IF('Estimates-split'!E9<0.1,"*","")))) -> -0.082 | C17: =TEXT('Estimates-split'!F9,"0.000")&IF('Estimates-split'!I9="","",IF('Estimates-split'!I9<0.01,"***",IF('Estimates-split'!I9<0.05,"**",IF('Estimates-split'!I9<0.1,"*","")))) -> 0.005 | D17: =TEXT('Estimates-split'!J9,"0.000")&IF('Estimates-split'!M9="","",IF('Estimates-split'!M9<0.01,"***",IF('Estimates-split'!M9<0.05,"**",IF('Estimates-split'!M9<0.1,"*","")))) -> -0.048 | E17: =TEXT('Estimates-split'!N9,"0.000")&IF('Estimates-split'!Q9="","",IF('Estimates-split'!Q9<0.01,"***",IF('Estimates-split'!Q9<0.05,"**",IF('Estimates-split'!Q9<0.1,"*","")))) -> -0.029
B18: =IF('Estimates-split'!D9="","(n/a)","("&TEXT('Estimates-split'!D9,"0.00")&")") -> (-0.61) | C18: =IF('Estimates-split'!H9="","(n/a)","("&TEXT('Estimates-split'!H9,"0.00")&")") -> (0.07) | D18: =IF('Estimates-split'!L9="","(n/a)","("&TEXT('Estimates-split'!L9,"0.00")&")") -> (-0.58) | E18: =IF('Estimates-split'!P9="","(n/a)","("&TEXT('Estimates-split'!P9,"0.00")&")") -> (-0.34)
A19: Fixed Income Allocation (%) | B19: =TEXT('Estimates-split'!B10,"0.000")&IF('Estimates-split'!E10="","",IF('Estimates-split'!E10<0.01,"***",IF('Estimates-split'!E10<0.05,"**",IF('Estimates-split'!E10<0.1,"*","")))) -> -0.091 | C19: =TEXT('Estimates-split'!F10,"0.000")&IF('Estimates-split'!I10="","",IF('Estimates-split'!I10<0.01,"***",IF('Estimates-split'!I10<0.05,"**",IF('Estimates-split'!I10<0.1,"*","")))) -> 0.000 | D19: =TEXT('Estimates-split'!J10,"0.000")&IF('Estimates-split'!M10="","",IF('Estimates-split'!M10<0.01,"***",IF('Estimates-split'!M10<0.05,"**",IF('Estimates-split'!M10<0.1,"*","")))) -> -0.059 | E19: =TEXT('Estimates-split'!N10,"0.000")&IF('Estimates-split'!Q10="","",IF('Estimates-split'!Q10<0.01,"***",IF('Estimates-split'!Q10<0.05,"**",IF('Estimates-split'!Q10<0.1,"*","")))) -> -0.035
B20: =IF('Estimates-split'!D10="","(n/a)","("&TEXT('Estimates-split'!D10,"0.00")&")") -> (-0.63) | C20: =IF('Estimates-split'!H10="","(n/a)","("&TEXT('Estimates-split'!H10,"0.00")&")") -> (0.00) | D20: =IF('Estimates-split'!L10="","(n/a)","("&TEXT('Estimates-split'!L10,"0.00")&")") -> (-0.61) | E20: =IF('Estimates-split'!P10="","(n/a)","("&TEXT('Estimates-split'!P10,"0.00")&")") -> (-0.36)
A21: Real Estate Allocation (%) | B21: =TEXT('Estimates-split'!B11,"0.000")&IF('Estimates-split'!E11="","",IF('Estimates-split'!E11<0.01,"***",IF('Estimates-split'!E11<0.05,"**",IF('Estimates-split'!E11<0.1,"*","")))) -> -0.062 | C21: =TEXT('Estimates-split'!F11,"0.000")&IF('Estimates-split'!I11="","",IF('Estimates-split'!I11<0.01,"***",IF('Estimates-split'!I11<0.05,"**",IF('Estimates-split'!I11<0.1,"*","")))) -> 0.026 | D21: =TEXT('Estimates-split'!J11,"0.000")&IF('Estimates-split'!M11="","",IF('Estimates-split'!M11<0.01,"***",IF('Estimates-split'!M11<0.05,"**",IF('Estimates-split'!M11<0.1,"*","")))) -> -0.091 | E21: =TEXT('Estimates-split'!N11,"0.000")&IF('Estimates-split'!Q11="","",IF('Estimates-split'!Q11<0.01,"***",IF('Estimates-split'!Q11<0.05,"**",IF('Estimates-split'!Q11<0.1,"*","")))) -> -0.079
B22: =IF('Estimates-split'!D11="","(n/a)","("&TEXT('Estimates-split'!D11,"0.00")&")") -> (-0.46) | C22: =IF('Estimates-split'!H11="","(n/a)","("&TEXT('Estimates-split'!H11,"0.00")&")") -> (0.43) | D22: =IF('Estimates-split'!L11="","(n/a)","("&TEXT('Estimates-split'!L11,"0.00")&")") -> (-1.14) | E22: =IF('Estimates-split'!P11="","(n/a)","("&TEXT('Estimates-split'!P11,"0.00")&")") -> (-0.90)
A23: Private Equity Allocation (%) | B23: =TEXT('Estimates-split'!B12,"0.000")&IF('Estimates-split'!E12="","",IF('Estimates-split'!E12<0.01,"***",IF('Estimates-split'!E12<0.05,"**",IF('Estimates-split'!E12<0.1,"*","")))) -> -0.073 | C23: =TEXT('Estimates-split'!F12,"0.000")&IF('Estimates-split'!I12="","",IF('Estimates-split'!I12<0.01,"***",IF('Estimates-split'!I12<0.05,"**",IF('Estimates-split'!I12<0.1,"*","")))) -> 0.025 | D23: =TEXT('Estimates-split'!J12,"0.000")&IF('Estimates-split'!M12="","",IF('Estimates-split'!M12<0.01,"***",IF('Estimates-split'!M12<0.05,"**",IF('Estimates-split'!M12<0.1,"*","")))) -> -0.042 | E23: =TEXT('Estimates-split'!N12,"0.000")&IF('Estimates-split'!Q12="","",IF('Estimates-split'!Q12<0.01,"***",IF('Estimates-split'!Q12<0.05,"**",IF('Estimates-split'!Q12<0.1,"*","")))) -> 0.011
B24: =IF('Estimates-split'!D12="","(n/a)","("&TEXT('Estimates-split'!D12,"0.00")&")") -> (-0.51) | C24: =IF('Estimates-split'!H12="","(n/a)","("&TEXT('Estimates-split'!H12,"0.00")&")") -> (0.39) | D24: =IF('Estimates-split'!L12="","(n/a)","("&TEXT('Estimates-split'!L12,"0.00")&")") -> (-0.47) | E24: =IF('Estimates-split'!P12="","(n/a)","("&TEXT('Estimates-split'!P12,"0.00")&")") -> (0.12)
A25: Hedge Fund Allocation (%) | B25: =TEXT('Estimates-split'!B13,"0.000")&IF('Estimates-split'!E13="","",IF('Estimates-split'!E13<0.01,"***",IF('Estimates-split'!E13<0.05,"**",IF('Estimates-split'!E13<0.1,"*","")))) -> -0.129 | C25: =TEXT('Estimates-split'!F13,"0.000")&IF('Estimates-split'!I13="","",IF('Estimates-split'!I13<0.01,"***",IF('Estimates-split'!I13<0.05,"**",IF('Estimates-split'!I13<0.1,"*","")))) -> -0.039 | D25: =TEXT('Estimates-split'!J13,"0.000")&IF('Estimates-split'!M13="","",IF('Estimates-split'!M13<0.01,"***",IF('Estimates-split'!M13<0.05,"**",IF('Estimates-split'!M13<0.1,"*","")))) -> -0.097 | E25: =TEXT('Estimates-split'!N13,"0.000")&IF('Estimates-split'!Q13="","",IF('Estimates-split'!Q13<0.01,"***",IF('Estimates-split'!Q13<0.05,"**",IF('Estimates-split'!Q13<0.1,"*","")))) -> -0.083
B26: =IF('Estimates-split'!D13="","(n/a)","("&TEXT('Estimates-split'!D13,"0.00")&")") -> (-0.96) | C26: =IF('Estimates-split'!H13="","(n/a)","("&TEXT('Estimates-split'!H13,"0.00")&")") -> (-0.59) | D26: =IF('Estimates-split'!L13="","(n/a)","("&TEXT('Estimates-split'!L13,"0.00")&")") -> (-1.27) | E26: =IF('Estimates-split'!P13="","(n/a)","("&TEXT('Estimates-split'!P13,"0.00")&")") -> (-1.12)
A27: Misc. Alternatives Allocation (%) | B27: =TEXT('Estimates-split'!B14,"0.000")&IF('Estimates-split'!E14="","",IF('Estimates-split'!E14<0.01,"***",IF('Estimates-split'!E14<0.05,"**",IF('Estimates-split'!E14<0.1,"*","")))) -> -0.096 | C27: =TEXT('Estimates-split'!F14,"0.000")&IF('Estimates-split'!I14="","",IF('Estimates-split'!I14<0.01,"***",IF('Estimates-split'!I14<0.05,"**",IF('Estimates-split'!I14<0.1,"*","")))) -> -0.010 | D27: =TEXT('Estimates-split'!J14,"0.000")&IF('Estimates-split'!M14="","",IF('Estimates-split'!M14<0.01,"***",IF('Estimates-split'!M14<0.05,"**",IF('Estimates-split'!M14<0.1,"*","")))) -> -0.115 | E27: =TEXT('Estimates-split'!N14,"0.000")&IF('Estimates-split'!Q14="","",IF('Estimates-split'!Q14<0.01,"***",IF('Estimates-split'!Q14<0.05,"**",IF('Estimates-split'!Q14<0.1,"*","")))) -> -0.076
B28: =IF('Estimates-split'!D14="","(n/a)","("&TEXT('Estimates-split'!D14,"0.00")&")") -> (-0.69) | C28: =IF('Estimates-split'!H14="","(n/a)","("&TEXT('Estimates-split'!H14,"0.00")&")") -> (-0.16) | D28: =IF('Estimates-split'!L14="","(n/a)","("&TEXT('Estimates-split'!L14,"0.00")&")") -> (-1.34) | E28: =IF('Estimates-split'!P14="","(n/a)","("&TEXT('Estimates-split'!P14,"0.00")&")") -> (-0.88)
A29: Commodities Allocation (%) | B29: =TEXT('Estimates-split'!B15,"0.000")&IF('Estimates-split'!E15="","",IF('Estimates-split'!E15<0.01,"***",IF('Estimates-split'!E15<0.05,"**",IF('Estimates-split'!E15<0.1,"*","")))) -> -0.143 | C29: =TEXT('Estimates-split'!F15,"0.000")&IF('Estimates-split'!I15="","",IF('Estimates-split'!I15<0.01,"***",IF('Estimates-split'!I15<0.05,"**",IF('Estimates-split'!I15<0.1,"*","")))) -> -0.047 | D29: =TEXT('Estimates-split'!J15,"0.000")&IF('Estimates-split'!M15="","",IF('Estimates-split'!M15<0.01,"***",IF('Estimates-split'!M15<0.05,"**",IF('Estimates-split'!M15<0.1,"*","")))) -> -0.139 | E29: =TEXT('Estimates-split'!N15,"0.000")&IF('Estimates-split'!Q15="","",IF('Estimates-split'!Q15<0.01,"***",IF('Estimates-split'!Q15<0.05,"**",IF('Estimates-split'!Q15<0.1,"*","")))) -> -0.123
B30: =IF('Estimates-split'!D15="","(n/a)","("&TEXT('Estimates-split'!D15,"0.00")&")") -> (-1.03) | C30: =IF('Estimates-split'!H15="","(n/a)","("&TEXT('Estimates-split'!H15,"0.00")&")") -> (-0.77) | D30: =IF('Estimates-split'!L15="","(n/a)","("&TEXT('Estimates-split'!L15,"0.00")&")") -> (-1.46) | E30: =IF('Estimates-split'!P15="","(n/a)","("&TEXT('Estimates-split'!P15,"0.00")&")") -> (-1.25)
A31: Cash Allocation (%) | B31: =TEXT('Estimates-split'!B16,"0.000")&IF('Estimates-split'!E16="","",IF('Estimates-split'!E16<0.01,"***",IF('Estimates-split'!E16<0.05,"**",IF('Estimates-split'!E16<0.1,"*","")))) -> -0.102 | C31: =TEXT('Estimates-split'!F16,"0.000")&IF('Estimates-split'!I16="","",IF('Estimates-split'!I16<0.01,"***",IF('Estimates-split'!I16<0.05,"**",IF('Estimates-split'!I16<0.1,"*","")))) -> -0.018 | D31: =TEXT('Estimates-split'!J16,"0.000")&IF('Estimates-split'!M16="","",IF('Estimates-split'!M16<0.01,"***",IF('Estimates-split'!M16<0.05,"**",IF('Estimates-split'!M16<0.1,"*","")))) -> -0.068 | E31: =TEXT('Estimates-split'!N16,"0.000")&IF('Estimates-split'!Q16="","",IF('Estimates-split'!Q16<0.01,"***",IF('Estimates-split'!Q16<0.05,"**",IF('Estimates-split'!Q16<0.1,"*","")))) -> -0.046
B32: =IF('Estimates-split'!D16="","(n/a)","("&TEXT('Estimates-split'!D16,"0.00")&")") -> (-0.69) | C32: =IF('Estimates-split'!H16="","(n/a)","("&TEXT('Estimates-split'!H16,"0.00")&")") -> (-0.23) | D32: =IF('Estimates-split'!L16="","(n/a)","("&TEXT('Estimates-split'!L16,"0.00")&")") -> (-0.61) | E32: =IF('Estimates-split'!P16="","(n/a)","("&TEXT('Estimates-split'!P16,"0.00")&")") -> (-0.41)
A33: Financial Center (0/1) | B33: =TEXT('Estimates-split'!B17,"0.000")&IF('Estimates-split'!E17="","",IF('Estimates-split'!E17<0.01,"***",IF('Estimates-split'!E17<0.05,"**",IF('Estimates-split'!E17<0.1,"*","")))) -> 0.110 | C33: =TEXT('Estimates-split'!F17,"0.000")&IF('Estimates-split'!I17="","",IF('Estimates-split'!I17<0.01,"***",IF('Estimates-split'!I17<0.05,"**",IF('Estimates-split'!I17<0.1,"*","")))) -> 0.144
B34: =IF('Estimates-split'!D17="","(n/a)","("&TEXT('Estimates-split'!D17,"0.00")&")") -> (0.77) | C34: =IF('Estimates-split'!H17="","(n/a)","("&TEXT('Estimates-split'!H17,"0.00")&")") -> (1.02)
A35: Log (CIO Age) (t-1) | C35: =TEXT('Estimates-split'!F18,"0.000")&IF('Estimates-split'!I18="","",IF('Estimates-split'!I18<0.01,"***",IF('Estimates-split'!I18<0.05,"**",IF('Estimates-split'!I18<0.1,"*","")))) -> -0.404 | D35: =TEXT('Estimates-split'!J18,"0.000")&IF('Estimates-split'!M18="","",IF('Estimates-split'!M18<0.01,"***",IF('Estimates-split'!M18<0.05,"**",IF('Estimates-split'!M18<0.1,"*","")))) -> 0.821 | E35: =TEXT('Estimates-split'!N18,"0.000")&IF('Estimates-split'!Q18="","",IF('Estimates-split'!Q18<0.01,"***",IF('Estimates-split'!Q18<0.05,"**",IF('Estimates-split'!Q18<0.1,"*","")))) -> 0.916
C36: =IF('Estimates-split'!H18="","(n/a)","("&TEXT('Estimates-split'!H18,"0.00")&")") -> (-0.77) | D36: =IF('Estimates-split'!L18="","(n/a)","("&TEXT('Estimates-split'!L18,"0.00")&")") -> (1.28) | E36: =IF('Estimates-split'!P18="","(n/a)","("&TEXT('Estimates-split'!P18,"0.00")&")") -> (1.37)
A37: Log (CIO Tenure) (t-1) | C37: =TEXT('Estimates-split'!F19,"0.000")&IF('Estimates-split'!I19="","",IF('Estimates-split'!I19<0.01,"***",IF('Estimates-split'!I19<0.05,"**",IF('Estimates-split'!I19<0.1,"*","")))) -> 0.036 | D37: =TEXT('Estimates-split'!J19,"0.000")&IF('Estimates-split'!M19="","",IF('Estimates-split'!M19<0.01,"***",IF('Estimates-split'!M19<0.05,"**",IF('Estimates-split'!M19<0.1,"*","")))) -> -0.012 | E37: =TEXT('Estimates-split'!N19,"0.000")&IF('Estimates-split'!Q19="","",IF('Estimates-split'!Q19<0.01,"***",IF('Estimates-split'!Q19<0.05,"**",IF('Estimates-split'!Q19<0.1,"*","")))) -> -0.037
C38: =IF('Estimates-split'!H19="","(n/a)","("&TEXT('Estimates-split'!H19,"0.00")&")") -> (0.38) | D38: =IF('Estimates-split'!L19="","(n/a)","("&TEXT('Estimates-split'!L19,"0.00")&")") -> (-0.10) | E38: =IF('Estimates-split'!P19="","(n/a)","("&TEXT('Estimates-split'!P19,"0.00")&")") -> (-0.28)
A39: CIO Prior Private Experience (0/1) | C39: =TEXT('Estimates-split'!F20,"0.000")&IF('Estimates-split'!I20="","",IF('Estimates-split'!I20<0.01,"***",IF('Estimates-split'!I20<0.05,"**",IF('Estimates-split'!I20<0.1,"*","")))) -> 0.031 | D39: =TEXT('Estimates-split'!J20,"0.000")&IF('Estimates-split'!M20="","",IF('Estimates-split'!M20<0.01,"***",IF('Estimates-split'!M20<0.05,"**",IF('Estimates-split'!M20<0.1,"*","")))) -> -0.037 | E39: =TEXT('Estimates-split'!N20,"0.000")&IF('Estimates-split'!Q20="","",IF('Estimates-split'!Q20<0.01,"***",IF('Estimates-split'!Q20<0.05,"**",IF('Estimates-split'!Q20<0.1,"*","")))) -> 0.004
C40: =IF('Estimates-split'!H20="","(n/a)","("&TEXT('Estimates-split'!H20,"0.00")&")") -> (0.29) | D40: =IF('Estimates-split'!L20="","(n/a)","("&TEXT('Estimates-split'!L20,"0.00")&")") -> (-0.22) | E40: =IF('Estimates-split'!P20="","(n/a)","("&TEXT('Estimates-split'!P20,"0.00")&")") -> (0.03)
A41: CIO Attended Elite College (0/1) | C41: =TEXT('Estimates-split'!F21,"0.000")&IF('Estimates-split'!I21="","",IF('Estimates-split'!I21<0.01,"***",IF('Estimates-split'!I21<0.05,"**",IF('Estimates-split'!I21<0.1,"*","")))) -> -0.112 | D41: =TEXT('Estimates-split'!J21,"0.000")&IF('Estimates-split'!M21="","",IF('Estimates-split'!M21<0.01,"***",IF('Estimates-split'!M21<0.05,"**",IF('Estimates-split'!M21<0.1,"*","")))) -> 0.244 | E41: =TEXT('Estimates-split'!N21,"0.000")&IF('Estimates-split'!Q21="","",IF('Estimates-split'!Q21<0.01,"***",IF('Estimates-split'!Q21<0.05,"**",IF('Estimates-split'!Q21<0.1,"*","")))) -> 0.289
...

Sheet Table XII-split
A1: Table XII: Conflicted CIOs: Fee Ratio in the First versus Second Half of Tenure
A2: This table repeats the regressions of Table XI with Fee Ratio as the dependent variable. Fee Ratio is the plan's total investment fees as a percentage of plan assets. Conflicted CIO x First Half of Tenure and Conflicted CIO x Second Half of Tenure are defined as in Table XI, and the omitted category is all plan-years run by non-conflicted CIOs. The other independent variables are as defined in Table I. The last row reports the p-value of a test that the first-half and second-half coefficients are equal. The standard errors are double clustered by plan and year. Coefficients marked with ***, **, and * are significant at the 1%, 5%, and 10% level, respectively.
B4: (1) | C4: (2) | D4: (3) | E4: (4)
B5: Fee Ratio (t) | C5: Fee Ratio (t) | D5: Fee Ratio (t) | E5: Fee Ratio (t)
A6: Conflicted CIO x First Half of Tenure (0/1) | B6: =TEXT('Estimates-split'!AH4,"0.000")&IF('Estimates-split'!AK4="","",IF('Estimates-split'!AK4<0.01,"***",IF('Estimates-split'!AK4<0.05,"**",IF('Estimates-split'!AK4<0.1,"*","")))) -> -0.045 | C6: =TEXT('Estimates-split'!AL4,"0.000")&IF('Estimates-split'!AO4="","",IF('Estimates-split'!AO4<0.01,"***",IF('Estimates-split'!AO4<0.05,"**",IF('Estimates-split'!AO4<0.1,"*","")))) -> -0.028 | D6: =TEXT('Estimates-split'!AP4,"0.000")&IF('Estimates-split'!AS4="","",IF('Estimates-split'!AS4<0.01,"***",IF('Estimates-split'!AS4<0.05,"**",IF('Estimates-split'!AS4<0.1,"*","")))) -> 0.039 | E6: =TEXT('Estimates-split'!AT4,"0.000")&IF('Estimates-split'!AW4="","",IF('Estimates-split'!AW4<0.01,"***",IF('Estimates-split'!AW4<0.05,"**",IF('Estimates-split'!AW4<0.1,"*","")))) -> 0.037
B7: =IF('Estimates-split'!AJ4="","(n/a)","("&TEXT('Estimates-split'!AJ4,"0.00")&")") -> (-1.30) | C7: =IF('Estimates-split'!AN4="","(n/a)","("&TEXT('Estimates-split'!AN4,"0.00")&")") -> (-0.62) | D7: =IF('Estimates-split'!AR4="","(n/a)","("&TEXT('Estimates-split'!AR4,"0.00")&")") -> (0.71) | E7: =IF('Estimates-split'!AV4="","(n/a)","("&TEXT('Estimates-split'!AV4,"0.00")&")") -> (0.67)
A8: Conflicted CIO x Second Half of Tenure (0/1) | B8: =TEXT('Estimates-split'!AH5,"0.000")&IF('Estimates-split'!AK5="","",IF('Estimates-split'!AK5<0.01,"***",IF('Estimates-split'!AK5<0.05,"**",IF('Estimates-split'!AK5<0.1,"*","")))) -> -0.047 | C8: =TEXT('Estimates-split'!AL5,"0.000")&IF('Estimates-split'!AO5="","",IF('Estimates-split'!AO5<0.01,"***",IF('Estimates-split'!AO5<0.05,"**",IF('Estimates-split'!AO5<0.1,"*","")))) -> -0.035 | D8: =TEXT('Estimates-split'!AP5,"0.000")&IF('Estimates-split'!AS5="","",IF('Estimates-split'!AS5<0.01,"***",IF('Estimates-split'!AS5<0.05,"**",IF('Estimates-split'!AS5<0.1,"*","")))) -> 0.031 | E8: =TEXT('Estimates-split'!AT5,"0.000")&IF('Estimates-split'!AW5="","",IF('Estimates-split'!AW5<0.01,"***",IF('Estimates-split'!AW5<0.05,"**",IF('Estimates-split'!AW5<0.1,"*","")))) -> 0.028
B9: =IF('Estimates-split'!AJ5="","(n/a)","("&TEXT('Estimates-split'!AJ5,"0.00")&")") -> (-1.17) | C9: =IF('Estimates-split'!AN5="","(n/a)","("&TEXT('Estimates-split'!AN5,"0.00")&")") -> (-0.90) | D9: =IF('Estimates-split'!AR5="","(n/a)","("&TEXT('Estimates-split'!AR5,"0.00")&")") -> (0.53) | E9: =IF('Estimates-split'!AV5="","(n/a)","("&TEXT('Estimates-split'!AV5,"0.00")&")") -> (0.50)
A10: Investment Return (t - 1) | B10: =TEXT('Estimates-split'!AH6,"0.000")&IF('Estimates-split'!AK6="","",IF('Estimates-split'!AK6<0.01,"***",IF('Estimates-split'!AK6<0.05,"**",IF('Estimates-split'!AK6<0.1,"*","")))) -> 0.000 | C10: =TEXT('Estimates-split'!AL6,"0.000")&IF('Estimates-split'!AO6="","",IF('Estimates-split'!AO6<0.01,"***",IF('Estimates-split'!AO6<0.05,"**",IF('Estimates-split'!AO6<0.1,"*","")))) -> 0.000 | D10: =TEXT('Estimates-split'!AP6,"0.000")&IF('Estimates-split'!AS6="","",IF('Estimates-split'!AS6<0.01,"***",IF('Estimates-split'!AS6<0.05,"**",IF('Estimates-split'!AS6<0.1,"*","")))) -> -0.001 | E10: =TEXT('Estimates-split'!AT6,"0.000")&IF('Estimates-split'!AW6="","",IF('Estimates-split'!AW6<0.01,"***",IF('Estimates-split'!AW6<0.05,"**",IF('Estimates-split'!AW6<0.1,"*","")))) -> -0.001**
B11: =IF('Estimates-split'!AJ6="","(n/a)","("&TEXT('Estimates-split'!AJ6,"0.00")&")") -> (-0.40) | C11: =IF('Estimates-split'!AN6="","(n/a)","("&TEXT('Estimates-split'!AN6,"0.00")&")") -> (-0.56) | D11: =IF('Estimates-split'!AR6="","(n/a)","("&TEXT('Estimates-split'!AR6,"0.00")&")") -> (-1.20) | E11: =IF('Estimates-split'!AV6="","(n/a)","("&TEXT('Estimates-split'!AV6,"0.00")&")") -> (-2.39)
A12: Log (Plan Size) (t-1) | B12: =TEXT('Estimates-split'!AH7,"0.000")&IF('Estimates-split'!AK7="","",IF('Estimates-split'!AK7<0.01,"***",IF('Estimates-split'!AK7<0.05,"**",IF('Estimates-split'!AK7<0.1,"*","")))) -> -0.022 | C12: =TEXT('Estimates-split'!AL7,"0.000")&IF('Estimates-split'!AO7="","",IF('Estimates-split'!AO7<0.01,"***",IF('Estimates-split'!AO7<0.05,"**",IF('Estimates-split'!AO7<0.1,"*","")))) -> -0.019 | D12: =TEXT('Estimates-split'!AP7,"0.000")&IF('Estimates-split'!AS7="","",IF('Estimates-split'!AS7<0.01,"***",IF('Estimates-split'!AS7<0.05,"**",IF('Estimates-split'!AS7<0.1,"*","")))) -> 0.008 | E12: =TEXT('Estimates-split'!AT7,"0.000")&IF('Estimates-split'!AW7="","",IF('Estimates-split'!AW7<0.01,"***",IF('Estimates-split'!AW7<0.05,"**",IF('Estimates-split'!AW7<0.1,"*","")))) -> 0.042
B13: =IF('Estimates-split'!AJ7="","(n/a)","("&TEXT('Estimates-split'!AJ7,"0.00")&")") -> (-1.62) | C13: =IF('Estimates-split'!AN7="","(n/a)","("&TEXT('Estimates-split'!AN7,"0.00")&")") -> (-1.32) | D13: =IF('Estimates-split'!AR7="","(n/a)","("&TEXT('Estimates-split'!AR7,"0.00")&")") -> (0.16) | E13: =IF('Estimates-split'!AV7="","(n/a)","("&TEXT('Estimates-split'!AV7,"0.00")&")") -> (0.41)
A14: Funding Ratio (t-1) | B14: =TEXT('Estimates-split'!AH8,"0.000")&IF('Estimates-split'!AK8="","",IF('Estimates-split'!AK8<0.01,"***",IF('Estimates-split'!AK8<0.05,"**",IF('Estimates-split'!AK8<0.1,"*","")))) -> -0.001 | C14: =TEXT('Estimates-split'!AL8,"0.000")&IF('Estimates-split'!AO8="","",IF('Estimates-split'!AO8<0.01,"***",IF('Estimates-split'!AO8<0.05,"**",IF('Estimates-split'!AO8<0.1,"*","")))) -> -0.001 | D14: =TEXT('Estimates-split'!AP8,"0.000")&IF('Estimates-split'!AS8="","",IF('Estimates-split'!AS8<0.01,"***",IF('Estimates-split'!AS8<0.05,"**",IF('Estimates-split'!AS8<0.1,"*","")))) -> -0.001 | E14: =TEXT('Estimates-split'!AT8,"0.000")&IF('Estimates-split'!AW8="","",IF('Estimates-split'!AW8<0.01,"***",IF('Estimates-split'!AW8<0.05,"**",IF('Estimates-split'!AW8<0.1,"*","")))) -> -0.002**
B15: =IF('Estimates-split'!AJ8="","(n/a)","("&TEXT('Estimates-split'!AJ8,"0.00")&")") -> (-0.94) | C15: =IF('Estimates-split'!AN8="","(n/a)","("&TEXT('Estimates-split'!AN8,"0.00")&")") -> (-1.18) | D15: =IF('Estimates-split'!AR8="","(n/a)","("&TEXT('Estimates-split'!AR8,"0.00")&")") -> (-1.14) | E15: =IF('Estimates-split'!AV8="","(n/a)","("&TEXT('Estimates-split'!AV8,"0.00")&")") -> (-2.38)
A16: Equity Allocation (%) | B16: =TEXT('Estimates-split'!AH9,"0.000")&IF('Estimates-split'!AK9="","",IF('Estimates-split'!AK9<0.01,"***",IF('Estimates-split'!AK9<0.05,"**",IF('Estimates-split'!AK9<0.1,"*","")))) -> -0.039 | C16: =TEXT('Estimates-split'!AL9,"0.000")&IF('Estimates-split'!AO9="","",IF('Estimates-split'!AO9<0.01,"***",IF('Estimates-split'!AO9<0.05,"**",IF('Estimates-split'!AO9<0.1,"*","")))) -> -0.082 | D16: =TEXT('Estimates-split'!AP9,"0.000")&IF('Estimates-split'!AS9="","",IF('Estimates-split'!AS9<0.01,"***",IF('Estimates-split'!AS9<0.05,"**",IF('Estimates-split'!AS9<0.1,"*","")))) -> -0.085 | E16: =TEXT('Estimates-split'!AT9,"0.000")&IF('Estimates-split'!AW9="","",IF('Estimates-split'!AW9<0.01,"***",IF('Estimates-split'!AW9<0.05,"**",IF('Estimates-split'!AW9<0.1,"*","")))) -> -0.086
B17: =IF('Estimates-split'!AJ9="","(n/a)","("&TEXT('Estimates-split'!AJ9,"0.00")&")") -> (-1.12) | C17: =IF('Estimates-split'!AN9="","(n/a)","("&TEXT('Estimates-split'!AN9,"0.00")&")") -> (-1.19) | D17: =IF('Estimates-split'!AR9="","(n/a)","("&TEXT('Estimates-split'!AR9,"0.00")&")") -> (-1.44) | E17: =IF('Estimates-split'!AV9="","(n/a)","("&TEXT('Estimates-split'!AV9,"0.00")&")") -> (-1.55)
A18: Fixed Income Allocation (%) | B18: =TEXT('Estimates-split'!AH10,"0.000")&IF('Estimates-split'!AK10="","",IF('Estimates-split'!AK10<0.01,"***",IF('Estimates-split'!AK10<0.05,"**",IF('Estimates-split'!AK10<0.1,"*","")))) -> -0.043 | C18: =TEXT('Estimates-split'!AL10,"0.000")&IF('Estimates-split'!AO10="","",IF('Estimates-split'!AO10<0.01,"***",IF('Estimates-split'!AO10<0.05,"**",IF('Estimates-split'!AO10<0.1,"*","")))) -> -0.087 | D18: =TEXT('Estimates-split'!AP10,"0.000")&IF('Estimates-split'!AS10="","",IF('Estimates-split'!AS10<0.01,"***",IF('Estimates-split'!AS10<0.05,"**",IF('Estimates-split'!AS10<0.1,"*","")))) -> -0.090 | E18: =TEXT('Estimates-split'!AT10,"0.000")&IF('Estimates-split'!AW10="","",IF('Estimates-split'!AW10<0.01,"***",IF('Estimates-split'!AW10<0.05,"**",IF('Estimates-split'!AW10<0.1,"*","")))) -> -0.091
B19: =IF('Estimates-split'!AJ10="","(n/a)","("&TEXT('Estimates-split'!AJ10,"0.00")&")") -> (-1.23) | C19: =IF('Estimates-split'!AN10="","(n/a)","("&TEXT('Estimates-split'!AN10,"0.00")&")") -> (-1.25) | D19: =IF('Estimates-split'!AR10="","(n/a)","("&TEXT('Estimates-split'!AR10,"0.00")&")") -> (-1.52) | E19: =IF('Estimates-split'!AV10="","(n/a)","("&TEXT('Estimates-split'!AV10,"0.00")&")") -> (-1.64)
A20: Real Estate Allocation (%) | B20: =TEXT('Estimates-split'!AH11,"0.000")&IF('Estimates-split'!AK11="","",IF('Estimates-split'!AK11<0.01,"***",IF('Estimates-split'!AK11<0.05,"**",IF('Estimates-split'!AK11<0.1,"*","")))) -> -0.032 | C20: =TEXT('Estimates-split'!AL11,"0.000")&IF('Estimates-split'!AO11="","",IF('Estimates-split'!AO11<0.01,"***",IF('Estimates-split'!AO11<0.05,"**",IF('Estimates-split'!AO11<0.1,"*","")))) -> -0.075 | D20: =TEXT('Estimates-split'!AP11,"0.000")&IF('Estimates-split'!AS11="","",IF('Estimates-split'!AS11<0.01,"***",IF('Estimates-split'!AS11<0.05,"**",IF('Estimates-split'!AS11<0.1,"*","")))) -> -0.085 | E20: =TEXT('Estimates-split'!AT11,"0.000")&IF('Estimates-split'!AW11="","",IF('Estimates-split'!AW11<0.01,"***",IF('Estimates-split'!AW11<0.05,"**",IF('Estimates-split'!AW11<0.1,"*","")))) -> -0.087
B21: =IF('Estimates-split'!AJ11="","(n/a)","("&TEXT('Estimates-split'!AJ11,"0.00")&")") -> (-0.90) | C21: =IF('Estimates-split'!AN11="","(n/a)","("&TEXT('Estimates-split'!AN11,"0.00")&")") -> (-1.08) | D21: =IF('Estimates-split'!AR11="","(n/a)","("&TEXT('Estimates-split'!AR11,"0.00")&")") -> (-1.45) | E21: =IF('Estimates-split'!AV11="","(n/a)","("&TEXT('Estimates-split'!AV11,"0.00")&")") -> (-1.59)
A22: Private Equity Allocation (%) | B22: =TEXT('Estimates-split'!AH12,"0.000")&IF('Estimates-split'!AK12="","",IF('Estimates-split'!AK12<0.01,"***",IF('Estimates-split'!AK12<0.05,"**",IF('Estimates-split'!AK12<0.1,"*","")))) -> -0.034 | C22: =TEXT('Estimates-split'!AL12,"0.000")&IF('Estimates-split'!AO12="","",IF('Estimates-split'!AO12<0.01,"***",IF('Estimates-split'!AO12<0.05,"**",IF('Estimates-split'!AO12<0.1,"*","")))) -> -0.077 | D22: =TEXT('Estimates-split'!AP12,"0.000")&IF('Estimates-split'!AS12="","",IF('Estimates-split'!AS12<0.01,"***",IF('Estimates-split'!AS12<0.05,"**",IF('Estimates-split'!AS12<0.1,"*","")))) -> -0.067 | E22: =TEXT('Estimates-split'!AT12,"0.000")&IF('Estimates-split'!AW12="","",IF('Estimates-split'!AW12<0.01,"***",IF('Estimates-split'!AW12<0.05,"**",IF('Estimates-split'!AW12<0.1,"*","")))) -> -0.065
B23: =IF('Estimates-split'!AJ12="","(n/a)","("&TEXT('Estimates-split'!AJ12,"0.00")&")") -> (-0.98) | C23: =IF('Estimates-split'!AN12="","(n/a)","("&TEXT('Estimates-split'!AN12,"0.00")&")") -> (-1.11) | D23: =IF('Estimates-split'!AR12="","(n/a)","("&TEXT('Estimates-split'!AR12,"0.00")&")") -> (-1.13) | E23: =IF('Estimates-split'!AV12="","(n/a)","("&TEXT('Estimates-split'!AV12,"0.00")&")") -> (-1.16)
A24: Hedge Fund Allocation (%) | B24: =TEXT('Estimates-split'!AH13,"0.000")&IF('Estimates-split'!AK13="","",IF('Estimates-split'!AK13<0.01,"***",IF('Estimates-split'!AK13<0.05,"**",IF('Estimates-split'!AK13<0.1,"*","")))) -> -0.022 | C24: =TEXT('Estimates-split'!AL13,"0.000")&IF('Estimates-split'!AO13="","",IF('Estimates-split'!AO13<0.01,"***",IF('Estimates-split'!AO13<0.05,"**",IF('Estimates-split'!AO13<0.1,"*","")))) -> -0.064 | D24: =TEXT('Estimates-split'!AP13,"0.000")&IF('Estimates-split'!AS13="","",IF('Estimates-split'!AS13<0.01,"***",IF('Estimates-split'!AS13<0.05,"**",IF('Estimates-split'!AS13<0.1,"*","")))) -> -0.069 | E24: =TEXT('Estimates-split'!AT13,"0.000")&IF('Estimates-split'!AW13="","",IF('Estimates-split'!AW13<0.01,"***",IF('Estimates-split'!AW13<0.05,"**",IF('Estimates-split'!AW13<0.1,"*","")))) -> -0.069
B25: =IF('Estimates-split'!AJ13="","(n/a)","("&TEXT('Estimates-split'!AJ13,"0.00")&")") -> (-0.62) | C25: =IF('Estimates-split'!AN13="","(n/a)","("&TEXT('Estimates-split'!AN13,"0.00")&")") -> (-0.92) | D25: =IF('Estimates-split'!AR13="","(n/a)","("&TEXT('Estimates-split'!AR13,"0.00")&")") -> (-1.17) | E25: =IF('Estimates-split'!AV13="","(n/a)","("&TEXT('Estimates-split'!AV13,"0.00")&")") -> (-1.25)
A26: Misc. Alternatives Allocation (%) | B26: =TEXT('Estimates-split'!AH14,"0.000")&IF('Estimates-split'!AK14="","",IF('Estimates-split'!AK14<0.01,"***",IF('Estimates-split'!AK14<0.05,"**",IF('Estimates-split'!AK14<0.1,"*","")))) -> -0.034 | C26: =TEXT('Estimates-split'!AL14,"0.000")&IF('Estimates-split'!AO14="","",IF('Estimates-split'!AO14<0.01,"***",IF('Estimates-split'!AO14<0.05,"**",IF('Estimates-split'!AO14<0.1,"*","")))) -> -0.075 | D26: =TEXT('Estimates-split'!AP14,"0.000")&IF('Estimates-split'!AS14="","",IF('Estimates-split'!AS14<0.01,"***",IF('Estimates-split'!AS14<0.05,"**",IF('Estimates-split'!AS14<0.1,"*","")))) -> -0.074 | E26: =TEXT('Estimates-split'!AT14,"0.000")&IF('Estimates-split'!AW14="","",IF('Estimates-split'!AW14<0.01,"***",IF('Estimates-split'!AW14<0.05,"**",IF('Estimates-split'!AW14<0.1,"*","")))) -> -0.073
B27: =IF('Estimates-split'!AJ14="","(n/a)","("&TEXT('Estimates-split'!AJ14,"0.00")&")") -> (-0.99) | C27: =IF('Estimates-split'!AN14="","(n/a)","("&TEXT('Estimates-split'!AN14,"0.00")&")") -> (-1.10) | D27: =IF('Estimates-split'!AR14="","(n/a)","("&TEXT('Estimates-split'!AR14,"0.00")&")") -> (-1.26) | E27: =IF('Estimates-split'!AV14="","(n/a)","("&TEXT('Estimates-split'!AV14,"0.00")&")") -> (-1.33)
A28: Commodities Allocation (%) | B28: =TEXT('Estimates-split'!AH15,"0.000")&IF('Estimates-split'!AK15="","",IF('Estimates-split'!AK15<0.01,"***",IF('Estimates-split'!AK15<0.05,"**",IF('Estimates-split'!AK15<0.1,"*","")))) -> -0.032 | C28: =TEXT('Estimates-split'!AL15,"0.000")&IF('Estimates-split'!AO15="","",IF('Estimates-split'!AO15<0.01,"***",IF('Estimates-split'!AO15<0.05,"**",IF('Estimates-split'!AO15<0.1,"*","")))) -> -0.073 | D28: =TEXT('Estimates-split'!AP15,"0.000")&IF('Estimates-split'!AS15="","",IF('Estimates-split'!AS15<0.01,"***",IF('Estimates-split'!AS15<0.05,"**",IF('Estimates-split'!AS15<0.1,"*","")))) -> -0.082 | E28: =TEXT('Estimates-split'!AT15,"0.000")&IF('Estimates-split'!AW15="","",IF('Estimates-split'!AW15<0.01,"***",IF('Estimates-split'!AW15<0.05,"**",IF('Estimates-split'!AW15<0.1,"*","")))) -> -0.083
B29: =IF('Estimates-split'!AJ15="","(n/a)","("&TEXT('Estimates-split'!AJ15,"0.00")&")") -> (-0.91) | C29: =IF('Estimates-split'!AN15="","(n/a)","("&TEXT('Estimates-split'!AN15,"0.00")&")") -> (-1.07) | D29: =IF('Estimates-split'!AR15="","(n/a)","("&TEXT('Estimates-split'!AR15,"0.00")&")") -> (-1.41) | E29: =IF('Estimates-split'!AV15="","(n/a)","("&TEXT('Estimates-split'!AV15,"0.00")&")") -> (-1.52)
A30: Cash Allocation (%) | B30: =TEXT('Estimates-split'!AH16,"0.000")&IF('Estimates-split'!AK16="","",IF('Estimates-split'!AK16<0.01,"***",IF('Estimates-split'!AK16<0.05,"**",IF('Estimates-split'!AK16<0.1,"*","")))) -> -0.036 | C30: =TEXT('Estimates-split'!AL16,"0.000")&IF('Estimates-split'!AO16="","",IF('Estimates-split'!AO16<0.01,"***",IF('Estimates-split'!AO16<0.05,"**",IF('Estimates-split'!AO16<0.1,"*","")))) -> -0.082 | D30: =TEXT('Estimates-split'!AP16,"0.000")&IF('Estimates-split'!AS16="","",IF('Estimates-split'!AS16<0.01,"***",IF('Estimates-split'!AS16<0.05,"**",IF('Estimates-split'!AS16<0.1,"*","")))) -> -0.080 | E30: =TEXT('Estimates-split'!AT16,"0.000")&IF('Estimates-split'!AW16="","",IF('Estimates-split'!AW16<0.01,"***",IF('Estimates-split'!AW16<0.05,"**",IF('Estimates-split'!AW16<0.1,"*","")))) -> -0.080
B31: =IF('Estimates-split'!AJ16="","(n/a)","("&TEXT('Estimates-split'!AJ16,"0.00")&")") -> (-1.04) | C31: =IF('Estimates-split'!AN16="","(n/a)","("&TEXT('Estimates-split'!AN16,"0.00")&")") -> (-1.17) | D31: =IF('Estimates-split'!AR16="","(n/a)","("&TEXT('Estimates-split'!AR16,"0.00")&")") -> (-1.35) | E31: =IF('Estimates-split'!AV16="","(n/a)","("&TEXT('Estimates-split'!AV16,"0.00")&")") -> (-1.44)
A32: Financial Center (0/1) | B32: =TEXT('Estimates-split'!AH17,"0.000")&IF('Estimates-split'!AK17="","",IF('Estimates-split'!AK17<0.01,"***",IF('Estimates-split'!AK17<0.05,"**",IF('Estimates-split'!AK17<0.1,"*","")))) -> -0.012 | C32: =TEXT('Estimates-split'!AL17,"0.000")&IF('Estimates-split'!AO17="","",IF('Estimates-split'!AO17<0.01,"***",IF('Estimates-split'!AO17<0.05,"**",IF('Estimates-split'!AO17<0.1,"*","")))) -> 0.033
B33: =IF('Estimates-split'!AJ17="","(n/a)","("&TEXT('Estimates-split'!AJ17,"0.00")&")") -> (-0.29) | C33: =IF('Estimates-split'!AN17="","(n/a)","("&TEXT('Estimates-split'!AN17,"0.00")&")") -> (0.81)
A34: Log (CIO Age) (t-1) | C34: =TEXT('Estimates-split'!AL18,"0.000")&IF('Estimates-split'!AO18="","",IF('Estimates-split'!AO18<0.01,"***",IF('Estimates-split'!AO18<0.05,"**",IF('Estimates-split'!AO18<0.1,"*","")))) -> 0.001 | D34: =TEXT('Estimates-split'!AP18,"0.000")&IF('Estimates-split'!AS18="","",IF('Estimates-split'!AS18<0.01,"***",IF('Estimates-split'!AS18<0.05,"**",IF('Estimates-split'!AS18<0.1,"*","")))) -> -0.185* | E34: =TEXT('Estimates-split'!AT18,"0.000")&IF('Estimates-split'!AW18="","",IF('Estimates-split'!AW18<0.01,"***",IF('Estimates-split'!AW18<0.05,"**",IF('Estimates-split'!AW18<0.1,"*","")))) -> -0.155
C35: =IF('Estimates-split'!AN18="","(n/a)","("&TEXT('Estimates-split'!AN18,"0.00")&")") -> (0.01) | D35: =IF('Estimates-split'!AR18="","(n/a)","("&TEXT('Estimates-split'!AR18,"0.00")&")") -> (-1.78) | E35: =IF('Estimates-split'!AV18="","(n/a)","("&TEXT('Estimates-split'!AV18,"0.00")&")") -> (-1.49)
A36: Log (CIO Tenure) (t-1) | C36: =TEXT('Estimates-split'!AL19,"0.000")&IF('Estimates-split'!AO19="","",IF('Estimates-split'!AO19<0.01,"***",IF('Estimates-split'!AO19<0.05,"**",IF('Estimates-split'!AO19<0.1,"*","")))) -> -0.015 | D36: =TEXT('Estimates-split'!AP19,"0.000")&IF('Estimates-split'!AS19="","",IF('Estimates-split'!AS19<0.01,"***",IF('Estimates-split'!AS19<0.05,"**",IF('Estimates-split'!AS19<0.1,"*","")))) -> 0.017 | E36: =TEXT('Estimates-split'!AT19,"0.000")&IF('Estimates-split'!AW19="","",IF('Estimates-split'!AW19<0.01,"***",IF('Estimates-split'!AW19<0.05,"**",IF('Estimates-split'!AW19<0.1,"*","")))) -> 0.014
C37: =IF('Estimates-split'!AN19="","(n/a)","("&TEXT('Estimates-split'!AN19,"0.00")&")") -> (-1.11) | D37: =IF('Estimates-split'!AR19="","(n/a)","("&TEXT('Estimates-split'!AR19,"0.00")&")") -> (1.57) | E37: =IF('Estimates-split'!AV19="","(n/a)","("&TEXT('Estimates-split'!AV19,"0.00")&")") -> (1.36)
A38: CIO Prior Private Experience (0/1) | C38: =TEXT('Estimates-split'!AL20,"0.000")&IF('Estimates-split'!AO20="","",IF('Estimates-split'!AO20<0.01,"***",IF('Estimates-split'!AO20<0.05,"**",IF('Estimates-split'!AO20<0.1,"*","")))) -> -0.056 | D38: =TEXT('Estimates-split'!AP20,"0.000")&IF('Estimates-split'!AS20="","",IF('Estimates-split'!AS20<0.01,"***",IF('Estimates-split'!AS20<0.05,"**",IF('Estimates-split'!AS20<0.1,"*","")))) -> -0.073 | E38: =TEXT('Estimates-split'!AT20,"0.000")&IF('Estimates-split'!AW20="","",IF('Estimates-split'!AW20<0.01,"***",IF('Estimates-split'!AW20<0.05,"**",IF('Estimates-split'!AW20<0.1,"*","")))) -> -0.067
C39: =IF('Estimates-split'!AN20="","(n/a)","("&TEXT('Estimates-split'!AN20,"0.00")&")") -> (-1.44) | D39: =IF('Estimates-split'!AR20="","(n/a)","("&TEXT('Estimates-split'!AR20,"0.00")&")") -> (-1.36) | E39: =IF('Estimates-split'!AV20="","(n/a)","("&TEXT('Estimates-split'!AV20,"0.00")&")") -> (-1.32)
A40: CIO Attended Elite College (0/1) | C40: =TEXT('Estimates-split'!AL21,"0.000")&IF('Estimates-split'!AO21="","",IF('Estimates-split'!AO21<0.01,"***",IF('Estimates-split'!AO21<0.05,"**",IF('Estimates-split'!AO21<0.1,"*","")))) -> 0.033 | D40: =TEXT('Estimates-split'!AP21,"0.000")&IF('Estimates-split'!AS21="","",IF('Estimates-split'!AS21<0.01,"***",IF('Estimates-split'!AS21<0.05,"**",IF('Estimates-split'!AS21<0.1,"*","")))) -> -0.059 | E40: =TEXT('Estimates-split'!AT21,"0.000")&IF('Estimates-split'!AW21="","",IF('Estimates-split'!AW21<0.01,"***",IF('Estimates-split'!AW21<0.05,"**",IF('Estimates-split'!AW21<0.1,"*","")))) -> -0.059
C41: =IF('Estimates-split'!AN21="","(n/a)","("&TEXT('Estimates-split'!AN21,"0.00")&")") -> (0.81) | D41: =IF('Estimates-split'!AR21="","(n/a)","("&TEXT('Estimates-split'!AR21,"0.00")&")") -> (-1.56) | E41: =IF('Estimates-split'!AV21="","(n/a)","("&TEXT('Estimates-split'!AV21,"0.00")&")") -> (-1.63)
...

Sheet Table XI
A1: Table XI: Conflicted CIOs: Plan Performance in the First versus Second Half of Tenure, Conflicted CIOs Only (updated benchmark)
A2: This table reports results of tests that regress the returns of public pension plans run by conflicted CIOs on an indicator variable, Second Half of Tenure, which is equal to 1 in the fiscal years in which the CIO's tenure exceeds one half of the CIO's tenure at departure and 0 otherwise. Conflicted CIOs are defined as in Table III, and the sample is restricted to their plan-years, so the coefficient compares the second half of a conflicted CIO's tenure with the first half. Tenure at departure is the CIO's tenure in the last fiscal year observed in the plan plus any gap to the departure year. The performance measure in Panel A is Peer-Adjusted Return, which is the difference of a plan's return and the average pension plan return each year. The performance measure in Panel B is Benchmark-Adjusted Return, which is calculated as the plan's return minus the return of its updated policy benchmark (the benchmark return reported in the plan's financial report or, where none is stated, an inferred value graded A or B). The other independent variables are as defined in Table I. Columns 5 and 6 include CIO fixed effects and omit the CIO-level controls; Column 6 restricts the sample to CIOs whose tenure at departure is at least four years, so that each half of tenure contains at least two fiscal years. The standard errors are double clustered by plan and year. Coefficients marked with ***, **, and * are significant at the 1%, 5%, and 10% level, respectively.
A4: Panel A. Peer-Adjusted Returns
B5: (1) | C5: (2) | D5: (3) | E5: (4) | F5: (5) | G5: (6)
B6: Peer-adj. Ret. (t) | C6: Peer-adj. Ret. (t) | D6: Peer-adj. Ret. (t) | E6: Peer-adj. Ret. (t) | F6: Peer-adj. Ret. (t) | G6: Peer-adj. Ret. (t)
A7: Second Half of Tenure (0/1) | B7: =TEXT(Estimates!B4,"0.000")&IF(Estimates!E4="","",IF(Estimates!E4<0.01,"***",IF(Estimates!E4<0.05,"**",IF(Estimates!E4<0.1,"*","")))) -> -0.229 | C7: =TEXT(Estimates!F4,"0.000")&IF(Estimates!I4="","",IF(Estimates!I4<0.01,"***",IF(Estimates!I4<0.05,"**",IF(Estimates!I4<0.1,"*","")))) -> -0.144 | D7: =TEXT(Estimates!J4,"0.000")&IF(Estimates!M4="","",IF(Estimates!M4<0.01,"***",IF(Estimates!M4<0.05,"**",IF(Estimates!M4<0.1,"*","")))) -> 0.044 | E7: =TEXT(Estimates!N4,"0.000")&IF(Estimates!Q4="","",IF(Estimates!Q4<0.01,"***",IF(Estimates!Q4<0.05,"**",IF(Estimates!Q4<0.1,"*","")))) -> -0.083 | F7: =TEXT(Estimates!R4,"0.000")&IF(Estimates!U4="","",IF(Estimates!U4<0.01,"***",IF(Estimates!U4<0.05,"**",IF(Estimates!U4<0.1,"*","")))) -> -0.969* | G7: =TEXT(Estimates!V4,"0.000")&IF(Estimates!Y4="","",IF(Estimates!Y4<0.01,"***",IF(Estimates!Y4<0.05,"**",IF(Estimates!Y4<0.1,"*","")))) -> -0.309
B8: =IF(Estimates!D4="","(n/a)","("&TEXT(Estimates!D4,"0.00")&")") -> (-1.25) | C8: =IF(Estimates!H4="","(n/a)","("&TEXT(Estimates!H4,"0.00")&")") -> (-0.68) | D8: =IF(Estimates!L4="","(n/a)","("&TEXT(Estimates!L4,"0.00")&")") -> (0.17) | E8: =IF(Estimates!P4="","(n/a)","("&TEXT(Estimates!P4,"0.00")&")") -> (-0.27) | F8: =IF(Estimates!T4="","(n/a)","("&TEXT(Estimates!T4,"0.00")&")") -> (-1.93) | G8: =IF(Estimates!X4="","(n/a)","("&TEXT(Estimates!X4,"0.00")&")") -> (-0.33)
A9: Investment Return (t - 1) | B9: =TEXT(Estimates!B5,"0.000")&IF(Estimates!E5="","",IF(Estimates!E5<0.01,"***",IF(Estimates!E5<0.05,"**",IF(Estimates!E5<0.1,"*","")))) -> 0.061 | C9: =TEXT(Estimates!F5,"0.000")&IF(Estimates!I5="","",IF(Estimates!I5<0.01,"***",IF(Estimates!I5<0.05,"**",IF(Estimates!I5<0.1,"*","")))) -> 0.032 | D9: =TEXT(Estimates!J5,"0.000")&IF(Estimates!M5="","",IF(Estimates!M5<0.01,"***",IF(Estimates!M5<0.05,"**",IF(Estimates!M5<0.1,"*","")))) -> -0.003 | E9: =TEXT(Estimates!N5,"0.000")&IF(Estimates!Q5="","",IF(Estimates!Q5<0.01,"***",IF(Estimates!Q5<0.05,"**",IF(Estimates!Q5<0.1,"*","")))) -> 0.015 | F9: =TEXT(Estimates!R5,"0.000")&IF(Estimates!U5="","",IF(Estimates!U5<0.01,"***",IF(Estimates!U5<0.05,"**",IF(Estimates!U5<0.1,"*","")))) -> -0.002 | G9: =TEXT(Estimates!V5,"0.000")&IF(Estimates!Y5="","",IF(Estimates!Y5<0.01,"***",IF(Estimates!Y5<0.05,"**",IF(Estimates!Y5<0.1,"*","")))) -> 0.030
B10: =IF(Estimates!D5="","(n/a)","("&TEXT(Estimates!D5,"0.00")&")") -> (0.88) | C10: =IF(Estimates!H5="","(n/a)","("&TEXT(Estimates!H5,"0.00")&")") -> (0.58) | D10: =IF(Estimates!L5="","(n/a)","("&TEXT(Estimates!L5,"0.00")&")") -> (-0.15) | E10: =IF(Estimates!P5="","(n/a)","("&TEXT(Estimates!P5,"0.00")&")") -> (0.41) | F10: =IF(Estimates!T5="","(n/a)","("&TEXT(Estimates!T5,"0.00")&")") -> (-0.05) | G10: =IF(Estimates!X5="","(n/a)","("&TEXT(Estimates!X5,"0.00")&")") -> (0.60)
A11: Log (Plan Size) (t-1) | B11: =TEXT(Estimates!B6,"0.000")&IF(Estimates!E6="","",IF(Estimates!E6<0.01,"***",IF(Estimates!E6<0.05,"**",IF(Estimates!E6<0.1,"*","")))) -> -0.046 | C11: =TEXT(Estimates!F6,"0.000")&IF(Estimates!I6="","",IF(Estimates!I6<0.01,"***",IF(Estimates!I6<0.05,"**",IF(Estimates!I6<0.1,"*","")))) -> -0.085 | D11: =TEXT(Estimates!J6,"0.000")&IF(Estimates!M6="","",IF(Estimates!M6<0.01,"***",IF(Estimates!M6<0.05,"**",IF(Estimates!M6<0.1,"*","")))) -> -0.405 | E11: =TEXT(Estimates!N6,"0.000")&IF(Estimates!Q6="","",IF(Estimates!Q6<0.01,"***",IF(Estimates!Q6<0.05,"**",IF(Estimates!Q6<0.1,"*","")))) -> 0.130 | F11: =TEXT(Estimates!R6,"0.000")&IF(Estimates!U6="","",IF(Estimates!U6<0.01,"***",IF(Estimates!U6<0.05,"**",IF(Estimates!U6<0.1,"*","")))) -> 1.409 | G11: =TEXT(Estimates!V6,"0.000")&IF(Estimates!Y6="","",IF(Estimates!Y6<0.01,"***",IF(Estimates!Y6<0.05,"**",IF(Estimates!Y6<0.1,"*","")))) -> 1.201
B12: =IF(Estimates!D6="","(n/a)","("&TEXT(Estimates!D6,"0.00")&")") -> (-0.42) | C12: =IF(Estimates!H6="","(n/a)","("&TEXT(Estimates!H6,"0.00")&")") -> (-0.77) | D12: =IF(Estimates!L6="","(n/a)","("&TEXT(Estimates!L6,"0.00")&")") -> (-0.43) | E12: =IF(Estimates!P6="","(n/a)","("&TEXT(Estimates!P6,"0.00")&")") -> (0.12) | F12: =IF(Estimates!T6="","(n/a)","("&TEXT(Estimates!T6,"0.00")&")") -> (0.64) | G12: =IF(Estimates!X6="","(n/a)","("&TEXT(Estimates!X6,"0.00")&")") -> (0.52)
A13: Funding Ratio (t-1) | B13: =TEXT(Estimates!B7,"0.000")&IF(Estimates!E7="","",IF(Estimates!E7<0.01,"***",IF(Estimates!E7<0.05,"**",IF(Estimates!E7<0.1,"*","")))) -> -0.019* | C13: =TEXT(Estimates!F7,"0.000")&IF(Estimates!I7="","",IF(Estimates!I7<0.01,"***",IF(Estimates!I7<0.05,"**",IF(Estimates!I7<0.1,"*","")))) -> -0.014 | D13: =TEXT(Estimates!J7,"0.000")&IF(Estimates!M7="","",IF(Estimates!M7<0.01,"***",IF(Estimates!M7<0.05,"**",IF(Estimates!M7<0.1,"*","")))) -> -0.016 | E13: =TEXT(Estimates!N7,"0.000")&IF(Estimates!Q7="","",IF(Estimates!Q7<0.01,"***",IF(Estimates!Q7<0.05,"**",IF(Estimates!Q7<0.1,"*","")))) -> -0.035 | F13: =TEXT(Estimates!R7,"0.000")&IF(Estimates!U7="","",IF(Estimates!U7<0.01,"***",IF(Estimates!U7<0.05,"**",IF(Estimates!U7<0.1,"*","")))) -> -0.093** | G13: =TEXT(Estimates!V7,"0.000")&IF(Estimates!Y7="","",IF(Estimates!Y7<0.01,"***",IF(Estimates!Y7<0.05,"**",IF(Estimates!Y7<0.1,"*","")))) -> -0.093*
B14: =IF(Estimates!D7="","(n/a)","("&TEXT(Estimates!D7,"0.00")&")") -> (-1.92) | C14: =IF(Estimates!H7="","(n/a)","("&TEXT(Estimates!H7,"0.00")&")") -> (-1.59) | D14: =IF(Estimates!L7="","(n/a)","("&TEXT(Estimates!L7,"0.00")&")") -> (-0.49) | E14: =IF(Estimates!P7="","(n/a)","("&TEXT(Estimates!P7,"0.00")&")") -> (-0.89) | F14: =IF(Estimates!T7="","(n/a)","("&TEXT(Estimates!T7,"0.00")&")") -> (-2.46) | G14: =IF(Estimates!X7="","(n/a)","("&TEXT(Estimates!X7,"0.00")&")") -> (-2.00)
A15: Equity Allocation (%) | B15: =TEXT(Estimates!B8,"0.000")&IF(Estimates!E8="","",IF(Estimates!E8<0.01,"***",IF(Estimates!E8<0.05,"**",IF(Estimates!E8<0.1,"*","")))) -> 0.076 | C15: =TEXT(Estimates!F8,"0.000")&IF(Estimates!I8="","",IF(Estimates!I8<0.01,"***",IF(Estimates!I8<0.05,"**",IF(Estimates!I8<0.1,"*","")))) -> 0.103 | D15: =TEXT(Estimates!J8,"0.000")&IF(Estimates!M8="","",IF(Estimates!M8<0.01,"***",IF(Estimates!M8<0.05,"**",IF(Estimates!M8<0.1,"*","")))) -> -0.629** | E15: =TEXT(Estimates!N8,"0.000")&IF(Estimates!Q8="","",IF(Estimates!Q8<0.01,"***",IF(Estimates!Q8<0.05,"**",IF(Estimates!Q8<0.1,"*","")))) -> -0.611 | F15: =TEXT(Estimates!R8,"0.000")&IF(Estimates!U8="","",IF(Estimates!U8<0.01,"***",IF(Estimates!U8<0.05,"**",IF(Estimates!U8<0.1,"*","")))) -> -1.558*** | G15: =TEXT(Estimates!V8,"0.000")&IF(Estimates!Y8="","",IF(Estimates!Y8<0.01,"***",IF(Estimates!Y8<0.05,"**",IF(Estimates!Y8<0.1,"*","")))) -> -2.156***
B16: =IF(Estimates!D8="","(n/a)","("&TEXT(Estimates!D8,"0.00")&")") -> (0.67) | C16: =IF(Estimates!H8="","(n/a)","("&TEXT(Estimates!H8,"0.00")&")") -> (0.89) | D16: =IF(Estimates!L8="","(n/a)","("&TEXT(Estimates!L8,"0.00")&")") -> (-2.14) | E16: =IF(Estimates!P8="","(n/a)","("&TEXT(Estimates!P8,"0.00")&")") -> (-1.63) | F16: =IF(Estimates!T8="","(n/a)","("&TEXT(Estimates!T8,"0.00")&")") -> (-3.47) | G16: =IF(Estimates!X8="","(n/a)","("&TEXT(Estimates!X8,"0.00")&")") -> (-3.71)
A17: Fixed Income Allocation (%) | B17: =TEXT(Estimates!B9,"0.000")&IF(Estimates!E9="","",IF(Estimates!E9<0.01,"***",IF(Estimates!E9<0.05,"**",IF(Estimates!E9<0.1,"*","")))) -> 0.037 | C17: =TEXT(Estimates!F9,"0.000")&IF(Estimates!I9="","",IF(Estimates!I9<0.01,"***",IF(Estimates!I9<0.05,"**",IF(Estimates!I9<0.1,"*","")))) -> 0.056 | D17: =TEXT(Estimates!J9,"0.000")&IF(Estimates!M9="","",IF(Estimates!M9<0.01,"***",IF(Estimates!M9<0.05,"**",IF(Estimates!M9<0.1,"*","")))) -> -0.658** | E17: =TEXT(Estimates!N9,"0.000")&IF(Estimates!Q9="","",IF(Estimates!Q9<0.01,"***",IF(Estimates!Q9<0.05,"**",IF(Estimates!Q9<0.1,"*","")))) -> -0.648* | F17: =TEXT(Estimates!R9,"0.000")&IF(Estimates!U9="","",IF(Estimates!U9<0.01,"***",IF(Estimates!U9<0.05,"**",IF(Estimates!U9<0.1,"*","")))) -> -1.619*** | G17: =TEXT(Estimates!V9,"0.000")&IF(Estimates!Y9="","",IF(Estimates!Y9<0.01,"***",IF(Estimates!Y9<0.05,"**",IF(Estimates!Y9<0.1,"*","")))) -> -2.255***
B18: =IF(Estimates!D9="","(n/a)","("&TEXT(Estimates!D9,"0.00")&")") -> (0.29) | C18: =IF(Estimates!H9="","(n/a)","("&TEXT(Estimates!H9,"0.00")&")") -> (0.46) | D18: =IF(Estimates!L9="","(n/a)","("&TEXT(Estimates!L9,"0.00")&")") -> (-2.15) | E18: =IF(Estimates!P9="","(n/a)","("&TEXT(Estimates!P9,"0.00")&")") -> (-1.74) | F18: =IF(Estimates!T9="","(n/a)","("&TEXT(Estimates!T9,"0.00")&")") -> (-3.54) | G18: =IF(Estimates!X9="","(n/a)","("&TEXT(Estimates!X9,"0.00")&")") -> (-3.82)
A19: Real Estate Allocation (%) | B19: =TEXT(Estimates!B10,"0.000")&IF(Estimates!E10="","",IF(Estimates!E10<0.01,"***",IF(Estimates!E10<0.05,"**",IF(Estimates!E10<0.1,"*","")))) -> 0.126 | C19: =TEXT(Estimates!F10,"0.000")&IF(Estimates!I10="","",IF(Estimates!I10<0.01,"***",IF(Estimates!I10<0.05,"**",IF(Estimates!I10<0.1,"*","")))) -> 0.154 | D19: =TEXT(Estimates!J10,"0.000")&IF(Estimates!M10="","",IF(Estimates!M10<0.01,"***",IF(Estimates!M10<0.05,"**",IF(Estimates!M10<0.1,"*","")))) -> -0.718* | E19: =TEXT(Estimates!N10,"0.000")&IF(Estimates!Q10="","",IF(Estimates!Q10<0.01,"***",IF(Estimates!Q10<0.05,"**",IF(Estimates!Q10<0.1,"*","")))) -> -0.658 | F19: =TEXT(Estimates!R10,"0.000")&IF(Estimates!U10="","",IF(Estimates!U10<0.01,"***",IF(Estimates!U10<0.05,"**",IF(Estimates!U10<0.1,"*","")))) -> -1.716** | G19: =TEXT(Estimates!V10,"0.000")&IF(Estimates!Y10="","",IF(Estimates!Y10<0.01,"***",IF(Estimates!Y10<0.05,"**",IF(Estimates!Y10<0.1,"*","")))) -> -2.645***
B20: =IF(Estimates!D10="","(n/a)","("&TEXT(Estimates!D10,"0.00")&")") -> (0.86) | C20: =IF(Estimates!H10="","(n/a)","("&TEXT(Estimates!H10,"0.00")&")") -> (1.20) | D20: =IF(Estimates!L10="","(n/a)","("&TEXT(Estimates!L10,"0.00")&")") -> (-2.06) | E20: =IF(Estimates!P10="","(n/a)","("&TEXT(Estimates!P10,"0.00")&")") -> (-1.63) | F20: =IF(Estimates!T10="","(n/a)","("&TEXT(Estimates!T10,"0.00")&")") -> (-2.56) | G20: =IF(Estimates!X10="","(n/a)","("&TEXT(Estimates!X10,"0.00")&")") -> (-3.38)
A21: Private Equity Allocation (%) | B21: =TEXT(Estimates!B11,"0.000")&IF(Estimates!E11="","",IF(Estimates!E11<0.01,"***",IF(Estimates!E11<0.05,"**",IF(Estimates!E11<0.1,"*","")))) -> 0.046 | C21: =TEXT(Estimates!F11,"0.000")&IF(Estimates!I11="","",IF(Estimates!I11<0.01,"***",IF(Estimates!I11<0.05,"**",IF(Estimates!I11<0.1,"*","")))) -> 0.097 | D21: =TEXT(Estimates!J11,"0.000")&IF(Estimates!M11="","",IF(Estimates!M11<0.01,"***",IF(Estimates!M11<0.05,"**",IF(Estimates!M11<0.1,"*","")))) -> -0.513 | E21: =TEXT(Estimates!N11,"0.000")&IF(Estimates!Q11="","",IF(Estimates!Q11<0.01,"***",IF(Estimates!Q11<0.05,"**",IF(Estimates!Q11<0.1,"*","")))) -> -0.553 | F21: =TEXT(Estimates!R11,"0.000")&IF(Estimates!U11="","",IF(Estimates!U11<0.01,"***",IF(Estimates!U11<0.05,"**",IF(Estimates!U11<0.1,"*","")))) -> -1.471*** | G21: =TEXT(Estimates!V11,"0.000")&IF(Estimates!Y11="","",IF(Estimates!Y11<0.01,"***",IF(Estimates!Y11<0.05,"**",IF(Estimates!Y11<0.1,"*","")))) -> -1.960***
B22: =IF(Estimates!D11="","(n/a)","("&TEXT(Estimates!D11,"0.00")&")") -> (0.33) | C22: =IF(Estimates!H11="","(n/a)","("&TEXT(Estimates!H11,"0.00")&")") -> (0.80) | D22: =IF(Estimates!L11="","(n/a)","("&TEXT(Estimates!L11,"0.00")&")") -> (-1.66) | E22: =IF(Estimates!P11="","(n/a)","("&TEXT(Estimates!P11,"0.00")&")") -> (-1.40) | F22: =IF(Estimates!T11="","(n/a)","("&TEXT(Estimates!T11,"0.00")&")") -> (-3.48) | G22: =IF(Estimates!X11="","(n/a)","("&TEXT(Estimates!X11,"0.00")&")") -> (-3.64)
A23: Hedge Fund Allocation (%) | B23: =TEXT(Estimates!B12,"0.000")&IF(Estimates!E12="","",IF(Estimates!E12<0.01,"***",IF(Estimates!E12<0.05,"**",IF(Estimates!E12<0.1,"*","")))) -> 0.043 | C23: =TEXT(Estimates!F12,"0.000")&IF(Estimates!I12="","",IF(Estimates!I12<0.01,"***",IF(Estimates!I12<0.05,"**",IF(Estimates!I12<0.1,"*","")))) -> 0.047 | D23: =TEXT(Estimates!J12,"0.000")&IF(Estimates!M12="","",IF(Estimates!M12<0.01,"***",IF(Estimates!M12<0.05,"**",IF(Estimates!M12<0.1,"*","")))) -> -0.679** | E23: =TEXT(Estimates!N12,"0.000")&IF(Estimates!Q12="","",IF(Estimates!Q12<0.01,"***",IF(Estimates!Q12<0.05,"**",IF(Estimates!Q12<0.1,"*","")))) -> -0.648* | F23: =TEXT(Estimates!R12,"0.000")&IF(Estimates!U12="","",IF(Estimates!U12<0.01,"***",IF(Estimates!U12<0.05,"**",IF(Estimates!U12<0.1,"*","")))) -> -1.566*** | G23: =TEXT(Estimates!V12,"0.000")&IF(Estimates!Y12="","",IF(Estimates!Y12<0.01,"***",IF(Estimates!Y12<0.05,"**",IF(Estimates!Y12<0.1,"*","")))) -> -2.101***
B24: =IF(Estimates!D12="","(n/a)","("&TEXT(Estimates!D12,"0.00")&")") -> (0.38) | C24: =IF(Estimates!H12="","(n/a)","("&TEXT(Estimates!H12,"0.00")&")") -> (0.46) | D24: =IF(Estimates!L12="","(n/a)","("&TEXT(Estimates!L12,"0.00")&")") -> (-2.42) | E24: =IF(Estimates!P12="","(n/a)","("&TEXT(Estimates!P12,"0.00")&")") -> (-2.01) | F24: =IF(Estimates!T12="","(n/a)","("&TEXT(Estimates!T12,"0.00")&")") -> (-3.43) | G24: =IF(Estimates!X12="","(n/a)","("&TEXT(Estimates!X12,"0.00")&")") -> (-3.61)
A25: Misc. Alternatives Allocation (%) | B25: =TEXT(Estimates!B13,"0.000")&IF(Estimates!E13="","",IF(Estimates!E13<0.01,"***",IF(Estimates!E13<0.05,"**",IF(Estimates!E13<0.1,"*","")))) -> 0.101 | C25: =TEXT(Estimates!F13,"0.000")&IF(Estimates!I13="","",IF(Estimates!I13<0.01,"***",IF(Estimates!I13<0.05,"**",IF(Estimates!I13<0.1,"*","")))) -> 0.137 | D25: =TEXT(Estimates!J13,"0.000")&IF(Estimates!M13="","",IF(Estimates!M13<0.01,"***",IF(Estimates!M13<0.05,"**",IF(Estimates!M13<0.1,"*","")))) -> -0.252 | E25: =TEXT(Estimates!N13,"0.000")&IF(Estimates!Q13="","",IF(Estimates!Q13<0.01,"***",IF(Estimates!Q13<0.05,"**",IF(Estimates!Q13<0.1,"*","")))) -> -0.311 | F25: =TEXT(Estimates!R13,"0.000")&IF(Estimates!U13="","",IF(Estimates!U13<0.01,"***",IF(Estimates!U13<0.05,"**",IF(Estimates!U13<0.1,"*","")))) -> -1.697* | G25: =TEXT(Estimates!V13,"0.000")&IF(Estimates!Y13="","",IF(Estimates!Y13<0.01,"***",IF(Estimates!Y13<0.05,"**",IF(Estimates!Y13<0.1,"*","")))) -> -2.538**
B26: =IF(Estimates!D13="","(n/a)","("&TEXT(Estimates!D13,"0.00")&")") -> (0.77) | C26: =IF(Estimates!H13="","(n/a)","("&TEXT(Estimates!H13,"0.00")&")") -> (1.62) | D26: =IF(Estimates!L13="","(n/a)","("&TEXT(Estimates!L13,"0.00")&")") -> (-0.32) | E26: =IF(Estimates!P13="","(n/a)","("&TEXT(Estimates!P13,"0.00")&")") -> (-0.30) | F26: =IF(Estimates!T13="","(n/a)","("&TEXT(Estimates!T13,"0.00")&")") -> (-1.81) | G26: =IF(Estimates!X13="","(n/a)","("&TEXT(Estimates!X13,"0.00")&")") -> (-2.74)
A27: Commodities Allocation (%) | B27: =TEXT(Estimates!B14,"0.000")&IF(Estimates!E14="","",IF(Estimates!E14<0.01,"***",IF(Estimates!E14<0.05,"**",IF(Estimates!E14<0.1,"*","")))) -> -0.136 | C27: =TEXT(Estimates!F14,"0.000")&IF(Estimates!I14="","",IF(Estimates!I14<0.01,"***",IF(Estimates!I14<0.05,"**",IF(Estimates!I14<0.1,"*","")))) -> -0.021 | D27: =TEXT(Estimates!J14,"0.000")&IF(Estimates!M14="","",IF(Estimates!M14<0.01,"***",IF(Estimates!M14<0.05,"**",IF(Estimates!M14<0.1,"*","")))) -> -0.684** | E27: =TEXT(Estimates!N14,"0.000")&IF(Estimates!Q14="","",IF(Estimates!Q14<0.01,"***",IF(Estimates!Q14<0.05,"**",IF(Estimates!Q14<0.1,"*","")))) -> -0.702* | F27: =TEXT(Estimates!R14,"0.000")&IF(Estimates!U14="","",IF(Estimates!U14<0.01,"***",IF(Estimates!U14<0.05,"**",IF(Estimates!U14<0.1,"*","")))) -> -1.472*** | G27: =TEXT(Estimates!V14,"0.000")&IF(Estimates!Y14="","",IF(Estimates!Y14<0.01,"***",IF(Estimates!Y14<0.05,"**",IF(Estimates!Y14<0.1,"*","")))) -> -1.744***
