Workbook

Sheet Single years
A1: Shock-Period vs. Non-Shock Coefficients: Event Study With FY2008 Base
A2: The event study has an indicator for each fiscal year 2005-2017 (FY2008 omitted) and endpoint bins for FY2002-2004 and FY2018-2020. Each column is one regression of performance on Conflicted CIO and Conflicted CIO interacted with period indicators (the base period omitted), the Table VIII controls, and the fixed effects shown; standard errors are double clustered by plan and year. The average effect of conflict in a group of years is Conflicted CIO plus the average of that group's interaction coefficients, weighting each coefficient by the number of fiscal years it covers in the FY2002-2020 sample and counting the base period as zero; the differences therefore do not depend on which period is omitted. Shock-period years are FY2009-2013 (Shock Period = 1); non-shock years are FY2002-2008 and FY2014-2020. Benchmark-Adjusted Return is the plan's return minus the updated policy benchmark (reported, or inferred and graded A or B). Coefficients marked with ***, **, and * are significant at the 1%, 5%, and 10% level, respectively.
B4: Peer-Adjusted Return | D4: Benchmark-Adjusted Return
B5: Fiscal-Year-End FE | C5: Plan and Fiscal-Year-End FE | D5: Fiscal-Year-End FE | E5: Plan and Fiscal-Year-End FE
A6: Panel A. Shock-period years vs. non-shock years
A7: Average effect of conflict, shock-period years (FY2009-2013) | B7: =IF(Estimates!I4="","",TEXT(Estimates!E4,"0.000")&IF(Estimates!I4<0.01,"***",IF(Estimates!I4<0.05,"**",IF(Estimates!I4<0.1,"*","")))) -> 0.141 | C7: =IF(Estimates!I5="","",TEXT(Estimates!E5,"0.000")&IF(Estimates!I5<0.01,"***",IF(Estimates!I5<0.05,"**",IF(Estimates!I5<0.1,"*","")))) -> -0.203 | D7: =IF(Estimates!I6="","",TEXT(Estimates!E6,"0.000")&IF(Estimates!I6<0.01,"***",IF(Estimates!I6<0.05,"**",IF(Estimates!I6<0.1,"*","")))) -> -0.004 | E7: =IF(Estimates!I7="","",TEXT(Estimates!E7,"0.000")&IF(Estimates!I7<0.01,"***",IF(Estimates!I7<0.05,"**",IF(Estimates!I7<0.1,"*","")))) -> 0.035
B8: =IF(Estimates!H4="","","("&TEXT(Estimates!H4,"0.00")&")") -> (1.05) | C8: =IF(Estimates!H5="","","("&TEXT(Estimates!H5,"0.00")&")") -> (-0.63) | D8: =IF(Estimates!H6="","","("&TEXT(Estimates!H6,"0.00")&")") -> (-0.04) | E8: =IF(Estimates!H7="","","("&TEXT(Estimates!H7,"0.00")&")") -> (0.23)
A9: Average effect of conflict, non-shock years | B9: =IF(Estimates!I8="","",TEXT(Estimates!E8,"0.000")&IF(Estimates!I8<0.01,"***",IF(Estimates!I8<0.05,"**",IF(Estimates!I8<0.1,"*","")))) -> -0.469** | C9: =IF(Estimates!I9="","",TEXT(Estimates!E9,"0.000")&IF(Estimates!I9<0.01,"***",IF(Estimates!I9<0.05,"**",IF(Estimates!I9<0.1,"*","")))) -> -0.694* | D9: =IF(Estimates!I10="","",TEXT(Estimates!E10,"0.000")&IF(Estimates!I10<0.01,"***",IF(Estimates!I10<0.05,"**",IF(Estimates!I10<0.1,"*","")))) -> -0.458** | E9: =IF(Estimates!I11="","",TEXT(Estimates!E11,"0.000")&IF(Estimates!I11<0.01,"***",IF(Estimates!I11<0.05,"**",IF(Estimates!I11<0.1,"*","")))) -> -0.274
B10: =IF(Estimates!H8="","","("&TEXT(Estimates!H8,"0.00")&")") -> (-2.24) | C10: =IF(Estimates!H9="","","("&TEXT(Estimates!H9,"0.00")&")") -> (-1.83) | D10: =IF(Estimates!H10="","","("&TEXT(Estimates!H10,"0.00")&")") -> (-2.46) | E10: =IF(Estimates!H11="","","("&TEXT(Estimates!H11,"0.00")&")") -> (-1.10)
A11: Difference: shock-period minus non-shock years | B11: =IF(Estimates!I12="","",TEXT(Estimates!E12,"0.000")&IF(Estimates!I12<0.01,"***",IF(Estimates!I12<0.05,"**",IF(Estimates!I12<0.1,"*","")))) -> 0.609*** | C11: =IF(Estimates!I13="","",TEXT(Estimates!E13,"0.000")&IF(Estimates!I13<0.01,"***",IF(Estimates!I13<0.05,"**",IF(Estimates!I13<0.1,"*","")))) -> 0.491* | D11: =IF(Estimates!I14="","",TEXT(Estimates!E14,"0.000")&IF(Estimates!I14<0.01,"***",IF(Estimates!I14<0.05,"**",IF(Estimates!I14<0.1,"*","")))) -> 0.454** | E11: =IF(Estimates!I15="","",TEXT(Estimates!E15,"0.000")&IF(Estimates!I15<0.01,"***",IF(Estimates!I15<0.05,"**",IF(Estimates!I15<0.1,"*","")))) -> 0.309
B12: =IF(Estimates!H12="","","("&TEXT(Estimates!H12,"0.00")&")") -> (3.39) | C12: =IF(Estimates!H13="","","("&TEXT(Estimates!H13,"0.00")&")") -> (1.77) | D12: =IF(Estimates!H14="","","("&TEXT(Estimates!H14,"0.00")&")") -> (2.48) | E12: =IF(Estimates!H15="","","("&TEXT(Estimates!H15,"0.00")&")") -> (1.40)
A13: p-value of the difference | B13: =Estimates!I12 -> 0.003273578 | C13: =Estimates!I13 -> 0.093922664 | D13: =Estimates!I14 -> 0.02330526 | E13: =Estimates!I15 -> 0.17919928
A15: Panel B. Non-shock years split into pre-shock and post-shock
A16: Average effect of conflict, pre-shock years (FY2002-2008) | B16: =IF(Estimates!I16="","",TEXT(Estimates!E16,"0.000")&IF(Estimates!I16<0.01,"***",IF(Estimates!I16<0.05,"**",IF(Estimates!I16<0.1,"*","")))) -> -1.050*** | C16: =IF(Estimates!I17="","",TEXT(Estimates!E17,"0.000")&IF(Estimates!I17<0.01,"***",IF(Estimates!I17<0.05,"**",IF(Estimates!I17<0.1,"*","")))) -> -1.217*** | D16: =IF(Estimates!I18="","",TEXT(Estimates!E18,"0.000")&IF(Estimates!I18<0.01,"***",IF(Estimates!I18<0.05,"**",IF(Estimates!I18<0.1,"*","")))) -> -0.806*** | E16: =IF(Estimates!I19="","",TEXT(Estimates!E19,"0.000")&IF(Estimates!I19<0.01,"***",IF(Estimates!I19<0.05,"**",IF(Estimates!I19<0.1,"*","")))) -> -0.774***
B17: =IF(Estimates!H16="","","("&TEXT(Estimates!H16,"0.00")&")") -> (-3.54) | C17: =IF(Estimates!H17="","","("&TEXT(Estimates!H17,"0.00")&")") -> (-3.17) | D17: =IF(Estimates!H18="","","("&TEXT(Estimates!H18,"0.00")&")") -> (-3.97) | E17: =IF(Estimates!H19="","","("&TEXT(Estimates!H19,"0.00")&")") -> (-3.27)
A18: Average effect of conflict, post-shock years (FY2014-2020) | B18: =IF(Estimates!I20="","",TEXT(Estimates!E20,"0.000")&IF(Estimates!I20<0.01,"***",IF(Estimates!I20<0.05,"**",IF(Estimates!I20<0.1,"*","")))) -> 0.113 | C18: =IF(Estimates!I21="","",TEXT(Estimates!E21,"0.000")&IF(Estimates!I21<0.01,"***",IF(Estimates!I21<0.05,"**",IF(Estimates!I21<0.1,"*","")))) -> -0.172 | D18: =IF(Estimates!I22="","",TEXT(Estimates!E22,"0.000")&IF(Estimates!I22<0.01,"***",IF(Estimates!I22<0.05,"**",IF(Estimates!I22<0.1,"*","")))) -> -0.111 | E18: =IF(Estimates!I23="","",TEXT(Estimates!E23,"0.000")&IF(Estimates!I23<0.01,"***",IF(Estimates!I23<0.05,"**",IF(Estimates!I23<0.1,"*","")))) -> 0.225
B19: =IF(Estimates!H20="","","("&TEXT(Estimates!H20,"0.00")&")") -> (0.69) | C19: =IF(Estimates!H21="","","("&TEXT(Estimates!H21,"0.00")&")") -> (-0.38) | D19: =IF(Estimates!H22="","","("&TEXT(Estimates!H22,"0.00")&")") -> (-0.41) | E19: =IF(Estimates!H23="","","("&TEXT(Estimates!H23,"0.00")&")") -> (0.55)
A20: Difference: shock-period minus pre-shock years | B20: =IF(Estimates!I24="","",TEXT(Estimates!E24,"0.000")&IF(Estimates!I24<0.01,"***",IF(Estimates!I24<0.05,"**",IF(Estimates!I24<0.1,"*","")))) -> 1.191*** | C20: =IF(Estimates!I25="","",TEXT(Estimates!E25,"0.000")&IF(Estimates!I25<0.01,"***",IF(Estimates!I25<0.05,"**",IF(Estimates!I25<0.1,"*","")))) -> 1.013*** | D20: =IF(Estimates!I26="","",TEXT(Estimates!E26,"0.000")&IF(Estimates!I26<0.01,"***",IF(Estimates!I26<0.05,"**",IF(Estimates!I26<0.1,"*","")))) -> 0.802*** | E20: =IF(Estimates!I27="","",TEXT(Estimates!E27,"0.000")&IF(Estimates!I27<0.01,"***",IF(Estimates!I27<0.05,"**",IF(Estimates!I27<0.1,"*","")))) -> 0.809***
B21: =IF(Estimates!H24="","","("&TEXT(Estimates!H24,"0.00")&")") -> (4.59) | C21: =IF(Estimates!H25="","","("&TEXT(Estimates!H25,"0.00")&")") -> (3.11) | D21: =IF(Estimates!H26="","","("&TEXT(Estimates!H26,"0.00")&")") -> (3.95) | E21: =IF(Estimates!H27="","","("&TEXT(Estimates!H27,"0.00")&")") -> (3.06)
A22: p-value of the difference | B22: =Estimates!I24 -> 0.00022867887 | C22: =Estimates!I25 -> 0.0060550243 | D22: =Estimates!I26 -> 0.00093932114 | E22: =Estimates!I27 -> 0.006792604
A23: Difference: shock-period minus post-shock years | B23: =IF(Estimates!I28="","",TEXT(Estimates!E28,"0.000")&IF(Estimates!I28<0.01,"***",IF(Estimates!I28<0.05,"**",IF(Estimates!I28<0.1,"*","")))) -> 0.028 | C23: =IF(Estimates!I29="","",TEXT(Estimates!E29,"0.000")&IF(Estimates!I29<0.01,"***",IF(Estimates!I29<0.05,"**",IF(Estimates!I29<0.1,"*","")))) -> -0.031 | D23: =IF(Estimates!I30="","",TEXT(Estimates!E30,"0.000")&IF(Estimates!I30<0.01,"***",IF(Estimates!I30<0.05,"**",IF(Estimates!I30<0.1,"*","")))) -> 0.107 | E23: =IF(Estimates!I31="","",TEXT(Estimates!E31,"0.000")&IF(Estimates!I31<0.01,"***",IF(Estimates!I31<0.05,"**",IF(Estimates!I31<0.1,"*","")))) -> -0.190
B24: =IF(Estimates!H28="","","("&TEXT(Estimates!H28,"0.00")&")") -> (0.18) | C24: =IF(Estimates!H29="","","("&TEXT(Estimates!H29,"0.00")&")") -> (-0.10) | D24: =IF(Estimates!H30="","","("&TEXT(Estimates!H30,"0.00")&")") -> (0.41) | E24: =IF(Estimates!H31="","","("&TEXT(Estimates!H31,"0.00")&")") -> (-0.54)
A25: p-value of the difference | B25: =Estimates!I28 -> 0.86171263 | C25: =Estimates!I29 -> 0.925046 | D25: =Estimates!I30 -> 0.68962702 | E25: =Estimates!I31 -> 0.59604349
A27: Panel C. Event-study coefficients
A28: Conflicted CIO (effect in the base period) | B28: =IF(Estimates!I32="","",TEXT(Estimates!E32,"0.000")&IF(Estimates!I32<0.01,"***",IF(Estimates!I32<0.05,"**",IF(Estimates!I32<0.1,"*","")))) -> -0.236 | C28: =IF(Estimates!I33="","",TEXT(Estimates!E33,"0.000")&IF(Estimates!I33<0.01,"***",IF(Estimates!I33<0.05,"**",IF(Estimates!I33<0.1,"*","")))) -> -0.807 | D28: =IF(Estimates!I34="","",TEXT(Estimates!E34,"0.000")&IF(Estimates!I34<0.01,"***",IF(Estimates!I34<0.05,"**",IF(Estimates!I34<0.1,"*","")))) -> -0.506** | E28: =IF(Estimates!I35="","",TEXT(Estimates!E35,"0.000")&IF(Estimates!I35<0.01,"***",IF(Estimates!I35<0.05,"**",IF(Estimates!I35<0.1,"*","")))) -> -0.509
B29: =IF(Estimates!H32="","","("&TEXT(Estimates!H32,"0.00")&")") -> (-0.61) | C29: =IF(Estimates!H33="","","("&TEXT(Estimates!H33,"0.00")&")") -> (-1.48) | D29: =IF(Estimates!H34="","","("&TEXT(Estimates!H34,"0.00")&")") -> (-2.34) | E29: =IF(Estimates!H35="","","("&TEXT(Estimates!H35,"0.00")&")") -> (-1.47)
A30: Conflicted CIO x FY2002-2004 | B30: =IF(Estimates!I36="","",TEXT(Estimates!E36,"0.000")&IF(Estimates!I36<0.01,"***",IF(Estimates!I36<0.05,"**",IF(Estimates!I36<0.1,"*","")))) -> -0.638** | C30: =IF(Estimates!I37="","",TEXT(Estimates!E37,"0.000")&IF(Estimates!I37<0.01,"***",IF(Estimates!I37<0.05,"**",IF(Estimates!I37<0.1,"*","")))) -> 0.019 | D30: =IF(Estimates!I38="","",TEXT(Estimates!E38,"0.000")&IF(Estimates!I38<0.01,"***",IF(Estimates!I38<0.05,"**",IF(Estimates!I38<0.1,"*","")))) -> -0.215 | E30: =IF(Estimates!I39="","",TEXT(Estimates!E39,"0.000")&IF(Estimates!I39<0.01,"***",IF(Estimates!I39<0.05,"**",IF(Estimates!I39<0.1,"*","")))) -> -0.169
B31: =IF(Estimates!H36="","","("&TEXT(Estimates!H36,"0.00")&")") -> (-2.55) | C31: =IF(Estimates!H37="","","("&TEXT(Estimates!H37,"0.00")&")") -> (0.04) | D31: =IF(Estimates!H38="","","("&TEXT(Estimates!H38,"0.00")&")") -> (-1.35) | E31: =IF(Estimates!H39="","","("&TEXT(Estimates!H39,"0.00")&")") -> (-0.60)
A32: Conflicted CIO x FY2005 | B32: =IF(Estimates!I40="","",TEXT(Estimates!E40,"0.000")&IF(Estimates!I40<0.01,"***",IF(Estimates!I40<0.05,"**",IF(Estimates!I40<0.1,"*","")))) -> -0.462*** | C32: =IF(Estimates!I41="","",TEXT(Estimates!E41,"0.000")&IF(Estimates!I41<0.01,"***",IF(Estimates!I41<0.05,"**",IF(Estimates!I41<0.1,"*","")))) -> -0.059 | D32: =IF(Estimates!I42="","",TEXT(Estimates!E42,"0.000")&IF(Estimates!I42<0.01,"***",IF(Estimates!I42<0.05,"**",IF(Estimates!I42<0.1,"*","")))) -> -0.171 | E32: =IF(Estimates!I43="","",TEXT(Estimates!E43,"0.000")&IF(Estimates!I43<0.01,"***",IF(Estimates!I43<0.05,"**",IF(Estimates!I43<0.1,"*","")))) -> -0.196
B33: =IF(Estimates!H40="","","("&TEXT(Estimates!H40,"0.00")&")") -> (-3.18) | C33: =IF(Estimates!H41="","","("&TEXT(Estimates!H41,"0.00")&")") -> (-0.25) | D33: =IF(Estimates!H42="","","("&TEXT(Estimates!H42,"0.00")&")") -> (-0.85) | E33: =IF(Estimates!H43="","","("&TEXT(Estimates!H43,"0.00")&")") -> (-0.79)
A34: Conflicted CIO x FY2006 | B34: =IF(Estimates!I44="","",TEXT(Estimates!E44,"0.000")&IF(Estimates!I44<0.01,"***",IF(Estimates!I44<0.05,"**",IF(Estimates!I44<0.1,"*","")))) -> -1.690*** | C34: =IF(Estimates!I45="","",TEXT(Estimates!E45,"0.000")&IF(Estimates!I45<0.01,"***",IF(Estimates!I45<0.05,"**",IF(Estimates!I45<0.1,"*","")))) -> -1.338*** | D34: =IF(Estimates!I46="","",TEXT(Estimates!E46,"0.000")&IF(Estimates!I46<0.01,"***",IF(Estimates!I46<0.05,"**",IF(Estimates!I46<0.1,"*","")))) -> -0.539** | E34: =IF(Estimates!I47="","",TEXT(Estimates!E47,"0.000")&IF(Estimates!I47<0.01,"***",IF(Estimates!I47<0.05,"**",IF(Estimates!I47<0.1,"*","")))) -> -0.430*
B35: =IF(Estimates!H44="","","("&TEXT(Estimates!H44,"0.00")&")") -> (-5.46) | C35: =IF(Estimates!H45="","","("&TEXT(Estimates!H45,"0.00")&")") -> (-3.73) | D35: =IF(Estimates!H46="","","("&TEXT(Estimates!H46,"0.00")&")") -> (-2.63) | E35: =IF(Estimates!H47="","","("&TEXT(Estimates!H47,"0.00")&")") -> (-1.87)
A36: Conflicted CIO x FY2007 | B36: =IF(Estimates!I48="","",TEXT(Estimates!E48,"0.000")&IF(Estimates!I48<0.01,"***",IF(Estimates!I48<0.05,"**",IF(Estimates!I48<0.1,"*","")))) -> -1.636*** | C36: =IF(Estimates!I49="","",TEXT(Estimates!E49,"0.000")&IF(Estimates!I49<0.01,"***",IF(Estimates!I49<0.05,"**",IF(Estimates!I49<0.1,"*","")))) -> -1.525*** | D36: =IF(Estimates!I50="","",TEXT(Estimates!E50,"0.000")&IF(Estimates!I50<0.01,"***",IF(Estimates!I50<0.05,"**",IF(Estimates!I50<0.1,"*","")))) -> -0.741*** | E36: =IF(Estimates!I51="","",TEXT(Estimates!E51,"0.000")&IF(Estimates!I51<0.01,"***",IF(Estimates!I51<0.05,"**",IF(Estimates!I51<0.1,"*","")))) -> -0.719***
B37: =IF(Estimates!H48="","","("&TEXT(Estimates!H48,"0.00")&")") -> (-4.72) | C37: =IF(Estimates!H49="","","("&TEXT(Estimates!H49,"0.00")&")") -> (-3.89) | D37: =IF(Estimates!H50="","","("&TEXT(Estimates!H50,"0.00")&")") -> (-4.92) | E37: =IF(Estimates!H51="","","("&TEXT(Estimates!H51,"0.00")&")") -> (-3.95)
A38: Conflicted CIO x FY2009 | B38: =IF(Estimates!I52="","",TEXT(Estimates!E52,"0.000")&IF(Estimates!I52<0.01,"***",IF(Estimates!I52<0.05,"**",IF(Estimates!I52<0.1,"*","")))) -> 1.637*** | C38: =IF(Estimates!I53="","",TEXT(Estimates!E53,"0.000")&IF(Estimates!I53<0.01,"***",IF(Estimates!I53<0.05,"**",IF(Estimates!I53<0.1,"*","")))) -> 1.782*** | D38: =IF(Estimates!I54="","",TEXT(Estimates!E54,"0.000")&IF(Estimates!I54<0.01,"***",IF(Estimates!I54<0.05,"**",IF(Estimates!I54<0.1,"*","")))) -> 1.249*** | E38: =IF(Estimates!I55="","",TEXT(Estimates!E55,"0.000")&IF(Estimates!I55<0.01,"***",IF(Estimates!I55<0.05,"**",IF(Estimates!I55<0.1,"*","")))) -> 1.278***
B39: =IF(Estimates!H52="","","("&TEXT(Estimates!H52,"0.00")&")") -> (4.20) | C39: =IF(Estimates!H53="","","("&TEXT(Estimates!H53,"0.00")&")") -> (4.09) | D39: =IF(Estimates!H54="","","("&TEXT(Estimates!H54,"0.00")&")") -> (4.32) | E39: =IF(Estimates!H55="","","("&TEXT(Estimates!H55,"0.00")&")") -> (4.12)
A40: Conflicted CIO x FY2010 | B40: =IF(Estimates!I56="","",TEXT(Estimates!E56,"0.000")&IF(Estimates!I56<0.01,"***",IF(Estimates!I56<0.05,"**",IF(Estimates!I56<0.1,"*","")))) -> -0.296 | C40: =IF(Estimates!I57="","",TEXT(Estimates!E57,"0.000")&IF(Estimates!I57<0.01,"***",IF(Estimates!I57<0.05,"**",IF(Estimates!I57<0.1,"*","")))) -> 0.115 | D40: =IF(Estimates!I58="","",TEXT(Estimates!E58,"0.000")&IF(Estimates!I58<0.01,"***",IF(Estimates!I58<0.05,"**",IF(Estimates!I58<0.1,"*","")))) -> 0.424 | E40: =IF(Estimates!I59="","",TEXT(Estimates!E59,"0.000")&IF(Estimates!I59<0.01,"***",IF(Estimates!I59<0.05,"**",IF(Estimates!I59<0.1,"*","")))) -> 0.455
B41: =IF(Estimates!H56="","","("&TEXT(Estimates!H56,"0.00")&")") -> (-0.54) | C41: =IF(Estimates!H57="","","("&TEXT(Estimates!H57,"0.00")&")") -> (0.20) | D41: =IF(Estimates!H58="","","("&TEXT(Estimates!H58,"0.00")&")") -> (1.14) | E41: =IF(Estimates!H59="","","("&TEXT(Estimates!H59,"0.00")&")") -> (0.96)
A42: Conflicted CIO x FY2011 | B42: =IF(Estimates!I60="","",TEXT(Estimates!E60,"0.000")&IF(Estimates!I60<0.01,"***",IF(Estimates!I60<0.05,"**",IF(Estimates!I60<0.1,"*","")))) -> 0.175 | C42: =IF(Estimates!I61="","",TEXT(Estimates!E61,"0.000")&IF(Estimates!I61<0.01,"***",IF(Estimates!I61<0.05,"**",IF(Estimates!I61<0.1,"*","")))) -> 0.295 | D42: =IF(Estimates!I62="","",TEXT(Estimates!E62,"0.000")&IF(Estimates!I62<0.01,"***",IF(Estimates!I62<0.05,"**",IF(Estimates!I62<0.1,"*","")))) -> 0.503 | E42: =IF(Estimates!I63="","",TEXT(Estimates!E63,"0.000")&IF(Estimates!I63<0.01,"***",IF(Estimates!I63<0.05,"**",IF(Estimates!I63<0.1,"*","")))) -> 0.510
B43: =IF(Estimates!H60="","","("&TEXT(Estimates!H60,"0.00")&")") -> (0.60) | C43: =IF(Estimates!H61="","","("&TEXT(Estimates!H61,"0.00")&")") -> (0.65) | D43: =IF(Estimates!H62="","","("&TEXT(Estimates!H62,"0.00")&")") -> (1.08) | E43: =IF(Estimates!H63="","","("&TEXT(Estimates!H63,"0.00")&")") -> (0.89)
...

Sheet Two-year bins
A1: Shock-Period vs. Non-Shock Coefficients: Event Study With Two-Year Bins (FY2007-08 Base)
A2: The event study uses two-year periods (FY2007-08 omitted; the shock period split into FY2009-10 and FY2011-13; FY2018-20 pooled; the 2001-02 bin contains only FY2002 in the regression sample). Each column is one regression of performance on Conflicted CIO and Conflicted CIO interacted with period indicators (the base period omitted), the Table VIII controls, and the fixed effects shown; standard errors are double clustered by plan and year. The average effect of conflict in a group of years is Conflicted CIO plus the average of that group's interaction coefficients, weighting each coefficient by the number of fiscal years it covers in the FY2002-2020 sample and counting the base period as zero; the differences therefore do not depend on which period is omitted. Shock-period years are FY2009-2013 (Shock Period = 1); non-shock years are FY2002-2008 and FY2014-2020. Benchmark-Adjusted Return is the plan's return minus the updated policy benchmark (reported, or inferred and graded A or B). Coefficients marked with ***, **, and * are significant at the 1%, 5%, and 10% level, respectively.
B4: Peer-Adjusted Return | D4: Benchmark-Adjusted Return
B5: Fiscal-Year-End FE | C5: Plan and Fiscal-Year-End FE | D5: Fiscal-Year-End FE | E5: Plan and Fiscal-Year-End FE
A6: Panel A. Shock-period years vs. non-shock years
A7: Average effect of conflict, shock-period years (FY2009-2013) | B7: =IF(Estimates!I92="","",TEXT(Estimates!E92,"0.000")&IF(Estimates!I92<0.01,"***",IF(Estimates!I92<0.05,"**",IF(Estimates!I92<0.1,"*","")))) -> 0.084 | C7: =IF(Estimates!I93="","",TEXT(Estimates!E93,"0.000")&IF(Estimates!I93<0.01,"***",IF(Estimates!I93<0.05,"**",IF(Estimates!I93<0.1,"*","")))) -> -0.240 | D7: =IF(Estimates!I94="","",TEXT(Estimates!E94,"0.000")&IF(Estimates!I94<0.01,"***",IF(Estimates!I94<0.05,"**",IF(Estimates!I94<0.1,"*","")))) -> -0.023 | E7: =IF(Estimates!I95="","",TEXT(Estimates!E95,"0.000")&IF(Estimates!I95<0.01,"***",IF(Estimates!I95<0.05,"**",IF(Estimates!I95<0.1,"*","")))) -> 0.020
B8: =IF(Estimates!H92="","","("&TEXT(Estimates!H92,"0.00")&")") -> (0.33) | C8: =IF(Estimates!H93="","","("&TEXT(Estimates!H93,"0.00")&")") -> (-0.76) | D8: =IF(Estimates!H94="","","("&TEXT(Estimates!H94,"0.00")&")") -> (-0.22) | E8: =IF(Estimates!H95="","","("&TEXT(Estimates!H95,"0.00")&")") -> (0.13)
A9: Average effect of conflict, non-shock years | B9: =IF(Estimates!I96="","",TEXT(Estimates!E96,"0.000")&IF(Estimates!I96<0.01,"***",IF(Estimates!I96<0.05,"**",IF(Estimates!I96<0.1,"*","")))) -> -0.516** | C9: =IF(Estimates!I97="","",TEXT(Estimates!E97,"0.000")&IF(Estimates!I97<0.01,"***",IF(Estimates!I97<0.05,"**",IF(Estimates!I97<0.1,"*","")))) -> -0.720** | D9: =IF(Estimates!I98="","",TEXT(Estimates!E98,"0.000")&IF(Estimates!I98<0.01,"***",IF(Estimates!I98<0.05,"**",IF(Estimates!I98<0.1,"*","")))) -> -0.473** | E9: =IF(Estimates!I99="","",TEXT(Estimates!E99,"0.000")&IF(Estimates!I99<0.01,"***",IF(Estimates!I99<0.05,"**",IF(Estimates!I99<0.1,"*","")))) -> -0.249
B10: =IF(Estimates!H96="","","("&TEXT(Estimates!H96,"0.00")&")") -> (-2.85) | C10: =IF(Estimates!H97="","","("&TEXT(Estimates!H97,"0.00")&")") -> (-2.12) | D10: =IF(Estimates!H98="","","("&TEXT(Estimates!H98,"0.00")&")") -> (-2.72) | E10: =IF(Estimates!H99="","","("&TEXT(Estimates!H99,"0.00")&")") -> (-0.99)
A11: Difference: shock-period minus non-shock years | B11: =IF(Estimates!I100="","",TEXT(Estimates!E100,"0.000")&IF(Estimates!I100<0.01,"***",IF(Estimates!I100<0.05,"**",IF(Estimates!I100<0.1,"*","")))) -> 0.601* | C11: =IF(Estimates!I101="","",TEXT(Estimates!E101,"0.000")&IF(Estimates!I101<0.01,"***",IF(Estimates!I101<0.05,"**",IF(Estimates!I101<0.1,"*","")))) -> 0.480 | D11: =IF(Estimates!I102="","",TEXT(Estimates!E102,"0.000")&IF(Estimates!I102<0.01,"***",IF(Estimates!I102<0.05,"**",IF(Estimates!I102<0.1,"*","")))) -> 0.449** | E11: =IF(Estimates!I103="","",TEXT(Estimates!E103,"0.000")&IF(Estimates!I103<0.01,"***",IF(Estimates!I103<0.05,"**",IF(Estimates!I103<0.1,"*","")))) -> 0.268
B12: =IF(Estimates!H100="","","("&TEXT(Estimates!H100,"0.00")&")") -> (1.90) | C12: =IF(Estimates!H101="","","("&TEXT(Estimates!H101,"0.00")&")") -> (1.28) | D12: =IF(Estimates!H102="","","("&TEXT(Estimates!H102,"0.00")&")") -> (2.31) | E12: =IF(Estimates!H103="","","("&TEXT(Estimates!H103,"0.00")&")") -> (1.07)
A13: p-value of the difference | B13: =Estimates!I100 -> 0.073261673 | C13: =Estimates!I101 -> 0.21606956 | D13: =Estimates!I102 -> 0.03275054 | E13: =Estimates!I103 -> 0.29690749
A15: Panel B. Non-shock years split into pre-shock and post-shock
A16: Average effect of conflict, pre-shock years (FY2002-2008) | B16: =IF(Estimates!I104="","",TEXT(Estimates!E104,"0.000")&IF(Estimates!I104<0.01,"***",IF(Estimates!I104<0.05,"**",IF(Estimates!I104<0.1,"*","")))) -> -1.091*** | C16: =IF(Estimates!I105="","",TEXT(Estimates!E105,"0.000")&IF(Estimates!I105<0.01,"***",IF(Estimates!I105<0.05,"**",IF(Estimates!I105<0.1,"*","")))) -> -1.261*** | D16: =IF(Estimates!I106="","",TEXT(Estimates!E106,"0.000")&IF(Estimates!I106<0.01,"***",IF(Estimates!I106<0.05,"**",IF(Estimates!I106<0.1,"*","")))) -> -0.841*** | E16: =IF(Estimates!I107="","",TEXT(Estimates!E107,"0.000")&IF(Estimates!I107<0.01,"***",IF(Estimates!I107<0.05,"**",IF(Estimates!I107<0.1,"*","")))) -> -0.798***
B17: =IF(Estimates!H104="","","("&TEXT(Estimates!H104,"0.00")&")") -> (-4.35) | C17: =IF(Estimates!H105="","","("&TEXT(Estimates!H105,"0.00")&")") -> (-3.60) | D17: =IF(Estimates!H106="","","("&TEXT(Estimates!H106,"0.00")&")") -> (-3.71) | E17: =IF(Estimates!H107="","","("&TEXT(Estimates!H107,"0.00")&")") -> (-2.94)
A18: Average effect of conflict, post-shock years (FY2014-2020) | B18: =IF(Estimates!I108="","",TEXT(Estimates!E108,"0.000")&IF(Estimates!I108<0.01,"***",IF(Estimates!I108<0.05,"**",IF(Estimates!I108<0.1,"*","")))) -> 0.058 | C18: =IF(Estimates!I109="","",TEXT(Estimates!E109,"0.000")&IF(Estimates!I109<0.01,"***",IF(Estimates!I109<0.05,"**",IF(Estimates!I109<0.1,"*","")))) -> -0.180 | D18: =IF(Estimates!I110="","",TEXT(Estimates!E110,"0.000")&IF(Estimates!I110<0.01,"***",IF(Estimates!I110<0.05,"**",IF(Estimates!I110<0.1,"*","")))) -> -0.104 | E18: =IF(Estimates!I111="","",TEXT(Estimates!E111,"0.000")&IF(Estimates!I111<0.01,"***",IF(Estimates!I111<0.05,"**",IF(Estimates!I111<0.1,"*","")))) -> 0.300
B19: =IF(Estimates!H108="","","("&TEXT(Estimates!H108,"0.00")&")") -> (0.32) | C19: =IF(Estimates!H109="","","("&TEXT(Estimates!H109,"0.00")&")") -> (-0.42) | D19: =IF(Estimates!H110="","","("&TEXT(Estimates!H110,"0.00")&")") -> (-0.38) | E19: =IF(Estimates!H111="","","("&TEXT(Estimates!H111,"0.00")&")") -> (0.75)
A20: Difference: shock-period minus pre-shock years | B20: =IF(Estimates!I112="","",TEXT(Estimates!E112,"0.000")&IF(Estimates!I112<0.01,"***",IF(Estimates!I112<0.05,"**",IF(Estimates!I112<0.1,"*","")))) -> 1.175*** | C20: =IF(Estimates!I113="","",TEXT(Estimates!E113,"0.000")&IF(Estimates!I113<0.01,"***",IF(Estimates!I113<0.05,"**",IF(Estimates!I113<0.1,"*","")))) -> 1.020** | D20: =IF(Estimates!I114="","",TEXT(Estimates!E114,"0.000")&IF(Estimates!I114<0.01,"***",IF(Estimates!I114<0.05,"**",IF(Estimates!I114<0.1,"*","")))) -> 0.818*** | E20: =IF(Estimates!I115="","",TEXT(Estimates!E115,"0.000")&IF(Estimates!I115<0.01,"***",IF(Estimates!I115<0.05,"**",IF(Estimates!I115<0.1,"*","")))) -> 0.818**
B21: =IF(Estimates!H112="","","("&TEXT(Estimates!H112,"0.00")&")") -> (3.22) | C21: =IF(Estimates!H113="","","("&TEXT(Estimates!H113,"0.00")&")") -> (2.52) | D21: =IF(Estimates!H114="","","("&TEXT(Estimates!H114,"0.00")&")") -> (3.09) | E21: =IF(Estimates!H115="","","("&TEXT(Estimates!H115,"0.00")&")") -> (2.59)
A22: p-value of the difference | B22: =Estimates!I112 -> 0.0047603354 | C22: =Estimates!I113 -> 0.021621484 | D22: =Estimates!I114 -> 0.0063615819 | E22: =Estimates!I115 -> 0.018430136
A23: Difference: shock-period minus post-shock years | B23: =IF(Estimates!I116="","",TEXT(Estimates!E116,"0.000")&IF(Estimates!I116<0.01,"***",IF(Estimates!I116<0.05,"**",IF(Estimates!I116<0.1,"*","")))) -> 0.027 | C23: =IF(Estimates!I117="","",TEXT(Estimates!E117,"0.000")&IF(Estimates!I117<0.01,"***",IF(Estimates!I117<0.05,"**",IF(Estimates!I117<0.1,"*","")))) -> -0.060 | D23: =IF(Estimates!I118="","",TEXT(Estimates!E118,"0.000")&IF(Estimates!I118<0.01,"***",IF(Estimates!I118<0.05,"**",IF(Estimates!I118<0.1,"*","")))) -> 0.081 | E23: =IF(Estimates!I119="","",TEXT(Estimates!E119,"0.000")&IF(Estimates!I119<0.01,"***",IF(Estimates!I119<0.05,"**",IF(Estimates!I119<0.1,"*","")))) -> -0.281
B24: =IF(Estimates!H116="","","("&TEXT(Estimates!H116,"0.00")&")") -> (0.09) | C24: =IF(Estimates!H117="","","("&TEXT(Estimates!H117,"0.00")&")") -> (-0.14) | D24: =IF(Estimates!H118="","","("&TEXT(Estimates!H118,"0.00")&")") -> (0.30) | E24: =IF(Estimates!H119="","","("&TEXT(Estimates!H119,"0.00")&")") -> (-0.77)
A25: p-value of the difference | B25: =Estimates!I116 -> 0.93292262 | C25: =Estimates!I117 -> 0.89233683 | D25: =Estimates!I118 -> 0.76437554 | E25: =Estimates!I119 -> 0.45377708
A27: Panel C. Event-study coefficients
A28: Conflicted CIO (effect in the base period) | B28: =IF(Estimates!I120="","",TEXT(Estimates!E120,"0.000")&IF(Estimates!I120<0.01,"***",IF(Estimates!I120<0.05,"**",IF(Estimates!I120<0.1,"*","")))) -> -1.159** | C28: =IF(Estimates!I121="","",TEXT(Estimates!E121,"0.000")&IF(Estimates!I121<0.01,"***",IF(Estimates!I121<0.05,"**",IF(Estimates!I121<0.1,"*","")))) -> -1.684*** | D28: =IF(Estimates!I122="","",TEXT(Estimates!E122,"0.000")&IF(Estimates!I122<0.01,"***",IF(Estimates!I122<0.05,"**",IF(Estimates!I122<0.1,"*","")))) -> -0.950** | E28: =IF(Estimates!I123="","",TEXT(Estimates!E123,"0.000")&IF(Estimates!I123<0.01,"***",IF(Estimates!I123<0.05,"**",IF(Estimates!I123<0.1,"*","")))) -> -0.954**
B29: =IF(Estimates!H120="","","("&TEXT(Estimates!H120,"0.00")&")") -> (-2.74) | C29: =IF(Estimates!H121="","","("&TEXT(Estimates!H121,"0.00")&")") -> (-3.48) | D29: =IF(Estimates!H122="","","("&TEXT(Estimates!H122,"0.00")&")") -> (-2.69) | E29: =IF(Estimates!H123="","","("&TEXT(Estimates!H123,"0.00")&")") -> (-2.51)
A30: Conflicted CIO x FY2002 (2001-02 bin) | B30: =IF(Estimates!I124="","",TEXT(Estimates!E124,"0.000")&IF(Estimates!I124<0.01,"***",IF(Estimates!I124<0.05,"**",IF(Estimates!I124<0.1,"*","")))) -> 0.651 | C30: =IF(Estimates!I125="","",TEXT(Estimates!E125,"0.000")&IF(Estimates!I125<0.01,"***",IF(Estimates!I125<0.05,"**",IF(Estimates!I125<0.1,"*","")))) -> 1.122 | D30: =IF(Estimates!I126="","",TEXT(Estimates!E126,"0.000")&IF(Estimates!I126<0.01,"***",IF(Estimates!I126<0.05,"**",IF(Estimates!I126<0.1,"*","")))) -> -0.536 | E30: =IF(Estimates!I127="","",TEXT(Estimates!E127,"0.000")&IF(Estimates!I127<0.01,"***",IF(Estimates!I127<0.05,"**",IF(Estimates!I127<0.1,"*","")))) -> -0.546
B31: =IF(Estimates!H124="","","("&TEXT(Estimates!H124,"0.00")&")") -> (1.07) | C31: =IF(Estimates!H125="","","("&TEXT(Estimates!H125,"0.00")&")") -> (1.54) | D31: =IF(Estimates!H126="","","("&TEXT(Estimates!H126,"0.00")&")") -> (-0.85) | E31: =IF(Estimates!H127="","","("&TEXT(Estimates!H127,"0.00")&")") -> (-0.79)
A32: Conflicted CIO x FY2003-04 | B32: =IF(Estimates!I128="","",TEXT(Estimates!E128,"0.000")&IF(Estimates!I128<0.01,"***",IF(Estimates!I128<0.05,"**",IF(Estimates!I128<0.1,"*","")))) -> 0.106 | C32: =IF(Estimates!I129="","",TEXT(Estimates!E129,"0.000")&IF(Estimates!I129<0.01,"***",IF(Estimates!I129<0.05,"**",IF(Estimates!I129<0.1,"*","")))) -> 0.789 | D32: =IF(Estimates!I130="","",TEXT(Estimates!E130,"0.000")&IF(Estimates!I130<0.01,"***",IF(Estimates!I130<0.05,"**",IF(Estimates!I130<0.1,"*","")))) -> 0.578 | E32: =IF(Estimates!I131="","",TEXT(Estimates!E131,"0.000")&IF(Estimates!I131<0.01,"***",IF(Estimates!I131<0.05,"**",IF(Estimates!I131<0.1,"*","")))) -> 0.682
B33: =IF(Estimates!H128="","","("&TEXT(Estimates!H128,"0.00")&")") -> (0.17) | C33: =IF(Estimates!H129="","","("&TEXT(Estimates!H129,"0.00")&")") -> (1.18) | D33: =IF(Estimates!H130="","","("&TEXT(Estimates!H130,"0.00")&")") -> (1.08) | E33: =IF(Estimates!H131="","","("&TEXT(Estimates!H131,"0.00")&")") -> (1.26)
A34: Conflicted CIO x FY2005-06 | B34: =IF(Estimates!I132="","",TEXT(Estimates!E132,"0.000")&IF(Estimates!I132<0.01,"***",IF(Estimates!I132<0.05,"**",IF(Estimates!I132<0.1,"*","")))) -> -0.194 | C34: =IF(Estimates!I133="","",TEXT(Estimates!E133,"0.000")&IF(Estimates!I133<0.01,"***",IF(Estimates!I133<0.05,"**",IF(Estimates!I133<0.1,"*","")))) -> 0.131 | D34: =IF(Estimates!I134="","",TEXT(Estimates!E134,"0.000")&IF(Estimates!I134<0.01,"***",IF(Estimates!I134<0.05,"**",IF(Estimates!I134<0.1,"*","")))) -> 0.069 | E34: =IF(Estimates!I135="","",TEXT(Estimates!E135,"0.000")&IF(Estimates!I135<0.01,"***",IF(Estimates!I135<0.05,"**",IF(Estimates!I135<0.1,"*","")))) -> 0.138
B35: =IF(Estimates!H132="","","("&TEXT(Estimates!H132,"0.00")&")") -> (-0.31) | C35: =IF(Estimates!H133="","","("&TEXT(Estimates!H133,"0.00")&")") -> (0.25) | D35: =IF(Estimates!H134="","","("&TEXT(Estimates!H134,"0.00")&")") -> (0.22) | E35: =IF(Estimates!H135="","","("&TEXT(Estimates!H135,"0.00")&")") -> (0.43)
A36: Conflicted CIO x FY2009-10 | B36: =IF(Estimates!I136="","",TEXT(Estimates!E136,"0.000")&IF(Estimates!I136<0.01,"***",IF(Estimates!I136<0.05,"**",IF(Estimates!I136<0.1,"*","")))) -> 1.478 | C36: =IF(Estimates!I137="","",TEXT(Estimates!E137,"0.000")&IF(Estimates!I137<0.01,"***",IF(Estimates!I137<0.05,"**",IF(Estimates!I137<0.1,"*","")))) -> 1.728* | D36: =IF(Estimates!I138="","",TEXT(Estimates!E138,"0.000")&IF(Estimates!I138<0.01,"***",IF(Estimates!I138<0.05,"**",IF(Estimates!I138<0.1,"*","")))) -> 1.222*** | E36: =IF(Estimates!I139="","",TEXT(Estimates!E139,"0.000")&IF(Estimates!I139<0.01,"***",IF(Estimates!I139<0.05,"**",IF(Estimates!I139<0.1,"*","")))) -> 1.249**
B37: =IF(Estimates!H136="","","("&TEXT(Estimates!H136,"0.00")&")") -> (1.66) | C37: =IF(Estimates!H137="","","("&TEXT(Estimates!H137,"0.00")&")") -> (1.90) | D37: =IF(Estimates!H138="","","("&TEXT(Estimates!H138,"0.00")&")") -> (2.89) | E37: =IF(Estimates!H139="","","("&TEXT(Estimates!H139,"0.00")&")") -> (2.79)
A38: Conflicted CIO x FY2011-13 | B38: =IF(Estimates!I140="","",TEXT(Estimates!E140,"0.000")&IF(Estimates!I140<0.01,"***",IF(Estimates!I140<0.05,"**",IF(Estimates!I140<0.1,"*","")))) -> 1.086** | C38: =IF(Estimates!I141="","",TEXT(Estimates!E141,"0.000")&IF(Estimates!I141<0.01,"***",IF(Estimates!I141<0.05,"**",IF(Estimates!I141<0.1,"*","")))) -> 1.254** | D38: =IF(Estimates!I142="","",TEXT(Estimates!E142,"0.000")&IF(Estimates!I142<0.01,"***",IF(Estimates!I142<0.05,"**",IF(Estimates!I142<0.1,"*","")))) -> 0.729* | E38: =IF(Estimates!I143="","",TEXT(Estimates!E143,"0.000")&IF(Estimates!I143<0.01,"***",IF(Estimates!I143<0.05,"**",IF(Estimates!I143<0.1,"*","")))) -> 0.791
B39: =IF(Estimates!H140="","","("&TEXT(Estimates!H140,"0.00")&")") -> (2.81) | C39: =IF(Estimates!H141="","","("&TEXT(Estimates!H141,"0.00")&")") -> (2.84) | D39: =IF(Estimates!H142="","","("&TEXT(Estimates!H142,"0.00")&")") -> (2.03) | E39: =IF(Estimates!H143="","","("&TEXT(Estimates!H143,"0.00")&")") -> (1.67)
A40: Conflicted CIO x FY2014-15 | B40: =IF(Estimates!I144="","",TEXT(Estimates!E144,"0.000")&IF(Estimates!I144<0.01,"***",IF(Estimates!I144<0.05,"**",IF(Estimates!I144<0.1,"*","")))) -> 0.926** | C40: =IF(Estimates!I145="","",TEXT(Estimates!E145,"0.000")&IF(Estimates!I145<0.01,"***",IF(Estimates!I145<0.05,"**",IF(Estimates!I145<0.1,"*","")))) -> 1.234** | D40: =IF(Estimates!I146="","",TEXT(Estimates!E146,"0.000")&IF(Estimates!I146<0.01,"***",IF(Estimates!I146<0.05,"**",IF(Estimates!I146<0.1,"*","")))) -> 0.735 | E40: =IF(Estimates!I147="","",TEXT(Estimates!E147,"0.000")&IF(Estimates!I147<0.01,"***",IF(Estimates!I147<0.05,"**",IF(Estimates!I147<0.1,"*","")))) -> 1.089**
B41: =IF(Estimates!H144="","","("&TEXT(Estimates!H144,"0.00")&")") -> (2.36) | C41: =IF(Estimates!H145="","","("&TEXT(Estimates!H145,"0.00")&")") -> (2.54) | D41: =IF(Estimates!H146="","","("&TEXT(Estimates!H146,"0.00")&")") -> (1.49) | E41: =IF(Estimates!H147="","","("&TEXT(Estimates!H147,"0.00")&")") -> (2.35)
A42: Conflicted CIO x FY2016-17 | B42: =IF(Estimates!I148="","",TEXT(Estimates!E148,"0.000")&IF(Estimates!I148<0.01,"***",IF(Estimates!I148<0.05,"**",IF(Estimates!I148<0.1,"*","")))) -> 0.648 | C42: =IF(Estimates!I149="","",TEXT(Estimates!E149,"0.000")&IF(Estimates!I149<0.01,"***",IF(Estimates!I149<0.05,"**",IF(Estimates!I149<0.1,"*","")))) -> 1.059* | D42: =IF(Estimates!I150="","",TEXT(Estimates!E150,"0.000")&IF(Estimates!I150<0.01,"***",IF(Estimates!I150<0.05,"**",IF(Estimates!I150<0.1,"*","")))) -> 0.407 | E42: =IF(Estimates!I151="","",TEXT(Estimates!E151,"0.000")&IF(Estimates!I151<0.01,"***",IF(Estimates!I151<0.05,"**",IF(Estimates!I151<0.1,"*","")))) -> 1.072*
B43: =IF(Estimates!H148="","","("&TEXT(Estimates!H148,"0.00")&")") -> (1.21) | C43: =IF(Estimates!H149="","","("&TEXT(Estimates!H149,"0.00")&")") -> (1.93) | D43: =IF(Estimates!H150="","","("&TEXT(Estimates!H150,"0.00")&")") -> (1.03) | E43: =IF(Estimates!H151="","","("&TEXT(Estimates!H151,"0.00")&")") -> (1.92)
...

Sheet Estimates
A1: Estimates behind the tables. Blue = regression output (coefficient, SE, minimum cluster count). t and p are formulas; p uses the t distribution with (min clusters - 1) df. SE double clustered by plan and year, with the eigenvalue fix.
A3: Event study | B3: Dependent variable | C3: Specification | D3: Term | E3: Coefficient | F3: SE | G3: Clusters (min) | H3: t | I3: p
A4: Single years | B4: Peer-Adjusted Return | C4: Fiscal-Year-End FE | D4: Average effect of conflict, shock-period years (FY2009-2013) | E4: 0.1407427 | F4: 0.13442646 | G4: 19 | H4: =IF(F4>0,E4/F4,"") -> 1.0469865 | I4: =IF(H4="","",TDIST(ABS(H4),G4-1,2)) -> 0.30896211
A5: Single years | B5: Peer-Adjusted Return | C5: Plan and Fiscal-Year-End FE | D5: Average effect of conflict, shock-period years (FY2009-2013) | E5: -0.20321999 | F5: 0.32166347 | G5: 19 | H5: =IF(F5>0,E5/F5,"") -> -0.63177826 | I5: =IF(H5="","",TDIST(ABS(H5),G5-1,2)) -> 0.53547402
A6: Single years | B6: Benchmark-Adjusted Return | C6: Fiscal-Year-End FE | D6: Average effect of conflict, shock-period years (FY2009-2013) | E6: -0.0039837177 | F6: 0.1068606 | G6: 19 | H6: =IF(F6>0,E6/F6,"") -> -0.037279576 | I6: =IF(H6="","",TDIST(ABS(H6),G6-1,2)) -> 0.97067243
A7: Single years | B7: Benchmark-Adjusted Return | C7: Plan and Fiscal-Year-End FE | D7: Average effect of conflict, shock-period years (FY2009-2013) | E7: 0.035128928 | F7: 0.1505546 | G7: 19 | H7: =IF(F7>0,E7/F7,"") -> 0.23333015 | I7: =IF(H7="","",TDIST(ABS(H7),G7-1,2)) -> 0.81813793
A8: Single years | B8: Peer-Adjusted Return | C8: Fiscal-Year-End FE | D8: Average effect of conflict, non-shock years | E8: -0.46870897 | F8: 0.20947735 | G8: 19 | H8: =IF(F8>0,E8/F8,"") -> -2.2375162 | I8: =IF(H8="","",TDIST(ABS(H8),G8-1,2)) -> 0.038138739
A9: Single years | B9: Peer-Adjusted Return | C9: Plan and Fiscal-Year-End FE | D9: Average effect of conflict, non-shock years | E9: -0.69435202 | F9: 0.37985629 | G9: 19 | H9: =IF(F9>0,E9/F9,"") -> -1.8279334 | I9: =IF(H9="","",TDIST(ABS(H9),G9-1,2)) -> 0.084183741
A10: Single years | B10: Benchmark-Adjusted Return | C10: Fiscal-Year-End FE | D10: Average effect of conflict, non-shock years | E10: -0.45832956 | F10: 0.18622289 | G10: 19 | H10: =IF(F10>0,E10/F10,"") -> -2.461188 | I10: =IF(H10="","",TDIST(ABS(H10),G10-1,2)) -> 0.024177731
A11: Single years | B11: Benchmark-Adjusted Return | C11: Plan and Fiscal-Year-End FE | D11: Average effect of conflict, non-shock years | E11: -0.2742945 | F11: 0.25002781 | G11: 19 | H11: =IF(F11>0,E11/F11,"") -> -1.097056 | I11: =IF(H11="","",TDIST(ABS(H11),G11-1,2)) -> 0.28707708
A12: Single years | B12: Peer-Adjusted Return | C12: Fiscal-Year-End FE | D12: Difference: shock-period minus non-shock years | E12: 0.60945166 | F12: 0.17985704 | G12: 19 | H12: =IF(F12>0,E12/F12,"") -> 3.3885338 | I12: =IF(H12="","",TDIST(ABS(H12),G12-1,2)) -> 0.003273578
A13: Single years | B13: Peer-Adjusted Return | C13: Plan and Fiscal-Year-End FE | D13: Difference: shock-period minus non-shock years | E13: 0.49113203 | F13: 0.27771262 | G13: 19 | H13: =IF(F13>0,E13/F13,"") -> 1.7684901 | I13: =IF(H13="","",TDIST(ABS(H13),G13-1,2)) -> 0.093922664
A14: Single years | B14: Benchmark-Adjusted Return | C14: Fiscal-Year-End FE | D14: Difference: shock-period minus non-shock years | E14: 0.45434584 | F14: 0.18328275 | G14: 19 | H14: =IF(F14>0,E14/F14,"") -> 2.478934 | I14: =IF(H14="","",TDIST(ABS(H14),G14-1,2)) -> 0.02330526
A15: Single years | B15: Benchmark-Adjusted Return | C15: Plan and Fiscal-Year-End FE | D15: Difference: shock-period minus non-shock years | E15: 0.30942343 | F15: 0.22138401 | G15: 19 | H15: =IF(F15>0,E15/F15,"") -> 1.3976774 | I15: =IF(H15="","",TDIST(ABS(H15),G15-1,2)) -> 0.17919928
... A155: Two-year bins | B155: Benchmark-Adjusted Return | C155: Plan and Fiscal-Year-End FE | D155: Conflicted CIO x FY2018-20 | E155: 1.4871222 | F155: 0.71417193 | G155: 19 | H155: =IF(F155>0,E155/F155,"") -> 2.0823029 | I155: =IF(H155="","",TDIST(ABS(H155),G155-1,2)) -> 0.05185463
