Workbook

Sheet Table VIII
A1: Table VIII: Conflicted CIOs and the Loglisci Shock, Peer- and Benchmark-Adjusted Returns
A2: Shock Period equals 1 for plan fiscal years ending between March 2009 and March 2014. The first row reports Conflicted CIO from the same regression without the Shock Period terms (the average effect of conflict over the whole sample). The next rows add Shock Period and Conflicted CIO x Shock Period: Conflicted CIO is then the effect of conflict outside the Shock Period, and the italic row is the effect within it (Conflicted CIO + Conflicted CIO x Shock Period). The control variables are those of Table VIII (the lagged return, Size, the lagged funding ratio, lagged allocations, Financial Center, lagged log CIO age and tenure, lagged sibling plans and the political-state indicator). Benchmark-Adjusted Return is the plan's return minus the updated policy benchmark (the benchmark return reported in the plan's financial report or, where none is stated, an inferred value graded A or B). The standard errors are double clustered by plan and year. Coefficients marked with ***, **, and * are significant at the 1%, 5%, and 10% level, respectively.
B4: Peer-Adjusted Return | E4: Benchmark-Adjusted Return
B5: Year FE | C5: Plan FE | D5: Plan and Year FE | E5: Year FE | F5: Plan FE | G5: Plan and Year FE
A6: Conflicted CIO, no Shock Period terms | B6: =IF(Estimates!I4="","",TEXT(Estimates!E4,"0.000")&IF(Estimates!I4<0.01,"***",IF(Estimates!I4<0.05,"**",IF(Estimates!I4<0.1,"*","")))) -> -0.573*** | C6: =IF(Estimates!I5="","",TEXT(Estimates!E5,"0.000")&IF(Estimates!I5<0.01,"***",IF(Estimates!I5<0.05,"**",IF(Estimates!I5<0.1,"*","")))) -> -0.687** | D6: =IF(Estimates!I6="","",TEXT(Estimates!E6,"0.000")&IF(Estimates!I6<0.01,"***",IF(Estimates!I6<0.05,"**",IF(Estimates!I6<0.1,"*","")))) -> -0.707** | E6: =IF(Estimates!I7="","",TEXT(Estimates!E7,"0.000")&IF(Estimates!I7<0.01,"***",IF(Estimates!I7<0.05,"**",IF(Estimates!I7<0.1,"*","")))) -> -0.408*** | F6: =IF(Estimates!I8="","",TEXT(Estimates!E8,"0.000")&IF(Estimates!I8<0.01,"***",IF(Estimates!I8<0.05,"**",IF(Estimates!I8<0.1,"*","")))) -> -0.253** | G6: =IF(Estimates!I9="","",TEXT(Estimates!E9,"0.000")&IF(Estimates!I9<0.01,"***",IF(Estimates!I9<0.05,"**",IF(Estimates!I9<0.1,"*","")))) -> -0.297*
B7: =IF(Estimates!H4="","","("&TEXT(Estimates!H4,"0.00")&")") -> (-3.41) | C7: =IF(Estimates!H5="","","("&TEXT(Estimates!H5,"0.00")&")") -> (-2.72) | D7: =IF(Estimates!H6="","","("&TEXT(Estimates!H6,"0.00")&")") -> (-2.79) | E7: =IF(Estimates!H7="","","("&TEXT(Estimates!H7,"0.00")&")") -> (-3.56) | F7: =IF(Estimates!H8="","","("&TEXT(Estimates!H8,"0.00")&")") -> (-2.12) | G7: =IF(Estimates!H9="","","("&TEXT(Estimates!H9,"0.00")&")") -> (-2.01)
A9: Conflicted CIO (outside Shock Period) | B9: =IF(Estimates!I10="","",TEXT(Estimates!E10,"0.000")&IF(Estimates!I10<0.01,"***",IF(Estimates!I10<0.05,"**",IF(Estimates!I10<0.1,"*","")))) -> -0.913*** | C9: =IF(Estimates!I11="","",TEXT(Estimates!E11,"0.000")&IF(Estimates!I11<0.01,"***",IF(Estimates!I11<0.05,"**",IF(Estimates!I11<0.1,"*","")))) -> -0.968*** | D9: =IF(Estimates!I12="","",TEXT(Estimates!E12,"0.000")&IF(Estimates!I12<0.01,"***",IF(Estimates!I12<0.05,"**",IF(Estimates!I12<0.1,"*","")))) -> -1.010*** | E9: =IF(Estimates!I13="","",TEXT(Estimates!E13,"0.000")&IF(Estimates!I13<0.01,"***",IF(Estimates!I13<0.05,"**",IF(Estimates!I13<0.1,"*","")))) -> -0.563*** | F9: =IF(Estimates!I14="","",TEXT(Estimates!E14,"0.000")&IF(Estimates!I14<0.01,"***",IF(Estimates!I14<0.05,"**",IF(Estimates!I14<0.1,"*","")))) -> -0.363* | G9: =IF(Estimates!I15="","",TEXT(Estimates!E15,"0.000")&IF(Estimates!I15<0.01,"***",IF(Estimates!I15<0.05,"**",IF(Estimates!I15<0.1,"*","")))) -> -0.407*
B10: =IF(Estimates!H10="","","("&TEXT(Estimates!H10,"0.00")&")") -> (-4.34) | C10: =IF(Estimates!H11="","","("&TEXT(Estimates!H11,"0.00")&")") -> (-3.10) | D10: =IF(Estimates!H12="","","("&TEXT(Estimates!H12,"0.00")&")") -> (-3.14) | E10: =IF(Estimates!H13="","","("&TEXT(Estimates!H13,"0.00")&")") -> (-3.13) | F10: =IF(Estimates!H14="","","("&TEXT(Estimates!H14,"0.00")&")") -> (-1.96) | G10: =IF(Estimates!H15="","","("&TEXT(Estimates!H15,"0.00")&")") -> (-1.92)
A11: Conflicted CIO x Shock Period | B11: =IF(Estimates!I16="","",TEXT(Estimates!E16,"0.000")&IF(Estimates!I16<0.01,"***",IF(Estimates!I16<0.05,"**",IF(Estimates!I16<0.1,"*","")))) -> 1.009** | C11: =IF(Estimates!I17="","",TEXT(Estimates!E17,"0.000")&IF(Estimates!I17<0.01,"***",IF(Estimates!I17<0.05,"**",IF(Estimates!I17<0.1,"*","")))) -> 0.891* | D11: =IF(Estimates!I18="","",TEXT(Estimates!E18,"0.000")&IF(Estimates!I18<0.01,"***",IF(Estimates!I18<0.05,"**",IF(Estimates!I18<0.1,"*","")))) -> 0.908* | E11: =IF(Estimates!I19="","",TEXT(Estimates!E19,"0.000")&IF(Estimates!I19<0.01,"***",IF(Estimates!I19<0.05,"**",IF(Estimates!I19<0.1,"*","")))) -> 0.425** | F11: =IF(Estimates!I20="","",TEXT(Estimates!E20,"0.000")&IF(Estimates!I20<0.01,"***",IF(Estimates!I20<0.05,"**",IF(Estimates!I20<0.1,"*","")))) -> 0.392 | G11: =IF(Estimates!I21="","",TEXT(Estimates!E21,"0.000")&IF(Estimates!I21<0.01,"***",IF(Estimates!I21<0.05,"**",IF(Estimates!I21<0.1,"*","")))) -> 0.315
B12: =IF(Estimates!H16="","","("&TEXT(Estimates!H16,"0.00")&")") -> (2.72) | C12: =IF(Estimates!H17="","","("&TEXT(Estimates!H17,"0.00")&")") -> (2.00) | D12: =IF(Estimates!H18="","","("&TEXT(Estimates!H18,"0.00")&")") -> (2.04) | E12: =IF(Estimates!H19="","","("&TEXT(Estimates!H19,"0.00")&")") -> (2.69) | F12: =IF(Estimates!H20="","","("&TEXT(Estimates!H20,"0.00")&")") -> (1.10) | G12: =IF(Estimates!H21="","","("&TEXT(Estimates!H21,"0.00")&")") -> (1.02)
A13: Effect of conflict within Shock Period | B13: =IF(Estimates!I22="","",TEXT(Estimates!E22,"0.000")&IF(Estimates!I22<0.01,"***",IF(Estimates!I22<0.05,"**",IF(Estimates!I22<0.1,"*","")))) -> 0.096 | C13: =IF(Estimates!I23="","",TEXT(Estimates!E23,"0.000")&IF(Estimates!I23<0.01,"***",IF(Estimates!I23<0.05,"**",IF(Estimates!I23<0.1,"*","")))) -> -0.078 | D13: =IF(Estimates!I24="","",TEXT(Estimates!E24,"0.000")&IF(Estimates!I24<0.01,"***",IF(Estimates!I24<0.05,"**",IF(Estimates!I24<0.1,"*","")))) -> -0.101 | E13: =IF(Estimates!I25="","",TEXT(Estimates!E25,"0.000")&IF(Estimates!I25<0.01,"***",IF(Estimates!I25<0.05,"**",IF(Estimates!I25<0.1,"*","")))) -> -0.138*** | F13: =IF(Estimates!I26="","",TEXT(Estimates!E26,"0.000")&IF(Estimates!I26<0.01,"***",IF(Estimates!I26<0.05,"**",IF(Estimates!I26<0.1,"*","")))) -> 0.029 | G13: =IF(Estimates!I27="","",TEXT(Estimates!E27,"0.000")&IF(Estimates!I27<0.01,"***",IF(Estimates!I27<0.05,"**",IF(Estimates!I27<0.1,"*","")))) -> -0.092
B14: =IF(Estimates!H22="","","("&TEXT(Estimates!H22,"0.00")&")") -> (0.44) | C14: =IF(Estimates!H23="","","("&TEXT(Estimates!H23,"0.00")&")") -> (-0.28) | D14: =IF(Estimates!H24="","","("&TEXT(Estimates!H24,"0.00")&")") -> (-0.36) | E14: =IF(Estimates!H25="","","("&TEXT(Estimates!H25,"0.00")&")") -> (-3.08) | F14: =IF(Estimates!H26="","","("&TEXT(Estimates!H26,"0.00")&")") -> (0.13) | G14: =IF(Estimates!H27="","","("&TEXT(Estimates!H27,"0.00")&")") -> (-0.49)
A16: Observations | B16: 1566 | C16: 1565 | D16: 1565 | E16: 1395 | F16: 1394 | G16: 1394
A17: Adjusted R-squared | B17: 0.064297918 | C17: 0.095559801 | D17: 0.089925541 | E17: 0.13673989 | F17: 0.03452514 | G17: 0.13387043

Sheet Event study FY2008
A1: Event Study Around the Loglisci Shock: FY2008 Base Year
A2: Each regression includes Conflicted CIO and Conflicted CIO interacted with indicators for every fiscal year except FY2008 (the last fiscal year before the Shock Period), with endpoint bins for years before 2005 and after 2017. Conflicted CIO is therefore the effect of conflict in FY2008 and each interaction is the change in that effect relative to FY2008. Shaded rows are the Shock Period. Tests: pre-shock leads (the pre-2005 bin and FY2005-2007) jointly zero; shock-period coefficients (FY2009-2013) jointly zero; post-period coefficients (FY2014-2017 and the post-2017 bin) jointly zero. The italic rows are the mean FY2009-2013 coefficient, the mean FY2014-2017 coefficient, and their difference (a test that the effect of conflict returns after the case is resolved). The control variables are those of Table VIII (the lagged return, Size, the lagged funding ratio, lagged allocations, Financial Center, lagged log CIO age and tenure, lagged sibling plans and the political-state indicator). Benchmark-Adjusted Return is the plan's return minus the updated policy benchmark (the benchmark return reported in the plan's financial report or, where none is stated, an inferred value graded A or B). The standard errors are double clustered by plan and year. Coefficients marked with ***, **, and * are significant at the 1%, 5%, and 10% level, respectively.
B4: Peer-Adjusted Return | E4: Benchmark-Adjusted Return
B5: Year FE | C5: Plan FE | D5: Plan and Year FE | E5: Year FE | F5: Plan FE | G5: Plan and Year FE
A6: Conflicted CIO (effect in FY2008) | B6: =IF(Estimates!I28="","",TEXT(Estimates!E28,"0.000")&IF(Estimates!I28<0.01,"***",IF(Estimates!I28<0.05,"**",IF(Estimates!I28<0.1,"*","")))) -> -0.525* | C6: =IF(Estimates!I29="","",TEXT(Estimates!E29,"0.000")&IF(Estimates!I29<0.01,"***",IF(Estimates!I29<0.05,"**",IF(Estimates!I29<0.1,"*","")))) -> -1.029** | D6: =IF(Estimates!I30="","",TEXT(Estimates!E30,"0.000")&IF(Estimates!I30<0.01,"***",IF(Estimates!I30<0.05,"**",IF(Estimates!I30<0.1,"*","")))) -> -0.932* | E6: =IF(Estimates!I31="","",TEXT(Estimates!E31,"0.000")&IF(Estimates!I31<0.01,"***",IF(Estimates!I31<0.05,"**",IF(Estimates!I31<0.1,"*","")))) -> -0.193 | F6: =IF(Estimates!I32="","",TEXT(Estimates!E32,"0.000")&IF(Estimates!I32<0.01,"***",IF(Estimates!I32<0.05,"**",IF(Estimates!I32<0.1,"*","")))) -> -0.700** | G6: =IF(Estimates!I33="","",TEXT(Estimates!E33,"0.000")&IF(Estimates!I33<0.01,"***",IF(Estimates!I33<0.05,"**",IF(Estimates!I33<0.1,"*","")))) -> -0.084
B7: =IF(Estimates!H28="","","("&TEXT(Estimates!H28,"0.00")&")") -> (-1.97) | C7: =IF(Estimates!H29="","","("&TEXT(Estimates!H29,"0.00")&")") -> (-2.66) | D7: =IF(Estimates!H30="","","("&TEXT(Estimates!H30,"0.00")&")") -> (-1.99) | E7: =IF(Estimates!H31="","","("&TEXT(Estimates!H31,"0.00")&")") -> (-1.21) | F7: =IF(Estimates!H32="","","("&TEXT(Estimates!H32,"0.00")&")") -> (-2.13) | G7: =IF(Estimates!H33="","","("&TEXT(Estimates!H33,"0.00")&")") -> (-0.28)
A9: Conflicted CIO x FY<2005 | B9: =IF(Estimates!I34="","",TEXT(Estimates!E34,"0.000")&IF(Estimates!I34<0.01,"***",IF(Estimates!I34<0.05,"**",IF(Estimates!I34<0.1,"*","")))) -> -0.319 | C9: =IF(Estimates!I35="","",TEXT(Estimates!E35,"0.000")&IF(Estimates!I35<0.01,"***",IF(Estimates!I35<0.05,"**",IF(Estimates!I35<0.1,"*","")))) -> 0.528 | D9: =IF(Estimates!I36="","",TEXT(Estimates!E36,"0.000")&IF(Estimates!I36<0.01,"***",IF(Estimates!I36<0.05,"**",IF(Estimates!I36<0.1,"*","")))) -> 0.253 | E9: =IF(Estimates!I37="","",TEXT(Estimates!E37,"0.000")&IF(Estimates!I37<0.01,"***",IF(Estimates!I37<0.05,"**",IF(Estimates!I37<0.1,"*","")))) -> -0.616*** | F9: =IF(Estimates!I38="","",TEXT(Estimates!E38,"0.000")&IF(Estimates!I38<0.01,"***",IF(Estimates!I38<0.05,"**",IF(Estimates!I38<0.1,"*","")))) -> 0.115 | G9: =IF(Estimates!I39="","",TEXT(Estimates!E39,"0.000")&IF(Estimates!I39<0.01,"***",IF(Estimates!I39<0.05,"**",IF(Estimates!I39<0.1,"*","")))) -> -0.613**
B10: =IF(Estimates!H34="","","("&TEXT(Estimates!H34,"0.00")&")") -> (-1.23) | C10: =IF(Estimates!H35="","","("&TEXT(Estimates!H35,"0.00")&")") -> (1.43) | D10: =IF(Estimates!H36="","","("&TEXT(Estimates!H36,"0.00")&")") -> (0.53) | E10: =IF(Estimates!H37="","","("&TEXT(Estimates!H37,"0.00")&")") -> (-4.37) | F10: =IF(Estimates!H38="","","("&TEXT(Estimates!H38,"0.00")&")") -> (0.35) | G10: =IF(Estimates!H39="","","("&TEXT(Estimates!H39,"0.00")&")") -> (-2.48)
A11: Conflicted CIO x FY2005 | B11: =IF(Estimates!I40="","",TEXT(Estimates!E40,"0.000")&IF(Estimates!I40<0.01,"***",IF(Estimates!I40<0.05,"**",IF(Estimates!I40<0.1,"*","")))) -> -0.184 | C11: =IF(Estimates!I41="","",TEXT(Estimates!E41,"0.000")&IF(Estimates!I41<0.01,"***",IF(Estimates!I41<0.05,"**",IF(Estimates!I41<0.1,"*","")))) -> 0.366** | D11: =IF(Estimates!I42="","",TEXT(Estimates!E42,"0.000")&IF(Estimates!I42<0.01,"***",IF(Estimates!I42<0.05,"**",IF(Estimates!I42<0.1,"*","")))) -> 0.134 | E11: =IF(Estimates!I43="","",TEXT(Estimates!E43,"0.000")&IF(Estimates!I43<0.01,"***",IF(Estimates!I43<0.05,"**",IF(Estimates!I43<0.1,"*","")))) -> -0.405** | F11: =IF(Estimates!I44="","",TEXT(Estimates!E44,"0.000")&IF(Estimates!I44<0.01,"***",IF(Estimates!I44<0.05,"**",IF(Estimates!I44<0.1,"*","")))) -> 0.618*** | G11: =IF(Estimates!I45="","",TEXT(Estimates!E45,"0.000")&IF(Estimates!I45<0.01,"***",IF(Estimates!I45<0.05,"**",IF(Estimates!I45<0.1,"*","")))) -> -0.435*
B12: =IF(Estimates!H40="","","("&TEXT(Estimates!H40,"0.00")&")") -> (-1.30) | C12: =IF(Estimates!H41="","","("&TEXT(Estimates!H41,"0.00")&")") -> (2.23) | D12: =IF(Estimates!H42="","","("&TEXT(Estimates!H42,"0.00")&")") -> (0.70) | E12: =IF(Estimates!H43="","","("&TEXT(Estimates!H43,"0.00")&")") -> (-2.31) | F12: =IF(Estimates!H44="","","("&TEXT(Estimates!H44,"0.00")&")") -> (2.88) | G12: =IF(Estimates!H45="","","("&TEXT(Estimates!H45,"0.00")&")") -> (-2.07)
A13: Conflicted CIO x FY2006 | B13: =IF(Estimates!I46="","",TEXT(Estimates!E46,"0.000")&IF(Estimates!I46<0.01,"***",IF(Estimates!I46<0.05,"**",IF(Estimates!I46<0.1,"*","")))) -> -1.320*** | C13: =IF(Estimates!I47="","",TEXT(Estimates!E47,"0.000")&IF(Estimates!I47<0.01,"***",IF(Estimates!I47<0.05,"**",IF(Estimates!I47<0.1,"*","")))) -> -0.362 | D13: =IF(Estimates!I48="","",TEXT(Estimates!E48,"0.000")&IF(Estimates!I48<0.01,"***",IF(Estimates!I48<0.05,"**",IF(Estimates!I48<0.1,"*","")))) -> -1.058*** | E13: =IF(Estimates!I49="","",TEXT(Estimates!E49,"0.000")&IF(Estimates!I49<0.01,"***",IF(Estimates!I49<0.05,"**",IF(Estimates!I49<0.1,"*","")))) -> -0.527** | F13: =IF(Estimates!I50="","",TEXT(Estimates!E50,"0.000")&IF(Estimates!I50<0.01,"***",IF(Estimates!I50<0.05,"**",IF(Estimates!I50<0.1,"*","")))) -> 0.933*** | G13: =IF(Estimates!I51="","",TEXT(Estimates!E51,"0.000")&IF(Estimates!I51<0.01,"***",IF(Estimates!I51<0.05,"**",IF(Estimates!I51<0.1,"*","")))) -> -0.440*
B14: =IF(Estimates!H46="","","("&TEXT(Estimates!H46,"0.00")&")") -> (-5.00) | C14: =IF(Estimates!H47="","","("&TEXT(Estimates!H47,"0.00")&")") -> (-1.39) | D14: =IF(Estimates!H48="","","("&TEXT(Estimates!H48,"0.00")&")") -> (-3.25) | E14: =IF(Estimates!H49="","","("&TEXT(Estimates!H49,"0.00")&")") -> (-2.64) | F14: =IF(Estimates!H50="","","("&TEXT(Estimates!H50,"0.00")&")") -> (4.43) | G14: =IF(Estimates!H51="","","("&TEXT(Estimates!H51,"0.00")&")") -> (-1.97)
A15: Conflicted CIO x FY2007 | B15: =IF(Estimates!I52="","",TEXT(Estimates!E52,"0.000")&IF(Estimates!I52<0.01,"***",IF(Estimates!I52<0.05,"**",IF(Estimates!I52<0.1,"*","")))) -> -1.541*** | C15: =IF(Estimates!I53="","",TEXT(Estimates!E53,"0.000")&IF(Estimates!I53<0.01,"***",IF(Estimates!I53<0.05,"**",IF(Estimates!I53<0.1,"*","")))) -> -0.866** | D15: =IF(Estimates!I54="","",TEXT(Estimates!E54,"0.000")&IF(Estimates!I54<0.01,"***",IF(Estimates!I54<0.05,"**",IF(Estimates!I54<0.1,"*","")))) -> -1.472*** | E15: =IF(Estimates!I55="","",TEXT(Estimates!E55,"0.000")&IF(Estimates!I55<0.01,"***",IF(Estimates!I55<0.05,"**",IF(Estimates!I55<0.1,"*","")))) -> -1.146*** | F15: =IF(Estimates!I56="","",TEXT(Estimates!E56,"0.000")&IF(Estimates!I56<0.01,"***",IF(Estimates!I56<0.05,"**",IF(Estimates!I56<0.1,"*","")))) -> -0.012 | G15: =IF(Estimates!I57="","",TEXT(Estimates!E57,"0.000")&IF(Estimates!I57<0.01,"***",IF(Estimates!I57<0.05,"**",IF(Estimates!I57<0.1,"*","")))) -> -1.150***
B16: =IF(Estimates!H52="","","("&TEXT(Estimates!H52,"0.00")&")") -> (-4.47) | C16: =IF(Estimates!H53="","","("&TEXT(Estimates!H53,"0.00")&")") -> (-2.67) | D16: =IF(Estimates!H54="","","("&TEXT(Estimates!H54,"0.00")&")") -> (-3.63) | E16: =IF(Estimates!H55="","","("&TEXT(Estimates!H55,"0.00")&")") -> (-6.29) | F16: =IF(Estimates!H56="","","("&TEXT(Estimates!H56,"0.00")&")") -> (-0.08) | G16: =IF(Estimates!H57="","","("&TEXT(Estimates!H57,"0.00")&")") -> (-5.70)
A17: Conflicted CIO x FY2009 | B17: =IF(Estimates!I58="","",TEXT(Estimates!E58,"0.000")&IF(Estimates!I58<0.01,"***",IF(Estimates!I58<0.05,"**",IF(Estimates!I58<0.1,"*","")))) -> 1.686*** | C17: =IF(Estimates!I59="","",TEXT(Estimates!E59,"0.000")&IF(Estimates!I59<0.01,"***",IF(Estimates!I59<0.05,"**",IF(Estimates!I59<0.1,"*","")))) -> 0.893** | D17: =IF(Estimates!I60="","",TEXT(Estimates!E60,"0.000")&IF(Estimates!I60<0.01,"***",IF(Estimates!I60<0.05,"**",IF(Estimates!I60<0.1,"*","")))) -> 1.784*** | E17: =IF(Estimates!I61="","",TEXT(Estimates!E61,"0.000")&IF(Estimates!I61<0.01,"***",IF(Estimates!I61<0.05,"**",IF(Estimates!I61<0.1,"*","")))) -> 0.535* | F17: =IF(Estimates!I62="","",TEXT(Estimates!E62,"0.000")&IF(Estimates!I62<0.01,"***",IF(Estimates!I62<0.05,"**",IF(Estimates!I62<0.1,"*","")))) -> -0.701 | G17: =IF(Estimates!I63="","",TEXT(Estimates!E63,"0.000")&IF(Estimates!I63<0.01,"***",IF(Estimates!I63<0.05,"**",IF(Estimates!I63<0.1,"*","")))) -> 0.555
B18: =IF(Estimates!H58="","","("&TEXT(Estimates!H58,"0.00")&")") -> (3.60) | C18: =IF(Estimates!H59="","","("&TEXT(Estimates!H59,"0.00")&")") -> (2.21) | D18: =IF(Estimates!H60="","","("&TEXT(Estimates!H60,"0.00")&")") -> (3.75) | E18: =IF(Estimates!H61="","","("&TEXT(Estimates!H61,"0.00")&")") -> (2.09) | F18: =IF(Estimates!H62="","","("&TEXT(Estimates!H62,"0.00")&")") -> (-1.69) | G18: =IF(Estimates!H63="","","("&TEXT(Estimates!H63,"0.00")&")") -> (1.69)
A19: Conflicted CIO x FY2010 | B19: =IF(Estimates!I64="","",TEXT(Estimates!E64,"0.000")&IF(Estimates!I64<0.01,"***",IF(Estimates!I64<0.05,"**",IF(Estimates!I64<0.1,"*","")))) -> 0.200 | C19: =IF(Estimates!I65="","",TEXT(Estimates!E65,"0.000")&IF(Estimates!I65<0.01,"***",IF(Estimates!I65<0.05,"**",IF(Estimates!I65<0.1,"*","")))) -> 0.427 | D19: =IF(Estimates!I66="","",TEXT(Estimates!E66,"0.000")&IF(Estimates!I66<0.01,"***",IF(Estimates!I66<0.05,"**",IF(Estimates!I66<0.1,"*","")))) -> 0.318 | E19: =IF(Estimates!I67="","",TEXT(Estimates!E67,"0.000")&IF(Estimates!I67<0.01,"***",IF(Estimates!I67<0.05,"**",IF(Estimates!I67<0.1,"*","")))) -> 0.108 | F19: =IF(Estimates!I68="","",TEXT(Estimates!E68,"0.000")&IF(Estimates!I68<0.01,"***",IF(Estimates!I68<0.05,"**",IF(Estimates!I68<0.1,"*","")))) -> 1.422** | G19: =IF(Estimates!I69="","",TEXT(Estimates!E69,"0.000")&IF(Estimates!I69<0.01,"***",IF(Estimates!I69<0.05,"**",IF(Estimates!I69<0.1,"*","")))) -> 0.004
B20: =IF(Estimates!H64="","","("&TEXT(Estimates!H64,"0.00")&")") -> (0.46) | C20: =IF(Estimates!H65="","","("&TEXT(Estimates!H65,"0.00")&")") -> (0.93) | D20: =IF(Estimates!H66="","","("&TEXT(Estimates!H66,"0.00")&")") -> (0.72) | E20: =IF(Estimates!H67="","","("&TEXT(Estimates!H67,"0.00")&")") -> (0.40) | F20: =IF(Estimates!H68="","","("&TEXT(Estimates!H68,"0.00")&")") -> (2.28) | G20: =IF(Estimates!H69="","","("&TEXT(Estimates!H69,"0.00")&")") -> (0.01)
A21: Conflicted CIO x FY2011 | B21: =IF(Estimates!I70="","",TEXT(Estimates!E70,"0.000")&IF(Estimates!I70<0.01,"***",IF(Estimates!I70<0.05,"**",IF(Estimates!I70<0.1,"*","")))) -> 0.250 | C21: =IF(Estimates!I71="","",TEXT(Estimates!E71,"0.000")&IF(Estimates!I71<0.01,"***",IF(Estimates!I71<0.05,"**",IF(Estimates!I71<0.1,"*","")))) -> -0.093 | D21: =IF(Estimates!I72="","",TEXT(Estimates!E72,"0.000")&IF(Estimates!I72<0.01,"***",IF(Estimates!I72<0.05,"**",IF(Estimates!I72<0.1,"*","")))) -> 0.242 | E21: =IF(Estimates!I73="","",TEXT(Estimates!E73,"0.000")&IF(Estimates!I73<0.01,"***",IF(Estimates!I73<0.05,"**",IF(Estimates!I73<0.1,"*","")))) -> -0.006 | F21: =IF(Estimates!I74="","",TEXT(Estimates!E74,"0.000")&IF(Estimates!I74<0.01,"***",IF(Estimates!I74<0.05,"**",IF(Estimates!I74<0.1,"*","")))) -> 0.117 | G21: =IF(Estimates!I75="","",TEXT(Estimates!E75,"0.000")&IF(Estimates!I75<0.01,"***",IF(Estimates!I75<0.05,"**",IF(Estimates!I75<0.1,"*","")))) -> -0.099
B22: =IF(Estimates!H70="","","("&TEXT(Estimates!H70,"0.00")&")") -> (1.22) | C22: =IF(Estimates!H71="","","("&TEXT(Estimates!H71,"0.00")&")") -> (-0.32) | D22: =IF(Estimates!H72="","","("&TEXT(Estimates!H72,"0.00")&")") -> (0.76) | E22: =IF(Estimates!H73="","","("&TEXT(Estimates!H73,"0.00")&")") -> (-0.02) | F22: =IF(Estimates!H74="","","("&TEXT(Estimates!H74,"0.00")&")") -> (0.35) | G22: =IF(Estimates!H75="","","("&TEXT(Estimates!H75,"0.00")&")") -> (-0.23)
A23: Conflicted CIO x FY2012 | B23: =IF(Estimates!I76="","",TEXT(Estimates!E76,"0.000")&IF(Estimates!I76<0.01,"***",IF(Estimates!I76<0.05,"**",IF(Estimates!I76<0.1,"*","")))) -> 0.274 | C23: =IF(Estimates!I77="","",TEXT(Estimates!E77,"0.000")&IF(Estimates!I77<0.01,"***",IF(Estimates!I77<0.05,"**",IF(Estimates!I77<0.1,"*","")))) -> 0.066 | D23: =IF(Estimates!I78="","",TEXT(Estimates!E78,"0.000")&IF(Estimates!I78<0.01,"***",IF(Estimates!I78<0.05,"**",IF(Estimates!I78<0.1,"*","")))) -> 0.570 | E23: =IF(Estimates!I79="","",TEXT(Estimates!E79,"0.000")&IF(Estimates!I79<0.01,"***",IF(Estimates!I79<0.05,"**",IF(Estimates!I79<0.1,"*","")))) -> -0.190 | F23: =IF(Estimates!I80="","",TEXT(Estimates!E80,"0.000")&IF(Estimates!I80<0.01,"***",IF(Estimates!I80<0.05,"**",IF(Estimates!I80<0.1,"*","")))) -> -0.213 | G23: =IF(Estimates!I81="","",TEXT(Estimates!E81,"0.000")&IF(Estimates!I81<0.01,"***",IF(Estimates!I81<0.05,"**",IF(Estimates!I81<0.1,"*","")))) -> -0.129
B24: =IF(Estimates!H76="","","("&TEXT(Estimates!H76,"0.00")&")") -> (0.93) | C24: =IF(Estimates!H77="","","("&TEXT(Estimates!H77,"0.00")&")") -> (0.26) | D24: =IF(Estimates!H78="","","("&TEXT(Estimates!H78,"0.00")&")") -> (1.61) | E24: =IF(Estimates!H79="","","("&TEXT(Estimates!H79,"0.00")&")") -> (-0.64) | F24: =IF(Estimates!H80="","","("&TEXT(Estimates!H80,"0.00")&")") -> (-0.53) | G24: =IF(Estimates!H81="","","("&TEXT(Estimates!H81,"0.00")&")") -> (-0.28)
A25: Conflicted CIO x FY2013 | B25: =IF(Estimates!I82="","",TEXT(Estimates!E82,"0.000")&IF(Estimates!I82<0.01,"***",IF(Estimates!I82<0.05,"**",IF(Estimates!I82<0.1,"*","")))) -> 0.800* | C25: =IF(Estimates!I83="","",TEXT(Estimates!E83,"0.000")&IF(Estimates!I83<0.01,"***",IF(Estimates!I83<0.05,"**",IF(Estimates!I83<0.1,"*","")))) -> 0.542 | D25: =IF(Estimates!I84="","",TEXT(Estimates!E84,"0.000")&IF(Estimates!I84<0.01,"***",IF(Estimates!I84<0.05,"**",IF(Estimates!I84<0.1,"*","")))) -> 0.920* | E25: =IF(Estimates!I85="","",TEXT(Estimates!E85,"0.000")&IF(Estimates!I85<0.01,"***",IF(Estimates!I85<0.05,"**",IF(Estimates!I85<0.1,"*","")))) -> -0.183 | F25: =IF(Estimates!I86="","",TEXT(Estimates!E86,"0.000")&IF(Estimates!I86<0.01,"***",IF(Estimates!I86<0.05,"**",IF(Estimates!I86<0.1,"*","")))) -> 0.934* | G25: =IF(Estimates!I87="","",TEXT(Estimates!E87,"0.000")&IF(Estimates!I87<0.01,"***",IF(Estimates!I87<0.05,"**",IF(Estimates!I87<0.1,"*","")))) -> -0.286
B26: =IF(Estimates!H82="","","("&TEXT(Estimates!H82,"0.00")&")") -> (2.02) | C26: =IF(Estimates!H83="","","("&TEXT(Estimates!H83,"0.00")&")") -> (1.63) | D26: =IF(Estimates!H84="","","("&TEXT(Estimates!H84,"0.00")&")") -> (1.89) | E26: =IF(Estimates!H85="","","("&TEXT(Estimates!H85,"0.00")&")") -> (-0.75) | F26: =IF(Estimates!H86="","","("&TEXT(Estimates!H86,"0.00")&")") -> (1.91) | G26: =IF(Estimates!H87="","","("&TEXT(Estimates!H87,"0.00")&")") -> (-0.62)
A27: Conflicted CIO x FY2014 | B27: =IF(Estimates!I88="","",TEXT(Estimates!E88,"0.000")&IF(Estimates!I88<0.01,"***",IF(Estimates!I88<0.05,"**",IF(Estimates!I88<0.1,"*","")))) -> 0.057 | C27: =IF(Estimates!I89="","",TEXT(Estimates!E89,"0.000")&IF(Estimates!I89<0.01,"***",IF(Estimates!I89<0.05,"**",IF(Estimates!I89<0.1,"*","")))) -> 0.496 | D27: =IF(Estimates!I90="","",TEXT(Estimates!E90,"0.000")&IF(Estimates!I90<0.01,"***",IF(Estimates!I90<0.05,"**",IF(Estimates!I90<0.1,"*","")))) -> 0.271 | E27: =IF(Estimates!I91="","",TEXT(Estimates!E91,"0.000")&IF(Estimates!I91<0.01,"***",IF(Estimates!I91<0.05,"**",IF(Estimates!I91<0.1,"*","")))) -> 0.412* | F27: =IF(Estimates!I92="","",TEXT(Estimates!E92,"0.000")&IF(Estimates!I92<0.01,"***",IF(Estimates!I92<0.05,"**",IF(Estimates!I92<0.1,"*","")))) -> 1.125*** | G27: =IF(Estimates!I93="","",TEXT(Estimates!E93,"0.000")&IF(Estimates!I93<0.01,"***",IF(Estimates!I93<0.05,"**",IF(Estimates!I93<0.1,"*","")))) -> 0.509
B28: =IF(Estimates!H88="","","("&TEXT(Estimates!H88,"0.00")&")") -> (0.30) | C28: =IF(Estimates!H89="","","("&TEXT(Estimates!H89,"0.00")&")") -> (1.66) | D28: =IF(Estimates!H90="","","("&TEXT(Estimates!H90,"0.00")&")") -> (0.67) | E28: =IF(Estimates!H91="","","("&TEXT(Estimates!H91,"0.00")&")") -> (1.85) | F28: =IF(Estimates!H92="","","("&TEXT(Estimates!H92,"0.00")&")") -> (2.97) | G28: =IF(Estimates!H93="","","("&TEXT(Estimates!H93,"0.00")&")") -> (1.33)
A29: Conflicted CIO x FY2015 | B29: =IF(Estimates!I94="","",TEXT(Estimates!E94,"0.000")&IF(Estimates!I94<0.01,"***",IF(Estimates!I94<0.05,"**",IF(Estimates!I94<0.1,"*","")))) -> 0.025 | C29: =IF(Estimates!I95="","",TEXT(Estimates!E95,"0.000")&IF(Estimates!I95<0.01,"***",IF(Estimates!I95<0.05,"**",IF(Estimates!I95<0.1,"*","")))) -> 0.580 | D29: =IF(Estimates!I96="","",TEXT(Estimates!E96,"0.000")&IF(Estimates!I96<0.01,"***",IF(Estimates!I96<0.05,"**",IF(Estimates!I96<0.1,"*","")))) -> 0.361 | E29: =IF(Estimates!I97="","",TEXT(Estimates!E97,"0.000")&IF(Estimates!I97<0.01,"***",IF(Estimates!I97<0.05,"**",IF(Estimates!I97<0.1,"*","")))) -> -0.494*** | F29: =IF(Estimates!I98="","",TEXT(Estimates!E98,"0.000")&IF(Estimates!I98<0.01,"***",IF(Estimates!I98<0.05,"**",IF(Estimates!I98<0.1,"*","")))) -> 0.498 | G29: =IF(Estimates!I99="","",TEXT(Estimates!E99,"0.000")&IF(Estimates!I99<0.01,"***",IF(Estimates!I99<0.05,"**",IF(Estimates!I99<0.1,"*","")))) -> -0.259
B30: =IF(Estimates!H94="","","("&TEXT(Estimates!H94,"0.00")&")") -> (0.08) | C30: =IF(Estimates!H95="","","("&TEXT(Estimates!H95,"0.00")&")") -> (1.57) | D30: =IF(Estimates!H96="","","("&TEXT(Estimates!H96,"0.00")&")") -> (0.72) | E30: =IF(Estimates!H97="","","("&TEXT(Estimates!H97,"0.00")&")") -> (-3.35) | F30: =IF(Estimates!H98="","","("&TEXT(Estimates!H98,"0.00")&")") -> (1.53) | G30: =IF(Estimates!H99="","","("&TEXT(Estimates!H99,"0.00")&")") -> (-1.10)
A31: Conflicted CIO x FY2016 | B31: =IF(Estimates!I100="","",TEXT(Estimates!E100,"0.000")&IF(Estimates!I100<0.01,"***",IF(Estimates!I100<0.05,"**",IF(Estimates!I100<0.1,"*","")))) -> -0.680*** | C31: =IF(Estimates!I101="","",TEXT(Estimates!E101,"0.000")&IF(Estimates!I101<0.01,"***",IF(Estimates!I101<0.05,"**",IF(Estimates!I101<0.1,"*","")))) -> 0.533 | D31: =IF(Estimates!I102="","",TEXT(Estimates!E102,"0.000")&IF(Estimates!I102<0.01,"***",IF(Estimates!I102<0.05,"**",IF(Estimates!I102<0.1,"*","")))) -> -0.124 | E31: =IF(Estimates!I103="","",TEXT(Estimates!E103,"0.000")&IF(Estimates!I103<0.01,"***",IF(Estimates!I103<0.05,"**",IF(Estimates!I103<0.1,"*","")))) -> -0.364** | F31: =IF(Estimates!I104="","",TEXT(Estimates!E104,"0.000")&IF(Estimates!I104<0.01,"***",IF(Estimates!I104<0.05,"**",IF(Estimates!I104<0.1,"*","")))) -> 0.220 | G31: =IF(Estimates!I105="","",TEXT(Estimates!E105,"0.000")&IF(Estimates!I105<0.01,"***",IF(Estimates!I105<0.05,"**",IF(Estimates!I105<0.1,"*","")))) -> 0.192
B32: =IF(Estimates!H100="","","("&TEXT(Estimates!H100,"0.00")&")") -> (-3.48) | C32: =IF(Estimates!H101="","","("&TEXT(Estimates!H101,"0.00")&")") -> (1.49) | D32: =IF(Estimates!H102="","","("&TEXT(Estimates!H102,"0.00")&")") -> (-0.27) | E32: =IF(Estimates!H103="","","("&TEXT(Estimates!H103,"0.00")&")") -> (-2.10) | F32: =IF(Estimates!H104="","","("&TEXT(Estimates!H104,"0.00")&")") -> (0.47) | G32: =IF(Estimates!H105="","","("&TEXT(Estimates!H105,"0.00")&")") -> (0.72)
A33: Conflicted CIO x FY2017 | B33: =IF(Estimates!I106="","",TEXT(Estimates!E106,"0.000")&IF(Estimates!I106<0.01,"***",IF(Estimates!I106<0.05,"**",IF(Estimates!I106<0.1,"*","")))) -> 0.659** | C33: =IF(Estimates!I107="","",TEXT(Estimates!E107,"0.000")&IF(Estimates!I107<0.01,"***",IF(Estimates!I107<0.05,"**",IF(Estimates!I107<0.1,"*","")))) -> 1.455*** | D33: =IF(Estimates!I108="","",TEXT(Estimates!E108,"0.000")&IF(Estimates!I108<0.01,"***",IF(Estimates!I108<0.05,"**",IF(Estimates!I108<0.1,"*","")))) -> 0.807* | E33: =IF(Estimates!I109="","",TEXT(Estimates!E109,"0.000")&IF(Estimates!I109<0.01,"***",IF(Estimates!I109<0.05,"**",IF(Estimates!I109<0.1,"*","")))) -> -0.289 | F33: =IF(Estimates!I110="","",TEXT(Estimates!E110,"0.000")&IF(Estimates!I110<0.01,"***",IF(Estimates!I110<0.05,"**",IF(Estimates!I110<0.1,"*","")))) -> 1.082 | G33: =IF(Estimates!I111="","",TEXT(Estimates!E111,"0.000")&IF(Estimates!I111<0.01,"***",IF(Estimates!I111<0.05,"**",IF(Estimates!I111<0.1,"*","")))) -> -0.266
B34: =IF(Estimates!H106="","","("&TEXT(Estimates!H106,"0.00")&")") -> (2.60) | C34: =IF(Estimates!H107="","","("&TEXT(Estimates!H107,"0.00")&")") -> (3.88) | D34: =IF(Estimates!H108="","","("&TEXT(Estimates!H108,"0.00")&")") -> (1.79) | E34: =IF(Estimates!H109="","","("&TEXT(Estimates!H109,"0.00")&")") -> (-1.03) | F34: =IF(Estimates!H110="","","("&TEXT(Estimates!H110,"0.00")&")") -> (1.39) | G34: =IF(Estimates!H111="","","("&TEXT(Estimates!H111,"0.00")&")") -> (-0.48)
A35: Conflicted CIO x FY>2017 | B35: =IF(Estimates!I112="","",TEXT(Estimates!E112,"0.000")&IF(Estimates!I112<0.01,"***",IF(Estimates!I112<0.05,"**",IF(Estimates!I112<0.1,"*","")))) -> 1.060** | C35: =IF(Estimates!I113="","",TEXT(Estimates!E113,"0.000")&IF(Estimates!I113<0.01,"***",IF(Estimates!I113<0.05,"**",IF(Estimates!I113<0.1,"*","")))) -> 1.803** | D35: =IF(Estimates!I114="","",TEXT(Estimates!E114,"0.000")&IF(Estimates!I114<0.01,"***",IF(Estimates!I114<0.05,"**",IF(Estimates!I114<0.1,"*","")))) -> 1.152* | E35: =IF(Estimates!I115="","",TEXT(Estimates!E115,"0.000")&IF(Estimates!I115<0.01,"***",IF(Estimates!I115<0.05,"**",IF(Estimates!I115<0.1,"*","")))) -> 0.647 | F35: =IF(Estimates!I116="","",TEXT(Estimates!E116,"0.000")&IF(Estimates!I116<0.01,"***",IF(Estimates!I116<0.05,"**",IF(Estimates!I116<0.1,"*","")))) -> 1.270* | G35: =IF(Estimates!I117="","",TEXT(Estimates!E117,"0.000")&IF(Estimates!I117<0.01,"***",IF(Estimates!I117<0.05,"**",IF(Estimates!I117<0.1,"*","")))) -> 0.535
B36: =IF(Estimates!H112="","","("&TEXT(Estimates!H112,"0.00")&")") -> (2.68) | C36: =IF(Estimates!H113="","","("&TEXT(Estimates!H113,"0.00")&")") -> (2.87) | D36: =IF(Estimates!H114="","","("&TEXT(Estimates!H114,"0.00")&")") -> (1.80) | E36: =IF(Estimates!H115="","","("&TEXT(Estimates!H115,"0.00")&")") -> (1.42) | F36: =IF(Estimates!H116="","","("&TEXT(Estimates!H116,"0.00")&")") -> (1.82) | G36: =IF(Estimates!H117="","","("&TEXT(Estimates!H117,"0.00")&")") -> (0.79)
A38: Mean FY2009-2013 coefficient | B38: =IF(Estimates!I118="","",TEXT(Estimates!E118,"0.000")&IF(Estimates!I118<0.01,"***",IF(Estimates!I118<0.05,"**",IF(Estimates!I118<0.1,"*","")))) -> 0.642** | C38: =IF(Estimates!I119="","",TEXT(Estimates!E119,"0.000")&IF(Estimates!I119<0.01,"***",IF(Estimates!I119<0.05,"**",IF(Estimates!I119<0.1,"*","")))) -> 0.367 | D38: =IF(Estimates!I120="","",TEXT(Estimates!E120,"0.000")&IF(Estimates!I120<0.01,"***",IF(Estimates!I120<0.05,"**",IF(Estimates!I120<0.1,"*","")))) -> 0.767** | E38: =IF(Estimates!I121="","",TEXT(Estimates!E121,"0.000")&IF(Estimates!I121<0.01,"***",IF(Estimates!I121<0.05,"**",IF(Estimates!I121<0.1,"*","")))) -> 0.053 | F38: =IF(Estimates!I122="","",TEXT(Estimates!E122,"0.000")&IF(Estimates!I122<0.01,"***",IF(Estimates!I122<0.05,"**",IF(Estimates!I122<0.1,"*","")))) -> 0.312 | G38: =IF(Estimates!I123="","",TEXT(Estimates!E123,"0.000")&IF(Estimates!I123<0.01,"***",IF(Estimates!I123<0.05,"**",IF(Estimates!I123<0.1,"*","")))) -> 0.009
B39: =IF(Estimates!H118="","","("&TEXT(Estimates!H118,"0.00")&")") -> (2.21) | C39: =IF(Estimates!H119="","","("&TEXT(Estimates!H119,"0.00")&")") -> (1.42) | D39: =IF(Estimates!H120="","","("&TEXT(Estimates!H120,"0.00")&")") -> (2.23) | E39: =IF(Estimates!H121="","","("&TEXT(Estimates!H121,"0.00")&")") -> (0.39) | F39: =IF(Estimates!H122="","","("&TEXT(Estimates!H122,"0.00")&")") -> (0.91) | G39: =IF(Estimates!H123="","","("&TEXT(Estimates!H123,"0.00")&")") -> (0.03)
A40: Mean FY2014-2017 coefficient | B40: =IF(Estimates!I124="","",TEXT(Estimates!E124,"0.000")&IF(Estimates!I124<0.01,"***",IF(Estimates!I124<0.05,"**",IF(Estimates!I124<0.1,"*","")))) -> 0.015 | C40: =IF(Estimates!I125="","",TEXT(Estimates!E125,"0.000")&IF(Estimates!I125<0.01,"***",IF(Estimates!I125<0.05,"**",IF(Estimates!I125<0.1,"*","")))) -> 0.766** | D40: =IF(Estimates!I126="","",TEXT(Estimates!E126,"0.000")&IF(Estimates!I126<0.01,"***",IF(Estimates!I126<0.05,"**",IF(Estimates!I126<0.1,"*","")))) -> 0.329 | E40: =IF(Estimates!I127="","",TEXT(Estimates!E127,"0.000")&IF(Estimates!I127<0.01,"***",IF(Estimates!I127<0.05,"**",IF(Estimates!I127<0.1,"*","")))) -> -0.184 | F40: =IF(Estimates!I128="","",TEXT(Estimates!E128,"0.000")&IF(Estimates!I128<0.01,"***",IF(Estimates!I128<0.05,"**",IF(Estimates!I128<0.1,"*","")))) -> 0.731 | G40: =IF(Estimates!I129="","",TEXT(Estimates!E129,"0.000")&IF(Estimates!I129<0.01,"***",IF(Estimates!I129<0.05,"**",IF(Estimates!I129<0.1,"*","")))) -> 0.044
B41: =IF(Estimates!H124="","","("&TEXT(Estimates!H124,"0.00")&")") -> (0.08) | C41: =IF(Estimates!H125="","","("&TEXT(Estimates!H125,"0.00")&")") -> (2.54) | D41: =IF(Estimates!H126="","","("&TEXT(Estimates!H126,"0.00")&")") -> (0.78) | E41: =IF(Estimates!H127="","","("&TEXT(Estimates!H127,"0.00")&")") -> (-1.37) | F41: =IF(Estimates!H128="","","("&TEXT(Estimates!H128,"0.00")&")") -> (1.59) | G41: =IF(Estimates!H129="","","("&TEXT(Estimates!H129,"0.00")&")") -> (0.14)
A42: Post-period mean minus shock-period mean | B42: =IF(Estimates!I130="","",TEXT(Estimates!E130,"0.000")&IF(Estimates!I130<0.01,"***",IF(Estimates!I130<0.05,"**",IF(Estimates!I130<0.1,"*","")))) -> -0.627*** | C42: =IF(Estimates!I131="","",TEXT(Estimates!E131,"0.000")&IF(Estimates!I131<0.01,"***",IF(Estimates!I131<0.05,"**",IF(Estimates!I131<0.1,"*","")))) -> 0.399 | D42: =IF(Estimates!I132="","",TEXT(Estimates!E132,"0.000")&IF(Estimates!I132<0.01,"***",IF(Estimates!I132<0.05,"**",IF(Estimates!I132<0.1,"*","")))) -> -0.438 | E42: =IF(Estimates!I133="","",TEXT(Estimates!E133,"0.000")&IF(Estimates!I133<0.01,"***",IF(Estimates!I133<0.05,"**",IF(Estimates!I133<0.1,"*","")))) -> -0.237* | F42: =IF(Estimates!I134="","",TEXT(Estimates!E134,"0.000")&IF(Estimates!I134<0.01,"***",IF(Estimates!I134<0.05,"**",IF(Estimates!I134<0.1,"*","")))) -> 0.419* | G42: =IF(Estimates!I135="","",TEXT(Estimates!E135,"0.000")&IF(Estimates!I135<0.01,"***",IF(Estimates!I135<0.05,"**",IF(Estimates!I135<0.1,"*","")))) -> 0.035
B43: =IF(Estimates!H130="","","("&TEXT(Estimates!H130,"0.00")&")") -> (-3.69) | C43: =IF(Estimates!H131="","","("&TEXT(Estimates!H131,"0.00")&")") -> (1.65) | D43: =IF(Estimates!H132="","","("&TEXT(Estimates!H132,"0.00")&")") -> (-1.67) | E43: =IF(Estimates!H133="","","("&TEXT(Estimates!H133,"0.00")&")") -> (-1.76) | F43: =IF(Estimates!H134="","","("&TEXT(Estimates!H134,"0.00")&")") -> (1.82) | G43: =IF(Estimates!H135="","","("&TEXT(Estimates!H135,"0.00")&")") -> (0.17)
...

Sheet Event study bins
A1: Event Study Around the Loglisci Shock: Two-Year Bins, FY2007-08 Base
A2: As in the FY2008 event study, but with Conflicted CIO interacted with two-year periods (the Shock Period split into FY2009-10 and FY2011-13, and FY2018-20 pooled); FY2007-08 is the omitted base period, so Conflicted CIO is the effect of conflict in FY2007-08. Shaded rows are the Shock Period. The control variables are those of Table VIII (the lagged return, Size, the lagged funding ratio, lagged allocations, Financial Center, lagged log CIO age and tenure, lagged sibling plans and the political-state indicator). Benchmark-Adjusted Return is the plan's return minus the updated policy benchmark (the benchmark return reported in the plan's financial report or, where none is stated, an inferred value graded A or B). The standard errors are double clustered by plan and year. Coefficients marked with ***, **, and * are significant at the 1%, 5%, and 10% level, respectively.
B4: Peer-Adjusted Return | E4: Benchmark-Adjusted Return
B5: Year FE | C5: Plan FE | D5: Plan and Year FE | E5: Year FE | F5: Plan FE | G5: Plan and Year FE
A6: Conflicted CIO (effect in FY2007-08) | B6: =IF(Estimates!I136="","",TEXT(Estimates!E136,"0.000")&IF(Estimates!I136<0.01,"***",IF(Estimates!I136<0.05,"**",IF(Estimates!I136<0.1,"*","")))) -> -1.384*** | C6: =IF(Estimates!I137="","",TEXT(Estimates!E137,"0.000")&IF(Estimates!I137<0.01,"***",IF(Estimates!I137<0.05,"**",IF(Estimates!I137<0.1,"*","")))) -> -1.513*** | D6: =IF(Estimates!I138="","",TEXT(Estimates!E138,"0.000")&IF(Estimates!I138<0.01,"***",IF(Estimates!I138<0.05,"**",IF(Estimates!I138<0.1,"*","")))) -> -1.753*** | E6: =IF(Estimates!I139="","",TEXT(Estimates!E139,"0.000")&IF(Estimates!I139<0.01,"***",IF(Estimates!I139<0.05,"**",IF(Estimates!I139<0.1,"*","")))) -> -0.867* | F6: =IF(Estimates!I140="","",TEXT(Estimates!E140,"0.000")&IF(Estimates!I140<0.01,"***",IF(Estimates!I140<0.05,"**",IF(Estimates!I140<0.1,"*","")))) -> -0.587* | G6: =IF(Estimates!I141="","",TEXT(Estimates!E141,"0.000")&IF(Estimates!I141<0.01,"***",IF(Estimates!I141<0.05,"**",IF(Estimates!I141<0.1,"*","")))) -> -0.772
B7: =IF(Estimates!H136="","","("&TEXT(Estimates!H136,"0.00")&")") -> (-3.40) | C7: =IF(Estimates!H137="","","("&TEXT(Estimates!H137,"0.00")&")") -> (-3.63) | D7: =IF(Estimates!H138="","","("&TEXT(Estimates!H138,"0.00")&")") -> (-3.45) | E7: =IF(Estimates!H139="","","("&TEXT(Estimates!H139,"0.00")&")") -> (-1.90) | F7: =IF(Estimates!H140="","","("&TEXT(Estimates!H140,"0.00")&")") -> (-2.02) | G7: =IF(Estimates!H141="","","("&TEXT(Estimates!H141,"0.00")&")") -> (-1.63)
A9: Conflicted CIO x FY2001-02 | B9: =IF(Estimates!I142="","",TEXT(Estimates!E142,"0.000")&IF(Estimates!I142<0.01,"***",IF(Estimates!I142<0.05,"**",IF(Estimates!I142<0.1,"*","")))) -> 0.949 | C9: =IF(Estimates!I143="","",TEXT(Estimates!E143,"0.000")&IF(Estimates!I143<0.01,"***",IF(Estimates!I143<0.05,"**",IF(Estimates!I143<0.1,"*","")))) -> 1.458** | D9: =IF(Estimates!I144="","",TEXT(Estimates!E144,"0.000")&IF(Estimates!I144<0.01,"***",IF(Estimates!I144<0.05,"**",IF(Estimates!I144<0.1,"*","")))) -> 1.453* | E9: =IF(Estimates!I145="","",TEXT(Estimates!E145,"0.000")&IF(Estimates!I145<0.01,"***",IF(Estimates!I145<0.05,"**",IF(Estimates!I145<0.1,"*","")))) -> -0.615 | F9: =IF(Estimates!I146="","",TEXT(Estimates!E146,"0.000")&IF(Estimates!I146<0.01,"***",IF(Estimates!I146<0.05,"**",IF(Estimates!I146<0.1,"*","")))) -> -0.188 | G9: =IF(Estimates!I147="","",TEXT(Estimates!E147,"0.000")&IF(Estimates!I147<0.01,"***",IF(Estimates!I147<0.05,"**",IF(Estimates!I147<0.1,"*","")))) -> -0.646
B10: =IF(Estimates!H142="","","("&TEXT(Estimates!H142,"0.00")&")") -> (1.50) | C10: =IF(Estimates!H143="","","("&TEXT(Estimates!H143,"0.00")&")") -> (2.14) | D10: =IF(Estimates!H144="","","("&TEXT(Estimates!H144,"0.00")&")") -> (1.92) | E10: =IF(Estimates!H145="","","("&TEXT(Estimates!H145,"0.00")&")") -> (-0.88) | F10: =IF(Estimates!H146="","","("&TEXT(Estimates!H146,"0.00")&")") -> (-0.24) | G10: =IF(Estimates!H147="","","("&TEXT(Estimates!H147,"0.00")&")") -> (-0.85)
A11: Conflicted CIO x FY2003-04 | B11: =IF(Estimates!I148="","",TEXT(Estimates!E148,"0.000")&IF(Estimates!I148<0.01,"***",IF(Estimates!I148<0.05,"**",IF(Estimates!I148<0.1,"*","")))) -> 0.351 | C11: =IF(Estimates!I149="","",TEXT(Estimates!E149,"0.000")&IF(Estimates!I149<0.01,"***",IF(Estimates!I149<0.05,"**",IF(Estimates!I149<0.1,"*","")))) -> 0.826 | D11: =IF(Estimates!I150="","",TEXT(Estimates!E150,"0.000")&IF(Estimates!I150<0.01,"***",IF(Estimates!I150<0.05,"**",IF(Estimates!I150<0.1,"*","")))) -> 0.906 | E11: =IF(Estimates!I151="","",TEXT(Estimates!E151,"0.000")&IF(Estimates!I151<0.01,"***",IF(Estimates!I151<0.05,"**",IF(Estimates!I151<0.1,"*","")))) -> 0.375 | F11: =IF(Estimates!I152="","",TEXT(Estimates!E152,"0.000")&IF(Estimates!I152<0.01,"***",IF(Estimates!I152<0.05,"**",IF(Estimates!I152<0.1,"*","")))) -> 0.083 | G11: =IF(Estimates!I153="","",TEXT(Estimates!E153,"0.000")&IF(Estimates!I153<0.01,"***",IF(Estimates!I153<0.05,"**",IF(Estimates!I153<0.1,"*","")))) -> 0.454
B12: =IF(Estimates!H148="","","("&TEXT(Estimates!H148,"0.00")&")") -> (0.58) | C12: =IF(Estimates!H149="","","("&TEXT(Estimates!H149,"0.00")&")") -> (1.72) | D12: =IF(Estimates!H150="","","("&TEXT(Estimates!H150,"0.00")&")") -> (1.35) | E12: =IF(Estimates!H151="","","("&TEXT(Estimates!H151,"0.00")&")") -> (0.61) | F12: =IF(Estimates!H152="","","("&TEXT(Estimates!H152,"0.00")&")") -> (0.18) | G12: =IF(Estimates!H153="","","("&TEXT(Estimates!H153,"0.00")&")") -> (0.73)
A13: Conflicted CIO x FY2005-06 | B13: =IF(Estimates!I154="","",TEXT(Estimates!E154,"0.000")&IF(Estimates!I154<0.01,"***",IF(Estimates!I154<0.05,"**",IF(Estimates!I154<0.1,"*","")))) -> 0.075 | C13: =IF(Estimates!I155="","",TEXT(Estimates!E155,"0.000")&IF(Estimates!I155<0.01,"***",IF(Estimates!I155<0.05,"**",IF(Estimates!I155<0.1,"*","")))) -> 0.471* | D13: =IF(Estimates!I156="","",TEXT(Estimates!E156,"0.000")&IF(Estimates!I156<0.01,"***",IF(Estimates!I156<0.05,"**",IF(Estimates!I156<0.1,"*","")))) -> 0.329 | E13: =IF(Estimates!I157="","",TEXT(Estimates!E157,"0.000")&IF(Estimates!I157<0.01,"***",IF(Estimates!I157<0.05,"**",IF(Estimates!I157<0.1,"*","")))) -> 0.207 | F13: =IF(Estimates!I158="","",TEXT(Estimates!E158,"0.000")&IF(Estimates!I158<0.01,"***",IF(Estimates!I158<0.05,"**",IF(Estimates!I158<0.1,"*","")))) -> 0.753*** | G13: =IF(Estimates!I159="","",TEXT(Estimates!E159,"0.000")&IF(Estimates!I159<0.01,"***",IF(Estimates!I159<0.05,"**",IF(Estimates!I159<0.1,"*","")))) -> 0.280
B14: =IF(Estimates!H154="","","("&TEXT(Estimates!H154,"0.00")&")") -> (0.13) | C14: =IF(Estimates!H155="","","("&TEXT(Estimates!H155,"0.00")&")") -> (1.83) | D14: =IF(Estimates!H156="","","("&TEXT(Estimates!H156,"0.00")&")") -> (0.64) | E14: =IF(Estimates!H157="","","("&TEXT(Estimates!H157,"0.00")&")") -> (0.48) | F14: =IF(Estimates!H158="","","("&TEXT(Estimates!H158,"0.00")&")") -> (3.31) | G14: =IF(Estimates!H159="","","("&TEXT(Estimates!H159,"0.00")&")") -> (0.64)
A15: Conflicted CIO x FY2009-10 | B15: =IF(Estimates!I160="","",TEXT(Estimates!E160,"0.000")&IF(Estimates!I160<0.01,"***",IF(Estimates!I160<0.05,"**",IF(Estimates!I160<0.1,"*","")))) -> 1.713** | C15: =IF(Estimates!I161="","",TEXT(Estimates!E161,"0.000")&IF(Estimates!I161<0.01,"***",IF(Estimates!I161<0.05,"**",IF(Estimates!I161<0.1,"*","")))) -> 1.131* | D15: =IF(Estimates!I162="","",TEXT(Estimates!E162,"0.000")&IF(Estimates!I162<0.01,"***",IF(Estimates!I162<0.05,"**",IF(Estimates!I162<0.1,"*","")))) -> 1.795** | E15: =IF(Estimates!I163="","",TEXT(Estimates!E163,"0.000")&IF(Estimates!I163<0.01,"***",IF(Estimates!I163<0.05,"**",IF(Estimates!I163<0.1,"*","")))) -> 0.966* | F15: =IF(Estimates!I164="","",TEXT(Estimates!E164,"0.000")&IF(Estimates!I164<0.01,"***",IF(Estimates!I164<0.05,"**",IF(Estimates!I164<0.1,"*","")))) -> 0.401 | G15: =IF(Estimates!I165="","",TEXT(Estimates!E165,"0.000")&IF(Estimates!I165<0.01,"***",IF(Estimates!I165<0.05,"**",IF(Estimates!I165<0.1,"*","")))) -> 0.921
B16: =IF(Estimates!H160="","","("&TEXT(Estimates!H160,"0.00")&")") -> (2.18) | C16: =IF(Estimates!H161="","","("&TEXT(Estimates!H161,"0.00")&")") -> (1.89) | D16: =IF(Estimates!H162="","","("&TEXT(Estimates!H162,"0.00")&")") -> (2.18) | E16: =IF(Estimates!H163="","","("&TEXT(Estimates!H163,"0.00")&")") -> (2.08) | F16: =IF(Estimates!H164="","","("&TEXT(Estimates!H164,"0.00")&")") -> (0.87) | G16: =IF(Estimates!H165="","","("&TEXT(Estimates!H165,"0.00")&")") -> (1.72)
A17: Conflicted CIO x FY2011-13 | B17: =IF(Estimates!I166="","",TEXT(Estimates!E166,"0.000")&IF(Estimates!I166<0.01,"***",IF(Estimates!I166<0.05,"**",IF(Estimates!I166<0.1,"*","")))) -> 1.273*** | C17: =IF(Estimates!I167="","",TEXT(Estimates!E167,"0.000")&IF(Estimates!I167<0.01,"***",IF(Estimates!I167<0.05,"**",IF(Estimates!I167<0.1,"*","")))) -> 0.628* | D17: =IF(Estimates!I168="","",TEXT(Estimates!E168,"0.000")&IF(Estimates!I168<0.01,"***",IF(Estimates!I168<0.05,"**",IF(Estimates!I168<0.1,"*","")))) -> 1.385*** | E17: =IF(Estimates!I169="","",TEXT(Estimates!E169,"0.000")&IF(Estimates!I169<0.01,"***",IF(Estimates!I169<0.05,"**",IF(Estimates!I169<0.1,"*","")))) -> 0.545 | F17: =IF(Estimates!I170="","",TEXT(Estimates!E170,"0.000")&IF(Estimates!I170<0.01,"***",IF(Estimates!I170<0.05,"**",IF(Estimates!I170<0.1,"*","")))) -> 0.136 | G17: =IF(Estimates!I171="","",TEXT(Estimates!E171,"0.000")&IF(Estimates!I171<0.01,"***",IF(Estimates!I171<0.05,"**",IF(Estimates!I171<0.1,"*","")))) -> 0.518
B18: =IF(Estimates!H166="","","("&TEXT(Estimates!H166,"0.00")&")") -> (3.11) | C18: =IF(Estimates!H167="","","("&TEXT(Estimates!H167,"0.00")&")") -> (1.89) | D18: =IF(Estimates!H168="","","("&TEXT(Estimates!H168,"0.00")&")") -> (2.98) | E18: =IF(Estimates!H169="","","("&TEXT(Estimates!H169,"0.00")&")") -> (1.19) | F18: =IF(Estimates!H170="","","("&TEXT(Estimates!H170,"0.00")&")") -> (0.35) | G18: =IF(Estimates!H171="","","("&TEXT(Estimates!H171,"0.00")&")") -> (0.92)
A19: Conflicted CIO x FY2014-15 | B19: =IF(Estimates!I172="","",TEXT(Estimates!E172,"0.000")&IF(Estimates!I172<0.01,"***",IF(Estimates!I172<0.05,"**",IF(Estimates!I172<0.1,"*","")))) -> 0.894** | C19: =IF(Estimates!I173="","",TEXT(Estimates!E173,"0.000")&IF(Estimates!I173<0.01,"***",IF(Estimates!I173<0.05,"**",IF(Estimates!I173<0.1,"*","")))) -> 1.015*** | D19: =IF(Estimates!I174="","",TEXT(Estimates!E174,"0.000")&IF(Estimates!I174<0.01,"***",IF(Estimates!I174<0.05,"**",IF(Estimates!I174<0.1,"*","")))) -> 1.158** | E19: =IF(Estimates!I175="","",TEXT(Estimates!E175,"0.000")&IF(Estimates!I175<0.01,"***",IF(Estimates!I175<0.05,"**",IF(Estimates!I175<0.1,"*","")))) -> 0.617 | F19: =IF(Estimates!I176="","",TEXT(Estimates!E176,"0.000")&IF(Estimates!I176<0.01,"***",IF(Estimates!I176<0.05,"**",IF(Estimates!I176<0.1,"*","")))) -> 0.660* | G19: =IF(Estimates!I177="","",TEXT(Estimates!E177,"0.000")&IF(Estimates!I177<0.01,"***",IF(Estimates!I177<0.05,"**",IF(Estimates!I177<0.1,"*","")))) -> 0.817
B20: =IF(Estimates!H172="","","("&TEXT(Estimates!H172,"0.00")&")") -> (2.24) | C20: =IF(Estimates!H173="","","("&TEXT(Estimates!H173,"0.00")&")") -> (3.13) | D20: =IF(Estimates!H174="","","("&TEXT(Estimates!H174,"0.00")&")") -> (2.23) | E20: =IF(Estimates!H175="","","("&TEXT(Estimates!H175,"0.00")&")") -> (1.09) | F20: =IF(Estimates!H176="","","("&TEXT(Estimates!H176,"0.00")&")") -> (1.80) | G20: =IF(Estimates!H177="","","("&TEXT(Estimates!H177,"0.00")&")") -> (1.45)
A21: Conflicted CIO x FY2016-17 | B21: =IF(Estimates!I178="","",TEXT(Estimates!E178,"0.000")&IF(Estimates!I178<0.01,"***",IF(Estimates!I178<0.05,"**",IF(Estimates!I178<0.1,"*","")))) -> 0.634 | C21: =IF(Estimates!I179="","",TEXT(Estimates!E179,"0.000")&IF(Estimates!I179<0.01,"***",IF(Estimates!I179<0.05,"**",IF(Estimates!I179<0.1,"*","")))) -> 1.313** | D21: =IF(Estimates!I180="","",TEXT(Estimates!E180,"0.000")&IF(Estimates!I180<0.01,"***",IF(Estimates!I180<0.05,"**",IF(Estimates!I180<0.1,"*","")))) -> 1.053 | E21: =IF(Estimates!I181="","",TEXT(Estimates!E181,"0.000")&IF(Estimates!I181<0.01,"***",IF(Estimates!I181<0.05,"**",IF(Estimates!I181<0.1,"*","")))) -> 0.334 | F21: =IF(Estimates!I182="","",TEXT(Estimates!E182,"0.000")&IF(Estimates!I182<0.01,"***",IF(Estimates!I182<0.05,"**",IF(Estimates!I182<0.1,"*","")))) -> 0.303 | G21: =IF(Estimates!I183="","",TEXT(Estimates!E183,"0.000")&IF(Estimates!I183<0.01,"***",IF(Estimates!I183<0.05,"**",IF(Estimates!I183<0.1,"*","")))) -> 0.758
B22: =IF(Estimates!H178="","","("&TEXT(Estimates!H178,"0.00")&")") -> (1.11) | C22: =IF(Estimates!H179="","","("&TEXT(Estimates!H179,"0.00")&")") -> (2.82) | D22: =IF(Estimates!H180="","","("&TEXT(Estimates!H180,"0.00")&")") -> (1.69) | E22: =IF(Estimates!H181="","","("&TEXT(Estimates!H181,"0.00")&")") -> (0.65) | F22: =IF(Estimates!H182="","","("&TEXT(Estimates!H182,"0.00")&")") -> (0.68) | G22: =IF(Estimates!H183="","","("&TEXT(Estimates!H183,"0.00")&")") -> (1.23)
A23: Conflicted CIO x FY2018-20 | B23: =IF(Estimates!I184="","",TEXT(Estimates!E184,"0.000")&IF(Estimates!I184<0.01,"***",IF(Estimates!I184<0.05,"**",IF(Estimates!I184<0.1,"*","")))) -> 1.914*** | C23: =IF(Estimates!I185="","",TEXT(Estimates!E185,"0.000")&IF(Estimates!I185<0.01,"***",IF(Estimates!I185<0.05,"**",IF(Estimates!I185<0.1,"*","")))) -> 2.231*** | D23: =IF(Estimates!I186="","",TEXT(Estimates!E186,"0.000")&IF(Estimates!I186<0.01,"***",IF(Estimates!I186<0.05,"**",IF(Estimates!I186<0.1,"*","")))) -> 1.964** | E23: =IF(Estimates!I187="","",TEXT(Estimates!E187,"0.000")&IF(Estimates!I187<0.01,"***",IF(Estimates!I187<0.05,"**",IF(Estimates!I187<0.1,"*","")))) -> 1.323* | F23: =IF(Estimates!I188="","",TEXT(Estimates!E188,"0.000")&IF(Estimates!I188<0.01,"***",IF(Estimates!I188<0.05,"**",IF(Estimates!I188<0.1,"*","")))) -> 1.060* | G23: =IF(Estimates!I189="","",TEXT(Estimates!E189,"0.000")&IF(Estimates!I189<0.01,"***",IF(Estimates!I189<0.05,"**",IF(Estimates!I189<0.1,"*","")))) -> 1.270
B24: =IF(Estimates!H184="","","("&TEXT(Estimates!H184,"0.00")&")") -> (3.45) | C24: =IF(Estimates!H185="","","("&TEXT(Estimates!H185,"0.00")&")") -> (2.96) | D24: =IF(Estimates!H186="","","("&TEXT(Estimates!H186,"0.00")&")") -> (2.27) | E24: =IF(Estimates!H187="","","("&TEXT(Estimates!H187,"0.00")&")") -> (2.01) | F24: =IF(Estimates!H188="","","("&TEXT(Estimates!H188,"0.00")&")") -> (1.82) | G24: =IF(Estimates!H189="","","("&TEXT(Estimates!H189,"0.00")&")") -> (1.62)
A26: p-value: pre-shock bins jointly zero | B26: 0.41707932 | C26: 0.06210718 | D26: 0.26800733 | E26: 0.72329616 | F26: 0.00056964645 | G26: 0.72880289
A27: p-value: shock-period bins jointly zero | B27: 0.018963525 | C27: 0.16395483 | D27: 0.026446173 | E27: 0.02766754 | F27: 0.67983848 | G27: 0.15706366
A28: p-value: post-period bins jointly zero | B28: 0.011720761 | C28: 0.016274354 | D28: 0.067557436 | E28: 0.04267672 | F28: 0.06606882 | G28: 0.37408968
A29: Observations | B29: 1566 | C29: 1565 | D29: 1565 | E29: 1395 | F29: 1394 | G29: 1394

Sheet Exposure
A1: Differential Exposure: Conflicted CIO x Shock Period With Allocation Controls
A2: Each row re-estimates Table VIII adding interactions that let the effect of asset allocation on returns differ in the Shock Period or in every fiscal year. Rows (2)-(3) interact the lagged private equity share, or all eight lagged allocation shares, with Shock Period; rows (4)-(5) interact them with fiscal-year indicators. The table reports Conflicted CIO x Shock Period. The lagged private equity share averages 5.45% for conflicted and 6.18% for other plan-years (6.35% and 7.16% in the Shock Period). The control variables are those of Table VIII (the lagged return, Size, the lagged funding ratio, lagged allocations, Financial Center, lagged log CIO age and tenure, lagged sibling plans and the political-state indicator). Benchmark-Adjusted Return is the plan's return minus the updated policy benchmark (the benchmark return reported in the plan's financial report or, where none is stated, an inferred value graded A or B). The standard errors are double clustered by plan and year. Coefficients marked with ***, **, and * are significant at the 1%, 5%, and 10% level, respectively.
B4: Peer-Adjusted Return | D4: Benchmark-Adjusted Return
B5: Year FE | C5: Plan and Year FE | D5: Year FE | E5: Plan and Year FE
A6: (1) Table VIII as estimated | B6: =IF(Estimates!I190="","",TEXT(Estimates!E190,"0.000")&IF(Estimates!I190<0.01,"***",IF(Estimates!I190<0.05,"**",IF(Estimates!I190<0.1,"*","")))) -> 1.009** | C6: =IF(Estimates!I191="","",TEXT(Estimates!E191,"0.000")&IF(Estimates!I191<0.01,"***",IF(Estimates!I191<0.05,"**",IF(Estimates!I191<0.1,"*","")))) -> 0.908* | D6: =IF(Estimates!I192="","",TEXT(Estimates!E192,"0.000")&IF(Estimates!I192<0.01,"***",IF(Estimates!I192<0.05,"**",IF(Estimates!I192<0.1,"*","")))) -> 0.425** | E6: =IF(Estimates!I193="","",TEXT(Estimates!E193,"0.000")&IF(Estimates!I193<0.01,"***",IF(Estimates!I193<0.05,"**",IF(Estimates!I193<0.1,"*","")))) -> 0.315
B7: =IF(Estimates!H190="","","("&TEXT(Estimates!H190,"0.00")&")") -> (2.72) | C7: =IF(Estimates!H191="","","("&TEXT(Estimates!H191,"0.00")&")") -> (2.04) | D7: =IF(Estimates!H192="","","("&TEXT(Estimates!H192,"0.00")&")") -> (2.69) | E7: =IF(Estimates!H193="","","("&TEXT(Estimates!H193,"0.00")&")") -> (1.02)
A8: (2) + Lagged PE share x Shock Period | B8: =IF(Estimates!I194="","",TEXT(Estimates!E194,"0.000")&IF(Estimates!I194<0.01,"***",IF(Estimates!I194<0.05,"**",IF(Estimates!I194<0.1,"*","")))) -> 0.934** | C8: =IF(Estimates!I195="","",TEXT(Estimates!E195,"0.000")&IF(Estimates!I195<0.01,"***",IF(Estimates!I195<0.05,"**",IF(Estimates!I195<0.1,"*","")))) -> 0.813* | D8: =IF(Estimates!I196="","",TEXT(Estimates!E196,"0.000")&IF(Estimates!I196<0.01,"***",IF(Estimates!I196<0.05,"**",IF(Estimates!I196<0.1,"*","")))) -> 0.352** | E8: =IF(Estimates!I197="","",TEXT(Estimates!E197,"0.000")&IF(Estimates!I197<0.01,"***",IF(Estimates!I197<0.05,"**",IF(Estimates!I197<0.1,"*","")))) -> 0.211
B9: =IF(Estimates!H194="","","("&TEXT(Estimates!H194,"0.00")&")") -> (2.58) | C9: =IF(Estimates!H195="","","("&TEXT(Estimates!H195,"0.00")&")") -> (1.89) | D9: =IF(Estimates!H196="","","("&TEXT(Estimates!H196,"0.00")&")") -> (2.36) | E9: =IF(Estimates!H197="","","("&TEXT(Estimates!H197,"0.00")&")") -> (0.73)
A10: (3) + All lagged allocations x Shock Period | B10: =IF(Estimates!I198="","",TEXT(Estimates!E198,"0.000")&IF(Estimates!I198<0.01,"***",IF(Estimates!I198<0.05,"**",IF(Estimates!I198<0.1,"*","")))) -> 0.845** | C10: =IF(Estimates!I199="","",TEXT(Estimates!E199,"0.000")&IF(Estimates!I199<0.01,"***",IF(Estimates!I199<0.05,"**",IF(Estimates!I199<0.1,"*","")))) -> 0.679* | D10: =IF(Estimates!I200="","",TEXT(Estimates!E200,"0.000")&IF(Estimates!I200<0.01,"***",IF(Estimates!I200<0.05,"**",IF(Estimates!I200<0.1,"*","")))) -> 0.335** | E10: =IF(Estimates!I201="","",TEXT(Estimates!E201,"0.000")&IF(Estimates!I201<0.01,"***",IF(Estimates!I201<0.05,"**",IF(Estimates!I201<0.1,"*","")))) -> 0.123
B11: =IF(Estimates!H198="","","("&TEXT(Estimates!H198,"0.00")&")") -> (2.87) | C11: =IF(Estimates!H199="","","("&TEXT(Estimates!H199,"0.00")&")") -> (1.80) | D11: =IF(Estimates!H200="","","("&TEXT(Estimates!H200,"0.00")&")") -> (2.54) | E11: =IF(Estimates!H201="","","("&TEXT(Estimates!H201,"0.00")&")") -> (0.58)
A12: (4) + Lagged PE share x fiscal-year indicators | B12: =IF(Estimates!I202="","",TEXT(Estimates!E202,"0.000")&IF(Estimates!I202<0.01,"***",IF(Estimates!I202<0.05,"**",IF(Estimates!I202<0.1,"*","")))) -> 0.922** | C12: =IF(Estimates!I203="","",TEXT(Estimates!E203,"0.000")&IF(Estimates!I203<0.01,"***",IF(Estimates!I203<0.05,"**",IF(Estimates!I203<0.1,"*","")))) -> 0.784* | D12: =IF(Estimates!I204="","",TEXT(Estimates!E204,"0.000")&IF(Estimates!I204<0.01,"***",IF(Estimates!I204<0.05,"**",IF(Estimates!I204<0.1,"*","")))) -> 0.365* | E12: =IF(Estimates!I205="","",TEXT(Estimates!E205,"0.000")&IF(Estimates!I205<0.01,"***",IF(Estimates!I205<0.05,"**",IF(Estimates!I205<0.1,"*","")))) -> 0.214
B13: =IF(Estimates!H202="","","("&TEXT(Estimates!H202,"0.00")&")") -> (2.31) | C13: =IF(Estimates!H203="","","("&TEXT(Estimates!H203,"0.00")&")") -> (1.74) | D13: =IF(Estimates!H204="","","("&TEXT(Estimates!H204,"0.00")&")") -> (1.97) | E13: =IF(Estimates!H205="","","("&TEXT(Estimates!H205,"0.00")&")") -> (0.64)
A14: (5) + All lagged allocations x fiscal-year indicators | B14: =IF(Estimates!I206="","",TEXT(Estimates!E206,"0.000")&IF(Estimates!I206<0.01,"***",IF(Estimates!I206<0.05,"**",IF(Estimates!I206<0.1,"*","")))) -> 0.567* | C14: =IF(Estimates!I207="","",TEXT(Estimates!E207,"0.000")&IF(Estimates!I207<0.01,"***",IF(Estimates!I207<0.05,"**",IF(Estimates!I207<0.1,"*","")))) -> 0.399 | D14: =IF(Estimates!I208="","",TEXT(Estimates!E208,"0.000")&IF(Estimates!I208<0.01,"***",IF(Estimates!I208<0.05,"**",IF(Estimates!I208<0.1,"*","")))) -> 0.157 | E14: =IF(Estimates!I209="","",TEXT(Estimates!E209,"0.000")&IF(Estimates!I209<0.01,"***",IF(Estimates!I209<0.05,"**",IF(Estimates!I209<0.1,"*","")))) -> -0.182
B15: =IF(Estimates!H206="","","("&TEXT(Estimates!H206,"0.00")&")") -> (1.79) | C15: =IF(Estimates!H207="","","("&TEXT(Estimates!H207,"0.00")&")") -> (0.88) | D15: =IF(Estimates!H208="","","("&TEXT(Estimates!H208,"0.00")&")") -> (0.60) | E15: =IF(Estimates!H209="","","("&TEXT(Estimates!H209,"0.00")&")") -> (-0.49)
A16: Observations | B16: 1566 | C16: 1565 | D16: 1395 | E16: 1394

Sheet Placebo windows
A1: Placebo Windows: Conflicted CIO x Five-Year Window
A2: Panel A re-estimates Table VIII with Shock Period replaced by an indicator for a five-year window of fiscal years (the window's main effect is absorbed by the year fixed effects where they are included); the shaded row is the actual window, FY2009-2013 (which differs from Shock Period only for plans with fiscal years ending in January-March 2014). Windows that overlap FY2009-2013 partly contain the actual shock. Panel B restricts the sample to FY2008 and earlier and compares FY2005-2008 with FY2001-2004, a window that lies entirely before the shock. The control variables are those of Table VIII (the lagged return, Size, the lagged funding ratio, lagged allocations, Financial Center, lagged log CIO age and tenure, lagged sibling plans and the political-state indicator). Benchmark-Adjusted Return is the plan's return minus the updated policy benchmark (the benchmark return reported in the plan's financial report or, where none is stated, an inferred value graded A or B). The standard errors are double clustered by plan and year. Coefficients marked with ***, **, and * are significant at the 1%, 5%, and 10% level, respectively.
B4: Peer-Adjusted Return | D4: Benchmark-Adjusted Return
B5: Year FE | C5: Plan and Year FE | D5: Year FE | E5: Plan and Year FE
A6: Panel A. Conflicted CIO x Window
A7: FY2002-2006 | B7: =IF(Estimates!I210="","",TEXT(Estimates!E210,"0.000")&IF(Estimates!I210<0.01,"***",IF(Estimates!I210<0.05,"**",IF(Estimates!I210<0.1,"*","")))) -> -0.710** | C7: =IF(Estimates!I211="","",TEXT(Estimates!E211,"0.000")&IF(Estimates!I211<0.01,"***",IF(Estimates!I211<0.05,"**",IF(Estimates!I211<0.1,"*","")))) -> -0.444 | D7: =IF(Estimates!I212="","",TEXT(Estimates!E212,"0.000")&IF(Estimates!I212<0.01,"***",IF(Estimates!I212<0.05,"**",IF(Estimates!I212<0.1,"*","")))) -> -0.420*** | E7: =IF(Estimates!I213="","",TEXT(Estimates!E213,"0.000")&IF(Estimates!I213<0.01,"***",IF(Estimates!I213<0.05,"**",IF(Estimates!I213<0.1,"*","")))) -> -0.372
B8: =IF(Estimates!H210="","","("&TEXT(Estimates!H210,"0.00")&")") -> (-2.12) | C8: =IF(Estimates!H211="","","("&TEXT(Estimates!H211,"0.00")&")") -> (-1.08) | D8: =IF(Estimates!H212="","","("&TEXT(Estimates!H212,"0.00")&")") -> (-2.88) | E8: =IF(Estimates!H213="","","("&TEXT(Estimates!H213,"0.00")&")") -> (-1.43)
A9: FY2003-2007 | B9: =IF(Estimates!I214="","",TEXT(Estimates!E214,"0.000")&IF(Estimates!I214<0.01,"***",IF(Estimates!I214<0.05,"**",IF(Estimates!I214<0.1,"*","")))) -> -1.245*** | C9: =IF(Estimates!I215="","",TEXT(Estimates!E215,"0.000")&IF(Estimates!I215<0.01,"***",IF(Estimates!I215<0.05,"**",IF(Estimates!I215<0.1,"*","")))) -> -1.180** | D9: =IF(Estimates!I216="","",TEXT(Estimates!E216,"0.000")&IF(Estimates!I216<0.01,"***",IF(Estimates!I216<0.05,"**",IF(Estimates!I216<0.1,"*","")))) -> -0.556 | E9: =IF(Estimates!I217="","",TEXT(Estimates!E217,"0.000")&IF(Estimates!I217<0.01,"***",IF(Estimates!I217<0.05,"**",IF(Estimates!I217<0.1,"*","")))) -> -0.532
B10: =IF(Estimates!H214="","","("&TEXT(Estimates!H214,"0.00")&")") -> (-3.07) | C10: =IF(Estimates!H215="","","("&TEXT(Estimates!H215,"0.00")&")") -> (-2.45) | D10: =IF(Estimates!H216="","","("&TEXT(Estimates!H216,"0.00")&")") -> (-1.61) | E10: =IF(Estimates!H217="","","("&TEXT(Estimates!H217,"0.00")&")") -> (-1.25)
