Workbook

Sheet Table III (updated)
A1: Table III: Conflicted CIO and Plan Performance Regressions (updated policy benchmark, file of Oct 16)
A2: This table reports results of tests that regress the returns of public pension plans on an indicator variable, Conflicted CIO, which is equal to 1 for all years prior to the plan's investment officer (CIO) departure for a position in a private asset management firm and 0 otherwise. The performance measure in Panel A is Peer-Adjusted Return, which is the difference of a plan's return and the average pension plan return each year. The performance measure in Panel B is Benchmark-Adjusted Return, which is calculated as the plan's return minus the return of its policy benchmark, when available. Policy benchmark returns are collected from plans' financial reports; where a report does not state the one-year benchmark return, it is inferred from the plan's reported multi-year benchmark returns or from its policy weights and component index returns (estimates graded A or B only). The other independent variables are as defined in Table I. Columns 5 and 6 redefine Conflicted CIO to equal 1 only in the last 5 or 10 years before departure. The standard errors are double clustered by plan and year. Coefficients marked with ***, **, and * are significant at the 1%, 5%, and 10% level, respectively.
A4: Panel A. Peer-Adjusted Returns
B5: (1) | C5: (2) | D5: (3) | E5: (4) | F5: (5) | G5: (6)
B6: Peer-adj. Ret. (t) | C6: Peer-adj. Ret. (t) | D6: Peer-adj. Ret. (t) | E6: Peer-adj. Ret. (t) | F6: Peer-adj. Ret. (t) | G6: Peer-adj. Ret. (t)
A7: Conflicted CIO (0/1) | B7: =IF(Estimates!H4="","n/a",TEXT(Estimates!D4,"0.000")&IF(Estimates!H4<0.01,"***",IF(Estimates!H4<0.05,"**",IF(Estimates!H4<0.1,"*","")))) -> -0.557*** | C7: =IF(Estimates!H5="","n/a",TEXT(Estimates!D5,"0.000")&IF(Estimates!H5<0.01,"***",IF(Estimates!H5<0.05,"**",IF(Estimates!H5<0.1,"*","")))) -> -0.582*** | D7: =IF(Estimates!H6="","n/a",TEXT(Estimates!D6,"0.000")&IF(Estimates!H6<0.01,"***",IF(Estimates!H6<0.05,"**",IF(Estimates!H6<0.1,"*","")))) -> -0.641** | E7: =IF(Estimates!H7="","n/a",TEXT(Estimates!D7,"0.000")&IF(Estimates!H7<0.01,"***",IF(Estimates!H7<0.05,"**",IF(Estimates!H7<0.1,"*","")))) -> -0.698** | F7: =IF(Estimates!H8="","n/a",TEXT(Estimates!D8,"0.000")&IF(Estimates!H8<0.01,"***",IF(Estimates!H8<0.05,"**",IF(Estimates!H8<0.1,"*","")))) -> -0.475* | G7: =IF(Estimates!H9="","n/a",TEXT(Estimates!D9,"0.000")&IF(Estimates!H9<0.01,"***",IF(Estimates!H9<0.05,"**",IF(Estimates!H9<0.1,"*","")))) -> -0.508**
B8: =IF(Estimates!G4="","","("&TEXT(Estimates!G4,"0.00")&")") -> (-3.68) | C8: =IF(Estimates!G5="","","("&TEXT(Estimates!G5,"0.00")&")") -> (-3.13) | D8: =IF(Estimates!G6="","","("&TEXT(Estimates!G6,"0.00")&")") -> (-2.21) | E8: =IF(Estimates!G7="","","("&TEXT(Estimates!G7,"0.00")&")") -> (-2.38) | F8: =IF(Estimates!G8="","","("&TEXT(Estimates!G8,"0.00")&")") -> (-2.10) | G8: =IF(Estimates!G9="","","("&TEXT(Estimates!G9,"0.00")&")") -> (-2.78)
A9: Investment Return (t - 1) | B9: =IF(Estimates!H10="","n/a",TEXT(Estimates!D10,"0.000")&IF(Estimates!H10<0.01,"***",IF(Estimates!H10<0.05,"**",IF(Estimates!H10<0.1,"*","")))) -> 0.014 | C9: =IF(Estimates!H11="","n/a",TEXT(Estimates!D11,"0.000")&IF(Estimates!H11<0.01,"***",IF(Estimates!H11<0.05,"**",IF(Estimates!H11<0.1,"*","")))) -> 0.004 | D9: =IF(Estimates!H12="","n/a",TEXT(Estimates!D12,"0.000")&IF(Estimates!H12<0.01,"***",IF(Estimates!H12<0.05,"**",IF(Estimates!H12<0.1,"*","")))) -> 0.011 | E9: =IF(Estimates!H13="","n/a",TEXT(Estimates!D13,"0.000")&IF(Estimates!H13<0.01,"***",IF(Estimates!H13<0.05,"**",IF(Estimates!H13<0.1,"*","")))) -> 0.000 | F9: =IF(Estimates!H14="","n/a",TEXT(Estimates!D14,"0.000")&IF(Estimates!H14<0.01,"***",IF(Estimates!H14<0.05,"**",IF(Estimates!H14<0.1,"*","")))) -> 0.004 | G9: =IF(Estimates!H15="","n/a",TEXT(Estimates!D15,"0.000")&IF(Estimates!H15<0.01,"***",IF(Estimates!H15<0.05,"**",IF(Estimates!H15<0.1,"*","")))) -> 0.004
B10: =IF(Estimates!G10="","","("&TEXT(Estimates!G10,"0.00")&")") -> (0.71) | C10: =IF(Estimates!G11="","","("&TEXT(Estimates!G11,"0.00")&")") -> (0.20) | D10: =IF(Estimates!G12="","","("&TEXT(Estimates!G12,"0.00")&")") -> (1.19) | E10: =IF(Estimates!G13="","","("&TEXT(Estimates!G13,"0.00")&")") -> (0.03) | F10: =IF(Estimates!G14="","","("&TEXT(Estimates!G14,"0.00")&")") -> (0.21) | G10: =IF(Estimates!G15="","","("&TEXT(Estimates!G15,"0.00")&")") -> (0.20)
A11: Log (Plan Size) (t-1) | B11: =IF(Estimates!H16="","n/a",TEXT(Estimates!D16,"0.000")&IF(Estimates!H16<0.01,"***",IF(Estimates!H16<0.05,"**",IF(Estimates!H16<0.1,"*","")))) -> 0.008 | C11: =IF(Estimates!H17="","n/a",TEXT(Estimates!D17,"0.000")&IF(Estimates!H17<0.01,"***",IF(Estimates!H17<0.05,"**",IF(Estimates!H17<0.1,"*","")))) -> 0.070 | D11: =IF(Estimates!H18="","n/a",TEXT(Estimates!D18,"0.000")&IF(Estimates!H18<0.01,"***",IF(Estimates!H18<0.05,"**",IF(Estimates!H18<0.1,"*","")))) -> -0.943** | E11: =IF(Estimates!H19="","n/a",TEXT(Estimates!D19,"0.000")&IF(Estimates!H19<0.01,"***",IF(Estimates!H19<0.05,"**",IF(Estimates!H19<0.1,"*","")))) -> -1.430* | F11: =IF(Estimates!H20="","n/a",TEXT(Estimates!D20,"0.000")&IF(Estimates!H20<0.01,"***",IF(Estimates!H20<0.05,"**",IF(Estimates!H20<0.1,"*","")))) -> 0.079 | G11: =IF(Estimates!H21="","n/a",TEXT(Estimates!D21,"0.000")&IF(Estimates!H21<0.01,"***",IF(Estimates!H21<0.05,"**",IF(Estimates!H21<0.1,"*","")))) -> 0.075
B12: =IF(Estimates!G16="","","("&TEXT(Estimates!G16,"0.00")&")") -> (0.15) | C12: =IF(Estimates!G17="","","("&TEXT(Estimates!G17,"0.00")&")") -> (1.14) | D12: =IF(Estimates!G18="","","("&TEXT(Estimates!G18,"0.00")&")") -> (-2.48) | E12: =IF(Estimates!G19="","","("&TEXT(Estimates!G19,"0.00")&")") -> (-1.95) | F12: =IF(Estimates!G20="","","("&TEXT(Estimates!G20,"0.00")&")") -> (1.28) | G12: =IF(Estimates!G21="","","("&TEXT(Estimates!G21,"0.00")&")") -> (1.23)
A13: Funding Ratio (t-1) | B13: =IF(Estimates!H22="","n/a",TEXT(Estimates!D22,"0.000")&IF(Estimates!H22<0.01,"***",IF(Estimates!H22<0.05,"**",IF(Estimates!H22<0.1,"*","")))) -> -0.005 | C13: =IF(Estimates!H23="","n/a",TEXT(Estimates!D23,"0.000")&IF(Estimates!H23<0.01,"***",IF(Estimates!H23<0.05,"**",IF(Estimates!H23<0.1,"*","")))) -> -0.006 | D13: =IF(Estimates!H24="","n/a",TEXT(Estimates!D24,"0.000")&IF(Estimates!H24<0.01,"***",IF(Estimates!H24<0.05,"**",IF(Estimates!H24<0.1,"*","")))) -> -0.027*** | E13: =IF(Estimates!H25="","n/a",TEXT(Estimates!D25,"0.000")&IF(Estimates!H25<0.01,"***",IF(Estimates!H25<0.05,"**",IF(Estimates!H25<0.1,"*","")))) -> -0.030*** | F13: =IF(Estimates!H26="","n/a",TEXT(Estimates!D26,"0.000")&IF(Estimates!H26<0.01,"***",IF(Estimates!H26<0.05,"**",IF(Estimates!H26<0.1,"*","")))) -> -0.005 | G13: =IF(Estimates!H27="","n/a",TEXT(Estimates!D27,"0.000")&IF(Estimates!H27<0.01,"***",IF(Estimates!H27<0.05,"**",IF(Estimates!H27<0.1,"*","")))) -> -0.005
B14: =IF(Estimates!G22="","","("&TEXT(Estimates!G22,"0.00")&")") -> (-1.17) | C14: =IF(Estimates!G23="","","("&TEXT(Estimates!G23,"0.00")&")") -> (-1.13) | D14: =IF(Estimates!G24="","","("&TEXT(Estimates!G24,"0.00")&")") -> (-3.16) | E14: =IF(Estimates!G25="","","("&TEXT(Estimates!G25,"0.00")&")") -> (-3.03) | F14: =IF(Estimates!G26="","","("&TEXT(Estimates!G26,"0.00")&")") -> (-1.01) | G14: =IF(Estimates!G27="","","("&TEXT(Estimates!G27,"0.00")&")") -> (-1.04)
A15: Equity Allocation (%) | B15: =IF(Estimates!H28="","n/a",TEXT(Estimates!D28,"0.000")&IF(Estimates!H28<0.01,"***",IF(Estimates!H28<0.05,"**",IF(Estimates!H28<0.1,"*","")))) -> -0.079 | C15: =IF(Estimates!H29="","n/a",TEXT(Estimates!D29,"0.000")&IF(Estimates!H29<0.01,"***",IF(Estimates!H29<0.05,"**",IF(Estimates!H29<0.1,"*","")))) -> 0.004 | D15: =IF(Estimates!H30="","n/a",TEXT(Estimates!D30,"0.000")&IF(Estimates!H30<0.01,"***",IF(Estimates!H30<0.05,"**",IF(Estimates!H30<0.1,"*","")))) -> -0.059 | E15: =IF(Estimates!H31="","n/a",TEXT(Estimates!D31,"0.000")&IF(Estimates!H31<0.01,"***",IF(Estimates!H31<0.05,"**",IF(Estimates!H31<0.1,"*","")))) -> -0.040 | F15: =IF(Estimates!H32="","n/a",TEXT(Estimates!D32,"0.000")&IF(Estimates!H32<0.01,"***",IF(Estimates!H32<0.05,"**",IF(Estimates!H32<0.1,"*","")))) -> 0.038 | G15: =IF(Estimates!H33="","n/a",TEXT(Estimates!D33,"0.000")&IF(Estimates!H33<0.01,"***",IF(Estimates!H33<0.05,"**",IF(Estimates!H33<0.1,"*","")))) -> 0.040
B16: =IF(Estimates!G28="","","("&TEXT(Estimates!G28,"0.00")&")") -> (-0.58) | C16: =IF(Estimates!G29="","","("&TEXT(Estimates!G29,"0.00")&")") -> (0.06) | D16: =IF(Estimates!G30="","","("&TEXT(Estimates!G30,"0.00")&")") -> (-0.79) | E16: =IF(Estimates!G31="","","("&TEXT(Estimates!G31,"0.00")&")") -> (-0.49) | F16: =IF(Estimates!G32="","","("&TEXT(Estimates!G32,"0.00")&")") -> (0.58) | G16: =IF(Estimates!G33="","","("&TEXT(Estimates!G33,"0.00")&")") -> (0.61)
A17: Fixed Income Allocation (%) | B17: =IF(Estimates!H34="","n/a",TEXT(Estimates!D34,"0.000")&IF(Estimates!H34<0.01,"***",IF(Estimates!H34<0.05,"**",IF(Estimates!H34<0.1,"*","")))) -> -0.088 | C17: =IF(Estimates!H35="","n/a",TEXT(Estimates!D35,"0.000")&IF(Estimates!H35<0.01,"***",IF(Estimates!H35<0.05,"**",IF(Estimates!H35<0.1,"*","")))) -> -0.001 | D17: =IF(Estimates!H36="","n/a",TEXT(Estimates!D36,"0.000")&IF(Estimates!H36<0.01,"***",IF(Estimates!H36<0.05,"**",IF(Estimates!H36<0.1,"*","")))) -> -0.069 | E17: =IF(Estimates!H37="","n/a",TEXT(Estimates!D37,"0.000")&IF(Estimates!H37<0.01,"***",IF(Estimates!H37<0.05,"**",IF(Estimates!H37<0.1,"*","")))) -> -0.047 | F17: =IF(Estimates!H38="","n/a",TEXT(Estimates!D38,"0.000")&IF(Estimates!H38<0.01,"***",IF(Estimates!H38<0.05,"**",IF(Estimates!H38<0.1,"*","")))) -> 0.033 | G17: =IF(Estimates!H39="","n/a",TEXT(Estimates!D39,"0.000")&IF(Estimates!H39<0.01,"***",IF(Estimates!H39<0.05,"**",IF(Estimates!H39<0.1,"*","")))) -> 0.036
B18: =IF(Estimates!G34="","","("&TEXT(Estimates!G34,"0.00")&")") -> (-0.60) | C18: =IF(Estimates!G35="","","("&TEXT(Estimates!G35,"0.00")&")") -> (-0.01) | D18: =IF(Estimates!G36="","","("&TEXT(Estimates!G36,"0.00")&")") -> (-0.80) | E18: =IF(Estimates!G37="","","("&TEXT(Estimates!G37,"0.00")&")") -> (-0.51) | F18: =IF(Estimates!G38="","","("&TEXT(Estimates!G38,"0.00")&")") -> (0.45) | G18: =IF(Estimates!G39="","","("&TEXT(Estimates!G39,"0.00")&")") -> (0.48)
A19: Real Estate Allocation (%) | B19: =IF(Estimates!H40="","n/a",TEXT(Estimates!D40,"0.000")&IF(Estimates!H40<0.01,"***",IF(Estimates!H40<0.05,"**",IF(Estimates!H40<0.1,"*","")))) -> -0.059 | C19: =IF(Estimates!H41="","n/a",TEXT(Estimates!D41,"0.000")&IF(Estimates!H41<0.01,"***",IF(Estimates!H41<0.05,"**",IF(Estimates!H41<0.1,"*","")))) -> 0.026 | D19: =IF(Estimates!H42="","n/a",TEXT(Estimates!D42,"0.000")&IF(Estimates!H42<0.01,"***",IF(Estimates!H42<0.05,"**",IF(Estimates!H42<0.1,"*","")))) -> -0.100 | E19: =IF(Estimates!H43="","n/a",TEXT(Estimates!D43,"0.000")&IF(Estimates!H43<0.01,"***",IF(Estimates!H43<0.05,"**",IF(Estimates!H43<0.1,"*","")))) -> -0.089 | F19: =IF(Estimates!H44="","n/a",TEXT(Estimates!D44,"0.000")&IF(Estimates!H44<0.01,"***",IF(Estimates!H44<0.05,"**",IF(Estimates!H44<0.1,"*","")))) -> 0.062 | G19: =IF(Estimates!H45="","n/a",TEXT(Estimates!D45,"0.000")&IF(Estimates!H45<0.01,"***",IF(Estimates!H45<0.05,"**",IF(Estimates!H45<0.1,"*","")))) -> 0.063
B20: =IF(Estimates!G40="","","("&TEXT(Estimates!G40,"0.00")&")") -> (-0.43) | C20: =IF(Estimates!G41="","","("&TEXT(Estimates!G41,"0.00")&")") -> (0.45) | D20: =IF(Estimates!G42="","","("&TEXT(Estimates!G42,"0.00")&")") -> (-1.41) | E20: =IF(Estimates!G43="","","("&TEXT(Estimates!G43,"0.00")&")") -> (-1.17) | F20: =IF(Estimates!G44="","","("&TEXT(Estimates!G44,"0.00")&")") -> (1.04) | G20: =IF(Estimates!G45="","","("&TEXT(Estimates!G45,"0.00")&")") -> (1.01)
A21: Private Equity Allocation (%) | B21: =IF(Estimates!H46="","n/a",TEXT(Estimates!D46,"0.000")&IF(Estimates!H46<0.01,"***",IF(Estimates!H46<0.05,"**",IF(Estimates!H46<0.1,"*","")))) -> -0.070 | C21: =IF(Estimates!H47="","n/a",TEXT(Estimates!D47,"0.000")&IF(Estimates!H47<0.01,"***",IF(Estimates!H47<0.05,"**",IF(Estimates!H47<0.1,"*","")))) -> 0.024 | D21: =IF(Estimates!H48="","n/a",TEXT(Estimates!D48,"0.000")&IF(Estimates!H48<0.01,"***",IF(Estimates!H48<0.05,"**",IF(Estimates!H48<0.1,"*","")))) -> -0.053 | E21: =IF(Estimates!H49="","n/a",TEXT(Estimates!D49,"0.000")&IF(Estimates!H49<0.01,"***",IF(Estimates!H49<0.05,"**",IF(Estimates!H49<0.1,"*","")))) -> -0.001 | F21: =IF(Estimates!H50="","n/a",TEXT(Estimates!D50,"0.000")&IF(Estimates!H50<0.01,"***",IF(Estimates!H50<0.05,"**",IF(Estimates!H50<0.1,"*","")))) -> 0.056 | G21: =IF(Estimates!H51="","n/a",TEXT(Estimates!D51,"0.000")&IF(Estimates!H51<0.01,"***",IF(Estimates!H51<0.05,"**",IF(Estimates!H51<0.1,"*","")))) -> 0.059
B22: =IF(Estimates!G46="","","("&TEXT(Estimates!G46,"0.00")&")") -> (-0.48) | C22: =IF(Estimates!G47="","","("&TEXT(Estimates!G47,"0.00")&")") -> (0.36) | D22: =IF(Estimates!G48="","","("&TEXT(Estimates!G48,"0.00")&")") -> (-0.64) | E22: =IF(Estimates!G49="","","("&TEXT(Estimates!G49,"0.00")&")") -> (-0.02) | F22: =IF(Estimates!G50="","","("&TEXT(Estimates!G50,"0.00")&")") -> (0.81) | G22: =IF(Estimates!G51="","","("&TEXT(Estimates!G51,"0.00")&")") -> (0.84)
A23: Hedge Fund Allocation (%) | B23: =IF(Estimates!H52="","n/a",TEXT(Estimates!D52,"0.000")&IF(Estimates!H52<0.01,"***",IF(Estimates!H52<0.05,"**",IF(Estimates!H52<0.1,"*","")))) -> -0.126 | C23: =IF(Estimates!H53="","n/a",TEXT(Estimates!D53,"0.000")&IF(Estimates!H53<0.01,"***",IF(Estimates!H53<0.05,"**",IF(Estimates!H53<0.1,"*","")))) -> -0.039 | D23: =IF(Estimates!H54="","n/a",TEXT(Estimates!D54,"0.000")&IF(Estimates!H54<0.01,"***",IF(Estimates!H54<0.05,"**",IF(Estimates!H54<0.1,"*","")))) -> -0.107 | E23: =IF(Estimates!H55="","n/a",TEXT(Estimates!D55,"0.000")&IF(Estimates!H55<0.01,"***",IF(Estimates!H55<0.05,"**",IF(Estimates!H55<0.1,"*","")))) -> -0.094 | F23: =IF(Estimates!H56="","n/a",TEXT(Estimates!D56,"0.000")&IF(Estimates!H56<0.01,"***",IF(Estimates!H56<0.05,"**",IF(Estimates!H56<0.1,"*","")))) -> -0.004 | G23: =IF(Estimates!H57="","n/a",TEXT(Estimates!D57,"0.000")&IF(Estimates!H57<0.01,"***",IF(Estimates!H57<0.05,"**",IF(Estimates!H57<0.1,"*","")))) -> -0.001
B24: =IF(Estimates!G52="","","("&TEXT(Estimates!G52,"0.00")&")") -> (-0.92) | C24: =IF(Estimates!G53="","","("&TEXT(Estimates!G53,"0.00")&")") -> (-0.60) | D24: =IF(Estimates!G54="","","("&TEXT(Estimates!G54,"0.00")&")") -> (-1.61) | E24: =IF(Estimates!G55="","","("&TEXT(Estimates!G55,"0.00")&")") -> (-1.38) | F24: =IF(Estimates!G56="","","("&TEXT(Estimates!G56,"0.00")&")") -> (-0.05) | G24: =IF(Estimates!G57="","","("&TEXT(Estimates!G57,"0.00")&")") -> (-0.02)
A25: Misc. Alternatives Allocation (%) | B25: =IF(Estimates!H58="","n/a",TEXT(Estimates!D58,"0.000")&IF(Estimates!H58<0.01,"***",IF(Estimates!H58<0.05,"**",IF(Estimates!H58<0.1,"*","")))) -> -0.093 | C25: =IF(Estimates!H59="","n/a",TEXT(Estimates!D59,"0.000")&IF(Estimates!H59<0.01,"***",IF(Estimates!H59<0.05,"**",IF(Estimates!H59<0.1,"*","")))) -> -0.011 | D25: =IF(Estimates!H60="","n/a",TEXT(Estimates!D60,"0.000")&IF(Estimates!H60<0.01,"***",IF(Estimates!H60<0.05,"**",IF(Estimates!H60<0.1,"*","")))) -> -0.125 | E25: =IF(Estimates!H61="","n/a",TEXT(Estimates!D61,"0.000")&IF(Estimates!H61<0.01,"***",IF(Estimates!H61<0.05,"**",IF(Estimates!H61<0.1,"*","")))) -> -0.087 | F25: =IF(Estimates!H62="","n/a",TEXT(Estimates!D62,"0.000")&IF(Estimates!H62<0.01,"***",IF(Estimates!H62<0.05,"**",IF(Estimates!H62<0.1,"*","")))) -> 0.024 | G25: =IF(Estimates!H63="","n/a",TEXT(Estimates!D63,"0.000")&IF(Estimates!H63<0.01,"***",IF(Estimates!H63<0.05,"**",IF(Estimates!H63<0.1,"*","")))) -> 0.027
B26: =IF(Estimates!G58="","","("&TEXT(Estimates!G58,"0.00")&")") -> (-0.65) | C26: =IF(Estimates!G59="","","("&TEXT(Estimates!G59,"0.00")&")") -> (-0.17) | D26: =IF(Estimates!G60="","","("&TEXT(Estimates!G60,"0.00")&")") -> (-1.56) | E26: =IF(Estimates!G61="","","("&TEXT(Estimates!G61,"0.00")&")") -> (-1.03) | F26: =IF(Estimates!G62="","","("&TEXT(Estimates!G62,"0.00")&")") -> (0.38) | G26: =IF(Estimates!G63="","","("&TEXT(Estimates!G63,"0.00")&")") -> (0.42)
A27: Commodities Allocation (%) | B27: =IF(Estimates!H64="","n/a",TEXT(Estimates!D64,"0.000")&IF(Estimates!H64<0.01,"***",IF(Estimates!H64<0.05,"**",IF(Estimates!H64<0.1,"*","")))) -> -0.140 | C27: =IF(Estimates!H65="","n/a",TEXT(Estimates!D65,"0.000")&IF(Estimates!H65<0.01,"***",IF(Estimates!H65<0.05,"**",IF(Estimates!H65<0.1,"*","")))) -> -0.048 | D27: =IF(Estimates!H66="","n/a",TEXT(Estimates!D66,"0.000")&IF(Estimates!H66<0.01,"***",IF(Estimates!H66<0.05,"**",IF(Estimates!H66<0.1,"*","")))) -> -0.149 | E27: =IF(Estimates!H67="","n/a",TEXT(Estimates!D67,"0.000")&IF(Estimates!H67<0.01,"***",IF(Estimates!H67<0.05,"**",IF(Estimates!H67<0.1,"*","")))) -> -0.135 | F27: =IF(Estimates!H68="","n/a",TEXT(Estimates!D68,"0.000")&IF(Estimates!H68<0.01,"***",IF(Estimates!H68<0.05,"**",IF(Estimates!H68<0.1,"*","")))) -> -0.014 | G27: =IF(Estimates!H69="","n/a",TEXT(Estimates!D69,"0.000")&IF(Estimates!H69<0.01,"***",IF(Estimates!H69<0.05,"**",IF(Estimates!H69<0.1,"*","")))) -> -0.012
B28: =IF(Estimates!G64="","","("&TEXT(Estimates!G64,"0.00")&")") -> (-0.99) | C28: =IF(Estimates!G65="","","("&TEXT(Estimates!G65,"0.00")&")") -> (-0.78) | D28: =IF(Estimates!G66="","","("&TEXT(Estimates!G66,"0.00")&")") -> (-1.70) | E28: =IF(Estimates!G67="","","("&TEXT(Estimates!G67,"0.00")&")") -> (-1.51) | F28: =IF(Estimates!G68="","","("&TEXT(Estimates!G68,"0.00")&")") -> (-0.22) | G28: =IF(Estimates!G69="","","("&TEXT(Estimates!G69,"0.00")&")") -> (-0.19)
A29: Cash Allocation (%) | B29: =IF(Estimates!H70="","n/a",TEXT(Estimates!D70,"0.000")&IF(Estimates!H70<0.01,"***",IF(Estimates!H70<0.05,"**",IF(Estimates!H70<0.1,"*","")))) -> -0.099 | C29: =IF(Estimates!H71="","n/a",TEXT(Estimates!D71,"0.000")&IF(Estimates!H71<0.01,"***",IF(Estimates!H71<0.05,"**",IF(Estimates!H71<0.1,"*","")))) -> -0.019 | D29: =IF(Estimates!H72="","n/a",TEXT(Estimates!D72,"0.000")&IF(Estimates!H72<0.01,"***",IF(Estimates!H72<0.05,"**",IF(Estimates!H72<0.1,"*","")))) -> -0.078 | E29: =IF(Estimates!H73="","n/a",TEXT(Estimates!D73,"0.000")&IF(Estimates!H73<0.01,"***",IF(Estimates!H73<0.05,"**",IF(Estimates!H73<0.1,"*","")))) -> -0.057 | F29: =IF(Estimates!H74="","n/a",TEXT(Estimates!D74,"0.000")&IF(Estimates!H74<0.01,"***",IF(Estimates!H74<0.05,"**",IF(Estimates!H74<0.1,"*","")))) -> 0.018 | G29: =IF(Estimates!H75="","n/a",TEXT(Estimates!D75,"0.000")&IF(Estimates!H75<0.01,"***",IF(Estimates!H75<0.05,"**",IF(Estimates!H75<0.1,"*","")))) -> 0.020
B30: =IF(Estimates!G70="","","("&TEXT(Estimates!G70,"0.00")&")") -> (-0.66) | C30: =IF(Estimates!G71="","","("&TEXT(Estimates!G71,"0.00")&")") -> (-0.24) | D30: =IF(Estimates!G72="","","("&TEXT(Estimates!G72,"0.00")&")") -> (-0.76) | E30: =IF(Estimates!G73="","","("&TEXT(Estimates!G73,"0.00")&")") -> (-0.54) | F30: =IF(Estimates!G74="","","("&TEXT(Estimates!G74,"0.00")&")") -> (0.24) | G30: =IF(Estimates!G75="","","("&TEXT(Estimates!G75,"0.00")&")") -> (0.26)
A31: Financial Center (0/1) | B31: =IF(Estimates!H76="","n/a",TEXT(Estimates!D76,"0.000")&IF(Estimates!H76<0.01,"***",IF(Estimates!H76<0.05,"**",IF(Estimates!H76<0.1,"*","")))) -> 0.113 | C31: =IF(Estimates!H77="","n/a",TEXT(Estimates!D77,"0.000")&IF(Estimates!H77<0.01,"***",IF(Estimates!H77<0.05,"**",IF(Estimates!H77<0.1,"*","")))) -> 0.142 | F31: =IF(Estimates!H78="","n/a",TEXT(Estimates!D78,"0.000")&IF(Estimates!H78<0.01,"***",IF(Estimates!H78<0.05,"**",IF(Estimates!H78<0.1,"*","")))) -> 0.153 | G31: =IF(Estimates!H79="","n/a",TEXT(Estimates!D79,"0.000")&IF(Estimates!H79<0.01,"***",IF(Estimates!H79<0.05,"**",IF(Estimates!H79<0.1,"*","")))) -> 0.139
B32: =IF(Estimates!G76="","","("&TEXT(Estimates!G76,"0.00")&")") -> (0.76) | C32: =IF(Estimates!G77="","","("&TEXT(Estimates!G77,"0.00")&")") -> (1.00) | F32: =IF(Estimates!G78="","","("&TEXT(Estimates!G78,"0.00")&")") -> (1.11) | G32: =IF(Estimates!G79="","","("&TEXT(Estimates!G79,"0.00")&")") -> (1.02)
A33: Log (CIO Age) (t-1) | C33: =IF(Estimates!H80="","n/a",TEXT(Estimates!D80,"0.000")&IF(Estimates!H80<0.01,"***",IF(Estimates!H80<0.05,"**",IF(Estimates!H80<0.1,"*","")))) -> -0.402 | D33: =IF(Estimates!H81="","n/a",TEXT(Estimates!D81,"0.000")&IF(Estimates!H81<0.01,"***",IF(Estimates!H81<0.05,"**",IF(Estimates!H81<0.1,"*","")))) -> 0.786 | E33: =IF(Estimates!H82="","n/a",TEXT(Estimates!D82,"0.000")&IF(Estimates!H82<0.01,"***",IF(Estimates!H82<0.05,"**",IF(Estimates!H82<0.1,"*","")))) -> 0.855 | F33: =IF(Estimates!H83="","n/a",TEXT(Estimates!D83,"0.000")&IF(Estimates!H83<0.01,"***",IF(Estimates!H83<0.05,"**",IF(Estimates!H83<0.1,"*","")))) -> -0.293 | G33: =IF(Estimates!H84="","n/a",TEXT(Estimates!D84,"0.000")&IF(Estimates!H84<0.01,"***",IF(Estimates!H84<0.05,"**",IF(Estimates!H84<0.1,"*","")))) -> -0.338
C34: =IF(Estimates!G80="","","("&TEXT(Estimates!G80,"0.00")&")") -> (-0.76) | D34: =IF(Estimates!G81="","","("&TEXT(Estimates!G81,"0.00")&")") -> (1.24) | E34: =IF(Estimates!G82="","","("&TEXT(Estimates!G82,"0.00")&")") -> (1.28) | F34: =IF(Estimates!G83="","","("&TEXT(Estimates!G83,"0.00")&")") -> (-0.54) | G34: =IF(Estimates!G84="","","("&TEXT(Estimates!G84,"0.00")&")") -> (-0.62)
A35: Log (CIO Tenure) (t-1) | C35: =IF(Estimates!H85="","n/a",TEXT(Estimates!D85,"0.000")&IF(Estimates!H85<0.01,"***",IF(Estimates!H85<0.05,"**",IF(Estimates!H85<0.1,"*","")))) -> 0.038 | D35: =IF(Estimates!H86="","n/a",TEXT(Estimates!D86,"0.000")&IF(Estimates!H86<0.01,"***",IF(Estimates!H86<0.05,"**",IF(Estimates!H86<0.1,"*","")))) -> 0.007 | E35: =IF(Estimates!H87="","n/a",TEXT(Estimates!D87,"0.000")&IF(Estimates!H87<0.01,"***",IF(Estimates!H87<0.05,"**",IF(Estimates!H87<0.1,"*","")))) -> -0.012 | F35: =IF(Estimates!H88="","n/a",TEXT(Estimates!D88,"0.000")&IF(Estimates!H88<0.01,"***",IF(Estimates!H88<0.05,"**",IF(Estimates!H88<0.1,"*","")))) -> 0.056 | G35: =IF(Estimates!H89="","n/a",TEXT(Estimates!D89,"0.000")&IF(Estimates!H89<0.01,"***",IF(Estimates!H89<0.05,"**",IF(Estimates!H89<0.1,"*","")))) -> 0.057
C36: =IF(Estimates!G85="","","("&TEXT(Estimates!G85,"0.00")&")") -> (0.40) | D36: =IF(Estimates!G86="","","("&TEXT(Estimates!G86,"0.00")&")") -> (0.07) | E36: =IF(Estimates!G87="","","("&TEXT(Estimates!G87,"0.00")&")") -> (-0.10) | F36: =IF(Estimates!G88="","","("&TEXT(Estimates!G88,"0.00")&")") -> (0.61) | G36: =IF(Estimates!G89="","","("&TEXT(Estimates!G89,"0.00")&")") -> (0.62)
A37: CIO Prior Private Experience (0/1) | C37: =IF(Estimates!H90="","n/a",TEXT(Estimates!D90,"0.000")&IF(Estimates!H90<0.01,"***",IF(Estimates!H90<0.05,"**",IF(Estimates!H90<0.1,"*","")))) -> 0.037 | D37: =IF(Estimates!H91="","n/a",TEXT(Estimates!D91,"0.000")&IF(Estimates!H91<0.01,"***",IF(Estimates!H91<0.05,"**",IF(Estimates!H91<0.1,"*","")))) -> -0.043 | E37: =IF(Estimates!H92="","n/a",TEXT(Estimates!D92,"0.000")&IF(Estimates!H92<0.01,"***",IF(Estimates!H92<0.05,"**",IF(Estimates!H92<0.1,"*","")))) -> -0.006 | F37: =IF(Estimates!H93="","n/a",TEXT(Estimates!D93,"0.000")&IF(Estimates!H93<0.01,"***",IF(Estimates!H93<0.05,"**",IF(Estimates!H93<0.1,"*","")))) -> -0.064 | G37: =IF(Estimates!H94="","n/a",TEXT(Estimates!D94,"0.000")&IF(Estimates!H94<0.01,"***",IF(Estimates!H94<0.05,"**",IF(Estimates!H94<0.1,"*","")))) -> -0.036
C38: =IF(Estimates!G90="","","("&TEXT(Estimates!G90,"0.00")&")") -> (0.36) | D38: =IF(Estimates!G91="","","("&TEXT(Estimates!G91,"0.00")&")") -> (-0.26) | E38: =IF(Estimates!G92="","","("&TEXT(Estimates!G92,"0.00")&")") -> (-0.04) | F38: =IF(Estimates!G93="","","("&TEXT(Estimates!G93,"0.00")&")") -> (-0.79) | G38: =IF(Estimates!G94="","","("&TEXT(Estimates!G94,"0.00")&")") -> (-0.48)
A39: CIO Attended Elite College (0/1) | C39: =IF(Estimates!H95="","n/a",TEXT(Estimates!D95,"0.000")&IF(Estimates!H95<0.01,"***",IF(Estimates!H95<0.05,"**",IF(Estimates!H95<0.1,"*","")))) -> -0.116 | D39: =IF(Estimates!H96="","n/a",TEXT(Estimates!D96,"0.000")&IF(Estimates!H96<0.01,"***",IF(Estimates!H96<0.05,"**",IF(Estimates!H96<0.1,"*","")))) -> 0.258 | E39: =IF(Estimates!H97="","n/a",TEXT(Estimates!D97,"0.000")&IF(Estimates!H97<0.01,"***",IF(Estimates!H97<0.05,"**",IF(Estimates!H97<0.1,"*","")))) -> 0.310 | F39: =IF(Estimates!H98="","n/a",TEXT(Estimates!D98,"0.000")&IF(Estimates!H98<0.01,"***",IF(Estimates!H98<0.05,"**",IF(Estimates!H98<0.1,"*","")))) -> -0.074 | G39: =IF(Estimates!H99="","n/a",TEXT(Estimates!D99,"0.000")&IF(Estimates!H99<0.01,"***",IF(Estimates!H99<0.05,"**",IF(Estimates!H99<0.1,"*","")))) -> -0.082
C40: =IF(Estimates!G95="","","("&TEXT(Estimates!G95,"0.00")&")") -> (-0.83) | D40: =IF(Estimates!G96="","","("&TEXT(Estimates!G96,"0.00")&")") -> (1.12) | E40: =IF(Estimates!G97="","","("&TEXT(Estimates!G97,"0.00")&")") -> (1.37) | F40: =IF(Estimates!G98="","","("&TEXT(Estimates!G98,"0.00")&")") -> (-0.58) | G40: =IF(Estimates!G99="","","("&TEXT(Estimates!G99,"0.00")&")") -> (-0.63)
A41: Separate Investment Board (0/1) | C41: =IF(Estimates!H100="","n/a",TEXT(Estimates!D100,"0.000")&IF(Estimates!H100<0.01,"***",IF(Estimates!H100<0.05,"**",IF(Estimates!H100<0.1,"*","")))) -> 0.267* | D41: =IF(Estimates!H101="","n/a",TEXT(Estimates!D101,"0.000")&IF(Estimates!H101<0.01,"***",IF(Estimates!H101<0.05,"**",IF(Estimates!H101<0.1,"*","")))) -> -0.277 | E41: =IF(Estimates!H102="","n/a",TEXT(Estimates!D102,"0.000")&IF(Estimates!H102<0.01,"***",IF(Estimates!H102<0.05,"**",IF(Estimates!H102<0.1,"*","")))) -> -0.199 | F41: =IF(Estimates!H103="","n/a",TEXT(Estimates!D103,"0.000")&IF(Estimates!H103<0.01,"***",IF(Estimates!H103<0.05,"**",IF(Estimates!H103<0.1,"*","")))) -> 0.276** | G41: =IF(Estimates!H104="","n/a",TEXT(Estimates!D104,"0.000")&IF(Estimates!H104<0.01,"***",IF(Estimates!H104<0.05,"**",IF(Estimates!H104<0.1,"*","")))) -> 0.272**
...

Sheet Benchmark versions
A1: Conflicted CIO coefficient in Table III under alternative benchmark-adjusted returns (same specifications as Table III columns 1-6)
A2: Each row re-estimates the six Table III columns with a different dependent variable; only the Conflicted CIO coefficient is shown, with all controls, fixed effects and clustering as in Table III. 'PPD return' is the plan's investment return in the Public Plans Database (the return used in the paper). 'Document return' is the total-fund return reported on the same page of the plan's financial report as the policy benchmark. 'Reported' benchmarks are stated in the report; 'inferred grade A/B' adds benchmark returns inferred from multi-year benchmark returns or from policy weights and component index returns, using only estimates graded A or B. The row marked 'agree within 0.5 pp' keeps only plan-years in which the PPD and document returns differ by at most 0.5 percentage points, removing fiscal-year misalignments between the two sources.
A4: Dependent variable | B4: (1) | C4: (2) | D4: (3) | E4: (4) | F4: (5) | G4: (6)
A5: Peer-adjusted return (Panel A, unchanged) | B5: =IF(Estimates!H216="","n/a",TEXT(Estimates!D216,"0.000")&IF(Estimates!H216<0.01,"***",IF(Estimates!H216<0.05,"**",IF(Estimates!H216<0.1,"*","")))) -> -0.557*** | C5: =IF(Estimates!H217="","n/a",TEXT(Estimates!D217,"0.000")&IF(Estimates!H217<0.01,"***",IF(Estimates!H217<0.05,"**",IF(Estimates!H217<0.1,"*","")))) -> -0.582*** | D5: =IF(Estimates!H218="","n/a",TEXT(Estimates!D218,"0.000")&IF(Estimates!H218<0.01,"***",IF(Estimates!H218<0.05,"**",IF(Estimates!H218<0.1,"*","")))) -> -0.641** | E5: =IF(Estimates!H219="","n/a",TEXT(Estimates!D219,"0.000")&IF(Estimates!H219<0.01,"***",IF(Estimates!H219<0.05,"**",IF(Estimates!H219<0.1,"*","")))) -> -0.698** | F5: =IF(Estimates!H220="","n/a",TEXT(Estimates!D220,"0.000")&IF(Estimates!H220<0.01,"***",IF(Estimates!H220<0.05,"**",IF(Estimates!H220<0.1,"*","")))) -> -0.475* | G5: =IF(Estimates!H221="","n/a",TEXT(Estimates!D221,"0.000")&IF(Estimates!H221<0.01,"***",IF(Estimates!H221<0.05,"**",IF(Estimates!H221<0.1,"*","")))) -> -0.508**
B6: =IF(Estimates!G216="","","("&TEXT(Estimates!G216,"0.00")&")") -> (-3.68) | C6: =IF(Estimates!G217="","","("&TEXT(Estimates!G217,"0.00")&")") -> (-3.13) | D6: =IF(Estimates!G218="","","("&TEXT(Estimates!G218,"0.00")&")") -> (-2.21) | E6: =IF(Estimates!G219="","","("&TEXT(Estimates!G219,"0.00")&")") -> (-2.38) | F6: =IF(Estimates!G220="","","("&TEXT(Estimates!G220,"0.00")&")") -> (-2.10) | G6: =IF(Estimates!G221="","","("&TEXT(Estimates!G221,"0.00")&")") -> (-2.78)
A7: Observations | B7: 1727 | C7: 1483 | D7: 1482 | E7: 1482 | F7: 1483 | G7: 1483
A8: Original benchmark-adjusted return (paper Panel B) | B8: =IF(Estimates!H222="","n/a",TEXT(Estimates!D222,"0.000")&IF(Estimates!H222<0.01,"***",IF(Estimates!H222<0.05,"**",IF(Estimates!H222<0.1,"*","")))) -> -0.518** | C8: =IF(Estimates!H223="","n/a",TEXT(Estimates!D223,"0.000")&IF(Estimates!H223<0.01,"***",IF(Estimates!H223<0.05,"**",IF(Estimates!H223<0.1,"*","")))) -> -0.598*** | D8: =IF(Estimates!H224="","n/a",TEXT(Estimates!D224,"0.000")&IF(Estimates!H224<0.01,"***",IF(Estimates!H224<0.05,"**",IF(Estimates!H224<0.1,"*","")))) -> -0.959** | E8: =IF(Estimates!H225="","n/a",TEXT(Estimates!D225,"0.000")&IF(Estimates!H225<0.01,"***",IF(Estimates!H225<0.05,"**",IF(Estimates!H225<0.1,"*","")))) -> -0.889* | F8: =IF(Estimates!H226="","n/a",TEXT(Estimates!D226,"0.000")&IF(Estimates!H226<0.01,"***",IF(Estimates!H226<0.05,"**",IF(Estimates!H226<0.1,"*","")))) -> -0.596* | G8: =IF(Estimates!H227="","n/a",TEXT(Estimates!D227,"0.000")&IF(Estimates!H227<0.01,"***",IF(Estimates!H227<0.05,"**",IF(Estimates!H227<0.1,"*","")))) -> -0.611**
B9: =IF(Estimates!G222="","","("&TEXT(Estimates!G222,"0.00")&")") -> (-2.65) | C9: =IF(Estimates!G223="","","("&TEXT(Estimates!G223,"0.00")&")") -> (-3.19) | D9: =IF(Estimates!G224="","","("&TEXT(Estimates!G224,"0.00")&")") -> (-2.23) | E9: =IF(Estimates!G225="","","("&TEXT(Estimates!G225,"0.00")&")") -> (-2.09) | F9: =IF(Estimates!G226="","","("&TEXT(Estimates!G226,"0.00")&")") -> (-1.87) | G9: =IF(Estimates!G227="","","("&TEXT(Estimates!G227,"0.00")&")") -> (-2.24)
A10: Observations | B10: 1240 | C10: 1072 | D10: 1069 | E10: 1069 | F10: 1072 | G10: 1072
A11: PPD return minus updated reported benchmark | B11: =IF(Estimates!H228="","n/a",TEXT(Estimates!D228,"0.000")&IF(Estimates!H228<0.01,"***",IF(Estimates!H228<0.05,"**",IF(Estimates!H228<0.1,"*","")))) -> -0.393** | C11: =IF(Estimates!H229="","n/a",TEXT(Estimates!D229,"0.000")&IF(Estimates!H229<0.01,"***",IF(Estimates!H229<0.05,"**",IF(Estimates!H229<0.1,"*","")))) -> -0.434*** | D11: =IF(Estimates!H230="","n/a",TEXT(Estimates!D230,"0.000")&IF(Estimates!H230<0.01,"***",IF(Estimates!H230<0.05,"**",IF(Estimates!H230<0.1,"*","")))) -> -0.319* | E11: =IF(Estimates!H231="","n/a",TEXT(Estimates!D231,"0.000")&IF(Estimates!H231<0.01,"***",IF(Estimates!H231<0.05,"**",IF(Estimates!H231<0.1,"*","")))) -> -0.333** | F11: =IF(Estimates!H232="","n/a",TEXT(Estimates!D232,"0.000")&IF(Estimates!H232<0.01,"***",IF(Estimates!H232<0.05,"**",IF(Estimates!H232<0.1,"*","")))) -> -0.380* | G11: =IF(Estimates!H233="","n/a",TEXT(Estimates!D233,"0.000")&IF(Estimates!H233<0.01,"***",IF(Estimates!H233<0.05,"**",IF(Estimates!H233<0.1,"*","")))) -> -0.424**
B12: =IF(Estimates!G228="","","("&TEXT(Estimates!G228,"0.00")&")") -> (-2.49) | C12: =IF(Estimates!G229="","","("&TEXT(Estimates!G229,"0.00")&")") -> (-4.12) | D12: =IF(Estimates!G230="","","("&TEXT(Estimates!G230,"0.00")&")") -> (-1.92) | E12: =IF(Estimates!G231="","","("&TEXT(Estimates!G231,"0.00")&")") -> (-2.12) | F12: =IF(Estimates!G232="","","("&TEXT(Estimates!G232,"0.00")&")") -> (-1.92) | G12: =IF(Estimates!G233="","","("&TEXT(Estimates!G233,"0.00")&")") -> (-2.42)
A13: Observations | B13: 1453 | C13: 1249 | D13: 1248 | E13: 1248 | F13: 1249 | G13: 1249
A14: PPD return minus updated benchmark (reported + inferred grade A/B) | B14: =IF(Estimates!H234="","n/a",TEXT(Estimates!D234,"0.000")&IF(Estimates!H234<0.01,"***",IF(Estimates!H234<0.05,"**",IF(Estimates!H234<0.1,"*","")))) -> -0.385** | C14: =IF(Estimates!H235="","n/a",TEXT(Estimates!D235,"0.000")&IF(Estimates!H235<0.01,"***",IF(Estimates!H235<0.05,"**",IF(Estimates!H235<0.1,"*","")))) -> -0.491*** | D14: =IF(Estimates!H236="","n/a",TEXT(Estimates!D236,"0.000")&IF(Estimates!H236<0.01,"***",IF(Estimates!H236<0.05,"**",IF(Estimates!H236<0.1,"*","")))) -> -0.373** | E14: =IF(Estimates!H237="","n/a",TEXT(Estimates!D237,"0.000")&IF(Estimates!H237<0.01,"***",IF(Estimates!H237<0.05,"**",IF(Estimates!H237<0.1,"*","")))) -> -0.411** | F14: =IF(Estimates!H238="","n/a",TEXT(Estimates!D238,"0.000")&IF(Estimates!H238<0.01,"***",IF(Estimates!H238<0.05,"**",IF(Estimates!H238<0.1,"*","")))) -> -0.384* | G14: =IF(Estimates!H239="","n/a",TEXT(Estimates!D239,"0.000")&IF(Estimates!H239<0.01,"***",IF(Estimates!H239<0.05,"**",IF(Estimates!H239<0.1,"*","")))) -> -0.441**
B15: =IF(Estimates!G234="","","("&TEXT(Estimates!G234,"0.00")&")") -> (-2.46) | C15: =IF(Estimates!G235="","","("&TEXT(Estimates!G235,"0.00")&")") -> (-4.15) | D15: =IF(Estimates!G236="","","("&TEXT(Estimates!G236,"0.00")&")") -> (-2.23) | E15: =IF(Estimates!G237="","","("&TEXT(Estimates!G237,"0.00")&")") -> (-2.15) | F15: =IF(Estimates!G238="","","("&TEXT(Estimates!G238,"0.00")&")") -> (-1.84) | G15: =IF(Estimates!G239="","","("&TEXT(Estimates!G239,"0.00")&")") -> (-2.36)
A16: Observations | B16: 1538 | C16: 1320 | D16: 1319 | E16: 1319 | F16: 1320 | G16: 1320
A17: PPD return minus updated benchmark (A/B), rows where PPD and document returns agree within 0.5 pp | B17: =IF(Estimates!H240="","n/a",TEXT(Estimates!D240,"0.000")&IF(Estimates!H240<0.01,"***",IF(Estimates!H240<0.05,"**",IF(Estimates!H240<0.1,"*","")))) -> -0.411** | C17: =IF(Estimates!H241="","n/a",TEXT(Estimates!D241,"0.000")&IF(Estimates!H241<0.01,"***",IF(Estimates!H241<0.05,"**",IF(Estimates!H241<0.1,"*","")))) -> -0.535*** | D17: =IF(Estimates!H242="","n/a",TEXT(Estimates!D242,"0.000")&IF(Estimates!H242<0.01,"***",IF(Estimates!H242<0.05,"**",IF(Estimates!H242<0.1,"*","")))) -> -0.457*** | E17: =IF(Estimates!H243="","n/a",TEXT(Estimates!D243,"0.000")&IF(Estimates!H243<0.01,"***",IF(Estimates!H243<0.05,"**",IF(Estimates!H243<0.1,"*","")))) -> -0.409** | F17: =IF(Estimates!H244="","n/a",TEXT(Estimates!D244,"0.000")&IF(Estimates!H244<0.01,"***",IF(Estimates!H244<0.05,"**",IF(Estimates!H244<0.1,"*","")))) -> -0.403* | G17: =IF(Estimates!H245="","n/a",TEXT(Estimates!D245,"0.000")&IF(Estimates!H245<0.01,"***",IF(Estimates!H245<0.05,"**",IF(Estimates!H245<0.1,"*","")))) -> -0.462**
B18: =IF(Estimates!G240="","","("&TEXT(Estimates!G240,"0.00")&")") -> (-2.70) | C18: =IF(Estimates!G241="","","("&TEXT(Estimates!G241,"0.00")&")") -> (-4.41) | D18: =IF(Estimates!G242="","","("&TEXT(Estimates!G242,"0.00")&")") -> (-3.11) | E18: =IF(Estimates!G243="","","("&TEXT(Estimates!G243,"0.00")&")") -> (-2.36) | F18: =IF(Estimates!G244="","","("&TEXT(Estimates!G244,"0.00")&")") -> (-1.94) | G18: =IF(Estimates!G245="","","("&TEXT(Estimates!G245,"0.00")&")") -> (-2.51)
A19: Observations | B19: 1502 | C19: 1286 | D19: 1284 | E19: 1284 | F19: 1286 | G19: 1286
A20: Document return minus updated benchmark (reported + inferred grade A/B) | B20: =IF(Estimates!H246="","n/a",TEXT(Estimates!D246,"0.000")&IF(Estimates!H246<0.01,"***",IF(Estimates!H246<0.05,"**",IF(Estimates!H246<0.1,"*","")))) -> -0.404** | C20: =IF(Estimates!H247="","n/a",TEXT(Estimates!D247,"0.000")&IF(Estimates!H247<0.01,"***",IF(Estimates!H247<0.05,"**",IF(Estimates!H247<0.1,"*","")))) -> -0.503*** | D20: =IF(Estimates!H248="","n/a",TEXT(Estimates!D248,"0.000")&IF(Estimates!H248<0.01,"***",IF(Estimates!H248<0.05,"**",IF(Estimates!H248<0.1,"*","")))) -> -0.320** | E20: =IF(Estimates!H249="","n/a",TEXT(Estimates!D249,"0.000")&IF(Estimates!H249<0.01,"***",IF(Estimates!H249<0.05,"**",IF(Estimates!H249<0.1,"*","")))) -> -0.357* | F20: =IF(Estimates!H250="","n/a",TEXT(Estimates!D250,"0.000")&IF(Estimates!H250<0.01,"***",IF(Estimates!H250<0.05,"**",IF(Estimates!H250<0.1,"*","")))) -> -0.390* | G20: =IF(Estimates!H251="","n/a",TEXT(Estimates!D251,"0.000")&IF(Estimates!H251<0.01,"***",IF(Estimates!H251<0.05,"**",IF(Estimates!H251<0.1,"*","")))) -> -0.445**
B21: =IF(Estimates!G246="","","("&TEXT(Estimates!G246,"0.00")&")") -> (-2.63) | C21: =IF(Estimates!G247="","","("&TEXT(Estimates!G247,"0.00")&")") -> (-4.21) | D21: =IF(Estimates!G248="","","("&TEXT(Estimates!G248,"0.00")&")") -> (-2.11) | E21: =IF(Estimates!G249="","","("&TEXT(Estimates!G249,"0.00")&")") -> (-2.06) | F21: =IF(Estimates!G250="","","("&TEXT(Estimates!G250,"0.00")&")") -> (-1.90) | G21: =IF(Estimates!G251="","","("&TEXT(Estimates!G251,"0.00")&")") -> (-2.47)
A22: Observations | B22: 1538 | C22: 1320 | D22: 1319 | E22: 1319 | F22: 1320 | G22: 1320
A23: Plan FE | B23: No | C23: No | D23: Yes | E23: Yes | F23: No | G23: No
A24: Year FE | B24: Yes | C24: Yes | D24: No | E24: Yes | F24: Yes | G24: Yes
A25: Last n years | F25: 5 | G25: 10
A27: Note on t-statistics: coefficients and observations match reghdfe exactly. In the year-FE-only columns (1), (2), (5) and (6), these two-way clustered t-statistics run about 4 to 17 percent larger than reghdfe reports for the published Table III (for example, original Panel B column 1: -2.65 here, -2.27 published); plan-FE columns (3) and (4) match to within 0.06. Use the attached Stata code for the exact figures.

Sheet Estimates
A1: Estimates behind the tables. Blue = regression output (coefficient, SE, minimum cluster count). t and p are formulas; p uses the t distribution with (min clusters - 1) df. SE double clustered by plan and fiscal year (Cameron-Gelbach-Miller, with the eigenvalue fix).
A3: Version | B3: Column | C3: Variable | D3: Coefficient | E3: SE | F3: Clusters (min) | G3: t | H3: p
A4: peer | B4: (1) | C4: Conflicted CIO (0/1) | D4: -0.55697013 | E4: 0.15141822 | F4: 19 | G4: =IF(E4>0,D4/E4,"") -> -3.678356 | H4: =IF(G4="","",TDIST(ABS(G4),F4-1,2)) -> 0.0017195765
A5: peer | B5: (2) | C5: Conflicted CIO (0/1) | D5: -0.58232518 | E5: 0.1862998 | F5: 19 | G5: =IF(E5>0,D5/E5,"") -> -3.1257424 | H5: =IF(G5="","",TDIST(ABS(G5),F5-1,2)) -> 0.0058407567
A6: peer | B6: (3) | C6: Conflicted CIO (0/1) | D6: -0.64076312 | E6: 0.29037999 | F6: 19 | G6: =IF(E6>0,D6/E6,"") -> -2.2066366 | H6: =IF(G6="","",TDIST(ABS(G6),F6-1,2)) -> 0.04056821
A7: peer | B7: (4) | C7: Conflicted CIO (0/1) | D7: -0.69792191 | E7: 0.29373848 | F7: 19 | G7: =IF(E7>0,D7/E7,"") -> -2.3759976 | H7: =IF(G7="","",TDIST(ABS(G7),F7-1,2)) -> 0.0288096
A8: peer | B8: (5) | C8: Conflicted CIO (0/1) | D8: -0.47452374 | E8: 0.22639981 | F8: 19 | G8: =IF(E8>0,D8/E8,"") -> -2.0959547 | H8: =IF(G8="","",TDIST(ABS(G8),F8-1,2)) -> 0.050488803
A9: peer | B9: (6) | C9: Conflicted CIO (0/1) | D9: -0.50834616 | E9: 0.1826916 | F9: 19 | G9: =IF(E9>0,D9/E9,"") -> -2.7825371 | H9: =IF(G9="","",TDIST(ABS(G9),F9-1,2)) -> 0.012287709
A10: peer | B10: (1) | C10: Investment Return (t - 1) | D10: 0.013909869 | E10: 0.019513777 | F10: 19 | G10: =IF(E10>0,D10/E10,"") -> 0.712823 | H10: =IF(G10="","",TDIST(ABS(G10),F10-1,2)) -> 0.48509434
A11: peer | B11: (2) | C11: Investment Return (t - 1) | D11: 0.004172387 | E11: 0.020972487 | F11: 19 | G11: =IF(E11>0,D11/E11,"") -> 0.19894574 | H11: =IF(G11="","",TDIST(ABS(G11),F11-1,2)) -> 0.84453511
A12: peer | B12: (3) | C12: Investment Return (t - 1) | D12: 0.010624341 | E12: 0.0089511849 | F12: 19 | G12: =IF(E12>0,D12/E12,"") -> 1.1869201 | H12: =IF(G12="","",TDIST(ABS(G12),F12-1,2)) -> 0.25068825
A13: peer | B13: (4) | C13: Investment Return (t - 1) | D13: 0.00044173875 | E13: 0.016470436 | F13: 19 | G13: =IF(E13>0,D13/E13,"") -> 0.0268201 | H13: =IF(G13="","",TDIST(ABS(G13),F13-1,2)) -> 0.97889833
A14: peer | B14: (5) | C14: Investment Return (t - 1) | D14: 0.004456023 | E14: 0.02131807 | F14: 19 | G14: =IF(E14>0,D14/E14,"") -> 0.20902563 | H14: =IF(G14="","",TDIST(ABS(G14),F14-1,2)) -> 0.83677553
A15: peer | B15: (6) | C15: Investment Return (t - 1) | D15: 0.0042878292 | E15: 0.020925077 | F15: 19 | G15: =IF(E15>0,D15/E15,"") -> 0.20491343 | H15: =IF(G15="","",TDIST(ABS(G15),F15-1,2)) -> 0.8399391
... A251: b_docAB (summary) | B251: (6) | C251: Conflicted CIO | D251: -0.4445863 | E251: 0.17983068 | F251: 19 | G251: =IF(E251>0,D251/E251,"") -> -2.4722494 | H251: =IF(G251="","",TDIST(ABS(G251),F251-1,2)) -> 0.023630368
