Workbook

Sheet Table V
A1: Table V: Conflicted CIOs: CIO Incentives and Plan Performance (updated benchmark)
A2: This table divides the sample by two proxies for a CIO's susceptibility to become conflicted: an indicator equal to 1 if the CIO is underpaid relative to the size of the plan, and an indicator equal to 1 for CIOs who are 46 years old or younger. Each panel reports regressions of plan performance on Conflicted CIO interacted with the group indicator, with all control variables also interacted with the group indicator, so that the two coefficients are estimated in one regression. The first pair of columns uses Peer-Adjusted Return, as in the paper. The second pair uses Benchmark-Adjusted Return computed with the original policy benchmark, and the third pair uses Benchmark-Adjusted Return recomputed as the plan's return minus the updated policy benchmark (the benchmark return reported in the plan's financial report; where none is stated, a value inferred from the plan's multi-year benchmark returns or from its policy weights and component index returns, graded A or B). The control variables are those of the corresponding regressions in the paper and are defined in Table I. All regressions include year fixed effects. The p-value row tests that the two Conflicted CIO coefficients are equal. The standard errors are double clustered by plan and year. Coefficients marked with ***, **, and * are significant at the 1%, 5%, and 10% level, respectively.
A4: Panel A. Effect of Conflict for Underpaid CIOs
B5: Peer-Adjusted Return (t) | D5: Benchmark-Adjusted Return, Original Benchmark (t) | F5: Benchmark-Adjusted Return, Updated Benchmark (t)
B6: Underpaid CIOs | C6: Not Underpaid CIOs | D6: Underpaid CIOs | E6: Not Underpaid CIOs | F6: Underpaid CIOs | G6: Not Underpaid CIOs
A7: Conflicted CIO | B7: =IF(Estimates!H4="","n/a",TEXT(Estimates!D4,"0.000")&IF(Estimates!H4<0.01,"***",IF(Estimates!H4<0.05,"**",IF(Estimates!H4<0.1,"*","")))) -> -0.870*** | C7: =IF(Estimates!H5="","n/a",TEXT(Estimates!D5,"0.000")&IF(Estimates!H5<0.01,"***",IF(Estimates!H5<0.05,"**",IF(Estimates!H5<0.1,"*","")))) -> -0.394 | D7: =IF(Estimates!H6="","n/a",TEXT(Estimates!D6,"0.000")&IF(Estimates!H6<0.01,"***",IF(Estimates!H6<0.05,"**",IF(Estimates!H6<0.1,"*","")))) -> -0.674* | E7: =IF(Estimates!H7="","n/a",TEXT(Estimates!D7,"0.000")&IF(Estimates!H7<0.01,"***",IF(Estimates!H7<0.05,"**",IF(Estimates!H7<0.1,"*","")))) -> -0.474 | F7: =IF(Estimates!H8="","n/a",TEXT(Estimates!D8,"0.000")&IF(Estimates!H8<0.01,"***",IF(Estimates!H8<0.05,"**",IF(Estimates!H8<0.1,"*","")))) -> -0.704*** | G7: =IF(Estimates!H9="","n/a",TEXT(Estimates!D9,"0.000")&IF(Estimates!H9<0.01,"***",IF(Estimates!H9<0.05,"**",IF(Estimates!H9<0.1,"*","")))) -> -0.193
B8: =IF(Estimates!G4="","","("&TEXT(Estimates!G4,"0.00")&")") -> (-4.27) | C8: =IF(Estimates!G5="","","("&TEXT(Estimates!G5,"0.00")&")") -> (-1.51) | D8: =IF(Estimates!G6="","","("&TEXT(Estimates!G6,"0.00")&")") -> (-1.75) | E8: =IF(Estimates!G7="","","("&TEXT(Estimates!G7,"0.00")&")") -> (-1.72) | F8: =IF(Estimates!G8="","","("&TEXT(Estimates!G8,"0.00")&")") -> (-2.98) | G8: =IF(Estimates!G9="","","("&TEXT(Estimates!G9,"0.00")&")") -> (-1.00)
A10: p-value: equal coefficients | B10: =IF(Estimates!H10="","",Estimates!H10) -> 0.10117275 | D10: =IF(Estimates!H11="","",Estimates!H11) -> 0.65822199 | F10: =IF(Estimates!H12="","",Estimates!H12) -> 0.11721219
A11: Observations | B11: 1495 | D11: 1061 | F11: 1308
A12: Adjusted R-squared | B12: 0.082215184 | D12: 0.13280402 | F12: 0.14180801
A13: Controls | B13: Yes | D13: Yes | F13: Yes
A14: Year FE | B14: Yes | D14: Yes | F14: Yes
A17: Panel B. Effect of Conflict for Younger CIOs
B18: Peer-Adjusted Return (t) | D18: Benchmark-Adjusted Return, Original Benchmark (t) | F18: Benchmark-Adjusted Return, Updated Benchmark (t)
B19: Young CIOs | C19: Not Young CIOs | D19: Young CIOs | E19: Not Young CIOs | F19: Young CIOs | G19: Not Young CIOs
A20: Conflicted CIO | B20: =IF(Estimates!H13="","n/a",TEXT(Estimates!D13,"0.000")&IF(Estimates!H13<0.01,"***",IF(Estimates!H13<0.05,"**",IF(Estimates!H13<0.1,"*","")))) -> -1.213*** | C20: =IF(Estimates!H14="","n/a",TEXT(Estimates!D14,"0.000")&IF(Estimates!H14<0.01,"***",IF(Estimates!H14<0.05,"**",IF(Estimates!H14<0.1,"*","")))) -> -0.385* | D20: =IF(Estimates!H15="","n/a",TEXT(Estimates!D15,"0.000")&IF(Estimates!H15<0.01,"***",IF(Estimates!H15<0.05,"**",IF(Estimates!H15<0.1,"*","")))) -> -0.865*** | E20: =IF(Estimates!H16="","n/a",TEXT(Estimates!D16,"0.000")&IF(Estimates!H16<0.01,"***",IF(Estimates!H16<0.05,"**",IF(Estimates!H16<0.1,"*","")))) -> -0.630** | F20: =IF(Estimates!H17="","n/a",TEXT(Estimates!D17,"0.000")&IF(Estimates!H17<0.01,"***",IF(Estimates!H17<0.05,"**",IF(Estimates!H17<0.1,"*","")))) -> -0.793*** | G20: =IF(Estimates!H18="","n/a",TEXT(Estimates!D18,"0.000")&IF(Estimates!H18<0.01,"***",IF(Estimates!H18<0.05,"**",IF(Estimates!H18<0.1,"*","")))) -> -0.364
B21: =IF(Estimates!G13="","","("&TEXT(Estimates!G13,"0.00")&")") -> (-3.56) | C21: =IF(Estimates!G14="","","("&TEXT(Estimates!G14,"0.00")&")") -> (-1.86) | D21: =IF(Estimates!G15="","","("&TEXT(Estimates!G15,"0.00")&")") -> (-3.07) | E21: =IF(Estimates!G16="","","("&TEXT(Estimates!G16,"0.00")&")") -> (-2.27) | F21: =IF(Estimates!G17="","","("&TEXT(Estimates!G17,"0.00")&")") -> (-4.88) | G21: =IF(Estimates!G18="","","("&TEXT(Estimates!G18,"0.00")&")") -> (-1.31)
A23: p-value: equal coefficients | B23: =IF(Estimates!H19="","",Estimates!H19) -> 0.05812707 | D23: =IF(Estimates!H20="","",Estimates!H20) -> 0.61521849 | F23: =IF(Estimates!H21="","",Estimates!H21) -> 0.24255844
A24: Observations | B24: 1628 | D24: 1165 | F24: 1426
A25: Adjusted R-squared | B25: 0.082693756 | D25: 0.13186617 | F25: 0.13076551
A26: Controls | B26: Yes | D26: Yes | F26: Yes
A27: Year FE | B27: Yes | D27: Yes | F27: Yes

Sheet Table VI
A1: Table VI: Conflicted CIOs: Alternative Pathways and Plan Performance (updated benchmark)
A2: This table divides the sample by two proxies for alternative pathways to the private sector: an indicator equal to 1 for CIOs with prior private firm experience, and an indicator equal to 1 for plans headquartered in financial centers. Each panel reports regressions of plan performance on Conflicted CIO interacted with the group indicator, with all control variables also interacted with the group indicator, so that the two coefficients are estimated in one regression. The first pair of columns uses Peer-Adjusted Return, as in the paper. The second pair uses Benchmark-Adjusted Return computed with the original policy benchmark, and the third pair uses Benchmark-Adjusted Return recomputed as the plan's return minus the updated policy benchmark (the benchmark return reported in the plan's financial report; where none is stated, a value inferred from the plan's multi-year benchmark returns or from its policy weights and component index returns, graded A or B). The control variables are those of the corresponding regressions in the paper and are defined in Table I. All regressions include year fixed effects. The p-value row tests that the two Conflicted CIO coefficients are equal. The standard errors are double clustered by plan and year (by plan and fiscal-year-end date in Panel B, as in the paper's code). Coefficients marked with ***, **, and * are significant at the 1%, 5%, and 10% level, respectively.
A4: Panel A. Effect of Conflict for CIOs With and Without Prior Private Experience
B5: Peer-Adjusted Return (t) | D5: Benchmark-Adjusted Return, Original Benchmark (t) | F5: Benchmark-Adjusted Return, Updated Benchmark (t)
B6: No Prior Private Exp. | C6: Prior Private Exp. | D6: No Prior Private Exp. | E6: Prior Private Exp. | F6: No Prior Private Exp. | G6: Prior Private Exp.
A7: Conflicted CIO | B7: =IF(Estimates!H22="","n/a",TEXT(Estimates!D22,"0.000")&IF(Estimates!H22<0.01,"***",IF(Estimates!H22<0.05,"**",IF(Estimates!H22<0.1,"*","")))) -> -0.774** | C7: =IF(Estimates!H23="","n/a",TEXT(Estimates!D23,"0.000")&IF(Estimates!H23<0.01,"***",IF(Estimates!H23<0.05,"**",IF(Estimates!H23<0.1,"*","")))) -> -0.266 | D7: =IF(Estimates!H24="","n/a",TEXT(Estimates!D24,"0.000")&IF(Estimates!H24<0.01,"***",IF(Estimates!H24<0.05,"**",IF(Estimates!H24<0.1,"*","")))) -> -0.447 | E7: =IF(Estimates!H25="","n/a",TEXT(Estimates!D25,"0.000")&IF(Estimates!H25<0.01,"***",IF(Estimates!H25<0.05,"**",IF(Estimates!H25<0.1,"*","")))) -> -0.817* | F7: =IF(Estimates!H26="","n/a",TEXT(Estimates!D26,"0.000")&IF(Estimates!H26<0.01,"***",IF(Estimates!H26<0.05,"**",IF(Estimates!H26<0.1,"*","")))) -> -0.388* | G7: =IF(Estimates!H27="","n/a",TEXT(Estimates!D27,"0.000")&IF(Estimates!H27<0.01,"***",IF(Estimates!H27<0.05,"**",IF(Estimates!H27<0.1,"*","")))) -> -0.366*
B8: =IF(Estimates!G22="","","("&TEXT(Estimates!G22,"0.00")&")") -> (-2.30) | C8: =IF(Estimates!G23="","","("&TEXT(Estimates!G23,"0.00")&")") -> (-1.05) | D8: =IF(Estimates!G24="","","("&TEXT(Estimates!G24,"0.00")&")") -> (-1.31) | E8: =IF(Estimates!G25="","","("&TEXT(Estimates!G25,"0.00")&")") -> (-1.81) | F8: =IF(Estimates!G26="","","("&TEXT(Estimates!G26,"0.00")&")") -> (-1.80) | G8: =IF(Estimates!G27="","","("&TEXT(Estimates!G27,"0.00")&")") -> (-1.90)
A10: p-value: equal coefficients | B10: =IF(Estimates!H28="","",Estimates!H28) -> 0.3483133 | D10: =IF(Estimates!H29="","",Estimates!H29) -> 0.5352974 | F10: =IF(Estimates!H30="","",Estimates!H30) -> 0.94875303
A11: Observations | B11: 1484 | D11: 1073 | F11: 1304
A12: Adjusted R-squared | B12: 0.064756054 | D12: 0.11995476 | F12: 0.1171751
A13: Controls | B13: Yes | D13: Yes | F13: Yes
A14: Year FE | B14: Yes | D14: Yes | F14: Yes
A17: Panel B. Effect of Conflict for Plans Located in Financial Centers
B18: Peer-Adjusted Return (t) | D18: Benchmark-Adjusted Return, Original Benchmark (t) | F18: Benchmark-Adjusted Return, Updated Benchmark (t)
B19: Non-Financial Center | C19: Financial Center | D19: Non-Financial Center | E19: Financial Center | F19: Non-Financial Center | G19: Financial Center
A20: Conflicted CIO | B20: =IF(Estimates!H31="","n/a",TEXT(Estimates!D31,"0.000")&IF(Estimates!H31<0.01,"***",IF(Estimates!H31<0.05,"**",IF(Estimates!H31<0.1,"*","")))) -> -0.612*** | C20: =IF(Estimates!H32="","n/a",TEXT(Estimates!D32,"0.000")&IF(Estimates!H32<0.01,"***",IF(Estimates!H32<0.05,"**",IF(Estimates!H32<0.1,"*","")))) -> -0.027 | D20: =IF(Estimates!H33="","n/a",TEXT(Estimates!D33,"0.000")&IF(Estimates!H33<0.01,"***",IF(Estimates!H33<0.05,"**",IF(Estimates!H33<0.1,"*","")))) -> -0.456 | E20: =IF(Estimates!H34="","n/a",TEXT(Estimates!D34,"0.000")&IF(Estimates!H34<0.01,"***",IF(Estimates!H34<0.05,"**",IF(Estimates!H34<0.1,"*","")))) -> -0.673** | F20: =IF(Estimates!H35="","n/a",TEXT(Estimates!D35,"0.000")&IF(Estimates!H35<0.01,"***",IF(Estimates!H35<0.05,"**",IF(Estimates!H35<0.1,"*","")))) -> -0.284 | G20: =IF(Estimates!H36="","n/a",TEXT(Estimates!D36,"0.000")&IF(Estimates!H36<0.01,"***",IF(Estimates!H36<0.05,"**",IF(Estimates!H36<0.1,"*","")))) -> -0.449
B21: =IF(Estimates!G31="","","("&TEXT(Estimates!G31,"0.00")&")") -> (-2.88) | C21: =IF(Estimates!G32="","","("&TEXT(Estimates!G32,"0.00")&")") -> (-0.09) | D21: =IF(Estimates!G33="","","("&TEXT(Estimates!G33,"0.00")&")") -> (-1.64) | E21: =IF(Estimates!G34="","","("&TEXT(Estimates!G34,"0.00")&")") -> (-2.00) | F21: =IF(Estimates!G35="","","("&TEXT(Estimates!G35,"0.00")&")") -> (-1.55) | G21: =IF(Estimates!G36="","","("&TEXT(Estimates!G36,"0.00")&")") -> (-1.33)
A23: p-value: equal coefficients | B23: =IF(Estimates!H37="","",Estimates!H37) -> 0.13422264 | D23: =IF(Estimates!H38="","",Estimates!H38) -> 0.59307089 | F23: =IF(Estimates!H39="","",Estimates!H39) -> 0.6631173
A24: Observations | B24: 1567 | D24: 1127 | F24: 1378
A25: Adjusted R-squared | B25: 0.052239382 | D25: 0.12542607 | F25: 0.12462556
A26: Controls | B26: Yes | D26: Yes | F26: Yes
A27: Year FE | B27: Yes | D27: Yes | F27: Yes

Sheet Table VII
A1: Table VII: Conflicted CIOs: Governance and Plan Performance (updated benchmark)
A2: This table divides the sample by two proxies for the strength of plan governance: an indicator equal to 1 if the plan's discount rate is above 8%, and an indicator equal to 1 for plans with a funding ratio of at least 92%. Each panel reports regressions of plan performance on Conflicted CIO interacted with the group indicator, with all control variables also interacted with the group indicator, so that the two coefficients are estimated in one regression. The first pair of columns uses Peer-Adjusted Return, as in the paper. The second pair uses Benchmark-Adjusted Return computed with the original policy benchmark, and the third pair uses Benchmark-Adjusted Return recomputed as the plan's return minus the updated policy benchmark (the benchmark return reported in the plan's financial report; where none is stated, a value inferred from the plan's multi-year benchmark returns or from its policy weights and component index returns, graded A or B). The control variables are those of the corresponding regressions in the paper and are defined in Table I. All regressions include year fixed effects. The p-value row tests that the two Conflicted CIO coefficients are equal. The standard errors are double clustered by plan and year. Coefficients marked with ***, **, and * are significant at the 1%, 5%, and 10% level, respectively.
A4: Panel A. Effect of Conflict Based on Liability Discount Rate
B5: Peer-Adjusted Return (t) | D5: Benchmark-Adjusted Return, Original Benchmark (t) | F5: Benchmark-Adjusted Return, Updated Benchmark (t)
B6: High Discount Rate | C6: Not High Discount Rate | D6: High Discount Rate | E6: Not High Discount Rate | F6: High Discount Rate | G6: Not High Discount Rate
A7: Conflicted CIO | B7: =IF(Estimates!H40="","n/a",TEXT(Estimates!D40,"0.000")&IF(Estimates!H40<0.01,"***",IF(Estimates!H40<0.05,"**",IF(Estimates!H40<0.1,"*","")))) -> -1.409 | C7: =IF(Estimates!H41="","n/a",TEXT(Estimates!D41,"0.000")&IF(Estimates!H41<0.01,"***",IF(Estimates!H41<0.05,"**",IF(Estimates!H41<0.1,"*","")))) -> -0.382 | D7: =IF(Estimates!H42="","n/a",TEXT(Estimates!D42,"0.000")&IF(Estimates!H42<0.01,"***",IF(Estimates!H42<0.05,"**",IF(Estimates!H42<0.1,"*","")))) -> -0.849 | E7: =IF(Estimates!H43="","n/a",TEXT(Estimates!D43,"0.000")&IF(Estimates!H43<0.01,"***",IF(Estimates!H43<0.05,"**",IF(Estimates!H43<0.1,"*","")))) -> -0.339* | F7: =IF(Estimates!H44="","n/a",TEXT(Estimates!D44,"0.000")&IF(Estimates!H44<0.01,"***",IF(Estimates!H44<0.05,"**",IF(Estimates!H44<0.1,"*","")))) -> -0.964*** | G7: =IF(Estimates!H45="","n/a",TEXT(Estimates!D45,"0.000")&IF(Estimates!H45<0.01,"***",IF(Estimates!H45<0.05,"**",IF(Estimates!H45<0.1,"*","")))) -> -0.094
B8: =IF(Estimates!G40="","","("&TEXT(Estimates!G40,"0.00")&")") -> (-1.45) | C8: =IF(Estimates!G41="","","("&TEXT(Estimates!G41,"0.00")&")") -> (-1.26) | D8: =IF(Estimates!G42="","","("&TEXT(Estimates!G42,"0.00")&")") -> (-1.10) | E8: =IF(Estimates!G43="","","("&TEXT(Estimates!G43,"0.00")&")") -> (-1.98) | F8: =IF(Estimates!G44="","","("&TEXT(Estimates!G44,"0.00")&")") -> (-3.64) | G8: =IF(Estimates!G45="","","("&TEXT(Estimates!G45,"0.00")&")") -> (-0.65)
A10: p-value: equal coefficients | B10: =IF(Estimates!H46="","",Estimates!H46) -> 0.41879561 | D10: =IF(Estimates!H47="","",Estimates!H47) -> 0.53503525 | F10: =IF(Estimates!H48="","",Estimates!H48) -> 0.018417527
A11: Observations | B11: 1552 | D11: 1116 | F11: 1365
A12: Adjusted R-squared | B12: 0.065747273 | D12: 0.15415492 | F12: 0.13707376
A13: Controls | B13: Yes | D13: Yes | F13: Yes
A14: Year FE | B14: Yes | D14: Yes | F14: Yes
A17: Panel B. Effect of Conflict Based on Funding
B18: Peer-Adjusted Return (t) | D18: Benchmark-Adjusted Return, Original Benchmark (t) | F18: Benchmark-Adjusted Return, Updated Benchmark (t)
B19: High Funding | C19: Lower Funding | D19: High Funding | E19: Lower Funding | F19: High Funding | G19: Lower Funding
A20: Conflicted CIO | B20: =IF(Estimates!H49="","n/a",TEXT(Estimates!D49,"0.000")&IF(Estimates!H49<0.01,"***",IF(Estimates!H49<0.05,"**",IF(Estimates!H49<0.1,"*","")))) -> -1.356*** | C20: =IF(Estimates!H50="","n/a",TEXT(Estimates!D50,"0.000")&IF(Estimates!H50<0.01,"***",IF(Estimates!H50<0.05,"**",IF(Estimates!H50<0.1,"*","")))) -> -0.314* | D20: =IF(Estimates!H51="","n/a",TEXT(Estimates!D51,"0.000")&IF(Estimates!H51<0.01,"***",IF(Estimates!H51<0.05,"**",IF(Estimates!H51<0.1,"*","")))) -> -1.077 | E20: =IF(Estimates!H52="","n/a",TEXT(Estimates!D52,"0.000")&IF(Estimates!H52<0.01,"***",IF(Estimates!H52<0.05,"**",IF(Estimates!H52<0.1,"*","")))) -> -0.434 | F20: =IF(Estimates!H53="","n/a",TEXT(Estimates!D53,"0.000")&IF(Estimates!H53<0.01,"***",IF(Estimates!H53<0.05,"**",IF(Estimates!H53<0.1,"*","")))) -> -0.983** | G20: =IF(Estimates!H54="","n/a",TEXT(Estimates!D54,"0.000")&IF(Estimates!H54<0.01,"***",IF(Estimates!H54<0.05,"**",IF(Estimates!H54<0.1,"*","")))) -> -0.185*
B21: =IF(Estimates!G49="","","("&TEXT(Estimates!G49,"0.00")&")") -> (-7.00) | C21: =IF(Estimates!G50="","","("&TEXT(Estimates!G50,"0.00")&")") -> (-2.03) | D21: =IF(Estimates!G51="","","("&TEXT(Estimates!G51,"0.00")&")") -> (-1.67) | E21: =IF(Estimates!G52="","","("&TEXT(Estimates!G52,"0.00")&")") -> (-1.69) | F21: =IF(Estimates!G53="","","("&TEXT(Estimates!G53,"0.00")&")") -> (-2.29) | G21: =IF(Estimates!G54="","","("&TEXT(Estimates!G54,"0.00")&")") -> (-1.92)
A23: p-value: equal coefficients | B23: =IF(Estimates!H55="","",Estimates!H55) -> 6.1540305e-05 | D23: =IF(Estimates!H56="","",Estimates!H56) -> 0.40751951 | F23: =IF(Estimates!H57="","",Estimates!H57) -> 0.08777937
A24: Observations | B24: 1660 | D24: 1200 | F24: 1458
A25: Adjusted R-squared | B25: 0.053092594 | D25: 0.13661353 | F25: 0.13688155
A26: Controls | B26: Yes | D26: Yes | F26: Yes
A27: Year FE | B27: Yes | D27: Yes | F27: Yes

Sheet Benchmark versions
A1: Cross-sectional Conflicted CIO coefficients under alternative performance measures
A2: Each block re-estimates one cross-sectional split with each performance measure. 'Updated' measures use the updated policy benchmark; 'reported only' drops inferred benchmark values; 'all inferred' adds grade C inferred values; 'document-matched' uses the total-fund return reported on the same page as the benchmark instead of the PPD return; the last row keeps only plan-years in which the PPD and document returns agree within 0.5 percentage points. Specifications, fixed effects and clustering as in the corresponding table.
A4: Table V, Panel A: Underpaid CIOs vs. Not Underpaid CIOs
B5: Underpaid CIOs x Conflicted | C5: Not Underpaid CIOs x Conflicted | D5: p-value: equal | E5: Observations
A6: Peer-adjusted return (paper) | B6: =IF(Estimates!H58="","n/a",TEXT(Estimates!D58,"0.000")&IF(Estimates!H58<0.01,"***",IF(Estimates!H58<0.05,"**",IF(Estimates!H58<0.1,"*","")))) -> -0.870*** | C6: =IF(Estimates!H59="","n/a",TEXT(Estimates!D59,"0.000")&IF(Estimates!H59<0.01,"***",IF(Estimates!H59<0.05,"**",IF(Estimates!H59<0.1,"*","")))) -> -0.394 | D6: =IF(Estimates!H60="","",Estimates!H60) -> 0.10117275 | E6: 1495
B7: =IF(Estimates!G58="","","("&TEXT(Estimates!G58,"0.00")&")") -> (-4.27) | C7: =IF(Estimates!G59="","","("&TEXT(Estimates!G59,"0.00")&")") -> (-1.51)
A8: Benchmark-adjusted, original benchmark | B8: =IF(Estimates!H61="","n/a",TEXT(Estimates!D61,"0.000")&IF(Estimates!H61<0.01,"***",IF(Estimates!H61<0.05,"**",IF(Estimates!H61<0.1,"*","")))) -> -0.674* | C8: =IF(Estimates!H62="","n/a",TEXT(Estimates!D62,"0.000")&IF(Estimates!H62<0.01,"***",IF(Estimates!H62<0.05,"**",IF(Estimates!H62<0.1,"*","")))) -> -0.474 | D8: =IF(Estimates!H63="","",Estimates!H63) -> 0.65822199 | E8: 1061
B9: =IF(Estimates!G61="","","("&TEXT(Estimates!G61,"0.00")&")") -> (-1.75) | C9: =IF(Estimates!G62="","","("&TEXT(Estimates!G62,"0.00")&")") -> (-1.72)
A10: Benchmark-adjusted, updated benchmark | B10: =IF(Estimates!H64="","n/a",TEXT(Estimates!D64,"0.000")&IF(Estimates!H64<0.01,"***",IF(Estimates!H64<0.05,"**",IF(Estimates!H64<0.1,"*","")))) -> -0.704*** | C10: =IF(Estimates!H65="","n/a",TEXT(Estimates!D65,"0.000")&IF(Estimates!H65<0.01,"***",IF(Estimates!H65<0.05,"**",IF(Estimates!H65<0.1,"*","")))) -> -0.193 | D10: =IF(Estimates!H66="","",Estimates!H66) -> 0.11721219 | E10: 1308
B11: =IF(Estimates!G64="","","("&TEXT(Estimates!G64,"0.00")&")") -> (-2.98) | C11: =IF(Estimates!G65="","","("&TEXT(Estimates!G65,"0.00")&")") -> (-1.00)
A12: Updated, reported benchmarks only | B12: =IF(Estimates!H67="","n/a",TEXT(Estimates!D67,"0.000")&IF(Estimates!H67<0.01,"***",IF(Estimates!H67<0.05,"**",IF(Estimates!H67<0.1,"*","")))) -> -0.593*** | C12: =IF(Estimates!H68="","n/a",TEXT(Estimates!D68,"0.000")&IF(Estimates!H68<0.01,"***",IF(Estimates!H68<0.05,"**",IF(Estimates!H68<0.1,"*","")))) -> -0.166 | D12: =IF(Estimates!H69="","",Estimates!H69) -> 0.13593864 | E12: 1243
B13: =IF(Estimates!G67="","","("&TEXT(Estimates!G67,"0.00")&")") -> (-3.10) | C13: =IF(Estimates!G68="","","("&TEXT(Estimates!G68,"0.00")&")") -> (-0.87)
A14: Updated, reported + all inferred | B14: =IF(Estimates!H70="","n/a",TEXT(Estimates!D70,"0.000")&IF(Estimates!H70<0.01,"***",IF(Estimates!H70<0.05,"**",IF(Estimates!H70<0.1,"*","")))) -> -0.651*** | C14: =IF(Estimates!H71="","n/a",TEXT(Estimates!D71,"0.000")&IF(Estimates!H71<0.01,"***",IF(Estimates!H71<0.05,"**",IF(Estimates!H71<0.1,"*","")))) -> -0.182 | D14: =IF(Estimates!H72="","",Estimates!H72) -> 0.14920917 | E14: 1438
B15: =IF(Estimates!G70="","","("&TEXT(Estimates!G70,"0.00")&")") -> (-3.13) | C15: =IF(Estimates!G71="","","("&TEXT(Estimates!G71,"0.00")&")") -> (-0.86)
A16: Updated, document-matched return | B16: =IF(Estimates!H73="","n/a",TEXT(Estimates!D73,"0.000")&IF(Estimates!H73<0.01,"***",IF(Estimates!H73<0.05,"**",IF(Estimates!H73<0.1,"*","")))) -> -0.744*** | C16: =IF(Estimates!H74="","n/a",TEXT(Estimates!D74,"0.000")&IF(Estimates!H74<0.01,"***",IF(Estimates!H74<0.05,"**",IF(Estimates!H74<0.1,"*","")))) -> -0.222 | D16: =IF(Estimates!H75="","",Estimates!H75) -> 0.071178876 | E16: 1308
B17: =IF(Estimates!G73="","","("&TEXT(Estimates!G73,"0.00")&")") -> (-3.82) | C17: =IF(Estimates!G74="","","("&TEXT(Estimates!G74,"0.00")&")") -> (-1.26)
A18: Updated, PPD and document returns agree within 0.5 pp | B18: =IF(Estimates!H76="","n/a",TEXT(Estimates!D76,"0.000")&IF(Estimates!H76<0.01,"***",IF(Estimates!H76<0.05,"**",IF(Estimates!H76<0.1,"*","")))) -> -0.776*** | C18: =IF(Estimates!H77="","n/a",TEXT(Estimates!D77,"0.000")&IF(Estimates!H77<0.01,"***",IF(Estimates!H77<0.05,"**",IF(Estimates!H77<0.1,"*","")))) -> -0.261 | D18: =IF(Estimates!H78="","",Estimates!H78) -> 0.07579404 | E18: 1275
B19: =IF(Estimates!G76="","","("&TEXT(Estimates!G76,"0.00")&")") -> (-3.92) | C19: =IF(Estimates!G77="","","("&TEXT(Estimates!G77,"0.00")&")") -> (-1.59)
A21: Table V, Panel B: Young CIOs vs. Not Young CIOs
B22: Young CIOs x Conflicted | C22: Not Young CIOs x Conflicted | D22: p-value: equal | E22: Observations
A23: Peer-adjusted return (paper) | B23: =IF(Estimates!H79="","n/a",TEXT(Estimates!D79,"0.000")&IF(Estimates!H79<0.01,"***",IF(Estimates!H79<0.05,"**",IF(Estimates!H79<0.1,"*","")))) -> -1.213*** | C23: =IF(Estimates!H80="","n/a",TEXT(Estimates!D80,"0.000")&IF(Estimates!H80<0.01,"***",IF(Estimates!H80<0.05,"**",IF(Estimates!H80<0.1,"*","")))) -> -0.385* | D23: =IF(Estimates!H81="","",Estimates!H81) -> 0.05812707 | E23: 1628
B24: =IF(Estimates!G79="","","("&TEXT(Estimates!G79,"0.00")&")") -> (-3.56) | C24: =IF(Estimates!G80="","","("&TEXT(Estimates!G80,"0.00")&")") -> (-1.86)
A25: Benchmark-adjusted, original benchmark | B25: =IF(Estimates!H82="","n/a",TEXT(Estimates!D82,"0.000")&IF(Estimates!H82<0.01,"***",IF(Estimates!H82<0.05,"**",IF(Estimates!H82<0.1,"*","")))) -> -0.865*** | C25: =IF(Estimates!H83="","n/a",TEXT(Estimates!D83,"0.000")&IF(Estimates!H83<0.01,"***",IF(Estimates!H83<0.05,"**",IF(Estimates!H83<0.1,"*","")))) -> -0.630** | D25: =IF(Estimates!H84="","",Estimates!H84) -> 0.61521849 | E25: 1165
B26: =IF(Estimates!G82="","","("&TEXT(Estimates!G82,"0.00")&")") -> (-3.07) | C26: =IF(Estimates!G83="","","("&TEXT(Estimates!G83,"0.00")&")") -> (-2.27)
A27: Benchmark-adjusted, updated benchmark | B27: =IF(Estimates!H85="","n/a",TEXT(Estimates!D85,"0.000")&IF(Estimates!H85<0.01,"***",IF(Estimates!H85<0.05,"**",IF(Estimates!H85<0.1,"*","")))) -> -0.793*** | C27: =IF(Estimates!H86="","n/a",TEXT(Estimates!D86,"0.000")&IF(Estimates!H86<0.01,"***",IF(Estimates!H86<0.05,"**",IF(Estimates!H86<0.1,"*","")))) -> -0.364 | D27: =IF(Estimates!H87="","",Estimates!H87) -> 0.24255844 | E27: 1426
B28: =IF(Estimates!G85="","","("&TEXT(Estimates!G85,"0.00")&")") -> (-4.88) | C28: =IF(Estimates!G86="","","("&TEXT(Estimates!G86,"0.00")&")") -> (-1.31)
A29: Updated, reported benchmarks only | B29: =IF(Estimates!H88="","n/a",TEXT(Estimates!D88,"0.000")&IF(Estimates!H88<0.01,"***",IF(Estimates!H88<0.05,"**",IF(Estimates!H88<0.1,"*","")))) -> -0.560*** | C29: =IF(Estimates!H89="","n/a",TEXT(Estimates!D89,"0.000")&IF(Estimates!H89<0.01,"***",IF(Estimates!H89<0.05,"**",IF(Estimates!H89<0.1,"*","")))) -> -0.386 | D29: =IF(Estimates!H90="","",Estimates!H90) -> 0.63120684 | E29: 1358
B30: =IF(Estimates!G88="","","("&TEXT(Estimates!G88,"0.00")&")") -> (-3.65) | C30: =IF(Estimates!G89="","","("&TEXT(Estimates!G89,"0.00")&")") -> (-1.32)
A31: Updated, reported + all inferred | B31: =IF(Estimates!H91="","n/a",TEXT(Estimates!D91,"0.000")&IF(Estimates!H91<0.01,"***",IF(Estimates!H91<0.05,"**",IF(Estimates!H91<0.1,"*","")))) -> -0.793*** | C31: =IF(Estimates!H92="","n/a",TEXT(Estimates!D92,"0.000")&IF(Estimates!H92<0.01,"***",IF(Estimates!H92<0.05,"**",IF(Estimates!H92<0.1,"*","")))) -> -0.313 | D31: =IF(Estimates!H93="","",Estimates!H93) -> 0.13161978 | E31: 1566
B32: =IF(Estimates!G91="","","("&TEXT(Estimates!G91,"0.00")&")") -> (-6.09) | C32: =IF(Estimates!G92="","","("&TEXT(Estimates!G92,"0.00")&")") -> (-1.11)
A33: Updated, document-matched return | B33: =IF(Estimates!H94="","n/a",TEXT(Estimates!D94,"0.000")&IF(Estimates!H94<0.01,"***",IF(Estimates!H94<0.05,"**",IF(Estimates!H94<0.1,"*","")))) -> -0.856*** | C33: =IF(Estimates!H95="","n/a",TEXT(Estimates!D95,"0.000")&IF(Estimates!H95<0.01,"***",IF(Estimates!H95<0.05,"**",IF(Estimates!H95<0.1,"*","")))) -> -0.360 | D33: =IF(Estimates!H96="","",Estimates!H96) -> 0.18877336 | E33: 1426
B34: =IF(Estimates!G94="","","("&TEXT(Estimates!G94,"0.00")&")") -> (-4.58) | C34: =IF(Estimates!G95="","","("&TEXT(Estimates!G95,"0.00")&")") -> (-1.34)
A35: Updated, PPD and document returns agree within 0.5 pp | B35: =IF(Estimates!H97="","n/a",TEXT(Estimates!D97,"0.000")&IF(Estimates!H97<0.01,"***",IF(Estimates!H97<0.05,"**",IF(Estimates!H97<0.1,"*","")))) -> -0.850*** | C35: =IF(Estimates!H98="","n/a",TEXT(Estimates!D98,"0.000")&IF(Estimates!H98<0.01,"***",IF(Estimates!H98<0.05,"**",IF(Estimates!H98<0.1,"*","")))) -> -0.391 | D35: =IF(Estimates!H99="","",Estimates!H99) -> 0.21993307 | E35: 1391
B36: =IF(Estimates!G97="","","("&TEXT(Estimates!G97,"0.00")&")") -> (-4.47) | C36: =IF(Estimates!G98="","","("&TEXT(Estimates!G98,"0.00")&")") -> (-1.45)
A38: Table VI, Panel A: Prior Private Exp. vs. No Prior Private Exp.
B39: Prior Private Exp. x Conflicted | C39: No Prior Private Exp. x Conflicted | D39: p-value: equal | E39: Observations
A40: Peer-adjusted return (paper) | B40: =IF(Estimates!H100="","n/a",TEXT(Estimates!D100,"0.000")&IF(Estimates!H100<0.01,"***",IF(Estimates!H100<0.05,"**",IF(Estimates!H100<0.1,"*","")))) -> -0.266 | C40: =IF(Estimates!H101="","n/a",TEXT(Estimates!D101,"0.000")&IF(Estimates!H101<0.01,"***",IF(Estimates!H101<0.05,"**",IF(Estimates!H101<0.1,"*","")))) -> -0.774** | D40: =IF(Estimates!H102="","",Estimates!H102) -> 0.3483133 | E40: 1484
B41: =IF(Estimates!G100="","","("&TEXT(Estimates!G100,"0.00")&")") -> (-1.05) | C41: =IF(Estimates!G101="","","("&TEXT(Estimates!G101,"0.00")&")") -> (-2.30)
A42: Benchmark-adjusted, original benchmark | B42: =IF(Estimates!H103="","n/a",TEXT(Estimates!D103,"0.000")&IF(Estimates!H103<0.01,"***",IF(Estimates!H103<0.05,"**",IF(Estimates!H103<0.1,"*","")))) -> -0.817* | C42: =IF(Estimates!H104="","n/a",TEXT(Estimates!D104,"0.000")&IF(Estimates!H104<0.01,"***",IF(Estimates!H104<0.05,"**",IF(Estimates!H104<0.1,"*","")))) -> -0.447 | D42: =IF(Estimates!H105="","",Estimates!H105) -> 0.5352974 | E42: 1073
B43: =IF(Estimates!G103="","","("&TEXT(Estimates!G103,"0.00")&")") -> (-1.81) | C43: =IF(Estimates!G104="","","("&TEXT(Estimates!G104,"0.00")&")") -> (-1.31)
...

Sheet Estimates
A1: Estimates behind the tables. Blue = regression output (coefficient, SE, minimum cluster count). t and p are formulas; p uses the t distribution with (min clusters - 1) df. SE double clustered by plan and fiscal year (plan and fiscal-year-end date for the financial-center split), with the eigenvalue fix.
A3: Split | B3: Dependent variable | C3: Term | D3: Coefficient | E3: SE | F3: Clusters (min) | G3: t | H3: p
A4: underpaid | B4: peer_adj_ret100 | C4: Underpaid CIOs x Conflicted | D4: -0.86980702 | E4: 0.20377637 | F4: 19 | G4: =IF(E4>0,D4/E4,"") -> -4.2684391 | H4: =IF(G4="","",TDIST(ABS(G4),F4-1,2)) -> 0.00046235312
A5: underpaid | B5: peer_adj_ret100 | C5: Not Underpaid CIOs x Conflicted | D5: -0.39400497 | E5: 0.26144816 | F5: 19 | G5: =IF(E5>0,D5/E5,"") -> -1.50701 | H5: =IF(G5="","",TDIST(ABS(G5),F5-1,2)) -> 0.14915764
A6: underpaid | B6: bench_adj_ret_pct | C6: Underpaid CIOs x Conflicted | D6: -0.67372259 | E6: 0.38418697 | F6: 19 | G6: =IF(E6>0,D6/E6,"") -> -1.753632 | H6: =IF(G6="","",TDIST(ABS(G6),F6-1,2)) -> 0.096505079
A7: underpaid | B7: bench_adj_ret_pct | C7: Not Underpaid CIOs x Conflicted | D7: -0.47407607 | E7: 0.27530956 | F7: 19 | G7: =IF(E7>0,D7/E7,"") -> -1.7219746 | H7: =IF(G7="","",TDIST(ABS(G7),F7-1,2)) -> 0.10221337
A8: underpaid | B8: b_AB | C8: Underpaid CIOs x Conflicted | D8: -0.70351924 | E8: 0.2358817 | F8: 19 | G8: =IF(E8>0,D8/E8,"") -> -2.9825088 | H8: =IF(G8="","",TDIST(ABS(G8),F8-1,2)) -> 0.0079831968
A9: underpaid | B9: b_AB | C9: Not Underpaid CIOs x Conflicted | D9: -0.19289142 | E9: 0.19318712 | F9: 19 | G9: =IF(E9>0,D9/E9,"") -> -0.99846933 | H9: =IF(G9="","",TDIST(ABS(G9),F9-1,2)) -> 0.33128613
A10: underpaid | B10: peer_adj_ret100 | C10: difference | D10: -0.47580205 | E10: 0.27540741 | F10: 19 | G10: =IF(E10>0,D10/E10,"") -> -1.7276298 | H10: =IF(G10="","",TDIST(ABS(G10),F10-1,2)) -> 0.10117275
A11: underpaid | B11: bench_adj_ret_pct | C11: difference | D11: -0.19964651 | E11: 0.44385288 | F11: 19 | G11: =IF(E11>0,D11/E11,"") -> -0.44980336 | H11: =IF(G11="","",TDIST(ABS(G11),F11-1,2)) -> 0.65822199
A12: underpaid | B12: b_AB | C12: difference | D12: -0.51062782 | E12: 0.31031438 | F12: 19 | G12: =IF(E12>0,D12/E12,"") -> -1.6455177 | H12: =IF(G12="","",TDIST(ABS(G12),F12-1,2)) -> 0.11721219
A13: young | B13: peer_adj_ret100 | C13: Young CIOs x Conflicted | D13: -1.2134866 | E13: 0.34087032 | F13: 19 | G13: =IF(E13>0,D13/E13,"") -> -3.5599657 | H13: =IF(G13="","",TDIST(ABS(G13),F13-1,2)) -> 0.0022378147
A14: young | B14: peer_adj_ret100 | C14: Not Young CIOs x Conflicted | D14: -0.38519655 | E14: 0.20669836 | F14: 19 | G14: =IF(E14>0,D14/E14,"") -> -1.8635685 | H14: =IF(G14="","",TDIST(ABS(G14),F14-1,2)) -> 0.078780131
A15: young | B15: bench_adj_ret_pct | C15: Young CIOs x Conflicted | D15: -0.86542936 | E15: 0.28192374 | F15: 19 | G15: =IF(E15>0,D15/E15,"") -> -3.0697285 | H15: =IF(G15="","",TDIST(ABS(G15),F15-1,2)) -> 0.0066019748
... A183: fund (versions) | B183: b_AB_ok | C183: difference | D183: -0.79654627 | E183: 0.42270733 | F183: 19 | G183: =IF(E183>0,D183/E183,"") -> -1.8843919 | H183: =IF(G183="","",TDIST(ABS(G183),F183-1,2)) -> 0.075766159
