Workbook

Sheet Table V
A1: Table V: CIO Incentives and Plan Performance, Narrow Controls
A2: Underpaid is the paper's indicator (CIO total compensation below $224,578, the pooled 2009-2014 median; see xsec_interactions_fye1.xlsx, Underpaid checks). Panel C instead uses pay below the median of reported CIO pay in the same fiscal year, filled within the CIO's spell at the plan. Young CIOs are 46 years old or younger (missing when CIO age is missing). Each panel reports one regression of plan performance on Conflicted CIO interacted with the group indicator, with the control variables also interacted with the group indicator, and fiscal-year-end date fixed effects. The control variables are Size, the lagged funding ratio and the lagged allocations to equities, fixed income, real estate, private equity, hedge funds, other alternatives, commodities and cash, each interacted with the group indicator (the funding split omits the lagged funding ratio, as in the paper's code). Benchmark-Adjusted Return is the plan's return minus the updated policy benchmark (reported in the plan's financial report or, where none is stated, an inferred value graded A or B). The p-value row tests that the two Conflicted CIO coefficients are equal. The standard errors are double clustered by plan and year (plan and fiscal-year-end date for the financial-center split). Coefficients marked with ***, **, and * are significant at the 1%, 5%, and 10% level, respectively.
A4: Panel A. Effect of Conflict for Underpaid CIOs
B5: Peer-Adjusted Return (t) | D5: Benchmark-Adjusted Return, Updated Benchmark (t)
B6: Underpaid CIOs | C6: Not Underpaid CIOs | D6: Underpaid CIOs | E6: Not Underpaid CIOs
A7: Conflicted CIO | B7: =IF(Estimates!I4="","n/a",TEXT(Estimates!E4,"0.000")&IF(Estimates!I4<0.01,"***",IF(Estimates!I4<0.05,"**",IF(Estimates!I4<0.1,"*","")))) -> -0.616*** | C7: =IF(Estimates!I5="","n/a",TEXT(Estimates!E5,"0.000")&IF(Estimates!I5<0.01,"***",IF(Estimates!I5<0.05,"**",IF(Estimates!I5<0.1,"*","")))) -> -0.316 | D7: =IF(Estimates!I6="","n/a",TEXT(Estimates!E6,"0.000")&IF(Estimates!I6<0.01,"***",IF(Estimates!I6<0.05,"**",IF(Estimates!I6<0.1,"*","")))) -> -0.398** | E7: =IF(Estimates!I7="","n/a",TEXT(Estimates!E7,"0.000")&IF(Estimates!I7<0.01,"***",IF(Estimates!I7<0.05,"**",IF(Estimates!I7<0.1,"*","")))) -> -0.300*
B8: =IF(Estimates!H4="","","("&TEXT(Estimates!H4,"0.00")&")") -> (-3.53) | C8: =IF(Estimates!H5="","","("&TEXT(Estimates!H5,"0.00")&")") -> (-1.24) | D8: =IF(Estimates!H6="","","("&TEXT(Estimates!H6,"0.00")&")") -> (-2.66) | E8: =IF(Estimates!H7="","","("&TEXT(Estimates!H7,"0.00")&")") -> (-1.79)
A10: p-value: equal coefficients | B10: =IF(Estimates!I8="","",Estimates!I8) -> 0.29490059 | D10: =IF(Estimates!I9="","",Estimates!I9) -> 0.65377058
A11: Observations | B11: 1638 | D11: 1450
A12: Adjusted R-squared | B12: 0.047164461 | D12: 0.14423533
A13: Controls | B13: Narrow | D13: Narrow
A14: Fiscal-Year-End FE | B14: Yes | D14: Yes
A17: Panel B. Effect of Conflict for Younger CIOs
B18: Peer-Adjusted Return (t) | D18: Benchmark-Adjusted Return, Updated Benchmark (t)
B19: Young CIOs | C19: Not Young CIOs | D19: Young CIOs | E19: Not Young CIOs
A20: Conflicted CIO | B20: =IF(Estimates!I10="","n/a",TEXT(Estimates!E10,"0.000")&IF(Estimates!I10<0.01,"***",IF(Estimates!I10<0.05,"**",IF(Estimates!I10<0.1,"*","")))) -> -0.681** | C20: =IF(Estimates!I11="","n/a",TEXT(Estimates!E11,"0.000")&IF(Estimates!I11<0.01,"***",IF(Estimates!I11<0.05,"**",IF(Estimates!I11<0.1,"*","")))) -> -0.467* | D20: =IF(Estimates!I12="","n/a",TEXT(Estimates!E12,"0.000")&IF(Estimates!I12<0.01,"***",IF(Estimates!I12<0.05,"**",IF(Estimates!I12<0.1,"*","")))) -> -0.482** | E20: =IF(Estimates!I13="","n/a",TEXT(Estimates!E13,"0.000")&IF(Estimates!I13<0.01,"***",IF(Estimates!I13<0.05,"**",IF(Estimates!I13<0.1,"*","")))) -> -0.473
B21: =IF(Estimates!H10="","","("&TEXT(Estimates!H10,"0.00")&")") -> (-2.32) | C21: =IF(Estimates!H11="","","("&TEXT(Estimates!H11,"0.00")&")") -> (-2.03) | D21: =IF(Estimates!H12="","","("&TEXT(Estimates!H12,"0.00")&")") -> (-2.16) | E21: =IF(Estimates!H13="","","("&TEXT(Estimates!H13,"0.00")&")") -> (-1.63)
A23: p-value: equal coefficients | B23: =IF(Estimates!I14="","",Estimates!I14) -> 0.60131375 | D23: =IF(Estimates!I15="","",Estimates!I15) -> 0.97922859
A24: Observations | B24: 1716 | D24: 1525
A25: Adjusted R-squared | B25: 0.054760146 | D25: 0.15048589
A26: Controls | B26: Narrow | D26: Narrow
A27: Fiscal-Year-End FE | B27: Yes | D27: Yes
A30: Panel C. Effect of Conflict for Underpaid CIOs, Annual Median
B31: Peer-Adjusted Return (t) | D31: Benchmark-Adjusted Return, Updated Benchmark (t)
B32: Underpaid (annual median) | C32: Not Underpaid (annual median) | D32: Underpaid (annual median) | E32: Not Underpaid (annual median)
A33: Conflicted CIO | B33: =IF(Estimates!I16="","n/a",TEXT(Estimates!E16,"0.000")&IF(Estimates!I16<0.01,"***",IF(Estimates!I16<0.05,"**",IF(Estimates!I16<0.1,"*","")))) -> -0.254 | C33: =IF(Estimates!I17="","n/a",TEXT(Estimates!E17,"0.000")&IF(Estimates!I17<0.01,"***",IF(Estimates!I17<0.05,"**",IF(Estimates!I17<0.1,"*","")))) -> -0.492 | D33: =IF(Estimates!I18="","n/a",TEXT(Estimates!E18,"0.000")&IF(Estimates!I18<0.01,"***",IF(Estimates!I18<0.05,"**",IF(Estimates!I18<0.1,"*","")))) -> -0.023 | E33: =IF(Estimates!I19="","n/a",TEXT(Estimates!E19,"0.000")&IF(Estimates!I19<0.01,"***",IF(Estimates!I19<0.05,"**",IF(Estimates!I19<0.1,"*","")))) -> -0.947*
B34: =IF(Estimates!H16="","","("&TEXT(Estimates!H16,"0.00")&")") -> (-1.16) | C34: =IF(Estimates!H17="","","("&TEXT(Estimates!H17,"0.00")&")") -> (-1.46) | D34: =IF(Estimates!H18="","","("&TEXT(Estimates!H18,"0.00")&")") -> (-0.12) | E34: =IF(Estimates!H19="","","("&TEXT(Estimates!H19,"0.00")&")") -> (-2.08)
A36: p-value: equal coefficients | B36: =IF(Estimates!I20="","",Estimates!I20) -> 0.55205402 | D36: =IF(Estimates!I21="","",Estimates!I21) -> 0.061668275
A37: Observations | B37: 1431 | D37: 1278
A38: Adjusted R-squared | B38: 0.070499117 | D38: 0.15734746
A39: Controls | B39: Narrow | D39: Narrow
A40: Fiscal-Year-End FE | B40: Yes | D40: Yes

Sheet Table VI
A1: Table VI: Alternative Pathways and Plan Performance, Narrow Controls
A2: Prior Private Exp. equals 1 for CIOs with prior private firm experience; Financial Center equals 1 for plans headquartered in financial centers. Each panel reports one regression of plan performance on Conflicted CIO interacted with the group indicator, with the control variables also interacted with the group indicator, and fiscal-year-end date fixed effects. The control variables are Size, the lagged funding ratio and the lagged allocations to equities, fixed income, real estate, private equity, hedge funds, other alternatives, commodities and cash, each interacted with the group indicator (the funding split omits the lagged funding ratio, as in the paper's code). Benchmark-Adjusted Return is the plan's return minus the updated policy benchmark (reported in the plan's financial report or, where none is stated, an inferred value graded A or B). The p-value row tests that the two Conflicted CIO coefficients are equal. The standard errors are double clustered by plan and year (plan and fiscal-year-end date for the financial-center split). Coefficients marked with ***, **, and * are significant at the 1%, 5%, and 10% level, respectively.
A4: Panel A. Effect of Conflict for CIOs With and Without Prior Private Experience
B5: Peer-Adjusted Return (t) | D5: Benchmark-Adjusted Return, Updated Benchmark (t)
B6: No Prior Private Exp. | C6: Prior Private Exp. | D6: No Prior Private Exp. | E6: Prior Private Exp.
A7: Conflicted CIO | B7: =IF(Estimates!I22="","n/a",TEXT(Estimates!E22,"0.000")&IF(Estimates!I22<0.01,"***",IF(Estimates!I22<0.05,"**",IF(Estimates!I22<0.1,"*","")))) -> -0.986*** | C7: =IF(Estimates!I23="","n/a",TEXT(Estimates!E23,"0.000")&IF(Estimates!I23<0.01,"***",IF(Estimates!I23<0.05,"**",IF(Estimates!I23<0.1,"*","")))) -> -0.134 | D7: =IF(Estimates!I24="","n/a",TEXT(Estimates!E24,"0.000")&IF(Estimates!I24<0.01,"***",IF(Estimates!I24<0.05,"**",IF(Estimates!I24<0.1,"*","")))) -> -0.688* | E7: =IF(Estimates!I25="","n/a",TEXT(Estimates!E25,"0.000")&IF(Estimates!I25<0.01,"***",IF(Estimates!I25<0.05,"**",IF(Estimates!I25<0.1,"*","")))) -> -0.237*
B8: =IF(Estimates!H22="","","("&TEXT(Estimates!H22,"0.00")&")") -> (-2.90) | C8: =IF(Estimates!H23="","","("&TEXT(Estimates!H23,"0.00")&")") -> (-0.64) | D8: =IF(Estimates!H24="","","("&TEXT(Estimates!H24,"0.00")&")") -> (-1.90) | E8: =IF(Estimates!H25="","","("&TEXT(Estimates!H25,"0.00")&")") -> (-2.04)
A10: p-value: equal coefficients | B10: =IF(Estimates!I26="","",Estimates!I26) -> 0.097929571 | D10: =IF(Estimates!I27="","",Estimates!I27) -> 0.29487865
A11: Observations | B11: 1623 | D11: 1441
A12: Adjusted R-squared | B12: 0.059999309 | D12: 0.14330565
A13: Controls | B13: Narrow | D13: Narrow
A14: Fiscal-Year-End FE | B14: Yes | D14: Yes
A17: Panel B. Effect of Conflict for Plans Located in Financial Centers
B18: Peer-Adjusted Return (t) | D18: Benchmark-Adjusted Return, Updated Benchmark (t)
B19: Non-Financial Center | C19: Financial Center | D19: Non-Financial Center | E19: Financial Center
A20: Conflicted CIO | B20: =IF(Estimates!I28="","n/a",TEXT(Estimates!E28,"0.000")&IF(Estimates!I28<0.01,"***",IF(Estimates!I28<0.05,"**",IF(Estimates!I28<0.1,"*","")))) -> -0.780*** | C20: =IF(Estimates!I29="","n/a",TEXT(Estimates!E29,"0.000")&IF(Estimates!I29<0.01,"***",IF(Estimates!I29<0.05,"**",IF(Estimates!I29<0.1,"*","")))) -> 0.184 | D20: =IF(Estimates!I30="","n/a",TEXT(Estimates!E30,"0.000")&IF(Estimates!I30<0.01,"***",IF(Estimates!I30<0.05,"**",IF(Estimates!I30<0.1,"*","")))) -> -0.506** | E20: =IF(Estimates!I31="","n/a",TEXT(Estimates!E31,"0.000")&IF(Estimates!I31<0.01,"***",IF(Estimates!I31<0.05,"**",IF(Estimates!I31<0.1,"*","")))) -> -0.187
B21: =IF(Estimates!H28="","","("&TEXT(Estimates!H28,"0.00")&")") -> (-3.25) | C21: =IF(Estimates!H29="","","("&TEXT(Estimates!H29,"0.00")&")") -> (0.77) | D21: =IF(Estimates!H30="","","("&TEXT(Estimates!H30,"0.00")&")") -> (-2.18) | E21: =IF(Estimates!H31="","","("&TEXT(Estimates!H31,"0.00")&")") -> (-1.00)
A23: p-value: equal coefficients | B23: =IF(Estimates!I32="","",Estimates!I32) -> 0.014735584 | D23: =IF(Estimates!I33="","",Estimates!I33) -> 0.35416353
A24: Observations | B24: 1723 | D24: 1532
A25: Adjusted R-squared | B25: 0.03773713 | D25: 0.14251116
A26: Controls | B26: Narrow | D26: Narrow
A27: Fiscal-Year-End FE | B27: Yes | D27: Yes

Sheet Table VII
A1: Table VII: Governance and Plan Performance, Narrow Controls
A2: High Discount Rate equals 1 if the plan's discount rate is above 8%; High Funding equals 1 for funding ratios of at least 92% (missing when the funding ratio is missing). Each panel reports one regression of plan performance on Conflicted CIO interacted with the group indicator, with the control variables also interacted with the group indicator, and fiscal-year-end date fixed effects. The control variables are Size, the lagged funding ratio and the lagged allocations to equities, fixed income, real estate, private equity, hedge funds, other alternatives, commodities and cash, each interacted with the group indicator (the funding split omits the lagged funding ratio, as in the paper's code). Benchmark-Adjusted Return is the plan's return minus the updated policy benchmark (reported in the plan's financial report or, where none is stated, an inferred value graded A or B). The p-value row tests that the two Conflicted CIO coefficients are equal. The standard errors are double clustered by plan and year (plan and fiscal-year-end date for the financial-center split). Coefficients marked with ***, **, and * are significant at the 1%, 5%, and 10% level, respectively.
A4: Panel A. Effect of Conflict Based on Liability Discount Rate
B5: Peer-Adjusted Return (t) | D5: Benchmark-Adjusted Return, Updated Benchmark (t)
B6: High Discount Rate | C6: Not High Discount Rate | D6: High Discount Rate | E6: Not High Discount Rate
A7: Conflicted CIO | B7: =IF(Estimates!I34="","n/a",TEXT(Estimates!E34,"0.000")&IF(Estimates!I34<0.01,"***",IF(Estimates!I34<0.05,"**",IF(Estimates!I34<0.1,"*","")))) -> -1.244** | C7: =IF(Estimates!I35="","n/a",TEXT(Estimates!E35,"0.000")&IF(Estimates!I35<0.01,"***",IF(Estimates!I35<0.05,"**",IF(Estimates!I35<0.1,"*","")))) -> -0.452* | D7: =IF(Estimates!I36="","n/a",TEXT(Estimates!E36,"0.000")&IF(Estimates!I36<0.01,"***",IF(Estimates!I36<0.05,"**",IF(Estimates!I36<0.1,"*","")))) -> -1.167*** | E7: =IF(Estimates!I37="","n/a",TEXT(Estimates!E37,"0.000")&IF(Estimates!I37<0.01,"***",IF(Estimates!I37<0.05,"**",IF(Estimates!I37<0.1,"*","")))) -> -0.288
B8: =IF(Estimates!H34="","","("&TEXT(Estimates!H34,"0.00")&")") -> (-2.16) | C8: =IF(Estimates!H35="","","("&TEXT(Estimates!H35,"0.00")&")") -> (-1.84) | D8: =IF(Estimates!H36="","","("&TEXT(Estimates!H36,"0.00")&")") -> (-4.89) | E8: =IF(Estimates!H37="","","("&TEXT(Estimates!H37,"0.00")&")") -> (-1.23)
A10: p-value: equal coefficients | B10: =IF(Estimates!I38="","",Estimates!I38) -> 0.31381265 | D10: =IF(Estimates!I39="","",Estimates!I39) -> 0.049361297
A11: Observations | B11: 1708 | D11: 1519
A12: Adjusted R-squared | B12: 0.053438458 | D12: 0.1543864
A13: Controls | B13: Narrow | D13: Narrow
A14: Fiscal-Year-End FE | B14: Yes | D14: Yes
A17: Panel B. Effect of Conflict Based on Funding
B18: Peer-Adjusted Return (t) | D18: Benchmark-Adjusted Return, Updated Benchmark (t)
B19: High Funding | C19: Lower Funding | D19: High Funding | E19: Lower Funding
A20: Conflicted CIO | B20: =IF(Estimates!I40="","n/a",TEXT(Estimates!E40,"0.000")&IF(Estimates!I40<0.01,"***",IF(Estimates!I40<0.05,"**",IF(Estimates!I40<0.1,"*","")))) -> -1.468*** | C20: =IF(Estimates!I41="","n/a",TEXT(Estimates!E41,"0.000")&IF(Estimates!I41<0.01,"***",IF(Estimates!I41<0.05,"**",IF(Estimates!I41<0.1,"*","")))) -> -0.384** | D20: =IF(Estimates!I42="","n/a",TEXT(Estimates!E42,"0.000")&IF(Estimates!I42<0.01,"***",IF(Estimates!I42<0.05,"**",IF(Estimates!I42<0.1,"*","")))) -> -1.459*** | E20: =IF(Estimates!I43="","n/a",TEXT(Estimates!E43,"0.000")&IF(Estimates!I43<0.01,"***",IF(Estimates!I43<0.05,"**",IF(Estimates!I43<0.1,"*","")))) -> -0.309
B21: =IF(Estimates!H40="","","("&TEXT(Estimates!H40,"0.00")&")") -> (-4.89) | C21: =IF(Estimates!H41="","","("&TEXT(Estimates!H41,"0.00")&")") -> (-2.33) | D21: =IF(Estimates!H42="","","("&TEXT(Estimates!H42,"0.00")&")") -> (-2.96) | E21: =IF(Estimates!H43="","","("&TEXT(Estimates!H43,"0.00")&")") -> (-1.60)
A23: p-value: equal coefficients | B23: =IF(Estimates!I44="","",Estimates!I44) -> 0.0011679446 | D23: =IF(Estimates!I45="","",Estimates!I45) -> 0.048349842
A24: Observations | B24: 1726 | D24: 1536
A25: Adjusted R-squared | B25: 0.050445247 | D25: 0.15356243
A26: Controls | B26: Narrow | D26: Narrow
A27: Fiscal-Year-End FE | B27: Yes | D27: Yes

Sheet Specification comparison
A1: Cross-Sectional Splits Under Alternative Controls and Fixed Effects
A2: Each block re-estimates one split under five specifications. 'Narrow controls' are listed in the table notes of Tables V-VII on this workbook; 'Paper controls' are the control variables of the corresponding regression in the paper's code. 'Paper-controls sample' keeps only plan-years with all of the paper's controls non-missing, so the row differs from the one above it only in the control variables. The last row of each block is the published specification. Benchmark-Adjusted Return is the plan's return minus the updated policy benchmark (reported in the plan's financial report or, where none is stated, an inferred value graded A or B). The p-value row tests that the two Conflicted CIO coefficients are equal. The standard errors are double clustered by plan and year (plan and fiscal-year-end date for the financial-center split). Coefficients marked with ***, **, and * are significant at the 1%, 5%, and 10% level, respectively.
A4: Table V, Panel A: Group 1 = Underpaid CIOs; Group 0 = Not Underpaid CIOs
B5: Peer-Adjusted Return (t) | G5: Benchmark-Adjusted Return, Updated Benchmark (t)
B6: Group 1 x Conflicted | C6: Group 0 x Conflicted | D6: p-value equal | E6: Obs. | G6: Group 1 x Conflicted | H6: Group 0 x Conflicted | I6: p-value equal | J6: Obs.
A7: Narrow controls, fiscal-year-end FE | B7: =IF(Estimates!I46="","n/a",TEXT(Estimates!E46,"0.000")&IF(Estimates!I46<0.01,"***",IF(Estimates!I46<0.05,"**",IF(Estimates!I46<0.1,"*","")))) -> -0.616*** | C7: =IF(Estimates!I47="","n/a",TEXT(Estimates!E47,"0.000")&IF(Estimates!I47<0.01,"***",IF(Estimates!I47<0.05,"**",IF(Estimates!I47<0.1,"*","")))) -> -0.316 | D7: =IF(Estimates!I48="","",Estimates!I48) -> 0.29490059 | E7: 1638 | G7: =IF(Estimates!I49="","n/a",TEXT(Estimates!E49,"0.000")&IF(Estimates!I49<0.01,"***",IF(Estimates!I49<0.05,"**",IF(Estimates!I49<0.1,"*","")))) -> -0.398** | H7: =IF(Estimates!I50="","n/a",TEXT(Estimates!E50,"0.000")&IF(Estimates!I50<0.01,"***",IF(Estimates!I50<0.05,"**",IF(Estimates!I50<0.1,"*","")))) -> -0.300* | I7: =IF(Estimates!I51="","",Estimates!I51) -> 0.65377058 | J7: 1450
B8: =IF(Estimates!H46="","","("&TEXT(Estimates!H46,"0.00")&")") -> (-3.53) | C8: =IF(Estimates!H47="","","("&TEXT(Estimates!H47,"0.00")&")") -> (-1.24) | G8: =IF(Estimates!H49="","","("&TEXT(Estimates!H49,"0.00")&")") -> (-2.66) | H8: =IF(Estimates!H50="","","("&TEXT(Estimates!H50,"0.00")&")") -> (-1.79)
A9: Narrow controls, year FE | B9: =IF(Estimates!I52="","n/a",TEXT(Estimates!E52,"0.000")&IF(Estimates!I52<0.01,"***",IF(Estimates!I52<0.05,"**",IF(Estimates!I52<0.1,"*","")))) -> -0.580*** | C9: =IF(Estimates!I53="","n/a",TEXT(Estimates!E53,"0.000")&IF(Estimates!I53<0.01,"***",IF(Estimates!I53<0.05,"**",IF(Estimates!I53<0.1,"*","")))) -> -0.299 | D9: =IF(Estimates!I54="","",Estimates!I54) -> 0.33578606 | E9: 1642 | G9: =IF(Estimates!I55="","n/a",TEXT(Estimates!E55,"0.000")&IF(Estimates!I55<0.01,"***",IF(Estimates!I55<0.05,"**",IF(Estimates!I55<0.1,"*","")))) -> -0.365** | H9: =IF(Estimates!I56="","n/a",TEXT(Estimates!E56,"0.000")&IF(Estimates!I56<0.01,"***",IF(Estimates!I56<0.05,"**",IF(Estimates!I56<0.1,"*","")))) -> -0.268* | I9: =IF(Estimates!I57="","",Estimates!I57) -> 0.65521405 | J9: 1456
B10: =IF(Estimates!H52="","","("&TEXT(Estimates!H52,"0.00")&")") -> (-3.40) | C10: =IF(Estimates!H53="","","("&TEXT(Estimates!H53,"0.00")&")") -> (-1.27) | G10: =IF(Estimates!H55="","","("&TEXT(Estimates!H55,"0.00")&")") -> (-2.75) | H10: =IF(Estimates!H56="","","("&TEXT(Estimates!H56,"0.00")&")") -> (-1.81)
A11: Narrow controls, fiscal-year-end FE, paper-controls sample | B11: =IF(Estimates!I58="","n/a",TEXT(Estimates!E58,"0.000")&IF(Estimates!I58<0.01,"***",IF(Estimates!I58<0.05,"**",IF(Estimates!I58<0.1,"*","")))) -> -0.585** | C11: =IF(Estimates!I59="","n/a",TEXT(Estimates!E59,"0.000")&IF(Estimates!I59<0.01,"***",IF(Estimates!I59<0.05,"**",IF(Estimates!I59<0.1,"*","")))) -> -0.410 | D11: =IF(Estimates!I60="","",Estimates!I60) -> 0.5573365 | E11: 1490 | G11: =IF(Estimates!I61="","n/a",TEXT(Estimates!E61,"0.000")&IF(Estimates!I61<0.01,"***",IF(Estimates!I61<0.05,"**",IF(Estimates!I61<0.1,"*","")))) -> -0.305 | H11: =IF(Estimates!I62="","n/a",TEXT(Estimates!E62,"0.000")&IF(Estimates!I62<0.01,"***",IF(Estimates!I62<0.05,"**",IF(Estimates!I62<0.1,"*","")))) -> -0.285 | I11: =IF(Estimates!I63="","",Estimates!I63) -> 0.93280651 | J11: 1319
B12: =IF(Estimates!H58="","","("&TEXT(Estimates!H58,"0.00")&")") -> (-2.76) | C12: =IF(Estimates!H59="","","("&TEXT(Estimates!H59,"0.00")&")") -> (-1.54) | G12: =IF(Estimates!H61="","","("&TEXT(Estimates!H61,"0.00")&")") -> (-1.67) | H12: =IF(Estimates!H62="","","("&TEXT(Estimates!H62,"0.00")&")") -> (-1.71)
A13: Paper controls, fiscal-year-end FE | B13: =IF(Estimates!I64="","n/a",TEXT(Estimates!E64,"0.000")&IF(Estimates!I64<0.01,"***",IF(Estimates!I64<0.05,"**",IF(Estimates!I64<0.1,"*","")))) -> -0.815*** | C13: =IF(Estimates!I65="","n/a",TEXT(Estimates!E65,"0.000")&IF(Estimates!I65<0.01,"***",IF(Estimates!I65<0.05,"**",IF(Estimates!I65<0.1,"*","")))) -> -0.267 | D13: =IF(Estimates!I66="","",Estimates!I66) -> 0.048708472 | E13: 1490 | G13: =IF(Estimates!I67="","n/a",TEXT(Estimates!E67,"0.000")&IF(Estimates!I67<0.01,"***",IF(Estimates!I67<0.05,"**",IF(Estimates!I67<0.1,"*","")))) -> -0.664** | H13: =IF(Estimates!I68="","n/a",TEXT(Estimates!E68,"0.000")&IF(Estimates!I68<0.01,"***",IF(Estimates!I68<0.05,"**",IF(Estimates!I68<0.1,"*","")))) -> -0.138 | I13: =IF(Estimates!I69="","",Estimates!I69) -> 0.11884577 | J13: 1319
B14: =IF(Estimates!H64="","","("&TEXT(Estimates!H64,"0.00")&")") -> (-4.28) | C14: =IF(Estimates!H65="","","("&TEXT(Estimates!H65,"0.00")&")") -> (-1.04) | G14: =IF(Estimates!H67="","","("&TEXT(Estimates!H67,"0.00")&")") -> (-2.79) | H14: =IF(Estimates!H68="","","("&TEXT(Estimates!H68,"0.00")&")") -> (-0.64)
A15: Paper controls, year FE (published specification) | B15: =IF(Estimates!I70="","n/a",TEXT(Estimates!E70,"0.000")&IF(Estimates!I70<0.01,"***",IF(Estimates!I70<0.05,"**",IF(Estimates!I70<0.1,"*","")))) -> -0.870*** | C15: =IF(Estimates!I71="","n/a",TEXT(Estimates!E71,"0.000")&IF(Estimates!I71<0.01,"***",IF(Estimates!I71<0.05,"**",IF(Estimates!I71<0.1,"*","")))) -> -0.394 | D15: =IF(Estimates!I72="","",Estimates!I72) -> 0.10117275 | E15: 1495 | G15: =IF(Estimates!I73="","n/a",TEXT(Estimates!E73,"0.000")&IF(Estimates!I73<0.01,"***",IF(Estimates!I73<0.05,"**",IF(Estimates!I73<0.1,"*","")))) -> -0.716*** | H15: =IF(Estimates!I74="","n/a",TEXT(Estimates!E74,"0.000")&IF(Estimates!I74<0.01,"***",IF(Estimates!I74<0.05,"**",IF(Estimates!I74<0.1,"*","")))) -> -0.197 | I15: =IF(Estimates!I75="","",Estimates!I75) -> 0.12300654 | J15: 1326
B16: =IF(Estimates!H70="","","("&TEXT(Estimates!H70,"0.00")&")") -> (-4.27) | C16: =IF(Estimates!H71="","","("&TEXT(Estimates!H71,"0.00")&")") -> (-1.51) | G16: =IF(Estimates!H73="","","("&TEXT(Estimates!H73,"0.00")&")") -> (-2.89) | H16: =IF(Estimates!H74="","","("&TEXT(Estimates!H74,"0.00")&")") -> (-1.03)
A18: Table V, Panel C: Group 1 = Underpaid (annual median); Group 0 = Not Underpaid (annual median)
B19: Peer-Adjusted Return (t) | G19: Benchmark-Adjusted Return, Updated Benchmark (t)
B20: Group 1 x Conflicted | C20: Group 0 x Conflicted | D20: p-value equal | E20: Obs. | G20: Group 1 x Conflicted | H20: Group 0 x Conflicted | I20: p-value equal | J20: Obs.
A21: Narrow controls, fiscal-year-end FE | B21: =IF(Estimates!I76="","n/a",TEXT(Estimates!E76,"0.000")&IF(Estimates!I76<0.01,"***",IF(Estimates!I76<0.05,"**",IF(Estimates!I76<0.1,"*","")))) -> -0.254 | C21: =IF(Estimates!I77="","n/a",TEXT(Estimates!E77,"0.000")&IF(Estimates!I77<0.01,"***",IF(Estimates!I77<0.05,"**",IF(Estimates!I77<0.1,"*","")))) -> -0.492 | D21: =IF(Estimates!I78="","",Estimates!I78) -> 0.55205402 | E21: 1431 | G21: =IF(Estimates!I79="","n/a",TEXT(Estimates!E79,"0.000")&IF(Estimates!I79<0.01,"***",IF(Estimates!I79<0.05,"**",IF(Estimates!I79<0.1,"*","")))) -> -0.023 | H21: =IF(Estimates!I80="","n/a",TEXT(Estimates!E80,"0.000")&IF(Estimates!I80<0.01,"***",IF(Estimates!I80<0.05,"**",IF(Estimates!I80<0.1,"*","")))) -> -0.947* | I21: =IF(Estimates!I81="","",Estimates!I81) -> 0.061668275 | J21: 1278
B22: =IF(Estimates!H76="","","("&TEXT(Estimates!H76,"0.00")&")") -> (-1.16) | C22: =IF(Estimates!H77="","","("&TEXT(Estimates!H77,"0.00")&")") -> (-1.46) | G22: =IF(Estimates!H79="","","("&TEXT(Estimates!H79,"0.00")&")") -> (-0.12) | H22: =IF(Estimates!H80="","","("&TEXT(Estimates!H80,"0.00")&")") -> (-2.08)
A23: Narrow controls, year FE | B23: =IF(Estimates!I82="","n/a",TEXT(Estimates!E82,"0.000")&IF(Estimates!I82<0.01,"***",IF(Estimates!I82<0.05,"**",IF(Estimates!I82<0.1,"*","")))) -> -0.271 | C23: =IF(Estimates!I83="","n/a",TEXT(Estimates!E83,"0.000")&IF(Estimates!I83<0.01,"***",IF(Estimates!I83<0.05,"**",IF(Estimates!I83<0.1,"*","")))) -> -0.486 | D23: =IF(Estimates!I84="","",Estimates!I84) -> 0.57764593 | E23: 1435 | G23: =IF(Estimates!I85="","n/a",TEXT(Estimates!E85,"0.000")&IF(Estimates!I85<0.01,"***",IF(Estimates!I85<0.05,"**",IF(Estimates!I85<0.1,"*","")))) -> 0.017 | H23: =IF(Estimates!I86="","n/a",TEXT(Estimates!E86,"0.000")&IF(Estimates!I86<0.01,"***",IF(Estimates!I86<0.05,"**",IF(Estimates!I86<0.1,"*","")))) -> -0.746* | I23: =IF(Estimates!I87="","",Estimates!I87) -> 0.10691955 | J23: 1284
B24: =IF(Estimates!H82="","","("&TEXT(Estimates!H82,"0.00")&")") -> (-1.33) | C24: =IF(Estimates!H83="","","("&TEXT(Estimates!H83,"0.00")&")") -> (-1.61) | G24: =IF(Estimates!H85="","","("&TEXT(Estimates!H85,"0.00")&")") -> (0.10) | H24: =IF(Estimates!H86="","","("&TEXT(Estimates!H86,"0.00")&")") -> (-1.83)
A25: Narrow controls, fiscal-year-end FE, paper-controls sample | B25: =IF(Estimates!I88="","n/a",TEXT(Estimates!E88,"0.000")&IF(Estimates!I88<0.01,"***",IF(Estimates!I88<0.05,"**",IF(Estimates!I88<0.1,"*","")))) -> -0.283 | C25: =IF(Estimates!I89="","n/a",TEXT(Estimates!E89,"0.000")&IF(Estimates!I89<0.01,"***",IF(Estimates!I89<0.05,"**",IF(Estimates!I89<0.1,"*","")))) -> -0.494* | D25: =IF(Estimates!I90="","",Estimates!I90) -> 0.39013954 | E25: 1308 | G25: =IF(Estimates!I91="","n/a",TEXT(Estimates!E91,"0.000")&IF(Estimates!I91<0.01,"***",IF(Estimates!I91<0.05,"**",IF(Estimates!I91<0.1,"*","")))) -> 0.011 | H25: =IF(Estimates!I92="","n/a",TEXT(Estimates!E92,"0.000")&IF(Estimates!I92<0.01,"***",IF(Estimates!I92<0.05,"**",IF(Estimates!I92<0.1,"*","")))) -> -0.689** | I25: =IF(Estimates!I93="","",Estimates!I93) -> 0.025496532 | J25: 1172
B26: =IF(Estimates!H88="","","("&TEXT(Estimates!H88,"0.00")&")") -> (-1.31) | C26: =IF(Estimates!H89="","","("&TEXT(Estimates!H89,"0.00")&")") -> (-1.92) | G26: =IF(Estimates!H91="","","("&TEXT(Estimates!H91,"0.00")&")") -> (0.07) | H26: =IF(Estimates!H92="","","("&TEXT(Estimates!H92,"0.00")&")") -> (-2.65)
A27: Paper controls, fiscal-year-end FE | B27: =IF(Estimates!I94="","n/a",TEXT(Estimates!E94,"0.000")&IF(Estimates!I94<0.01,"***",IF(Estimates!I94<0.05,"**",IF(Estimates!I94<0.1,"*","")))) -> -0.328 | C27: =IF(Estimates!I95="","n/a",TEXT(Estimates!E95,"0.000")&IF(Estimates!I95<0.01,"***",IF(Estimates!I95<0.05,"**",IF(Estimates!I95<0.1,"*","")))) -> -0.175 | D27: =IF(Estimates!I96="","",Estimates!I96) -> 0.68890504 | E27: 1308 | G27: =IF(Estimates!I97="","n/a",TEXT(Estimates!E97,"0.000")&IF(Estimates!I97<0.01,"***",IF(Estimates!I97<0.05,"**",IF(Estimates!I97<0.1,"*","")))) -> -0.124 | H27: =IF(Estimates!I98="","n/a",TEXT(Estimates!E98,"0.000")&IF(Estimates!I98<0.01,"***",IF(Estimates!I98<0.05,"**",IF(Estimates!I98<0.1,"*","")))) -> -0.415 | I27: =IF(Estimates!I99="","",Estimates!I99) -> 0.47495651 | J27: 1172
B28: =IF(Estimates!H94="","","("&TEXT(Estimates!H94,"0.00")&")") -> (-1.24) | C28: =IF(Estimates!H95="","","("&TEXT(Estimates!H95,"0.00")&")") -> (-0.64) | G28: =IF(Estimates!H97="","","("&TEXT(Estimates!H97,"0.00")&")") -> (-0.41) | H28: =IF(Estimates!H98="","","("&TEXT(Estimates!H98,"0.00")&")") -> (-1.48)
A29: Paper controls, year FE (published specification) | B29: =IF(Estimates!I100="","n/a",TEXT(Estimates!E100,"0.000")&IF(Estimates!I100<0.01,"***",IF(Estimates!I100<0.05,"**",IF(Estimates!I100<0.1,"*","")))) -> -0.413* | C29: =IF(Estimates!I101="","n/a",TEXT(Estimates!E101,"0.000")&IF(Estimates!I101<0.01,"***",IF(Estimates!I101<0.05,"**",IF(Estimates!I101<0.1,"*","")))) -> -0.243 | D29: =IF(Estimates!I102="","",Estimates!I102) -> 0.60654049 | E29: 1313 | G29: =IF(Estimates!I103="","n/a",TEXT(Estimates!E103,"0.000")&IF(Estimates!I103<0.01,"***",IF(Estimates!I103<0.05,"**",IF(Estimates!I103<0.1,"*","")))) -> -0.131 | H29: =IF(Estimates!I104="","n/a",TEXT(Estimates!E104,"0.000")&IF(Estimates!I104<0.01,"***",IF(Estimates!I104<0.05,"**",IF(Estimates!I104<0.1,"*","")))) -> -0.384 | I29: =IF(Estimates!I105="","",Estimates!I105) -> 0.52280464 | J29: 1179
B30: =IF(Estimates!H100="","","("&TEXT(Estimates!H100,"0.00")&")") -> (-1.78) | C30: =IF(Estimates!H101="","","("&TEXT(Estimates!H101,"0.00")&")") -> (-1.01) | G30: =IF(Estimates!H103="","","("&TEXT(Estimates!H103,"0.00")&")") -> (-0.44) | H30: =IF(Estimates!H104="","","("&TEXT(Estimates!H104,"0.00")&")") -> (-1.61)
A32: Table V, Panel B: Group 1 = Young CIOs; Group 0 = Not Young CIOs
B33: Peer-Adjusted Return (t) | G33: Benchmark-Adjusted Return, Updated Benchmark (t)
B34: Group 1 x Conflicted | C34: Group 0 x Conflicted | D34: p-value equal | E34: Obs. | G34: Group 1 x Conflicted | H34: Group 0 x Conflicted | I34: p-value equal | J34: Obs.
A35: Narrow controls, fiscal-year-end FE | B35: =IF(Estimates!I106="","n/a",TEXT(Estimates!E106,"0.000")&IF(Estimates!I106<0.01,"***",IF(Estimates!I106<0.05,"**",IF(Estimates!I106<0.1,"*","")))) -> -0.681** | C35: =IF(Estimates!I107="","n/a",TEXT(Estimates!E107,"0.000")&IF(Estimates!I107<0.01,"***",IF(Estimates!I107<0.05,"**",IF(Estimates!I107<0.1,"*","")))) -> -0.467* | D35: =IF(Estimates!I108="","",Estimates!I108) -> 0.60131375 | E35: 1716 | G35: =IF(Estimates!I109="","n/a",TEXT(Estimates!E109,"0.000")&IF(Estimates!I109<0.01,"***",IF(Estimates!I109<0.05,"**",IF(Estimates!I109<0.1,"*","")))) -> -0.482** | H35: =IF(Estimates!I110="","n/a",TEXT(Estimates!E110,"0.000")&IF(Estimates!I110<0.01,"***",IF(Estimates!I110<0.05,"**",IF(Estimates!I110<0.1,"*","")))) -> -0.473 | I35: =IF(Estimates!I111="","",Estimates!I111) -> 0.97922859 | J35: 1525
B36: =IF(Estimates!H106="","","("&TEXT(Estimates!H106,"0.00")&")") -> (-2.32) | C36: =IF(Estimates!H107="","","("&TEXT(Estimates!H107,"0.00")&")") -> (-2.03) | G36: =IF(Estimates!H109="","","("&TEXT(Estimates!H109,"0.00")&")") -> (-2.16) | H36: =IF(Estimates!H110="","","("&TEXT(Estimates!H110,"0.00")&")") -> (-1.63)
A37: Narrow controls, year FE | B37: =IF(Estimates!I112="","n/a",TEXT(Estimates!E112,"0.000")&IF(Estimates!I112<0.01,"***",IF(Estimates!I112<0.05,"**",IF(Estimates!I112<0.1,"*","")))) -> -0.747** | C37: =IF(Estimates!I113="","n/a",TEXT(Estimates!E113,"0.000")&IF(Estimates!I113<0.01,"***",IF(Estimates!I113<0.05,"**",IF(Estimates!I113<0.1,"*","")))) -> -0.390* | D37: =IF(Estimates!I114="","",Estimates!I114) -> 0.36161895 | E37: 1720 | G37: =IF(Estimates!I115="","n/a",TEXT(Estimates!E115,"0.000")&IF(Estimates!I115<0.01,"***",IF(Estimates!I115<0.05,"**",IF(Estimates!I115<0.1,"*","")))) -> -0.394** | H37: =IF(Estimates!I116="","n/a",TEXT(Estimates!E116,"0.000")&IF(Estimates!I116<0.01,"***",IF(Estimates!I116<0.05,"**",IF(Estimates!I116<0.1,"*","")))) -> -0.378 | I37: =IF(Estimates!I117="","",Estimates!I117) -> 0.96322446 | J37: 1531
B38: =IF(Estimates!H112="","","("&TEXT(Estimates!H112,"0.00")&")") -> (-2.84) | C38: =IF(Estimates!H113="","","("&TEXT(Estimates!H113,"0.00")&")") -> (-1.87) | G38: =IF(Estimates!H115="","","("&TEXT(Estimates!H115,"0.00")&")") -> (-2.12) | H38: =IF(Estimates!H116="","","("&TEXT(Estimates!H116,"0.00")&")") -> (-1.42)
A39: Narrow controls, fiscal-year-end FE, paper-controls sample | B39: =IF(Estimates!I118="","n/a",TEXT(Estimates!E118,"0.000")&IF(Estimates!I118<0.01,"***",IF(Estimates!I118<0.05,"**",IF(Estimates!I118<0.1,"*","")))) -> -0.858** | C39: =IF(Estimates!I119="","n/a",TEXT(Estimates!E119,"0.000")&IF(Estimates!I119<0.01,"***",IF(Estimates!I119<0.05,"**",IF(Estimates!I119<0.1,"*","")))) -> -0.509** | D39: =IF(Estimates!I120="","",Estimates!I120) -> 0.46262089 | E39: 1615 | G39: =IF(Estimates!I121="","n/a",TEXT(Estimates!E121,"0.000")&IF(Estimates!I121<0.01,"***",IF(Estimates!I121<0.05,"**",IF(Estimates!I121<0.1,"*","")))) -> -0.553** | H39: =IF(Estimates!I122="","n/a",TEXT(Estimates!E122,"0.000")&IF(Estimates!I122<0.01,"***",IF(Estimates!I122<0.05,"**",IF(Estimates!I122<0.1,"*","")))) -> -0.504 | I39: =IF(Estimates!I123="","",Estimates!I123) -> 0.89713034 | J39: 1431
B40: =IF(Estimates!H118="","","("&TEXT(Estimates!H118,"0.00")&")") -> (-2.15) | C40: =IF(Estimates!H119="","","("&TEXT(Estimates!H119,"0.00")&")") -> (-2.19) | G40: =IF(Estimates!H121="","","("&TEXT(Estimates!H121,"0.00")&")") -> (-2.41) | H40: =IF(Estimates!H122="","","("&TEXT(Estimates!H122,"0.00")&")") -> (-1.64)
A41: Paper controls, fiscal-year-end FE | B41: =IF(Estimates!I124="","n/a",TEXT(Estimates!E124,"0.000")&IF(Estimates!I124<0.01,"***",IF(Estimates!I124<0.05,"**",IF(Estimates!I124<0.1,"*","")))) -> -1.015** | C41: =IF(Estimates!I125="","n/a",TEXT(Estimates!E125,"0.000")&IF(Estimates!I125<0.01,"***",IF(Estimates!I125<0.05,"**",IF(Estimates!I125<0.1,"*","")))) -> -0.418** | D41: =IF(Estimates!I126="","",Estimates!I126) -> 0.18402878 | E41: 1615 | G41: =IF(Estimates!I127="","n/a",TEXT(Estimates!E127,"0.000")&IF(Estimates!I127<0.01,"***",IF(Estimates!I127<0.05,"**",IF(Estimates!I127<0.1,"*","")))) -> -0.850*** | H41: =IF(Estimates!I128="","n/a",TEXT(Estimates!E128,"0.000")&IF(Estimates!I128<0.01,"***",IF(Estimates!I128<0.05,"**",IF(Estimates!I128<0.1,"*","")))) -> -0.399 | I41: =IF(Estimates!I129="","",Estimates!I129) -> 0.2186411 | J41: 1431
B42: =IF(Estimates!H124="","","("&TEXT(Estimates!H124,"0.00")&")") -> (-2.67) | C42: =IF(Estimates!H125="","","("&TEXT(Estimates!H125,"0.00")&")") -> (-2.22) | G42: =IF(Estimates!H127="","","("&TEXT(Estimates!H127,"0.00")&")") -> (-4.35) | H42: =IF(Estimates!H128="","","("&TEXT(Estimates!H128,"0.00")&")") -> (-1.46)
A43: Paper controls, year FE (published specification) | B43: =IF(Estimates!I130="","n/a",TEXT(Estimates!E130,"0.000")&IF(Estimates!I130<0.01,"***",IF(Estimates!I130<0.05,"**",IF(Estimates!I130<0.1,"*","")))) -> -1.216*** | C43: =IF(Estimates!I131="","n/a",TEXT(Estimates!E131,"0.000")&IF(Estimates!I131<0.01,"***",IF(Estimates!I131<0.05,"**",IF(Estimates!I131<0.1,"*","")))) -> -0.370* | D43: =IF(Estimates!I132="","",Estimates!I132) -> 0.049998381 | E43: 1621 | G43: =IF(Estimates!I133="","n/a",TEXT(Estimates!E133,"0.000")&IF(Estimates!I133<0.01,"***",IF(Estimates!I133<0.05,"**",IF(Estimates!I133<0.1,"*","")))) -> -0.776*** | H43: =IF(Estimates!I134="","n/a",TEXT(Estimates!E134,"0.000")&IF(Estimates!I134<0.01,"***",IF(Estimates!I134<0.05,"**",IF(Estimates!I134<0.1,"*","")))) -> -0.356 | I43: =IF(Estimates!I135="","",Estimates!I135) -> 0.23065267 | J43: 1439
...

Sheet Compensation splits
A1: Effect of Conflict by CIO Pay: Alternative Definitions
A2: Each row splits the sample by a different definition of high versus low CIO pay, computed from reported CIO_TotalComp over all plan-years with reported pay and filled within the CIO's spell at the plan (years without reported pay take the nearest earlier reported year, or the first reported year), as the paper's Underpaid measure is filled. The first row reproduces the paper's Underpaid cutoff on this sample (spells without any reported pay drop out). Inflation-adjusted pay deflates by the CPI-U annual average (BLS series CUUR0000SA0) to 2020 dollars. Pay given plan size is the residual from a regression of log pay on Size and fiscal-year indicators. The top-third, top-quarter and bottom-third cutoffs are computed within each fiscal year. The last columns report the share of plan-years in the lower-paid group, overall, for conflicted plan-years, and by period (2001-2008 / 2009-2014 / 2015-2020). Panel A uses the narrow controls with fiscal-year-end date fixed effects; Panel B uses the paper's controls for the Underpaid split with year fixed effects (the published specification). Benchmark-Adjusted Return is the plan's return minus the updated policy benchmark (reported in the plan's financial report or, where none is stated, an inferred value graded A or B). The p-value row tests that the two Conflicted CIO coefficients are equal. The standard errors are double clustered by plan and year (plan and fiscal-year-end date for the financial-center split). Coefficients marked with ***, **, and * are significant at the 1%, 5%, and 10% level, respectively.
A4: Panel A. Narrow controls, fiscal-year-end FE
B5: Peer-Adjusted Return (t) | G5: Benchmark-Adjusted Return, Updated Benchmark (t)
A6: Definition of the lower-paid group | B6: Lower-paid x Conflicted | C6: Higher-paid x Conflicted | D6: p-value equal | E6: Obs. | G6: Lower-paid x Conflicted | H6: Higher-paid x Conflicted | I6: p-value equal | J6: Obs. | L6: Share lower-paid (all / conflicted) | M6: Share lower-paid by period
A7: Below $224,578 (paper code: pooled 2009-14 median) | B7: =IF(Estimates!I256="","n/a",TEXT(Estimates!E256,"0.000")&IF(Estimates!I256<0.01,"***",IF(Estimates!I256<0.05,"**",IF(Estimates!I256<0.1,"*","")))) -> -0.465** | C7: =IF(Estimates!I257="","n/a",TEXT(Estimates!E257,"0.000")&IF(Estimates!I257<0.01,"***",IF(Estimates!I257<0.05,"**",IF(Estimates!I257<0.1,"*","")))) -> -0.248 | D7: =IF(Estimates!I258="","",Estimates!I258) -> 0.60773047 | E7: 1431 | G7: =IF(Estimates!I259="","n/a",TEXT(Estimates!E259,"0.000")&IF(Estimates!I259<0.01,"***",IF(Estimates!I259<0.05,"**",IF(Estimates!I259<0.1,"*","")))) -> -0.357 | H7: =IF(Estimates!I260="","n/a",TEXT(Estimates!E260,"0.000")&IF(Estimates!I260<0.01,"***",IF(Estimates!I260<0.05,"**",IF(Estimates!I260<0.1,"*","")))) -> -0.575 | I7: =IF(Estimates!I261="","",Estimates!I261) -> 0.61031574 | J7: 1278 | L7: 0.53 / 0.64 | M7: 0.73 / 0.47 / 0.27
B8: =IF(Estimates!H256="","","("&TEXT(Estimates!H256,"0.00")&")") -> (-2.42) | C8: =IF(Estimates!H257="","","("&TEXT(Estimates!H257,"0.00")&")") -> (-0.70) | G8: =IF(Estimates!H259="","","("&TEXT(Estimates!H259,"0.00")&")") -> (-1.70) | H8: =IF(Estimates!H260="","","("&TEXT(Estimates!H260,"0.00")&")") -> (-1.39)
A9: Below the median of that fiscal year (paper text) | B9: =IF(Estimates!I262="","n/a",TEXT(Estimates!E262,"0.000")&IF(Estimates!I262<0.01,"***",IF(Estimates!I262<0.05,"**",IF(Estimates!I262<0.1,"*","")))) -> -0.254 | C9: =IF(Estimates!I263="","n/a",TEXT(Estimates!E263,"0.000")&IF(Estimates!I263<0.01,"***",IF(Estimates!I263<0.05,"**",IF(Estimates!I263<0.1,"*","")))) -> -0.492 | D9: =IF(Estimates!I264="","",Estimates!I264) -> 0.55205402 | E9: 1431 | G9: =IF(Estimates!I265="","n/a",TEXT(Estimates!E265,"0.000")&IF(Estimates!I265<0.01,"***",IF(Estimates!I265<0.05,"**",IF(Estimates!I265<0.1,"*","")))) -> -0.023 | H9: =IF(Estimates!I266="","n/a",TEXT(Estimates!E266,"0.000")&IF(Estimates!I266<0.01,"***",IF(Estimates!I266<0.05,"**",IF(Estimates!I266<0.1,"*","")))) -> -0.947* | I9: =IF(Estimates!I267="","",Estimates!I267) -> 0.061668275 | J9: 1278 | L9: 0.47 / 0.56 | M9: 0.45 / 0.50 / 0.44
B10: =IF(Estimates!H262="","","("&TEXT(Estimates!H262,"0.00")&")") -> (-1.16) | C10: =IF(Estimates!H263="","","("&TEXT(Estimates!H263,"0.00")&")") -> (-1.46) | G10: =IF(Estimates!H265="","","("&TEXT(Estimates!H265,"0.00")&")") -> (-0.12) | H10: =IF(Estimates!H266="","","("&TEXT(Estimates!H266,"0.00")&")") -> (-2.08)
A11: Below the pooled median of inflation-adjusted pay | B11: =IF(Estimates!I268="","n/a",TEXT(Estimates!E268,"0.000")&IF(Estimates!I268<0.01,"***",IF(Estimates!I268<0.05,"**",IF(Estimates!I268<0.1,"*","")))) -> -0.330 | C11: =IF(Estimates!I269="","n/a",TEXT(Estimates!E269,"0.000")&IF(Estimates!I269<0.01,"***",IF(Estimates!I269<0.05,"**",IF(Estimates!I269<0.1,"*","")))) -> -0.422 | D11: =IF(Estimates!I270="","",Estimates!I270) -> 0.81298991 | E11: 1431 | G11: =IF(Estimates!I271="","n/a",TEXT(Estimates!E271,"0.000")&IF(Estimates!I271<0.01,"***",IF(Estimates!I271<0.05,"**",IF(Estimates!I271<0.1,"*","")))) -> -0.162 | H11: =IF(Estimates!I272="","n/a",TEXT(Estimates!E272,"0.000")&IF(Estimates!I272<0.01,"***",IF(Estimates!I272<0.05,"**",IF(Estimates!I272<0.1,"*","")))) -> -0.667* | I11: =IF(Estimates!I273="","",Estimates!I273) -> 0.17720688 | J11: 1278 | L11: 0.48 / 0.52 | M11: 0.62 / 0.47 / 0.27
B12: =IF(Estimates!H268="","","("&TEXT(Estimates!H268,"0.00")&")") -> (-1.39) | C12: =IF(Estimates!H269="","","("&TEXT(Estimates!H269,"0.00")&")") -> (-1.37) | G12: =IF(Estimates!H271="","","("&TEXT(Estimates!H271,"0.00")&")") -> (-0.79) | H12: =IF(Estimates!H272="","","("&TEXT(Estimates!H272,"0.00")&")") -> (-1.80)
A13: Below the median pay given plan size (paper text) | B13: =IF(Estimates!I274="","n/a",TEXT(Estimates!E274,"0.000")&IF(Estimates!I274<0.01,"***",IF(Estimates!I274<0.05,"**",IF(Estimates!I274<0.1,"*","")))) -> -0.231 | C13: =IF(Estimates!I275="","n/a",TEXT(Estimates!E275,"0.000")&IF(Estimates!I275<0.01,"***",IF(Estimates!I275<0.05,"**",IF(Estimates!I275<0.1,"*","")))) -> -0.627 | D13: =IF(Estimates!I276="","",Estimates!I276) -> 0.40472635 | E13: 1431 | G13: =IF(Estimates!I277="","n/a",TEXT(Estimates!E277,"0.000")&IF(Estimates!I277<0.01,"***",IF(Estimates!I277<0.05,"**",IF(Estimates!I277<0.1,"*","")))) -> -0.117 | H13: =IF(Estimates!I278="","n/a",TEXT(Estimates!E278,"0.000")&IF(Estimates!I278<0.01,"***",IF(Estimates!I278<0.05,"**",IF(Estimates!I278<0.1,"*","")))) -> -0.800 | I13: =IF(Estimates!I279="","",Estimates!I279) -> 0.15870862 | J13: 1278 | L13: 0.46 / 0.56 | M13: 0.46 / 0.48 / 0.46
B14: =IF(Estimates!H274="","","("&TEXT(Estimates!H274,"0.00")&")") -> (-1.07) | C14: =IF(Estimates!H275="","","("&TEXT(Estimates!H275,"0.00")&")") -> (-1.57) | G14: =IF(Estimates!H277="","","("&TEXT(Estimates!H277,"0.00")&")") -> (-0.76) | H14: =IF(Estimates!H278="","","("&TEXT(Estimates!H278,"0.00")&")") -> (-1.68)
A15: Top third of pay that year vs. rest | B15: =IF(Estimates!I280="","n/a",TEXT(Estimates!E280,"0.000")&IF(Estimates!I280<0.01,"***",IF(Estimates!I280<0.05,"**",IF(Estimates!I280<0.1,"*","")))) -> -0.249 | C15: =IF(Estimates!I281="","n/a",TEXT(Estimates!E281,"0.000")&IF(Estimates!I281<0.01,"***",IF(Estimates!I281<0.05,"**",IF(Estimates!I281<0.1,"*","")))) -> -0.346 | D15: =IF(Estimates!I282="","",Estimates!I282) -> 0.83451248 | E15: 1431 | G15: =IF(Estimates!I283="","n/a",TEXT(Estimates!E283,"0.000")&IF(Estimates!I283<0.01,"***",IF(Estimates!I283<0.05,"**",IF(Estimates!I283<0.1,"*","")))) -> -0.250 | H15: =IF(Estimates!I284="","n/a",TEXT(Estimates!E284,"0.000")&IF(Estimates!I284<0.01,"***",IF(Estimates!I284<0.05,"**",IF(Estimates!I284<0.1,"*","")))) -> -0.487 | I15: =IF(Estimates!I285="","",Estimates!I285) -> 0.54297663 | J15: 1278 | L15: 0.63 / 0.74 | M15: 0.61 / 0.67 / 0.61
B16: =IF(Estimates!H280="","","("&TEXT(Estimates!H280,"0.00")&")") -> (-1.52) | C16: =IF(Estimates!H281="","","("&TEXT(Estimates!H281,"0.00")&")") -> (-0.73) | G16: =IF(Estimates!H283="","","("&TEXT(Estimates!H283,"0.00")&")") -> (-1.28) | H16: =IF(Estimates!H284="","","("&TEXT(Estimates!H284,"0.00")&")") -> (-1.31)
A17: Top quarter of pay that year vs. rest | B17: =IF(Estimates!I286="","n/a",TEXT(Estimates!E286,"0.000")&IF(Estimates!I286<0.01,"***",IF(Estimates!I286<0.05,"**",IF(Estimates!I286<0.1,"*","")))) -> -0.317 | C17: =IF(Estimates!I287="","n/a",TEXT(Estimates!E287,"0.000")&IF(Estimates!I287<0.01,"***",IF(Estimates!I287<0.05,"**",IF(Estimates!I287<0.1,"*","")))) -> -0.607 | D17: =IF(Estimates!I288="","",Estimates!I288) -> 0.51488494 | E17: 1431 | G17: =IF(Estimates!I289="","n/a",TEXT(Estimates!E289,"0.000")&IF(Estimates!I289<0.01,"***",IF(Estimates!I289<0.05,"**",IF(Estimates!I289<0.1,"*","")))) -> -0.375 | H17: =IF(Estimates!I290="","n/a",TEXT(Estimates!E290,"0.000")&IF(Estimates!I290<0.01,"***",IF(Estimates!I290<0.05,"**",IF(Estimates!I290<0.1,"*","")))) -> -0.546 | I17: =IF(Estimates!I291="","",Estimates!I291) -> 0.68954297 | J17: 1278 | L17: 0.73 / 0.82 | M17: 0.74 / 0.76 / 0.68
B18: =IF(Estimates!H286="","","("&TEXT(Estimates!H286,"0.00")&")") -> (-1.66) | C18: =IF(Estimates!H287="","","("&TEXT(Estimates!H287,"0.00")&")") -> (-1.41) | G18: =IF(Estimates!H289="","","("&TEXT(Estimates!H289,"0.00")&")") -> (-1.61) | H18: =IF(Estimates!H290="","","("&TEXT(Estimates!H290,"0.00")&")") -> (-1.33)
A19: Bottom third of pay that year vs. rest | B19: =IF(Estimates!I292="","n/a",TEXT(Estimates!E292,"0.000")&IF(Estimates!I292<0.01,"***",IF(Estimates!I292<0.05,"**",IF(Estimates!I292<0.1,"*","")))) -> -0.146 | C19: =IF(Estimates!I293="","n/a",TEXT(Estimates!E293,"0.000")&IF(Estimates!I293<0.01,"***",IF(Estimates!I293<0.05,"**",IF(Estimates!I293<0.1,"*","")))) -> -0.525* | D19: =IF(Estimates!I294="","",Estimates!I294) -> 0.35181479 | E19: 1431 | G19: =IF(Estimates!I295="","n/a",TEXT(Estimates!E295,"0.000")&IF(Estimates!I295<0.01,"***",IF(Estimates!I295<0.05,"**",IF(Estimates!I295<0.1,"*","")))) -> -0.197 | H19: =IF(Estimates!I296="","n/a",TEXT(Estimates!E296,"0.000")&IF(Estimates!I296<0.01,"***",IF(Estimates!I296<0.05,"**",IF(Estimates!I296<0.1,"*","")))) -> -0.552 | I19: =IF(Estimates!I297="","",Estimates!I297) -> 0.410203 | J19: 1278 | L19: 0.28 / 0.36 | M19: 0.27 / 0.31 / 0.25
B20: =IF(Estimates!H292="","","("&TEXT(Estimates!H292,"0.00")&")") -> (-0.50) | C20: =IF(Estimates!H293="","","("&TEXT(Estimates!H293,"0.00")&")") -> (-2.05) | G20: =IF(Estimates!H295="","","("&TEXT(Estimates!H295,"0.00")&")") -> (-0.85) | H20: =IF(Estimates!H296="","","("&TEXT(Estimates!H296,"0.00")&")") -> (-1.62)
A23: Panel B. Paper controls, year FE (published specification)
B24: Peer-Adjusted Return (t) | G24: Benchmark-Adjusted Return, Updated Benchmark (t)
A25: Definition of the lower-paid group | B25: Lower-paid x Conflicted | C25: Higher-paid x Conflicted | D25: p-value equal | E25: Obs. | G25: Lower-paid x Conflicted | H25: Higher-paid x Conflicted | I25: p-value equal | J25: Obs. | L25: Share lower-paid (all / conflicted) | M25: Share lower-paid by period
A26: Below $224,578 (paper code: pooled 2009-14 median) | B26: =IF(Estimates!I298="","n/a",TEXT(Estimates!E298,"0.000")&IF(Estimates!I298<0.01,"***",IF(Estimates!I298<0.05,"**",IF(Estimates!I298<0.1,"*","")))) -> -0.867*** | C26: =IF(Estimates!I299="","n/a",TEXT(Estimates!E299,"0.000")&IF(Estimates!I299<0.01,"***",IF(Estimates!I299<0.05,"**",IF(Estimates!I299<0.1,"*","")))) -> -0.076 | D26: =IF(Estimates!I300="","",Estimates!I300) -> 0.019236452 | E26: 1313 | G26: =IF(Estimates!I301="","n/a",TEXT(Estimates!E301,"0.000")&IF(Estimates!I301<0.01,"***",IF(Estimates!I301<0.05,"**",IF(Estimates!I301<0.1,"*","")))) -> -0.795*** | H26: =IF(Estimates!I302="","n/a",TEXT(Estimates!E302,"0.000")&IF(Estimates!I302<0.01,"***",IF(Estimates!I302<0.05,"**",IF(Estimates!I302<0.1,"*","")))) -> -0.071 | I26: =IF(Estimates!I303="","",Estimates!I303) -> 0.028543039 | J26: 1179 | L26: 0.53 / 0.64 | M26: 0.73 / 0.47 / 0.27
B27: =IF(Estimates!H298="","","("&TEXT(Estimates!H298,"0.00")&")") -> (-4.45) | C27: =IF(Estimates!H299="","","("&TEXT(Estimates!H299,"0.00")&")") -> (-0.34) | G27: =IF(Estimates!H301="","","("&TEXT(Estimates!H301,"0.00")&")") -> (-3.83) | H27: =IF(Estimates!H302="","","("&TEXT(Estimates!H302,"0.00")&")") -> (-0.35)
A28: Below the median of that fiscal year (paper text) | B28: =IF(Estimates!I304="","n/a",TEXT(Estimates!E304,"0.000")&IF(Estimates!I304<0.01,"***",IF(Estimates!I304<0.05,"**",IF(Estimates!I304<0.1,"*","")))) -> -0.413* | C28: =IF(Estimates!I305="","n/a",TEXT(Estimates!E305,"0.000")&IF(Estimates!I305<0.01,"***",IF(Estimates!I305<0.05,"**",IF(Estimates!I305<0.1,"*","")))) -> -0.243 | D28: =IF(Estimates!I306="","",Estimates!I306) -> 0.60654049 | E28: 1313 | G28: =IF(Estimates!I307="","n/a",TEXT(Estimates!E307,"0.000")&IF(Estimates!I307<0.01,"***",IF(Estimates!I307<0.05,"**",IF(Estimates!I307<0.1,"*","")))) -> -0.131 | H28: =IF(Estimates!I308="","n/a",TEXT(Estimates!E308,"0.000")&IF(Estimates!I308<0.01,"***",IF(Estimates!I308<0.05,"**",IF(Estimates!I308<0.1,"*","")))) -> -0.384 | I28: =IF(Estimates!I309="","",Estimates!I309) -> 0.52280464 | J28: 1179 | L28: 0.47 / 0.56 | M28: 0.45 / 0.50 / 0.44
B29: =IF(Estimates!H304="","","("&TEXT(Estimates!H304,"0.00")&")") -> (-1.78) | C29: =IF(Estimates!H305="","","("&TEXT(Estimates!H305,"0.00")&")") -> (-1.01) | G29: =IF(Estimates!H307="","","("&TEXT(Estimates!H307,"0.00")&")") -> (-0.44) | H29: =IF(Estimates!H308="","","("&TEXT(Estimates!H308,"0.00")&")") -> (-1.61)
A30: Below the pooled median of inflation-adjusted pay | B30: =IF(Estimates!I310="","n/a",TEXT(Estimates!E310,"0.000")&IF(Estimates!I310<0.01,"***",IF(Estimates!I310<0.05,"**",IF(Estimates!I310<0.1,"*","")))) -> -0.719*** | C30: =IF(Estimates!I311="","n/a",TEXT(Estimates!E311,"0.000")&IF(Estimates!I311<0.01,"***",IF(Estimates!I311<0.05,"**",IF(Estimates!I311<0.1,"*","")))) -> -0.231 | D30: =IF(Estimates!I312="","",Estimates!I312) -> 0.042105606 | E30: 1313 | G30: =IF(Estimates!I313="","n/a",TEXT(Estimates!E313,"0.000")&IF(Estimates!I313<0.01,"***",IF(Estimates!I313<0.05,"**",IF(Estimates!I313<0.1,"*","")))) -> -0.534** | H30: =IF(Estimates!I314="","n/a",TEXT(Estimates!E314,"0.000")&IF(Estimates!I314<0.01,"***",IF(Estimates!I314<0.05,"**",IF(Estimates!I314<0.1,"*","")))) -> -0.165 | I30: =IF(Estimates!I315="","",Estimates!I315) -> 0.17279722 | J30: 1179 | L30: 0.48 / 0.52 | M30: 0.62 / 0.47 / 0.27
B31: =IF(Estimates!H310="","","("&TEXT(Estimates!H310,"0.00")&")") -> (-3.85) | C31: =IF(Estimates!H311="","","("&TEXT(Estimates!H311,"0.00")&")") -> (-1.15) | G31: =IF(Estimates!H313="","","("&TEXT(Estimates!H313,"0.00")&")") -> (-2.33) | H31: =IF(Estimates!H314="","","("&TEXT(Estimates!H314,"0.00")&")") -> (-0.96)
A32: Below the median pay given plan size (paper text) | B32: =IF(Estimates!I316="","n/a",TEXT(Estimates!E316,"0.000")&IF(Estimates!I316<0.01,"***",IF(Estimates!I316<0.05,"**",IF(Estimates!I316<0.1,"*","")))) -> -0.395** | C32: =IF(Estimates!I317="","n/a",TEXT(Estimates!E317,"0.000")&IF(Estimates!I317<0.01,"***",IF(Estimates!I317<0.05,"**",IF(Estimates!I317<0.1,"*","")))) -> -0.627** | D32: =IF(Estimates!I318="","",Estimates!I318) -> 0.45624068 | E32: 1313 | G32: =IF(Estimates!I319="","n/a",TEXT(Estimates!E319,"0.000")&IF(Estimates!I319<0.01,"***",IF(Estimates!I319<0.05,"**",IF(Estimates!I319<0.1,"*","")))) -> -0.375 | H32: =IF(Estimates!I320="","n/a",TEXT(Estimates!E320,"0.000")&IF(Estimates!I320<0.01,"***",IF(Estimates!I320<0.05,"**",IF(Estimates!I320<0.1,"*","")))) -> -0.407 | I32: =IF(Estimates!I321="","",Estimates!I321) -> 0.95102682 | J32: 1179 | L32: 0.46 / 0.56 | M32: 0.46 / 0.48 / 0.46
B33: =IF(Estimates!H316="","","("&TEXT(Estimates!H316,"0.00")&")") -> (-2.42) | C33: =IF(Estimates!H317="","","("&TEXT(Estimates!H317,"0.00")&")") -> (-2.61) | G33: =IF(Estimates!H319="","","("&TEXT(Estimates!H319,"0.00")&")") -> (-1.20) | H33: =IF(Estimates!H320="","","("&TEXT(Estimates!H320,"0.00")&")") -> (-1.45)
A34: Top third of pay that year vs. rest | B34: =IF(Estimates!I322="","n/a",TEXT(Estimates!E322,"0.000")&IF(Estimates!I322<0.01,"***",IF(Estimates!I322<0.05,"**",IF(Estimates!I322<0.1,"*","")))) -> -0.321* | C34: =IF(Estimates!I323="","n/a",TEXT(Estimates!E323,"0.000")&IF(Estimates!I323<0.01,"***",IF(Estimates!I323<0.05,"**",IF(Estimates!I323<0.1,"*","")))) -> -0.378 | D34: =IF(Estimates!I324="","",Estimates!I324) -> 0.87222584 | E34: 1313 | G34: =IF(Estimates!I325="","n/a",TEXT(Estimates!E325,"0.000")&IF(Estimates!I325<0.01,"***",IF(Estimates!I325<0.05,"**",IF(Estimates!I325<0.1,"*","")))) -> -0.370* | H34: =IF(Estimates!I326="","n/a",TEXT(Estimates!E326,"0.000")&IF(Estimates!I326<0.01,"***",IF(Estimates!I326<0.05,"**",IF(Estimates!I326<0.1,"*","")))) -> -0.208 | I34: =IF(Estimates!I327="","",Estimates!I327) -> 0.69968635 | J34: 1179 | L34: 0.63 / 0.74 | M34: 0.61 / 0.67 / 0.61
B35: =IF(Estimates!H322="","","("&TEXT(Estimates!H322,"0.00")&")") -> (-1.87) | C35: =IF(Estimates!H323="","","("&TEXT(Estimates!H323,"0.00")&")") -> (-1.21) | G35: =IF(Estimates!H325="","","("&TEXT(Estimates!H325,"0.00")&")") -> (-1.99) | H35: =IF(Estimates!H326="","","("&TEXT(Estimates!H326,"0.00")&")") -> (-0.60)
A36: Top quarter of pay that year vs. rest | B36: =IF(Estimates!I328="","n/a",TEXT(Estimates!E328,"0.000")&IF(Estimates!I328<0.01,"***",IF(Estimates!I328<0.05,"**",IF(Estimates!I328<0.1,"*","")))) -> -0.366** | C36: =IF(Estimates!I329="","n/a",TEXT(Estimates!E329,"0.000")&IF(Estimates!I329<0.01,"***",IF(Estimates!I329<0.05,"**",IF(Estimates!I329<0.1,"*","")))) -> -0.407 | D36: =IF(Estimates!I330="","",Estimates!I330) -> 0.90928508 | E36: 1313 | G36: =IF(Estimates!I331="","n/a",TEXT(Estimates!E331,"0.000")&IF(Estimates!I331<0.01,"***",IF(Estimates!I331<0.05,"**",IF(Estimates!I331<0.1,"*","")))) -> -0.445*** | H36: =IF(Estimates!I332="","n/a",TEXT(Estimates!E332,"0.000")&IF(Estimates!I332<0.01,"***",IF(Estimates!I332<0.05,"**",IF(Estimates!I332<0.1,"*","")))) -> -0.281 | I36: =IF(Estimates!I333="","",Estimates!I333) -> 0.69611179 | J36: 1179 | L36: 0.73 / 0.82 | M36: 0.74 / 0.76 / 0.68
B37: =IF(Estimates!H328="","","("&TEXT(Estimates!H328,"0.00")&")") -> (-2.33) | C37: =IF(Estimates!H329="","","("&TEXT(Estimates!H329,"0.00")&")") -> (-1.41) | G37: =IF(Estimates!H331="","","("&TEXT(Estimates!H331,"0.00")&")") -> (-2.89) | H37: =IF(Estimates!H332="","","("&TEXT(Estimates!H332,"0.00")&")") -> (-0.70)
A38: Bottom third of pay that year vs. rest | B38: =IF(Estimates!I334="","n/a",TEXT(Estimates!E334,"0.000")&IF(Estimates!I334<0.01,"***",IF(Estimates!I334<0.05,"**",IF(Estimates!I334<0.1,"*","")))) -> -0.515 | C38: =IF(Estimates!I335="","n/a",TEXT(Estimates!E335,"0.000")&IF(Estimates!I335<0.01,"***",IF(Estimates!I335<0.05,"**",IF(Estimates!I335<0.1,"*","")))) -> -0.401** | D38: =IF(Estimates!I336="","",Estimates!I336) -> 0.83221992 | E38: 1313 | G38: =IF(Estimates!I337="","n/a",TEXT(Estimates!E337,"0.000")&IF(Estimates!I337<0.01,"***",IF(Estimates!I337<0.05,"**",IF(Estimates!I337<0.1,"*","")))) -> -0.444 | H38: =IF(Estimates!I338="","n/a",TEXT(Estimates!E338,"0.000")&IF(Estimates!I338<0.01,"***",IF(Estimates!I338<0.05,"**",IF(Estimates!I338<0.1,"*","")))) -> -0.221 | I38: =IF(Estimates!I339="","",Estimates!I339) -> 0.65057279 | J38: 1179 | L38: 0.28 / 0.36 | M38: 0.27 / 0.31 / 0.25
B39: =IF(Estimates!H334="","","("&TEXT(Estimates!H334,"0.00")&")") -> (-1.02) | C39: =IF(Estimates!H335="","","("&TEXT(Estimates!H335,"0.00")&")") -> (-2.40) | G39: =IF(Estimates!H337="","","("&TEXT(Estimates!H337,"0.00")&")") -> (-1.13) | H39: =IF(Estimates!H338="","","("&TEXT(Estimates!H338,"0.00")&")") -> (-1.20)

Sheet Period split
A1: Effect of Conflict in 2001-2008 and 2009-2020
A2: Each regression interacts Conflicted CIO and the control variables with an indicator for fiscal years 2001-2008, as in the cross-sectional splits. The first specification uses the narrow controls with fiscal-year-end date fixed effects; the second uses the paper's controls for the Underpaid split with year fixed effects. The sample has 192 conflicted plan-years (32 CIOs) in 2001-2008 and 175 (27 CIOs) in 2009-2020. Benchmark-Adjusted Return is the plan's return minus the updated policy benchmark (reported in the plan's financial report or, where none is stated, an inferred value graded A or B). The p-value row tests that the two Conflicted CIO coefficients are equal. The standard errors are double clustered by plan and year (plan and fiscal-year-end date for the financial-center split). Coefficients marked with ***, **, and * are significant at the 1%, 5%, and 10% level, respectively.
B4: Peer-Adjusted Return (t) | G4: Benchmark-Adjusted Return, Updated Benchmark (t)
A5: Specification | B5: 2001-2008 x Conflicted | C5: 2009-2020 x Conflicted | D5: p-value equal | E5: Obs. | G5: 2001-2008 x Conflicted | H5: 2009-2020 x Conflicted | I5: p-value equal | J5: Obs.
A6: Narrow controls, fiscal-year-end FE | B6: =IF(Estimates!I340="","n/a",TEXT(Estimates!E340,"0.000")&IF(Estimates!I340<0.01,"***",IF(Estimates!I340<0.05,"**",IF(Estimates!I340<0.1,"*","")))) -> -1.000*** | C6: =IF(Estimates!I341="","n/a",TEXT(Estimates!E341,"0.000")&IF(Estimates!I341<0.01,"***",IF(Estimates!I341<0.05,"**",IF(Estimates!I341<0.1,"*","")))) -> -0.325 | D6: =IF(Estimates!I342="","",Estimates!I342) -> 0.044219635 | E6: 1723 | G6: =IF(Estimates!I343="","n/a",TEXT(Estimates!E343,"0.000")&IF(Estimates!I343<0.01,"***",IF(Estimates!I343<0.05,"**",IF(Estimates!I343<0.1,"*","")))) -> -0.850*** | H6: =IF(Estimates!I344="","n/a",TEXT(Estimates!E344,"0.000")&IF(Estimates!I344<0.01,"***",IF(Estimates!I344<0.05,"**",IF(Estimates!I344<0.1,"*","")))) -> -0.255 | I6: =IF(Estimates!I345="","",Estimates!I345) -> 0.091801817 | J6: 1532
B7: =IF(Estimates!H340="","","("&TEXT(Estimates!H340,"0.00")&")") -> (-6.01) | C7: =IF(Estimates!H341="","","("&TEXT(Estimates!H341,"0.00")&")") -> (-1.31) | G7: =IF(Estimates!H343="","","("&TEXT(Estimates!H343,"0.00")&")") -> (-4.81) | H7: =IF(Estimates!H344="","","("&TEXT(Estimates!H344,"0.00")&")") -> (-0.94)
A8: Paper controls, year FE (published specification) | B8: =IF(Estimates!I346="","n/a",TEXT(Estimates!E346,"0.000")&IF(Estimates!I346<0.01,"***",IF(Estimates!I346<0.05,"**",IF(Estimates!I346<0.1,"*","")))) -> -1.191*** | C8: =IF(Estimates!I347="","n/a",TEXT(Estimates!E347,"0.000")&IF(Estimates!I347<0.01,"***",IF(Estimates!I347<0.05,"**",IF(Estimates!I347<0.1,"*","")))) -> -0.054 | D8: =IF(Estimates!I348="","",Estimates!I348) -> 0.0042486231 | E8: 1566 | G8: =IF(Estimates!I349="","n/a",TEXT(Estimates!E349,"0.000")&IF(Estimates!I349<0.01,"***",IF(Estimates!I349<0.05,"**",IF(Estimates!I349<0.1,"*","")))) -> -0.774*** | H8: =IF(Estimates!I350="","n/a",TEXT(Estimates!E350,"0.000")&IF(Estimates!I350<0.01,"***",IF(Estimates!I350<0.05,"**",IF(Estimates!I350<0.1,"*","")))) -> -0.032 | I8: =IF(Estimates!I351="","",Estimates!I351) -> 0.0055065929 | J8: 1395
B9: =IF(Estimates!H346="","","("&TEXT(Estimates!H346,"0.00")&")") -> (-4.17) | C9: =IF(Estimates!H347="","","("&TEXT(Estimates!H347,"0.00")&")") -> (-0.38) | G9: =IF(Estimates!H349="","","("&TEXT(Estimates!H349,"0.00")&")") -> (-4.29) | H9: =IF(Estimates!H350="","","("&TEXT(Estimates!H350,"0.00")&")") -> (-0.24)

Sheet Log pay x time
A1: Log CIO Pay Interaction, Allowing the Effect of Conflict to Vary Over Time
A2: Each column re-estimates the Log CIO Total Comp. column of the interaction specification (xsec_interactions_fye1.xlsx: all Table III controls, fiscal-year-end date fixed effects, log pay in the same fiscal year centered at its regression-sample mean, plan-years with reported pay). Columns (2)-(4) add interactions of Conflicted CIO with an indicator for 2001-2008, a linear fiscal-year trend, or fiscal-year indicators (each centered), so that the effect of conflict may differ over time; in column (4) the log pay interaction is identified only from differences in pay among conflicted CIOs in the same fiscal year. Benchmark-Adjusted Return is the plan's return minus the updated policy benchmark (reported in the plan's financial report or, where none is stated, an inferred value graded A or B). The standard errors are double clustered by plan and year. Coefficients marked with ***, **, and * are significant at the 1%, 5%, and 10% level, respectively.
A4: Panel A. Peer-Adjusted Returns
B5: (1) Log pay (as in the Interactions sheet) | C5: (2) + Conflicted x 2001-2008 indicator | D5: (3) + Conflicted x linear year trend | E5: (4) + Conflicted x fiscal-year indicators
A6: Conflicted CIO (at mean log pay) | B6: =IF(Estimates!I352="","n/a",TEXT(Estimates!E352,"0.000")&IF(Estimates!I352<0.01,"***",IF(Estimates!I352<0.05,"**",IF(Estimates!I352<0.1,"*","")))) -> -0.295** | C6: =IF(Estimates!I353="","n/a",TEXT(Estimates!E353,"0.000")&IF(Estimates!I353<0.01,"***",IF(Estimates!I353<0.05,"**",IF(Estimates!I353<0.1,"*","")))) -> -0.257* | D6: =IF(Estimates!I354="","n/a",TEXT(Estimates!E354,"0.000")&IF(Estimates!I354<0.01,"***",IF(Estimates!I354<0.05,"**",IF(Estimates!I354<0.1,"*","")))) -> -0.275* | E6: =IF(Estimates!I355="","n/a",TEXT(Estimates!E355,"0.000")&IF(Estimates!I355<0.01,"***",IF(Estimates!I355<0.05,"**",IF(Estimates!I355<0.1,"*","")))) -> -0.173
B7: =IF(Estimates!H352="","","("&TEXT(Estimates!H352,"0.00")&")") -> (-2.13) | C7: =IF(Estimates!H353="","","("&TEXT(Estimates!H353,"0.00")&")") -> (-1.81) | D7: =IF(Estimates!H354="","","("&TEXT(Estimates!H354,"0.00")&")") -> (-1.96) | E7: =IF(Estimates!H355="","","("&TEXT(Estimates!H355,"0.00")&")") -> (-1.09)
